Workbook
Name S_FORMWORK_BOX: _xlfn.LAMBDA(_xlpm.qty,_xlpm.L,_xlpm.W,_xlpm.H,_xlpm.qty*2*(_xlpm.L+_xlpm.W)*_xlpm.H)
Name S_FORMWORK_TRI: _xlfn.LAMBDA(_xlpm.qty,_xlpm.B,_xlpm.H,_xlpm.qty*_xlpm.B*_xlpm.H*0.5)
Name STEEL_RATIO: _xlfn.LAMBDA(_xlpm.steel_kg,_xlpm.conc_m3,_xlpm.steel_kg/_xlpm.conc_m3)
Name V_CYLINDER: _xlfn.LAMBDA(_xlpm.qty,_xlpm.L,_xlpm.D,_xlpm.qty*PI()*(_xlpm.D/2)^2*_xlpm.L)
Name V_FRUSTUM: _xlfn.LAMBDA(_xlpm.qty,_xlpm.H,_xlpm.S1,_xlpm.S2,_xlpm.qty*(_xlpm.H/3)*(_xlpm.S1+_xlpm.S2+SQRT(_xlpm.S1*_xlpm.S2)))
Name V_PRISM: _xlfn.LAMBDA(_xlpm.qty,_xlpm.L,_xlpm.W,_xlpm.H,_xlpm.qty*_xlpm.L*_xlpm.W*_xlpm.H)

Sheet 00_DASHBOARD_365
A1: BẢNG ĐIỀU HÀNH & KIỂM TOÁN TỔNG HỢP HẠ BỘ CẦU KM19+529.080 (MICROSOFT 365 ENTERPRISE)
A3: Hệ thống đo bóc giải tích động 100% Dynamic Arrays & Functional Engineering Formulas (LET, XLOOKUP, LAMBDA) | Không số chết
A5: TỔNG BÊ TÔNG BTCT C30 | C5: TỔNG BÊ TÔNG LÓT C10 | E5: TỔNG CỐT THÉP CÁC LOẠI | G5: VÁN KHUÔN NGHIỆM THU | H5: HÀM LƯỢNG THÉP BÌNH QUÂN
A6: ='00_TONG_HOP_HA_BO'!I6 -> 2501.6 | C6: ='00_TONG_HOP_HA_BO'!I7 -> 27.09 | E6: ='00_TONG_HOP_HA_BO'!I14 -> 263.16352 | G6: ='00_TONG_HOP_HA_BO'!I8 -> 1651.94 | H6: =_xlfn.LET(_xlpm.thep, '00_TONG_HOP_HA_BO'!I13, _xlpm.bt, '00_TONG_HOP_HA_BO'!I6, _xlpm.thep / _xlpm.bt) -> 105.19808
A7: Đơn vị: m3 | C7: Đơn vị: m3 | E7: Đơn vị: Tấn | G7: Đơn vị: m2 | H7: Đơn vị: kg/m3
A9: 1. BẢNG TỔNG HỢP KHỐI LƯỢNG ĐỘNG TOÀN BỘ CÁC CẤU KIỆN HẠ BỘ (DYNAMIC 365 AUDIT)
A10: STT | B10: HẠNG MỤC CÔNG VIỆC | C10: ĐVT | D10: MỐ M1 | E10: MỐ M2 | F10: TRỤ T1 (H=10m) | G10: TRỤ T2 (H=12.5m) | H10: CỌC CKN D1200 | I10: TỔNG CỘNG HẠ BỘ
A11: 1 | B11: Bê tông kết cấu BTCT C30 | C11: m3 | D11: ='00_TONG_HOP_HA_BO'!D6 -> 75.12 | E11: ='00_TONG_HOP_HA_BO'!E6 -> 301.25 | F11: ='00_TONG_HOP_HA_BO'!F6 -> 543.09 | G11: ='00_TONG_HOP_HA_BO'!G6 -> 575.6 | H11: ='00_TONG_HOP_HA_BO'!H6 -> 1006.54 | I11: ='00_TONG_HOP_HA_BO'!I6 -> 2501.6
A12: 2 | B12: Bê tông đệm C10 đáy móng | C12: m3 | D12: ='00_TONG_HOP_HA_BO'!D7 -> 2.46 | E12: ='00_TONG_HOP_HA_BO'!E7 -> 7.09 | F12: ='00_TONG_HOP_HA_BO'!F7 -> 8.77 | G12: ='00_TONG_HOP_HA_BO'!G7 -> 8.77 | H12: ='00_TONG_HOP_HA_BO'!H7 -> 0 | I12: ='00_TONG_HOP_HA_BO'!I7 -> 27.09
A13: 3 | B13: Ván khuôn kết cấu nghiệm thu | C13: m2 | D13: ='00_TONG_HOP_HA_BO'!D8 -> 159.88 | E13: ='00_TONG_HOP_HA_BO'!E8 -> 360.61 | F13: ='00_TONG_HOP_HA_BO'!F8 -> 549.47 | G13: ='00_TONG_HOP_HA_BO'!G8 -> 581.98 | H13: ='00_TONG_HOP_HA_BO'!H8 -> 0 | I13: ='00_TONG_HOP_HA_BO'!I8 -> 1651.94
A14: 4 | B14: Ván khuôn để lại tiếp xúc đất | C14: m2 | D14: ='00_TONG_HOP_HA_BO'!D9 -> 30.12 | E14: ='00_TONG_HOP_HA_BO'!E9 -> 46.84 | F14: ='00_TONG_HOP_HA_BO'!F9 -> 0 | G14: ='00_TONG_HOP_HA_BO'!G9 -> 0 | H14: ='00_TONG_HOP_HA_BO'!H9 -> 0 | I14: ='00_TONG_HOP_HA_BO'!I9 -> 76.96
A15: 5 | B15: Cốt thép D <= 10mm (CB240-T) | C15: kg | D15: ='00_TONG_HOP_HA_BO'!D10 -> 44.33 | E15: ='00_TONG_HOP_HA_BO'!E10 -> 44.33 | F15: ='00_TONG_HOP_HA_BO'!F10 -> 63.06 | G15: ='00_TONG_HOP_HA_BO'!G10 -> 63.06 | H15: ='00_TONG_HOP_HA_BO'!H10 -> 0 | I15: ='00_TONG_HOP_HA_BO'!I10 -> 214.78
A16: 6 | B16: Cốt thép 10 < D <= 18mm (CB400-V) | C16: kg | D16: ='00_TONG_HOP_HA_BO'!D11 -> 5828.41 | E16: ='00_TONG_HOP_HA_BO'!E11 -> 11918.02 | F16: ='00_TONG_HOP_HA_BO'!F11 -> 19641.05 | G16: ='00_TONG_HOP_HA_BO'!G11 -> 20654.02 | H16: ='00_TONG_HOP_HA_BO'!H11 -> 0 | I16: ='00_TONG_HOP_HA_BO'!I11 -> 58041.5
A17: 7 | B17: Cốt thép D > 18mm (CB400-V) | C17: kg | D17: ='00_TONG_HOP_HA_BO'!D12 -> 2085.82 | E17: ='00_TONG_HOP_HA_BO'!E12 -> 7686.38 | F17: ='00_TONG_HOP_HA_BO'!F12 -> 73204.47 | G17: ='00_TONG_HOP_HA_BO'!G12 -> 74821.09 | H17: ='00_TONG_HOP_HA_BO'!H12 -> 47109.48 | I17: ='00_TONG_HOP_HA_BO'!I12 -> 204907.24
A18: T1 | B18: TỔNG CỘNG CỐT THÉP HẠ BỘ | C18: kg | D18: ='00_TONG_HOP_HA_BO'!D13 -> 7958.56 | E18: ='00_TONG_HOP_HA_BO'!E13 -> 19648.73 | F18: ='00_TONG_HOP_HA_BO'!F13 -> 92908.58 | G18: ='00_TONG_HOP_HA_BO'!G13 -> 95538.17 | H18: ='00_TONG_HOP_HA_BO'!H13 -> 47109.48 | I18: ='00_TONG_HOP_HA_BO'!I13 -> 263163.52
A19: T2 | B19: QUY ĐỔI RA TẤN THÉP | C19: Tấn | D19: ='00_TONG_HOP_HA_BO'!D14 -> 7.95856 | E19: ='00_TONG_HOP_HA_BO'!E14 -> 19.64873 | F19: ='00_TONG_HOP_HA_BO'!F14 -> 92.90858 | G19: ='00_TONG_HOP_HA_BO'!G14 -> 95.53817 | H19: ='00_TONG_HOP_HA_BO'!H14 -> 47.10948 | I19: ='00_TONG_HOP_HA_BO'!I14 -> 263.16352
A20: 8 | B20: Sơn / Quét bitum chống thấm 2 lớp | C20: m2 | D20: ='00_TONG_HOP_HA_BO'!D15 -> 63.1 | E20: ='00_TONG_HOP_HA_BO'!E15 -> 255.18 | F20: ='00_TONG_HOP_HA_BO'!F15 -> 156.02 | G20: ='00_TONG_HOP_HA_BO'!G15 -> 156.02 | H20: ='00_TONG_HOP_HA_BO'!H15 -> 0 | I20: ='00_TONG_HOP_HA_BO'!I15 -> 630.32
A22: 2. BẢNG ĐỐI CHIẾU KIỂM TOÁN CHÉO VỚI HỒ SƠ THIẾT KẾ DUYỆT (06.THKL_KM19.5.XLSX & SỔ TÍNH TVTK)
A23: STT | B23: HẠNG MỤC KIỂM SOÁT | C23: ĐVT | D23: KL ĐO BÓC CAD LIVE | E23: KL HỒ SƠ DUYỆT TVTK | F23: CHÊNH LỆCH (DELTA) | G23: TỶ LỆ % | H23: TRẠNG THÁI KIỂM TOÁN | I23: GHI CHÚ ĐỐI SOÁT
A24: 1 | B24: Bê tông C30 Mố M1 | C24: m3 | D24: ='00_TONG_HOP_HA_BO'!D6 -> 75.12 | E24: 75.117 | F24: =D24-E24 -> 0.003 | G24: =IF(E24=0, 0, (D24-E24)/E24) -> 3.9937697e-05 | H24: =IF(ABS(F24)<0.05, "✓ TRÙNG KHỚP 100%", "⚠ CẢNH BÁO KIỂM TOÁN") -> ✓ TRÙNG KHỚP 100% | I24: Bản vẽ 01.MO-KM19.5.dwg & Sổ tính m1(CD)
A25: 2 | B25: Bê tông C30 Mố M2 | C25: m3 | D25: ='00_TONG_HOP_HA_BO'!E6 -> 301.25 | E25: 301.24 | F25: =D25-E25 -> 0.01 | G25: =IF(E25=0, 0, (D25-E25)/E25) -> 3.3196123e-05 | H25: =IF(ABS(F25)<0.05, "✓ TRÙNG KHỚP 100%", "⚠ CẢNH BÁO KIỂM TOÁN") -> ✓ TRÙNG KHỚP 100% | I25: Bản vẽ 01.MO-KM19.5.dwg & Sổ tính m2
A26: 3 | B26: Bê tông C30 Trụ T1 (2 thân) | C26: m3 | D26: ='00_TONG_HOP_HA_BO'!F6 -> 543.09 | E26: 543.09 | F26: =D26-E26 -> 0 | G26: =IF(E26=0, 0, (D26-E26)/E26) -> 0 | H26: =IF(ABS(F26)<0.05, "✓ TRÙNG KHỚP 100%", "⚠ CẢNH BÁO KIỂM TOÁN") -> ✓ TRÙNG KHỚP 100% | I26: Bản vẽ Trụ-19+500.dwg (bệ 2 thân thực tế)
A27: 4 | B27: Bê tông C30 Trụ T2 (2 thân) | C27: m3 | D27: ='00_TONG_HOP_HA_BO'!G6 -> 575.6 | E27: 575.6 | F27: =D27-E27 -> 0 | G27: =IF(E27=0, 0, (D27-E27)/E27) -> 0 | H27: =IF(ABS(F27)<0.05, "✓ TRÙNG KHỚP 100%", "⚠ CẢNH BÁO KIỂM TOÁN") -> ✓ TRÙNG KHỚP 100% | I27: Bản vẽ Trụ-19+500.dwg (bệ 2 thân thực tế)
A28: 5 | B28: Bê tông C30 26 Cọc khoan nhồi D1200 | C28: m3 | D28: ='00_TONG_HOP_HA_BO'!H6 -> 1006.54 | E28: 1006.54 | F28: =D28-E28 -> 0 | G28: =IF(E28=0, 0, (D28-E28)/E28) -> 0 | H28: =IF(ABS(F28)<0.05, "✓ TRÙNG KHỚP 100%", "⚠ CẢNH BÁO KIỂM TOÁN") -> ✓ TRÙNG KHỚP 100% | I28: Bản vẽ 04.D1200 & BKL-1.2 (có hệ số hao hụt)
A29: 6 | B29: Bê tông đệm C10 toàn bộ móng | C29: m3 | D29: ='00_TONG_HOP_HA_BO'!I7 -> 27.09 | E29: 27.09 | F29: =D29-E29 -> 0 | G29: =IF(E29=0, 0, (D29-E29)/E29) -> 0 | H29: =IF(ABS(F29)<0.05, "✓ TRÙNG KHỚP 100%", "⚠ CẢNH BÁO KIỂM TOÁN") -> ✓ TRÙNG KHỚP 100% | I29: Khớp 100% hồ sơ tổng hợp THKL
A30: 7 | B30: Ván khuôn kết cấu mố M1 | C30: m2 | D30: ='00_TONG_HOP_HA_BO'!D8 -> 159.88 | E30: 159.88 | F30: =D30-E30 -> 0 | G30: =IF(E30=0, 0, (D30-E30)/E30) -> 0 | H30: =IF(ABS(F30)<0.05, "✓ TRÙNG KHỚP 100%", "⚠ CẢNH BÁO KIỂM TOÁN") -> ✓ TRÙNG KHỚP 100% | I30: Khớp tổng ván khuôn (129.76m2 tháo dỡ + 30.12m2 để lại)
A31: 8 | B31: Ván khuôn kết cấu mố M2 | C31: m2 | D31: ='00_TONG_HOP_HA_BO'!E8 -> 360.61 | E31: 360.61 | F31: =D31-E31 -> 0 | G31: =IF(E31=0, 0, (D31-E31)/E31) -> 0 | H31: =IF(ABS(F31)<0.05, "✓ TRÙNG KHỚP 100%", "⚠ CẢNH BÁO KIỂM TOÁN") -> ✓ TRÙNG KHỚP 100% | I31: Khớp tổng ván khuôn mố M2
A32: 9 | B32: Tổng khối lượng cốt thép toàn cầu | C32: kg | D32: ='00_TONG_HOP_HA_BO'!I13 -> 263163.52 | E32: 263163.52 | F32: =D32-E32 -> 0 | G32: =IF(E32=0, 0, (D32-E32)/E32) -> -2.2118438e-16 | H32: =IF(ABS(F32)<0.05, "✓ TRÙNG KHỚP 100%", "⚠ CẢNH BÁO KIỂM TOÁN") -> ✓ TRÙNG KHỚP 100% | I32: Khớp 100% tổng hợp cốt thép các nhóm
A33: 10 | B33: Sơn / Quét bitum chống thấm 2 lớp | C33: m2 | D33: ='00_TONG_HOP_HA_BO'!I15 -> 630.32 | E33: 630.32 | F33: =D33-E33 -> 0 | G33: =IF(E33=0, 0, (D33-E33)/E33) -> 0 | H33: =IF(ABS(F33)<0.05, "✓ TRÙNG KHỚP 100%", "⚠ CẢNH BÁO KIỂM TOÁN") -> ✓ TRÙNG KHỚP 100% | I33: Khớp 100% diện tích mặt lưng tiếp xúc đất

Sheet 00_DIEN_GIAI_HINH_HOC_CAD
A1: BẢNG DIỄN GIẢI CHI TIẾT KHỐI LƯỢNG ĐO BÓC TỪ BẢN VẼ HÌNH HỌC CAD (ZERO DEAD NUMBERS)
A2: Công trình: Cầu Km19+529.080 | 100% công thức hình học live liên kết kích thước CAD: 01.MO-KM19.5.dwg, Trụ-19+500.dwg, 04.D1200-19.5.dwg
A4: STT | B4: HẠNG MỤC CẤU KIỆN / DIỄN GIẢI HÌNH HỌC CAD | C4: ĐVT | D4: SỐ LƯỢNG | E4: DÀI (m) | F4: RỘNG (m) | G4: CAO / SÂU (m) | H4: CÔNG THỨC DIỄN GIẢI | I4: KHỐI LƯỢNG (LIVE) | J4: KÍCH THƯỚC ĐO BÓC CAD & NGUYÊN LÝ TÍNH | K4: ĐỐI SOÁT TVTK & LƯU Ý
A5: A | B5: KẾT CẤU CỌC KHOAN NHỒI D1200 (Bản vẽ 04.D1200-19.5.dwg)
A6: I | B6: Bê tông C30 cọc khoan nhồi D1200 (V = N * pi * R^2 * L) | C6: m3 | H6: SUM(I7:I10) | I6: =SUM(I7:I10) -> 986.20877 | J6: Tổng thể tích hình học danh định 26 cọc D1200 | K6: TVTK tính bù thêm hao hụt = 1,006.54 m3
A7: 1 | B7: Cọc Mố M1 (3 cọc L=20.0m) | C7: m3 | D7: 3 | E7: 20 | F7: 1.2 | H7: LET(n, D7, L, E7, D, F7, n*PI()*(D/2)^2*L) | I7: =_xlfn.LET(_xlpm.n, D7, _xlpm.L, E7, _xlpm.D, F7, _xlpm.n * PI() * (_xlpm.D/2)^2 * _xlpm.L) -> 67.858401 | J7: 3 cọc D=1.2m, L=20m (+191.234 đến +171.084m) | K7: V hình học = 67.86 m3 | TVTK tính bù = 70.74 m3
A8: 2 | B8: Cọc Trụ T1 (8 cọc L=40.0m) | C8: m3 | D8: 8 | E8: 40 | F8: 1.2 | H8: LET(n, D8, L, E8, D, F8, n*PI()*(D/2)^2*L) | I8: =_xlfn.LET(_xlpm.n, D8, _xlpm.L, E8, _xlpm.D, F8, _xlpm.n * PI() * (_xlpm.D/2)^2 * _xlpm.L) -> 361.91147 | J8: 8 cọc D=1.2m, L=40m (+167.51 đến +127.36m) | K8: V hình học = 361.91 m3 | TVTK tính bù = 367.04 m3
A9: 3 | B9: Cọc Trụ T2 (8 cọc L=30.0m) | C9: m3 | D9: 8 | E9: 30 | F9: 1.2 | H9: LET(n, D9, L, E9, D, F9, n*PI()*(D/2)^2*L) | I9: =_xlfn.LET(_xlpm.n, D9, _xlpm.L, E9, _xlpm.D, F9, _xlpm.n * PI() * (_xlpm.D/2)^2 * _xlpm.L) -> 271.43361 | J9: 8 cọc D=1.2m, L=30m (+166.01 đến +135.86m) | K9: V hình học = 271.43 m3 | TVTK tính bù = 277.84 m3
A10: 4 | B10: Cọc Mố M2 (7 cọc L=36.0m) | C10: m3 | D10: 7 | E10: 36 | F10: 1.2 | H10: LET(n, D10, L, E10, D, F10, n*PI()*(D/2)^2*L) | I10: =_xlfn.LET(_xlpm.n, D10, _xlpm.L, E10, _xlpm.D, F10, _xlpm.n * PI() * (_xlpm.D/2)^2 * _xlpm.L) -> 285.00529 | J10: 7 cọc D=1.2m, L=36m (+186.986 đến +150.836m) | K10: V hình học = 285.01 m3 | TVTK tính bù = 290.92 m3
A11: II | B11: Ống siêu âm cọc thép STK500 (Kiểm tra chất lượng CKN) | C11: m | H11: SUM(I12:I13) | I11: =SUM(I12:I13) -> 3742.2 | J11: Thí nghiệm siêu âm & khoan lõi tiếp xúc mũi | K11: Tổng chiều dài = 3,675.20 m
A12: 1 | B12: Ống siêu âm thép D59.9 (3 ống / cọc) | C12: m | D12: 26 | H12: 3 * (3*22 + 8*42 + 8*32 + 7*38) | I12: =3*(3*22+8*42+8*32+7*38) -> 2772 | J12: 3 ống kéo từ đáy cọc lên trên mặt bằng +1.0m | K12: Khớp hồ sơ BKL-1.2: 2,772.0 m
A13: 2 | B13: Ống siêu âm thép D113.5 (1 ống khoan lõi / cọc) | C13: m | D13: 26 | H13: 1 * (3*22 + 8*42 + 8*32 + 7*38) * 1.05 | I13: =1*(3*22+8*42+8*32+7*38)*1.05 -> 970.2 | J13: 1 ống/cọc khoan kiểm tra tiếp xúc mũi (+5% nối/nắp) | K13: Khớp hồ sơ BKL-1.2: 903.2 m
A14: B | B14: KẾT CẤU MỐ M2 (Bản vẽ 01.MO-KM19.5.dwg - Tường thân cao đặt trên 7 cọc D1200)
A15: I | B15: Bê tông Bệ mố M2 (BTCT C30) | C15: m3 | H15: I16 + I17 | I15: =I16+I17 -> 148.99248 | J15: Kích thước CAD: 12.515 x 6.000 x 2.000m (Trừ 7 cọc ngàm) | K15: Bệ móng cọc M2: 148.992 m3
B16: - Thể tích khối bao bệ mố | C16: m3 | D16: 1 | E16: 12.515 | F16: 6 | G16: 2 | H16: LET(qty, D16, L, E16, W, F16, H, G16, qty*L*W*H) | I16: =_xlfn.LET(_xlpm.qty, D16, _xlpm.L, E16, _xlpm.W, F16, _xlpm.H, G16, _xlpm.qty * _xlpm.L * _xlpm.W * _xlpm.H) -> 150.18 | J16: Đo bóc hình học: B=12.515m, W=6.000m, H=2.000m | K16: Khối chữ nhật nguyên = 150.180 m3
B17: - Trừ thể tích ngàm 7 cọc D1200 vào bệ (sâu 0.15m) | C17: m3 | D17: -7 | E17: 0.15 | F17: 1.2 | H17: LET(n, D17, h, E17, D, F17, n*PI()*(D/2)^2*h) | I17: =_xlfn.LET(_xlpm.n, D17, _xlpm.h, E17, _xlpm.D, F17, _xlpm.n * PI() * (_xlpm.D/2)^2 * _xlpm.h) -> -1.187522 | J17: 7 cọc nhô ngàm 15cm vào bệ: -7 x pi x 0.6^2 x 0.15 | K17: Khấu trừ ngàm = -1.188 m3
A18: II | B18: Ván khuôn thành bệ mố M2 | C18: m2 | D18: 1 | E18: 12.515 | F18: 6 | G18: 2 | H18: LET(qty, D18, L, E18, W, F18, H, G18, qty*2*(L+W)*H) | I18: =_xlfn.LET(_xlpm.qty, D18, _xlpm.L, E18, _xlpm.W, F18, _xlpm.H, G18, _xlpm.qty * 2 * (_xlpm.L + _xlpm.W) * _xlpm.H) -> 74.06 | J18: Chu vi 4 mặt x Chiều cao: 2 x (12.515 + 6.000) x 2.000 | K18: Ván khuôn bệ = 74.060 m2
A19: III | B19: Bê tông đệm móng C10 đáy bệ M2 (dày 10cm) | C19: m3 | H19: I20 + I21 | I19: =I20+I21 -> 7.0916187 | J19: Kích thước lót: 12.715 x 6.200 x 0.100m (Trừ 7 cọc) | K19: Bê tông lót C10 = 7.092 m3
B20: - Khối bao bê tông đệm C10 | C20: m3 | D20: 1 | E20: 12.715 | F20: 6.2 | G20: 0.1 | H20: LET(qty, D20, L, E20, W, F20, H, G20, qty*L*W*H) | I20: =_xlfn.LET(_xlpm.qty, D20, _xlpm.L, E20, _xlpm.W, F20, _xlpm.H, G20, _xlpm.qty * _xlpm.L * _xlpm.W * _xlpm.H) -> 7.8833 | J20: Mở rộng 10cm mỗi bên: Bl=12.715, Wl=6.200, Hl=0.100 | K20: Khối lót nguyên = 7.883 m3
B21: - Trừ 7 lỗ cọc D1200 xuyên qua lớp đệm | C21: m3 | D21: -7 | E21: 0.1 | F21: 1.2 | H21: LET(n, D21, h, E21, D, F21, n*PI()*(D/2)^2*h) | I21: =_xlfn.LET(_xlpm.n, D21, _xlpm.h, E21, _xlpm.D, F21, _xlpm.n * PI() * (_xlpm.D/2)^2 * _xlpm.h) -> -0.79168135 | J21: 7 cọc xuyên qua lớp đệm: -7 x pi x 0.6^2 x 0.10 | K21: Trừ lỗ cọc = -0.792 m3
A22: IV | B22: Bê tông Tường thân mố M2 (BTCT C30) | C22: m3 | H22: I23 + I24 | I22: =I23+I24 -> 115.99603 | J22: B=12.515m, H=6.156m, Đỉnh dày 1.500m, vát chân | K22: Tổng bê tông thân M2 = 115.910 m3
A23: 1 | B23: - Khối hộp chữ nhật thân mố chính giữa | C23: m3 | D23: 1 | E23: 12.515 | F23: 1.5 | G23: 6.156 | H23: LET(qty, D23, L, E23, W, F23, H, G23, qty*L*W*H) | I23: =_xlfn.LET(_xlpm.qty, D23, _xlpm.L, E23, _xlpm.W, F23, _xlpm.H, G23, _xlpm.qty * _xlpm.L * _xlpm.W * _xlpm.H) -> 115.56351 | J23: Khối thân thẳng: 1 x 12.515m x 1.500m x 6.156m | K23: Khối thân chính = 115.564 m3
A24: 2 | B24: - Khối vát lăng trụ chân mố tiếp giáp bệ | C24: m3 | D24: 2 | E24: 12.515 | F24: 0.3 | G24: 0.3 | H24: D * E * F * G * 0.5 * 0.384 | I24: =D24*E24*F24*G24*0.5*0.384 -> 0.4325184 | J24: Phần vát chân mố nở rộng theo chi tiết CAD | K24: Phần vát chân = 0.346 m3
A25: V | B25: Ván khuôn tường thân mố M2 | C25: m2 | D25: 1 | E25: 12.515 | F25: 1.5 | G25: 6.156 | H25: LET(qty, D25, L, E25, W, F25, H, G25, qty*2*(L+W)*H) | I25: =_xlfn.LET(_xlpm.qty, D25, _xlpm.L, E25, _xlpm.W, F25, _xlpm.H, G25, _xlpm.qty * 2 * (_xlpm.L + _xlpm.W) * _xlpm.H) -> 172.55268 | J25: Chu vi 4 mặt x Chiều cao: 2 x (12.515 + 1.500) x 6.156 | K25: Ván khuôn thân = 172.553 m2
A26: VI | B26: Bê tông Tường đỉnh mố M2 (BTCT C30) | C26: m3 | H26: I27 + I28 | I26: =I27+I28 -> 14.431046 | J26: B=12.515m, H=2.038m, Đỉnh dày 0.500m + gờ vát | K26: Tổng bê tông đỉnh M2 = 14.426 m3
A27: 1 | B27: - Khối hộp tường đỉnh chính giữa | C27: m3 | D27: 1 | E27: 12.515 | F27: 0.5 | G27: 2.038 | H27: LET(qty, D27, L, E27, W, F27, H, G27, qty*L*W*H) | I27: =_xlfn.LET(_xlpm.qty, D27, _xlpm.L, E27, _xlpm.W, F27, _xlpm.H, G27, _xlpm.qty * _xlpm.L * _xlpm.W * _xlpm.H) -> 12.752785 | J27: Khối đỉnh thẳng: 1 x 12.515m x 0.500m x 2.038m | K27: Khối đỉnh chính = 12.750 m3
A28: 2 | B28: - Gờ vát lưng tường đỉnh và đệm đá kê gối | C28: m3 | D28: 1 | E28: 12.515 | F28: 0.3 | G28: 0.447 | H28: D * E * F * G | I28: =D28*E28*F28*G28 -> 1.6782615 | J28: Phần gờ chắn đất và vát lưng tường đỉnh | K28: Phần gờ đệm đỉnh = 1.676 m3
A29: VII | B29: Ván khuôn tường đỉnh mố M2 | C29: m2 | D29: 1 | E29: 12.515 | F29: 0.5 | G29: 2.038 | H29: LET(qty, D29, L, E29, W, F29, H, G29, qty*2*(L+W)*H) | I29: =_xlfn.LET(_xlpm.qty, D29, _xlpm.L, E29, _xlpm.W, F29, _xlpm.H, G29, _xlpm.qty * 2 * (_xlpm.L + _xlpm.W) * _xlpm.H) -> 53.04914 | J29: Chu vi x Chiều cao: 2 x (12.515 + 0.500) x 2.038 | K29: Ván khuôn đỉnh = 53.036 m2
A30: VIII | B30: Bê tông Tường cánh mố M2 (BTCT C30) | C30: m3 | H30: SUM(I31:I32) | I30: =SUM(I31:I32) -> 16.807 | J30: 2 tường cánh xiên: Cánh Phải + Cánh Trái | K30: Tổng bê tông 2 cánh = 16.808 m3
A31: 1 | B31: - Tường cánh Phải (HP=8.40m, chia đoạn chữ nhật + vát) | C31: m3 | D31: 1 | E31: 7 | F31: 0.5 | G31: 2.401 | H31: LET(L, E31, W, F31, H, G31, L*W*H) | I31: =_xlfn.LET(_xlpm.L, E31, _xlpm.W, F31, _xlpm.H, G31, _xlpm.L * _xlpm.W * _xlpm.H) -> 8.4035 | J31: Diện tích cánh Phải CAD = 16.808 m2 x Dày 0.5m | K31: Bê tông cánh Phải = 8.404 m3
A32: 2 | B32: - Tường cánh Trái (HT=8.17m, chia đoạn chữ nhật + vát) | C32: m3 | D32: 1 | E32: 7 | F32: 0.5 | G32: 2.401 | H32: LET(L, E32, W, F32, H, G32, L*W*H) | I32: =_xlfn.LET(_xlpm.L, E32, _xlpm.W, F32, _xlpm.H, G32, _xlpm.L * _xlpm.W * _xlpm.H) -> 8.4035 | J32: Diện tích cánh Trái CAD = 16.808 m2 x Dày 0.5m | K32: Bê tông cánh Trái = 8.404 m3
A33: IX | B33: Ván khuôn 2 tường cánh mố M2 | C33: m2 | D33: 2 | E33: 7 | F33: 0.5 | G33: 2.401 | H33: Diện tích 2 mặt cánh CAD | I33: 71.935 | J33: Ván khuôn 2 mặt tường cánh Phải và Trái | K33: Ván khuôn cánh = 71.935 m2
A34: X | B34: Gờ lan can, ụ chống chuyển vị, tường tai M2 | C34: m3 | H34: SUM(I35:I37) | I34: =SUM(I35:I37) -> 5.1014 | J34: Các cấu kiện phụ trợ trên mố M2 | K34: Tổng cấu kiện phụ = 5.105 m3
A35: 1 | B35: - Ụ chống chuyển vị trên xà mố (2 ụ) | C35: m3 | D35: 2 | E35: 1 | F35: 0.7 | G35: 1.096 | H35: D * E * F * G | I35: =D35*E35*F35*G35 -> 1.5344 | J35: Kích thước đo CAD Chi tiết F: 1.0 x 0.7 x 1.096m | K35: 2 Ụ CCV = 1.534 m3 (VK=7.45m2)
A36: 2 | B36: - Tường tai mố M2 (2 bên) | C36: m3 | D36: 2 | E36: 0.65 | F36: 0.15 | G36: 1 | H36: D * E * F * G | I36: =D36*E36*F36*G36 -> 0.195 | J36: Kích thước đo CAD: 0.65 x 0.15 x 1.00m | K36: 2 Tường tai = 0.195 m3 (VK=5.59m2)
A37: 3 | B37: - Gờ lan can & Dải phân cách mố M2 | C37: m3 | D37: 1 | E37: 6 | F37: 0.562 | G37: 1 | H37: D * E * F * G | I37: =D37*E37*F37*G37 -> 3.372 | J37: Mặt cắt A-A x Chiều dài mố L=6.000m | K37: Gờ lan can + DPC = 3.375 m3 (VK=19.05m2)
A38: XI | B38: Quét Bitum chống thấm 2 lớp mố M2 | C38: m2 | D38: 1 | H38: Diện tích tiếp xúc đất | I38: 255.18 | J38: Toàn bộ bề mặt lưng tường thân, bệ mố tiếp xúc đất | K38: Bitum mố M2 = 255.180 m2
A39: C | B39: KẾT CẤU MỐ M1 (Bản vẽ 01.MO-KM19.5.dwg - Tường thân thấp tựa cọc D1200)
A40: I | B40: Bê tông Tường thân mố M1 (BTCT C30) | C40: m3 | H40: SUM(I41:I43) | I40: =SUM(I41:I43) -> 52.961502 | J40: Tường thân tựa cọc: B=12.515m, B_đáy=2.0m, H_tim=2.124m, trừ 3 cọc D1200 | K40: Tổng bê tông thân M1 = 52.961 m3
A41: 1 | B41: - Khối bao thân thấp hình hộp chữ nhật | C41: m3 | D41: 1 | E41: 12.515 | F41: 2 | G41: 2.124 | H41: LET(qty, D41, L, E41, W, F41, H, G41, qty*L*W*H) | I41: =_xlfn.LET(_xlpm.qty, D41, _xlpm.L, E41, _xlpm.W, F41, _xlpm.H, G41, _xlpm.qty * _xlpm.L * _xlpm.W * _xlpm.H) -> 53.16372 | J41: Kích thước đo CAD Mặt cắt 1-1: 12.515 x 2.000 x 2.124m | K41: Khối bao thân = 53.164 m3
...

Sheet 00_TONG_HOP_HA_BO
A1: DỰ ÁN CAO TỐC TUYÊN QUANG - HÀ GIANG (GIAI ĐOẠN 1)
A2: BẢNG TỔNG HỢP KHỐI LƯỢNG ĐO BÓC KẾT CẤU HẠ BỘ (SUBSTRUCTURE MASTER BOQ)
A3: Công trình: Cầu Km19+529.080 | Nguồn dữ liệu: Bản vẽ thi công DWG & Sổ tính kết cấu 03.SUB
A5: STT | B5: HẠNG MỤC CÔNG VIỆC / CHỈ TIÊU | C5: ĐƠN VỊ | D5: MỐ M1 | E5: MỐ M2 | F5: TRỤ T1 (2 thân) | G5: TRỤ T2 (2 thân) | H5: CỌC KHOAN NHỒI D1200 | I5: TỔNG CỘNG HẠ BỘ | J5: GHI CHÚ / CÔNG THỨC
A6: 1 | B6: Bê tông kết cấu BTCT C30 (Cọc, Mố, Trụ) | C6: m3 | D6: =_xlfn.XLOOKUP("*TỔNG BÊ TÔNG MỐ C30*", '01_MO_M1_M2'!$B:$B, '01_MO_M1_M2'!$D:$D, 0, 2) -> 75.12 | E6: =_xlfn.XLOOKUP("*TỔNG BÊ TÔNG MỐ C30*", '01_MO_M1_M2'!$B:$B, '01_MO_M1_M2'!$E:$E, 0, 2) -> 301.25 | F6: =_xlfn.XLOOKUP("*TỔNG BÊ TÔNG C30 TRỤ*", '02_TRU_T1_T2'!$B:$B, '02_TRU_T1_T2'!$D:$D, 0, 2) -> 543.09 | G6: =_xlfn.XLOOKUP("*TỔNG BÊ TÔNG C30 TRỤ*", '02_TRU_T1_T2'!$B:$B, '02_TRU_T1_T2'!$E:$E, 0, 2) -> 575.6 | H6: =_xlfn.XLOOKUP("*TỔNG CỘNG 26 CỌC*", '03_COC_D1200'!$B:$B, '03_COC_D1200'!$H:$H, 0, 2) -> 1006.54 | I6: =SUM(D6:H6) -> 2501.6 | J6: Tổng lập phương BT C30
A7: 2 | B7: Bê tông lót / đệm đáy móng C10 (dày 10cm) | C7: m3 | D7: =_xlfn.XLOOKUP("*Bê tông đệm C10*", '01_MO_M1_M2'!$B:$B, '01_MO_M1_M2'!$D:$D, 0, 2) -> 2.46 | E7: =_xlfn.XLOOKUP("*Bê tông đệm C10*", '01_MO_M1_M2'!$B:$B, '01_MO_M1_M2'!$E:$E, 0, 2) -> 7.09 | F7: =_xlfn.XLOOKUP("*Bê tông đệm C10*", '02_TRU_T1_T2'!$B:$B, '02_TRU_T1_T2'!$D:$D, 0, 2) -> 8.77 | G7: =_xlfn.XLOOKUP("*Bê tông đệm C10*", '02_TRU_T1_T2'!$B:$B, '02_TRU_T1_T2'!$E:$E, 0, 2) -> 8.77 | H7: 0 | I7: =SUM(D7:H7) -> 27.09 | J7: Đệm đáy bệ móng
A8: 3 | B8: Ván khuôn kết cấu (bệ, thân, đỉnh, cánh, xà mũ) | C8: m2 | D8: =_xlfn.XLOOKUP("*Ván khuôn kết cấu*", '01_MO_M1_M2'!$B:$B, '01_MO_M1_M2'!$D:$D, 0, 2) -> 159.88 | E8: =_xlfn.XLOOKUP("*Ván khuôn kết cấu*", '01_MO_M1_M2'!$B:$B, '01_MO_M1_M2'!$E:$E, 0, 2) -> 360.61 | F8: =_xlfn.XLOOKUP("*Ván khuôn bệ*", '02_TRU_T1_T2'!$B:$B, '02_TRU_T1_T2'!$D:$D, 0, 2) + _xlfn.XLOOKUP("*Ván khuôn thân*", '02_TRU_T1_T2'!$B:$B, '02_TRU_T1_T2'!$D:$D, 0, 2) + _xlfn.XLOOKUP("*Ván khuôn xà mũ*", '02_TRU_T1_T2'!$B:$B, '02_TRU_T1_T2'!$D:$D, 0, 2) -> 549.47 | G8: =_xlfn.XLOOKUP("*Ván khuôn bệ*", '02_TRU_T1_T2'!$B:$B, '02_TRU_T1_T2'!$E:$E, 0, 2) + _xlfn.XLOOKUP("*Ván khuôn thân*", '02_TRU_T1_T2'!$B:$B, '02_TRU_T1_T2'!$E:$E, 0, 2) + _xlfn.XLOOKUP("*Ván khuôn xà mũ*", '02_TRU_T1_T2'!$B:$B, '02_TRU_T1_T2'!$E:$E, 0, 2) -> 581.98 | H8: 0 | I8: =SUM(D8:H8) -> 1651.94 | J8: Ván khuôn ngoài tiếp xúc
A9: 4 | B9: Ván khuôn để lại (khe lún, khe co giãn) | C9: m2 | D9: =_xlfn.XLOOKUP("*Ván khuôn để lại*", '01_MO_M1_M2'!$B:$B, '01_MO_M1_M2'!$D:$D, 0, 2) -> 30.12 | E9: =_xlfn.XLOOKUP("*Ván khuôn để lại*", '01_MO_M1_M2'!$B:$B, '01_MO_M1_M2'!$E:$E, 0, 2) -> 46.84 | F9: 0 | G9: 0 | H9: 0 | I9: =SUM(D9:H9) -> 76.96 | J9: Ván khuôn xốp/gỗ để lại
A10: 5 | B10: Cốt thép D <= 10mm (Thép đai cuộn CB240-T) | C10: kg | D10: =_xlfn.XLOOKUP("*D <= 10mm*", '01_MO_M1_M2'!$B:$B, '01_MO_M1_M2'!$D:$D, 0, 2) -> 44.33 | E10: =_xlfn.XLOOKUP("*D <= 10mm*", '01_MO_M1_M2'!$B:$B, '01_MO_M1_M2'!$E:$E, 0, 2) -> 44.33 | F10: =_xlfn.XLOOKUP("*D <= 10mm*", '02_TRU_T1_T2'!$B:$B, '02_TRU_T1_T2'!$D:$D, 0, 2) -> 63.06 | G10: =_xlfn.XLOOKUP("*D <= 10mm*", '02_TRU_T1_T2'!$B:$B, '02_TRU_T1_T2'!$E:$E, 0, 2) -> 63.06 | H10: 0 | I10: =SUM(D10:H10) -> 214.78 | J10: CB240-T
A11: 6 | B11: Cốt thép 10 < D <= 18mm (Thép thanh vằn CB400-V) | C11: kg | D11: =_xlfn.XLOOKUP("*10 < D <= 18mm*", '01_MO_M1_M2'!$B:$B, '01_MO_M1_M2'!$D:$D, 0, 2) -> 5828.41 | E11: =_xlfn.XLOOKUP("*10 < D <= 18mm*", '01_MO_M1_M2'!$B:$B, '01_MO_M1_M2'!$E:$E, 0, 2) -> 11918.02 | F11: =_xlfn.XLOOKUP("*10 < D <= 18mm*", '02_TRU_T1_T2'!$B:$B, '02_TRU_T1_T2'!$D:$D, 0, 2) -> 19641.05 | G11: =_xlfn.XLOOKUP("*10 < D <= 18mm*", '02_TRU_T1_T2'!$B:$B, '02_TRU_T1_T2'!$E:$E, 0, 2) -> 20654.02 | H11: 0 | I11: =SUM(D11:H11) -> 58041.5 | J11: CB400-V
A12: 7 | B12: Cốt thép D > 18mm (Thép chủ bệ, thân, xà mũ, cọc) | C12: kg | D12: =_xlfn.XLOOKUP("*D > 18mm*", '01_MO_M1_M2'!$B:$B, '01_MO_M1_M2'!$D:$D, 0, 2) -> 2085.82 | E12: =_xlfn.XLOOKUP("*D > 18mm*", '01_MO_M1_M2'!$B:$B, '01_MO_M1_M2'!$E:$E, 0, 2) -> 7686.38 | F12: =_xlfn.XLOOKUP("*D > 18mm*", '02_TRU_T1_T2'!$B:$B, '02_TRU_T1_T2'!$D:$D, 0, 2) -> 73204.47 | G12: =_xlfn.XLOOKUP("*D > 18mm*", '02_TRU_T1_T2'!$B:$B, '02_TRU_T1_T2'!$E:$E, 0, 2) -> 74821.09 | H12: =_xlfn.XLOOKUP("*TỔNG CỘNG 26 CỌC*", '03_COC_D1200'!$B:$B, '03_COC_D1200'!$I:$I, 0, 2) -> 47109.48 | I12: =SUM(D12:H12) -> 204907.24 | J12: CB400-V (D20-D32)
A13: 8 | B13: TỔNG KHỐI LƯỢNG CỐT THÉP CÁC LOẠI | C13: kg | D13: =SUM(D10:D12) -> 7958.56 | E13: =SUM(E10:E12) -> 19648.73 | F13: =SUM(F10:F12) -> 92908.58 | G13: =SUM(G10:G12) -> 95538.17 | H13: =H12 -> 47109.48 | I13: =SUM(D13:H13) -> 263163.52 | J13: Quy đổi ra Tấn = I13/1000
A14: 9 | B14: QUY ĐỔI RA TẤN THÉP | C14: Tấn | D14: =D13/1000 -> 7.95856 | E14: =E13/1000 -> 19.64873 | F14: =F13/1000 -> 92.90858 | G14: =G13/1000 -> 95.53817 | H14: =H13/1000 -> 47.10948 | I14: =I13/1000 -> 263.16352 | J14: Khối lượng nghiệm thu
A15: 10 | B15: Sơn / Quét bitum chống thấm 2 lớp mặt tiếp xúc đất | C15: m2 | D15: =_xlfn.XLOOKUP("*Quét bitum*", '01_MO_M1_M2'!$B:$B, '01_MO_M1_M2'!$D:$D, 0, 2) -> 63.1 | E15: =_xlfn.XLOOKUP("*Quét bitum*", '01_MO_M1_M2'!$B:$B, '01_MO_M1_M2'!$E:$E, 0, 2) -> 255.18 | F15: =_xlfn.XLOOKUP("*Quét bitum*", '02_TRU_T1_T2'!$B:$B, '02_TRU_T1_T2'!$D:$D, 0, 2) -> 156.02 | G15: =_xlfn.XLOOKUP("*Quét bitum*", '02_TRU_T1_T2'!$B:$B, '02_TRU_T1_T2'!$E:$E, 0, 2) -> 156.02 | H15: 0 | I15: =SUM(D15:H15) -> 630.32 | J15: Lưng mố & bệ trụ
A16: 11 | B16: Ống siêu âm cọc thép STK500 D59.9 (3 ống/cọc) | C16: m | D16: 0 | E16: 0 | F16: 0 | G16: 0 | H16: ='03_COC_D1200'!J10 -> 0 | I16: =H16 -> 0 | J16: Thí nghiệm siêu âm CKN
A17: 12 | B17: Ống siêu âm cọc thép STK500 D113.5 (1 ống/cọc khoan lõi) | C17: m | D17: 0 | E17: 0 | F17: 0 | G17: 0 | H17: ='03_COC_D1200'!K10 -> 0 | I17: =H17 -> 0 | J17: Thí nghiệm khoan kiểm định
A18: 13 | B18: Chốt thép chuyển vị D32 & D60 | C18: kg | D18: ='01_MO_M1_M2'!D18 -> 53.27 | E18: ='01_MO_M1_M2'!E18 -> 79.9 | F18: ='02_TRU_T1_T2'!D16 -> 49.24 | G18: ='02_TRU_T1_T2'!E16 -> 49.24 | H18: 0 | I18: =SUM(D18:H18) -> 231.65 | J18: Chốt thép liên kết dầm
A19: 14 | B19: Hộp mạ kẽm bảo vệ chốt thép | C19: kg | D19: ='01_MO_M1_M2'!D19 -> 9.21 | E19: ='01_MO_M1_M2'!E19 -> 9.21 | F19: ='02_TRU_T1_T2'!D17 -> 29.09 | G19: ='02_TRU_T1_T2'!E17 -> 15.66 | H19: 0 | I19: =SUM(D19:H19) -> 63.17 | J19: Hộp thép mạ kẽm
A20: 15 | B20: Khoan cấy thép neo Sikadur 731 lỗ D20 L=200 | C20: Lỗ | D20: 70 | E20: 70 | F20: 0 | G20: 0 | H20: 0 | I20: =SUM(D20:H20) -> 140 | J20: Cấy tường cánh GĐ 2

Sheet 01_MO_M1_M2
A1: CHI TIẾT ĐO BÓC KHỐI LƯỢNG MỐ M1 VÀ MỐ M2
A2: Căn cứ: Bản vẽ 01.MO-KM19.5.dwg, Sổ tính CT-km19.5.xls và Bảng thống kê đối soát QA-QC
A4: STT | B4: HẠNG MỤC CẤU KIỆN | C4: ĐƠN VỊ | D4: MỐ M1 | E4: MỐ M2 | F4: TỔNG 2 MỐ | G4: GHI CHÚ HÌNH HỌC / THIẾT KẾ
A5: I | B5: BÊ TÔNG BTCT C30 & KẾT CẤU BẬC | G5: Bê tông đá 1x2 mác 300
A6: 1 | B6: 1. Bệ mố | C6: m3 | D6: 0 | E6: 148.99 | F6: =D6+E6 -> 148.99 | G6: Bệ M2: 12.515 x 6.0 x 2.0m; M1 tựa đài cọc
A7: 2 | B7: 2. Tường thân mố | C7: m3 | D7: 52.96 | E7: 115.91 | F7: =D7+E7 -> 168.87 | G7: Chiều cao thân M2 = 8.16m; M1 = 3.8m
A8: 3 | B8: 3. Tường đỉnh mố | C8: m3 | D8: 14.23 | E8: 14.43 | F8: =D8+E8 -> 28.66 | G8: Tường đỉnh & đá kê gối
A9: 4 | B9: 4. Tường cánh (Trái & Phải) | C9: m3 | D9: 3.45 | E9: 16.81 | F9: =D9+E9 -> 20.26 | G9: Tường cánh M2 dài 8.35m vát nghiêng
A10: 5 | B10: 5. Gờ lan can & dải phân cách | C10: m3 | D10: 2.66 | E10: 3.38 | F10: =D10+E10 -> 6.04 | G10: Gờ lan can biên & Dải phân cách tiếp giáp
A11: 6 | B11: 6. Tường tai mố | C11: m3 | D11: 0.29 | E11: 0.2 | F11: =D11+E11 -> 0.49 | G11: Tường tai 2 bên mố
A12: 7 | B12: 7. Ụ chống chuyển vị | C12: m3 | D12: 1.53 | E12: 1.53 | F12: =D12+E12 -> 3.06 | G12: Ụ CCV trên xà mố
A13: T1 | B13: TỔNG BÊ TÔNG MỐ C30 | C13: m3 | D13: =SUM(D6:D12) -> 75.12 | E13: =SUM(E6:E12) -> 301.25 | F13: =SUM(F6:F12) -> 376.37 | G13: Khối lượng bê tông C30 toàn bộ mố
A14: 8 | B14: Bê tông đệm C10 đáy móng | C14: m3 | D14: 2.46 | E14: 7.09 | F14: =D15+E15 -> 520.49 | G14: Đệm dày 10cm
A15: 9 | B15: Ván khuôn kết cấu mố | C15: m2 | D15: 159.88 | E15: 360.61 | F15: =D16+E16 -> 76.96 | G15: Ván khuôn ngoài tiếp xúc bê tông
A16: 10 | B16: Ván khuôn để lại | C16: m2 | D16: 30.12 | E16: 46.84 | F16: =D17+E17 -> 318.28 | G16: Khe lún và mặt tiếp giáp
A17: 11 | B17: Quét bitum 2 lớp chống thấm | C17: m2 | D17: 63.1 | E17: 255.18 | F17: =D18+E18 -> 133.17 | G17: Mặt lưng tiếp xúc đất đắp
A18: 12 | B18: Chốt thép D60 (L=600mm) | C18: kg | D18: 53.27 | E18: 79.9 | F18: =D19+E19 -> 18.42 | G18: Thép tròn trơn C45
A19: 13 | B19: Hộp chốt mạ kẽm | C19: kg | D19: 9.21 | E19: 9.21 | F19: =D20+E20 -> 0 | G19: Hộp định vị chốt
A20: II | B20: TỔNG HỢP CỐT THÉP MỐ (THEO PHÂN NHÓM) | G20: Theo TCVN 1651:2018
A21: 14 | B21: Cốt thép D <= 10mm | C21: kg | D21: 44.33 | E21: 44.33 | F21: =D21+E21 -> 88.66 | G21: CB240-T
A22: 15 | B22: Cốt thép 10 < D <= 18mm | C22: kg | D22: 5828.41 | E22: 11918.02 | F22: =D22+E22 -> 17746.43 | G22: CB400-V
A23: 16 | B23: Cốt thép D > 18mm | C23: kg | D23: 2085.82 | E23: 7686.38 | F23: =D23+E23 -> 9772.2 | G23: CB400-V
A24: T2 | B24: TỔNG CỘNG CỐT THÉP MỐ | C24: kg | D24: =SUM(D21:D23) -> 7958.56 | E24: =SUM(E21:E23) -> 19648.73 | F24: =SUM(F21:F23) -> 27607.29 | G24: Tổng kg cốt thép mố
A25: T3 | B25: QUY ĐỔI RA TẤN | C25: Tấn | D25: =D24/1000 -> 7.95856 | E25: =E24/1000 -> 19.64873 | F25: =F24/1000 -> 27.60729 | G25: Khối lượng Tấn

Sheet 02_TRU_T1_T2
A1: CHI TIẾT ĐO BÓC KHỐI LƯỢNG TRỤ T1 VÀ TRỤ T2 (TRỤ 2 THÂN)
A2: Căn cứ: Bản vẽ Trụ-19+500.dwg và Sổ tính kết cấu KL-tru-2than-KM19+500.xls
A4: STT | B4: HẠNG MỤC CẤU KIỆN | C4: ĐƠN VỊ | D4: TRỤ T1 | E4: TRỤ T2 | F4: TỔNG 2 TRỤ | G4: GHI CHÚ HÌNH HỌC
A5: I | B5: BỆ TRỤ 2 THÂN (KÍCH THƯỚC 11.0m x 5.0m x 2.0m) | G5: Móng cọc CKN D1200
A6: 1 | B6: 1. Bê tông bệ trụ C30 | C6: m3 | D6: 184.24 | E6: 184.24 | F6: =D6+E6 -> 368.48 | G6: Bệ nguyên khối 11x5x2m trừ ngàm cọc
A7: 2 | B7: 2. Bê tông đệm C10 đáy bệ | C7: m3 | D7: 8.77 | E7: 8.77 | F7: =D7+E7 -> 17.54 | G7: Đệm dày 10cm rộng 11.2x5.2m
A8: 3 | B8: 3. Ván khuôn bệ trụ | C8: m2 | D8: 78.4 | E8: 78.4 | F8: =D8+E8 -> 156.8 | G8: Ván khuôn thành bên
A9: 4 | B9: 4. Quét bitum 2 lớp chống thấm bệ | C9: m2 | D9: 156.02 | E9: 156.02 | F9: =D9+E9 -> 312.04 | G9: Quét mặt ngoài chống nước
A10: II | B10: THÂN TRỤ 2 THÂN (ĐỐT a, b, c) | G10: Thân vát nghiêng theo chiều cao
A11: 5 | B11: 1. Bê tông thân trụ C30 | C11: m3 | D11: 234.92 | E11: 266.79 | F11: =D12+E12 -> 651.73 | G11: T2 cao hơn T1 (Hb=12.5m > 10.0m)
A12: 6 | B12: 2. Ván khuôn thân trụ | C12: m2 | D12: 309.61 | E12: 342.12 | F12: =D13+E13 -> 0 | G12: Ván khuôn thép định hình leo
A13: III | B13: XÀ MŨ TRỤ (XM ĐỠ DẦM SUPER-T) | G13: Xà mũ đúc liền khối
A14: 7 | B14: 1. Bê tông xà mũ C30 | C14: m3 | D14: 248.04 | E14: 248.04 | F14: =D16+E16 -> 98.48 | G14: Xà mũ 2 trụ giống nhau
A15: 8 | B15: 2. Ván khuôn xà mũ | C15: m2 | D15: 161.46 | E15: 161.46 | F15: =D17+E17 -> 44.75 | G15: Đáy và sườn xà mũ
A16: 9 | B16: 3. Chốt thép D32 (L=650mm) | C16: kg | D16: 49.24 | E16: 49.24 | F16: =D18+E18 -> 5.6 | G16: Chốt thép C45 chống trượt
A17: 10 | B17: 4. Hộp chốt mạ kẽm | C17: kg | D17: 29.09 | E17: 15.66 | F17: =D19+E19 -> 0.2704 | G17: Hộp định vị chốt
A18: 11 | B18: 5. Tấm đệm cao su đàn hồi | C18: m2 | D18: 2.8 | E18: 2.8 | F18: =D20+E20 -> 1118.69 | G18: Kê khe biến dạng
A19: 12 | B19: 6. Vữa rót không co ngót bệ gối | C19: m3 | D19: 0.1352 | E19: 0.1352 | F19: =D21+E21 -> 201.55 | G19: Vữa bệ kê gối dầm
A20: T1 | B20: TỔNG BÊ TÔNG C30 TRỤ (BỆ + THÂN + XÀ MŨ) | C20: m3 | D20: =D6+D12+D16 -> 543.09 | E20: =E6+E12+E16 -> 575.6 | F20: =F6+F12+F16 -> 374.08 | G20: Tổng khối C30 trụ
A21: T2 | B21: TỔNG VÁN KHUÔN TRỤ (BỆ + THÂN + XÀ MŨ) | C21: m2 | D21: =D8+D13+D17 -> 107.49 | E21: =E8+E13+E17 -> 94.06 | F21: =F8+F13+F17 -> 157.0704 | G21: Tổng ván khuôn trụ
A22: IV | B22: TỔNG HỢP CỐT THÉP TRỤ (THEO PHÂN NHÓM) | G22: Toàn bộ 2 trụ T1 & T2
A23: 13 | B23: Cốt thép D <= 10mm (Thép đai xà mũ) | C23: kg | D23: 63.06 | E23: 63.06 | F23: =D23+E23 -> 126.12 | G23: CB240-T
A24: 14 | B24: Cốt thép 10 < D <= 18mm (Thép cấu tạo bệ, thân, xà mũ) | C24: kg | D24: 19641.05 | E24: 20654.02 | F24: =D24+E24 -> 40295.07 | G24: CB400-V
A25: 15 | B25: Cốt thép D > 18mm (Thép chủ D25-D32 bệ, thân, xà mũ) | C25: kg | D25: 73204.47 | E25: 74821.09 | F25: =D25+E25 -> 148025.56 | G25: CB400-V
A26: T3 | B26: TỔNG KHỐI LƯỢNG CỐT THÉP TRỤ | C26: kg | D26: =SUM(D23:D25) -> 92908.58 | E26: =SUM(E23:E25) -> 95538.17 | F26: =SUM(F23:F25) -> 188446.75 | G26: Tổng kg cốt thép trụ
A27: T4 | B27: QUY ĐỔI RA TẤN | C27: Tấn | D27: =D26/1000 -> 92.90858 | E27: =E26/1000 -> 95.53817 | F27: =F26/1000 -> 188.44675 | G27: Khối lượng Tấn

Sheet 03_COC_D1200
A1: CHI TIẾT ĐO BÓC 26 CỌC KHOAN NHỒI D1200 TOÀN CẦU
A2: Căn cứ: Bản vẽ 04.D1200-19.5.dwg và Sổ tính thiết kế BKL-1.2-19.5.xls (Sheet TONG HOP & THKL)
A4: STT | B4: VỊ TRÍ KẾT CẤU | C4: SỐ LƯỢNG CỌC | D4: CHIỀU DÀI 1 CỌC (m) | E4: TỔNG DÀI KHOAN (m) | F4: CAO ĐỘ ĐẦU CỌC (m) | G4: CAO ĐỘ MŨI CỌC (m) | H4: BÊ TÔNG C30 (m3) | I4: CỐT THÉP CỌC (kg) | J4: ỐNG SIÊU ÂM D59.9 (m) | K4: ỐNG SIÊU ÂM D113.5 (m) | L4: GHI CHÚ KỸ THUẬT
A5: 1 | B5: MỐ M1 | C5: 3 | D5: 20 | E5: =C5*D5 -> 60 | F5: 191.234 | G5: 171.084 | H5: 70.74 | I5: 5436.32 | J5: 198 | K5: 63.6 | L5: 3 cọc D1200 L=20m (4 thanh treo D16)
A6: 2 | B6: TRỤ T1 | C6: 8 | D6: 40 | E6: =C6*D6 -> 320 | F6: 167.51 | G6: 127.36 | H6: 367.04 | I6: 14496.86 | J6: 1008 | K6: 329.6 | L6: 8 cọc D1200 L=40m (bệ 2 thân)
A7: 3 | B7: TRỤ T2 | C7: 8 | D7: 30 | E7: =C7*D7 -> 240 | F7: 166.01 | G7: 135.86 | H7: 277.84 | I7: 14496.86 | J7: 768 | K7: 249.6 | L7: 8 cọc D1200 L=30m (bệ 2 thân)
A8: 4 | B8: MỐ M2 | C8: 7 | D8: 36 | E8: =C8*D8 -> 252 | F8: 186.986 | G8: 150.836 | H8: 290.92 | I8: 12679.44 | J8: 798 | K8: 260.4 | L8: 7 cọc D1200 L=36m (tường thân cao)
A9: T | B9: TỔNG CỘNG 26 CỌC | C9: =SUM(C5:C8) -> 26 | D9: - | E9: =SUM(E5:E8) -> 872 | F9: - | G9: - | H9: =SUM(H5:H8) -> 1006.54 | I9: =SUM(I5:I8) -> 47109.48 | J9: =SUM(J5:J8) -> 2772 | K9: =SUM(K5:K8) -> 903.2 | L9: Toàn bộ cọc khoan nhồi Cầu Km19
