Workbook

Sheet 00_DASHBOARD_TOAN_CAU
B2: BÁO CÁO ĐO BÓC KHỐI LƯỢNG HÌNH HỌC TOÀN DIỆN - CẦU KM19+529.080
B3: 100% Công thức động hình học (Dài x Rộng x Cao x Số lượng) | Không số chết | Khớp 100% Hồ sơ TKBVTC
B5: TỔNG BÊ TÔNG TOÀN CẦU | E5: TỔNG CỐT THÉP THƯỜNG | H5: CÁP DƯL 15.2MM KÉO TRƯỚC | K5: CỌC KHOAN NHỒI D1200MM | N5: TỔNG DIỆN TÍCH VÁN KHUÔN | Q5: VẬT LIỆU HẠT ĐẮP LÒNG MỐ
B6: ='06_MASTER_BOQ_TIEN_LUONG'!G45 | E6: ='06_MASTER_BOQ_TIEN_LUONG'!G46 | H6: ='01_DIEN_GIAI_SUPER_T'!J25 | K6: ='02_DIEN_GIAI_HA_BO'!H39 | N6: ='06_MASTER_BOQ_TIEN_LUONG'!G47 | Q6: ='04_DIEN_GIAI_DUONG_TU_NON'!J44
B8: m³ (C10 đến C45) | E8: Tấn (CB400-V / CB240-T) | H8: Tấn (44 tao/dầm x 15 phiến) | K8: Mét (26 cọc đại trà) | N8: m² (Dầm, Mố, Trụ, Phụ trợ) | Q8: m³ (Hạt đầm chặt K98)
B10: BẢNG ĐỐI CHIẾU KIỂM TOÁN CHÉO CHI TIẾT VỚI HỒ SƠ THIẾT KẾ DUYỆT (06.THKL_KM19.5)
B11: STT | C11: Phân hệ Hạng mục Công việc | D11: Quy cách / Mác vật liệu | E11: ĐVT | F11: Khối lượng Thiết kế Duyệt | G11: Khối lượng Bóc tách Hình học 365 | H11: Chênh lệch (Delta) | I11: Tỷ lệ Sai số | J11: Kết quả Kiểm toán Audit
B12: I. KẾT CẤU PHẦN TRÊN (SUPERSTRUCTURE)
B13: 1 | C13: Dầm chủ Super-T 38.2m (15 phiến) | D13: Bê tông C45/50 | E13: m³ | F13: 434.55 | G13: ='01_DIEN_GIAI_SUPER_T'!J24 | H13: =G13-F13 | I13: =IF(F13=0,0,H13/F13) | J13: =IF(ABS(I13)<0.001," KHỚP 100%"," CẦN SOÁT")
B14: 2 | C14: Cáp DƯL 15.2mm kéo trước | D14: ASTM A416 Grade 270 | E14: kg | F14: 29911.2 | G14: ='01_DIEN_GIAI_SUPER_T'!J25*1000 | H14: =G14-F14 | I14: =IF(F14=0,0,H14/F14) | J14: =IF(ABS(I14)<0.001," KHỚP 100%"," CẦN SOÁT")
B15: 3 | C15: Thép thanh thường dầm (BBS 23 mã) | D15: CB400-V (10<D<=18 & D>18) | E15: kg | F15: 89668.81 | G15: ='01_DIEN_GIAI_SUPER_T'!J26*1000 | H15: =G15-F15 | I15: =IF(F15=0,0,H15/F15) | J15: =IF(ABS(I15)<0.001," KHỚP 100%"," CẦN SOÁT")
B16: 4 | C16: Ván khuôn dầm chủ Super-T | D16: Thép định hình / Phủ phim | E16: m² | F16: 5098.77 | G16: ='01_DIEN_GIAI_SUPER_T'!J27 | H16: =G16-F16 | I16: =IF(F16=0,0,H16/F16) | J16: =IF(ABS(I16)<0.001," KHỚP 100%"," CẦN SOÁT")
B17: 5 | C17: Dầm ngang BTCT 3 nhịp | D17: Bê tông C35/45 | E17: m³ | F17: 19.38 | G17: ='01_DIEN_GIAI_SUPER_T'!J35 | H17: =G17-F17 | I17: =IF(F17=0,0,H17/F17) | J17: =IF(ABS(I17)<0.001," KHỚP 100%"," CẦN SOÁT")
B18: 6 | C18: Bản mặt cầu & Bản LTN | D18: Bê tông C35/45 | E18: m³ | F18: 327.33 | G18: ='01_DIEN_GIAI_SUPER_T'!J43 | H18: =G18-F18 | I18: =IF(F18=0,0,H18/F18) | J18: =IF(ABS(I18)<0.001," KHỚP 100%"," CẦN SOÁT")
B19: 7 | C19: Cốt thép BMC, DN & Bản LTN | D19: CB400-V (D<=18 & D>18) | E19: kg | F19: 88357.51 | G19: ='01_DIEN_GIAI_SUPER_T'!J44*1000 | H19: =G19-F19 | I19: =IF(F19=0,0,H19/F19) | J19: =IF(ABS(I19)<0.001," KHỚP 100%"," CẦN SOÁT")
B20: 8 | C20: Tấm ván khuôn đúc sẵn (510 tấm) | D20: Bê tông C25/30 | E20: m³ | F20: 13.23 | G20: ='01_DIEN_GIAI_SUPER_T'!J50 | H20: =G20-F20 | I20: =IF(F20=0,0,H20/F20) | J20: =IF(ABS(I20)<0.001," KHỚP 100%"," CẦN SOÁT")
B21: 9 | C21: Mặt đường Asphalt C16 (t=7cm) | D21: BTN C16 & Chống thấm | E21: m² | F21: 1380.39 | G21: ='01_DIEN_GIAI_SUPER_T'!J56 | H21: =G21-F21 | I21: =IF(F21=0,0,H21/F21) | J21: =IF(ABS(I21)<0.001," KHỚP 100%"," CẦN SOÁT")
B22: II. KẾT CẤU PHẦN DƯỚI (SUBSTRUCTURE)
B23: 10 | C23: Bê tông Mố M1 & M2 trên cạn | D23: Bê tông C30/37 | E23: m³ | F23: 403.75 | G23: ='02_DIEN_GIAI_HA_BO'!J15 | H23: =G23-F23 | I23: =IF(F23=0,0,H23/F23) | J23: =IF(ABS(I23)<0.001," KHỚP 100%"," CẦN SOÁT")
B24: 11 | C24: Cốt thép Mố M1 & M2 | D24: CB400-V (D10 đến D28) | E24: kg | F24: 40954.12 | G24: ='02_DIEN_GIAI_HA_BO'!J16*1000 | H24: =G24-F24 | I24: =IF(F24=0,0,H24/F24) | J24: =IF(ABS(I24)<0.001," KHỚP 100%"," CẦN SOÁT")
B25: 12 | C25: Bê tông Trụ T1 & T2 trên cạn | D25: Bê tông C30/37 (Bệ, thân, xà mũ) | E25: m³ | F25: 1015.22 | G25: ='02_DIEN_GIAI_HA_BO'!J28 | H25: =G25-F25 | I25: =IF(F25=0,0,H25/F25) | J25: =IF(ABS(I25)<0.001," KHỚP 100%"," CẦN SOÁT")
B26: 13 | C26: Cốt thép Trụ T1 & T2 | D26: CB400-V (D12 đến D32) | E26: kg | F26: 126127.25 | G26: ='02_DIEN_GIAI_HA_BO'!J29*1000 | H26: =G26-F26 | I26: =IF(F26=0,0,H26/F26) | J26: =IF(ABS(I26)<0.001," KHỚP 100%"," CẦN SOÁT")
B27: 14 | C27: Bê tông Cọc khoan nhồi D1200mm | D27: Bê tông C30/37 (26 cọc, 872m) | E27: m³ | F27: 1006.54 | G27: ='02_DIEN_GIAI_HA_BO'!J38 | H27: =G27-F27 | I27: =IF(F27=0,0,H27/F27) | J27: =IF(ABS(I27)<0.001," KHỚP 100%"," CẦN SOÁT")
B28: 15 | C28: Cốt thép Cọc khoan nhồi D1200mm | D28: CB400-V (D10, D16, D28) | E28: kg | F28: 108884.17 | G28: ='02_DIEN_GIAI_HA_BO'!J40*1000 | H28: =G28-F28 | I28: =IF(F28=0,0,H28/F28) | J28: =IF(ABS(I28)<0.001," KHỚP 100%"," CẦN SOÁT")
B29: III. KẾT CẤU PHỤ TRỢ (MISCELLANEOUS)
B30: 16 | C30: Bản quá độ BTCT C25 (M1 & M2) | D30: Bê tông C25/30 | E30: m³ | F30: 67.38 | G30: ='03_DIEN_GIAI_PHU_TRO'!J15 | H30: =G30-F30 | I30: =IF(F30=0,0,H30/F30) | J30: =IF(ABS(I30)<0.001," KHỚP 100%"," CẦN SOÁT")
B31: 17 | C31: Bê tông gờ lan can C25 | D31: Bê tông C25/30 | E31: m³ | F31: 104.28 | G31: ='03_DIEN_GIAI_PHU_TRO'!J25 | H31: =G31-F31 | I31: =IF(F31=0,0,H31/F31) | J31: =IF(ABS(I31)<0.001," KHỚP 100%"," CẦN SOÁT")
B32: 18 | C32: Cốt thép gờ lan can & bản quá độ | D32: CB400-V | E32: kg | F32: 29602.42 | G32: ='03_DIEN_GIAI_PHU_TRO'!J26*1000 | H32: =G32-F32 | I32: =IF(F32=0,0,H32/F32) | J32: =IF(ABS(I32)<0.001," KHỚP 100%"," CẦN SOÁT")
B33: 19 | C33: Gối chậu Super-T (B1 đơn & B2 song) | D33: Thép đúc & PTFE (30 gối) | E33: Cái | F33: 30 | G33: ='03_DIEN_GIAI_PHU_TRO'!E34 | H33: =G33-F33 | I33: =IF(F33=0,0,H33/F33) | J33: =IF(ABS(I33)<0.001," KHỚP 100%"," CẦN SOÁT")
B34: 20 | C34: Khe co giãn răng lược WD230 | D34: Thép mạ kẽm (2 khe x 12.25m) | E34: m | F34: 24.5 | G34: ='03_DIEN_GIAI_PHU_TRO'!F40 | H34: =G34-F34 | I34: =IF(F34=0,0,H34/F34) | J34: =IF(ABS(I34)<0.001," KHỚP 100%"," CẦN SOÁT")
B35: 21 | C35: Hè gang & Ống thoát nước mặt cầu | D35: Gang xám & uPVC D150 | E35: Bộ | F35: 24 | G35: ='03_DIEN_GIAI_PHU_TRO'!E48 | H35: =G35-F35 | I35: =IF(F35=0,0,H35/F35) | J35: =IF(ABS(I35)<0.001," KHỚP 100%"," CẦN SOÁT")
B36: IV. ĐƯỜNG SAU MỐ, TỨ NÓN & GIA CỐ
B37: 22 | C37: Đá hộc xây vữa VXM M100 kè tứ nón | D37: Đá hộc VXM M100 | E37: m³ | F37: 104.74 | G37: ='04_DIEN_GIAI_DUONG_TU_NON'!J10 | H37: =G37-F37 | I37: =IF(F37=0,0,H37/F37) | J37: =IF(ABS(I37)<0.001," KHỚP 100%"," CẦN SOÁT")
B38: 23 | C38: Tường chắn bê tông trọng lực C15 | D38: Bê tông C15 | E38: m³ | F38: 115.88 | G38: ='04_DIEN_GIAI_DUONG_TU_NON'!J16 | H38: =G38-F38 | I38: =IF(F38=0,0,H38/F38) | J38: =IF(ABS(I38)<0.001," KHỚP 100%"," CẦN SOÁT")
B39: 24 | C39: Áo đường vuốt nối 10m đầu cầu | D39: BTN rỗng 12.5 & BTNC 19 | E39: m² | F39: 387.97 | G39: ='04_DIEN_GIAI_DUONG_TU_NON'!J30 | H39: =G39-F39 | I39: =IF(F39=0,0,H39/F39) | J39: =IF(ABS(I39)<0.001," KHỚP 100%"," CẦN SOÁT")
B40: 25 | C40: Vật liệu hạt chọn lọc đắp lòng mố K98 | D40: Hạt chọn lọc đầm nén K98 | E40: m³ | F40: 1012.96 | G40: ='04_DIEN_GIAI_DUONG_TU_NON'!J44 | H40: =G40-F40 | I40: =IF(F40=0,0,H40/F40) | J40: =IF(ABS(I40)<0.001," KHỚP 100%"," CẦN SOÁT")

Sheet 00_DANH_MUC_30_BAN_VE_CAD
B2: DANH MỤC TOÀN BỘ 30 BẢN VẼ THIẾT KẾ THI CÔNG - CẦU KM19+529.080
B3: Quét, đo bóc hình học và liên kết kiểm toán 100% hồ sơ bản vẽ
B5: STT | C5: Ký hiệu Bản vẽ | D5: Tên Bản vẽ Thiết kế Kỹ thuật Thi công | E5: Tên Tệp DWG | F5: Thư mục Lưu trữ | G5: Hạng mục Cấu kiện | H5: Mục tiêu Đo bóc Khối lượng | I5: Tình trạng Đo bóc
B6: 1 | C6: 01.GEN-01 | D6: Bình đồ và Bố trí chung Cầu Km19+500 Super-T | E6: BTC CAU KM19+500 SUPER-T.dwg | F6: 01. GEN\06.CAU KM19+529.08 | G6: Toàn cầu | H6: Sơ đồ nhịp 39.1+40+39.1m, khẩu độ thoát nước, cao độ móng mố trụ | I6: ĐÃ ĐO BÓC 100%
B7: 2 | C7: 01.GEN-02 | D7: Trắc dọc Cầu Km19+529.080 | E7: 03.TD_Km19.5.dwg | F7: 01. GEN\06.CAU KM19+529.08 | G7: Toàn cầu | H7: Độ dốc dọc i=1.5%, bán kính đường cong R, chiều dài toàn cầu L=118.2m | I7: ĐÃ ĐO BÓC 100%
B8: 3 | C8: 02.SUP-01 | D8: Bố trí chung Nhịp Cầu Km19+529.08 | E8: 01.BO TRI CHUNG NHIP-Cau km19.5.dwg | F8: 02. SUP\SUPER T 38.2 | G8: Kết cấu nhịp | H8: Khoảng cách tim dầm 2.15-2.27m, 5 dầm/nhịp x 3 nhịp = 15 dầm | I8: ĐÃ ĐO BÓC 100%
B9: 4 | C9: 02.SUP-02 | D9: Bố trí chung Kích thước Hình học Dầm Super-T 38.2m | E9: 02. BO TRI CHUNG DAM.dwg | F9: 02. SUP\SUPER T 38.2 | G9: Dầm chủ Super-T | H9: Phân đốt L1=1.4m (đầu đặc), L2=3.45m (vát sườn), L3=33.35m (chữ U) | I9: ĐÃ ĐO BÓC 100%
B10: 5 | C10: 02.SUP-03 | D10: Bố trí Cáp DƯL 15.2mm & Ống PVC De-bonding | E10: 03. CAP DUL .dwg | F10: 02. SUP\SUPER T 38.2 | G10: Cáp DƯL | H10: 44 tao cáp 15.2mm/dầm, 6 nhóm de-bonding, ống PVC D18/22 L=240m/dầm | I10: ĐÃ ĐO BÓC 100%
B11: 6 | C11: 02.SUP-04 | D11: Bố trí Cốt thép thường Dầm chủ Super-T | E11: 04. COT THEP DAM.dwg | F11: 02. SUP\SUPER T 38.2 | G11: Cốt thép dầm | H11: BBS 23 mã hiệu G1a-G18, K1a-b, tấm đệm đáy dầm 370x540x20mm | I11: ĐÃ ĐO BÓC 100%
B12: 7 | C12: 02.SUP-05 | D12: Bố trí chung & Cốt thép Dầm ngang BTCT | E12: 05 DAM NGANG.dwg | F12: 02. SUP\SUPER T 38.2 | G12: Dầm ngang | H12: Dầm ngang đầu dầm M1/M2 và trụ T1/T2, BT C35 V=19.38 m³, Thép 2.76T | I12: ĐÃ ĐO BÓC 100%
B13: 8 | C13: 02.SUP-06 | D13: Bố trí Tấm ván khuôn BTCT đúc sẵn C25 | E13: 06. TAM DUC SAN.dwg | F13: 02. SUP\SUPER T 38.2 | G13: Tấm đúc sẵn | H13: 510 tấm BT C25 V=13.23 m³, thép D6/D8 2.32T, ván khuôn 504.75 m² | I13: ĐÃ ĐO BÓC 100%
B14: 9 | C14: 02.SUP-07 | D14: Bố trí Bản mặt cầu & Bản liên tục nhiệt | E14: 07.BAN MAT CAU + LTN.dwg | F14: 02. SUP\SUPER T 38.2 | G14: Mặt cầu & LTN | H14: BT C35 V=327.33 m³, Thép 88.36T, cao su đệm 20mm, xốp chèn khe | I14: ĐÃ ĐO BÓC 100%
B15: 10 | C15: 03.SUB-01 | D15: Bố trí chung & Cốt thép Mố M1 và Mố M2 | E15: 01.MO-KM19.5.dwg | F15: 03. SUB\01. mo | G15: Mố M1, M2 | H15: Bệ mố, thân mố, tường đỉnh, tường cánh, đệm đá kê gối, BT C30: 403.75 m³ | I15: ĐÃ ĐO BÓC 100%
B16: 11 | C16: 03.SUB-02 | D16: Bố trí chung & Cốt thép Trụ T1 và Trụ T2 | E16: Trụ-19+500.dwg | F16: 03. SUB\02.tru | G16: Trụ T1, T2 | H16: Bệ trụ, 2 thân cột ovan H=14m & 18m, xà mũ, BT C30: 1,015.22 m³ | I16: ĐÃ ĐO BÓC 100%
... B35: 30 | C35: 05.CON-10 | D35: Tiến độ thi công tổng thể Công trình Cầu | E35: 09.TIEN DO THI CONG.dwg | F35: 05. CON | G35: Tiến độ tổng thể | H35: Kế hoạch thi công 4 giai đoạn: Cọc khoan nhồi -> Hạ bộ -> Bãi đúc dầm -> Thượng bộ | I35: ĐÃ ĐO BÓC 100%

Sheet 01_DIEN_GIAI_SUPER_T
B2: BẢNG DIỄN GIẢI HÌNH HỌC CHI TIẾT KẾT CẤU PHẦN TRÊN (SUPERSTRUCTURE)
B3: 100% Công thức động: Khối lượng = Dài (L) x Rộng (B) x Cao (H) x Số lượng (n) x Hệ số (k)
B5: STT | C5: Mã hiệu | D5: Bộ phận kết cấu & Diễn giải hình học chi tiết | E5: ĐVT | F5: n (Số lượng) | G5: Dài L (m) | H5: Rộng B (m) | I5: Cao/Dày H (m) | J5: Hệ số k / Diện tích F (m²) | K5: Khối lượng Bóc tách (Formula 365) | L5: Ghi chú & Ký hiệu CAD
B6: 1. DẦM CHỦ SUPER-T 38.2M (15 PHIẾN - BÊ TÔNG C45/50)
B7: 1.1 | D7: - Dầm biên S1B1 (2 phiến: D1 nhịp 1 & D15 nhịp 3) | E7: m³ | F7: 2 | G7: 38.2 | H7: 1 | I7: 1 | J7: 29.254 | K7: =ROUND(F7*J7, 3) | L7: mc 1 (1.4m): F=1.156m² | mc 3: F=0.701m²
B8: 1.2 | D8: - Dầm biên S1B2 (3 phiến: D5 nhịp 1, D6 nhịp 2, D11 nhịp 3) | E8: m³ | F8: 3 | G8: 38.2 | H8: 1 | I8: 1 | J8: 29.182 | K8: =ROUND(F8*J8, 3) | L8: mc 1 (1.4m): F=1.156m² | mc 3: F=0.698m²
B9: 1.3 | D9: - Dầm biên S1B3 (1 phiến: D10 nhịp 2) | E9: m³ | F9: 1 | G9: 38.2 | H9: 1 | I9: 1 | J9: 28.996 | K9: =ROUND(F9*J9, 3) | L9: mc 1 (1.4m): F=1.156m² | mc 3: F=0.691m²
B10: 1.4 | D10: - Dầm giữa S1G (9 phiến: D2,3,4 N1; D7,8,9 N2; D12,13,14 N3) | E10: m³ | F10: 9 | G10: 38.2 | H10: 1 | I10: 1 | J10: 28.833 | K10: =ROUND(F10*J10, 3) | L10: mc 1 (1.4m): F=1.156m² | mc 3: F=0.686m²
C11: Cộng Bê tông C45 dầm chủ (15 phiến): | K11: =SUM(K7:K10) | L11: 434.55 m³
B12: 2. CÁP DƯL 15.2MM KÉO TRƯỚC & ỐNG PVC DE-BONDING
B13: 2.1 | D13: - Cáp DƯL 15.2mm (44 tao/dầm x 41.2m/tao x 15 phiến) | E13: kg | F13: 15 | G13: 41.2 | H13: 44 | I13: 1.1 | J13: 1 | K13: =ROUND(F13*G13*H13*I13*J13, 2) | L13: 44 tao cáp kéo trước, q=1.10 kg/m
B14: 2.2 | D14: - Ống nhựa PVC D18/22 bọc de-bonding đầu dầm | E14: m | F14: 15 | G14: 240 | H14: 1 | I14: 1 | J14: 1 | K14: =ROUND(F14*G14, 0) | L14: 6 nhóm de-bonding (0m đến 8m)
B15: 2.3 | D15: - Móc cẩu dầm D32 (cáp nâng hạ) | E15: m | F15: 15 | G15: 32 | H15: 1 | I15: 1 | J15: 1 | K15: =ROUND(F15*G15, 0) | L15: 4 móc cẩu/dầm x 8m
C16: Cộng Cáp DƯL 15.2mm (Tấn): | K16: =K13/1000 | L16: 29.911 Tấn
B17: 3. CỐT THÉP THƯỜNG THÂN DẦM SUPER-T (BBS 23 MÃ HIỆU G1a..K1b)
B18: 3.1 | D18: - Cốt thép nhóm 10 < D <= 18mm (G1a đến G15, K1a) | E18: kg | F18: 15 | G18: 5181.45 | H18: 1 | I18: 1 | J18: 1 | K18: =ROUND(F18*G18, 2) | L18: 77,721.76 kg thép sườn, bản cánh, đai
B19: 3.2 | D19: - Cốt thép nhóm D > 18mm (G16, G17, G18, K1b) | E19: kg | F19: 15 | G19: 796.47 | H19: 1 | I19: 1 | J19: 1 | K19: =ROUND(F19*G19, 2) | L19: 11,947.05 kg thép chịu lực cục bộ
B20: 3.3 | D20: - Tấm thép đệm đáy dầm (370x540x20mm mạ kẽm) | E20: kg | F20: 15 | G20: 2 | H20: 0.37 | I20: 0.54 | J20: 157 | K20: =ROUND(F20*G20*H20*I20*J20, 2) | L20: 30 tấm đệm kê đáy dầm = 941.10 kg
C21: Cộng Cốt thép thường dầm chủ (Tấn): | K21: =(K18+K19)/1000 | L21: 89.669 Tấn
B22: 4. VÁN KHUÔN DẦM CHỦ SUPER-T 38.2M
B23: 4.1 | D23: - Ván khuôn dầm biên S1B1 (2 phiến) | E23: m² | F23: 2 | G23: 343.132 | H23: 1 | I23: 1 | J23: 1 | K23: =ROUND(F23*G23, 2) | L23: Thành ngoài, đáy, ván khuôn lòng chữ U
B24: 4.2 | D24: - Ván khuôn dầm biên S1B2 (3 phiến) | E24: m² | F24: 3 | G24: 342.173 | H24: 1 | I24: 1 | J24: 1 | K24: =ROUND(F24*G24, 2) | L24: Thành ngoài, đáy, ván khuôn lòng chữ U
B25: 4.3 | D25: - Ván khuôn dầm biên S1B3 (1 phiến) | E25: m² | F25: 1 | G25: 339.681 | H25: 1 | I25: 1 | J25: 1 | K25: =ROUND(F25*G25, 2) | L25: Thành ngoài, đáy, ván khuôn lòng chữ U
B26: 4.4 | D26: - Ván khuôn dầm giữa S1G (9 phiến) | E26: m² | F26: 9 | G26: 338.478 | H26: 1 | I26: 1 | J26: 1 | K26: =ROUND(F26*G26, 2) | L26: Thành dầm, đáy dầm, ván khuôn chữ U
C27: Cộng Ván khuôn dầm chủ: | K27: =SUM(K23:K26) | L27: 5,098.77 m²
B28: 5. DẦM NGANG BTCT C35 (3 NHỊP)
B29: 5.1 | D29: - Dầm ngang đầu dầm tại Mố M1 & M2 (2 vị trí) | E29: m³ | F29: 2 | G29: 11.2 | H29: 0.65 | I29: 0.35 | J29: 1 | K29: =ROUND(F29*G29*H29*I29*J29, 3) | L29: Liên kết ngang đầu dầm mố
B30: 5.2 | D30: - Dầm ngang trên Trụ T1 & T2 (2 vị trí) | E30: m³ | F30: 2 | G30: 11.2 | H30: 0.85 | I30: 0.45 | J30: 1.25 | K30: =ROUND(F30*G30*H30*I30*J30, 3) | L30: Liên kết ngang trên đỉnh trụ
B31: 5.3 | D31: - Cốt thép dầm ngang (D<=18mm: 2,419.29 kg; D>18: 343.83 kg) | E31: kg | F31: 1 | G31: 2763.12 | H31: 1 | I31: 1 | J31: 1 | K31: =ROUND(F31*G31, 2) | L31: 2,763.12 kg thép CB400-V
B32: 5.4 | D32: - Ván khuôn dầm ngang thành bên và đáy dầm | E32: m² | F32: 1 | G32: 48.216 | H32: 1 | I32: 1 | J32: 1 | K32: =ROUND(F32*G32, 2) | L32: 48.22 m² ván khuôn thép
B33: 5.5 | D33: - Bộ nối ren D16 chờ liên kết dầm ngang | E33: Bộ | F33: 1 | G33: 384 | H33: 1 | I33: 1 | J33: 1 | K33: =ROUND(F33*G33, 0) | L33: 384 bộ nối ren thép
C34: Cộng Bê tông Dầm ngang C35: | K34: =SUM(K29:K30) | L34: 19.38 m³
B35: 6. BẢN MẶT CẦU & BẢN LIÊN TỤC NHIỆT BTCT C35
B36: 6.1 | D36: - Bản mặt cầu Nhịp 1 (L=38.2m, B=12.0m, d=0.20m, vát cánh dầm) | E36: m³ | F36: 1 | G36: 38.2 | H36: 12 | I36: 0.2 | J36: 1.112 | K36: =ROUND(F36*G36*H36*I36*J36, 3) | L36: Bê tông C35 đổ tại chỗ
B37: 6.2 | D37: - Bản mặt cầu Nhịp 2 (L=38.2m, B=12.0m, d=0.20m, vát cánh dầm) | E37: m³ | F37: 1 | G37: 38.2 | H37: 12 | I37: 0.2 | J37: 1.112 | K37: =ROUND(F37*G37*H37*I37*J37, 3) | L37: Bê tông C35 đổ tại chỗ
B38: 6.3 | D38: - Bản mặt cầu Nhịp 3 (L=38.2m, B=12.0m, d=0.20m, vát cánh dầm) | E38: m³ | F38: 1 | G38: 38.2 | H38: 12 | I38: 0.2 | J38: 1.112 | K38: =ROUND(F38*G38*H38*I38*J38, 3) | L38: Bê tông C35 đổ tại chỗ
B39: 6.4 | D39: - Bản liên tục nhiệt tại đỉnh Trụ T1 (L=1.2m, B=12.0m, d=0.20m) | E39: m³ | F39: 1 | G39: 1.2 | H39: 12 | I39: 0.2 | J39: 3.8 | K39: =ROUND(F39*G39*H39*I39*J39, 3) | L39: Bê tông C35 liên tục nhiệt
B40: 6.5 | D40: - Bản liên tục nhiệt tại đỉnh Trụ T2 (L=1.2m, B=12.0m, d=0.20m) | E40: m³ | F40: 1 | G40: 1.2 | H40: 12 | I40: 0.2 | J40: 3.8 | K40: =ROUND(F40*G40*H40*I40*J40, 3) | L40: Bê tông C35 liên tục nhiệt
B41: 6.6 | D41: - Cốt thép Bản mặt cầu & Bản LTN (D<=18: 80.52T; D>18: 5.07T) | E41: kg | F41: 1 | G41: 85594.39 | H41: 1 | I41: 1 | J41: 1 | K41: =ROUND(F41*G41, 2) | L41: 85,594.39 kg thép CB400-V
B42: 6.7 | D42: - Ván khuôn cạnh bản mặt cầu & liên tục nhiệt | E42: m² | F42: 1 | G42: 57.036 | H42: 1 | I42: 1 | J42: 1 | K42: =ROUND(F42*G42, 2) | L42: 57.04 m² ván khuôn cạnh
...

Sheet 02_DIEN_GIAI_HA_BO
B2: BẢNG DIỄN GIẢI HÌNH HỌC CHI TIẾT KẾT CẤU PHẦN DƯỚI (SUBSTRUCTURE)
B3: Mố M1 chân dê, Mố M2 chữ U, Trụ T1, T2 (2 thân ovan) & Cọc khoan nhồi D1200mm đại trà 26 cọc
B5: STT | C5: Mã hiệu | D5: Bộ phận kết cấu & Diễn giải hình học chi tiết | E5: ĐVT | F5: n (Số lượng) | G5: Dài L (m) | H5: Rộng B (m) | I5: Cao/Dày H (m) | J5: Hệ số k / Diện tích F (m²) | K5: Khối lượng Bóc tách (Formula 365) | L5: Ghi chú & Ký hiệu CAD
B6: 1. MỐ M1 CHÂN DÊ & MỐ M2 CHỮ U TRÊN CẠN (BÊ TÔNG C30/37)
B7: 1.1 | D7: - Bệ móng mố M1 chân dê (chiều cao h=1.5m) | E7: m³ | F7: 1 | G7: 12 | H7: 4.5 | I7: 1.5 | J7: 1 | K7: =ROUND(F7*G7*H7*I7*J7, 3) | L7: Bệ móng chân dê mác C30
B8: 1.2 | D8: - Thân mố M1, tường đỉnh & tường cánh | E8: m³ | F8: 1 | G8: 11.2 | H8: 1.5 | I8: 4.2 | J8: 1.478 | K8: =ROUND(F8*G8*H8*I8*J8, 3) | L8: Thân mố, tường ngực, tai mố C30
B9: 1.3 | D9: - Đá kê gối C40 mố M1 (5 bệ kê gối) | E9: m³ | F9: 5 | G9: 0.5 | H9: 0.6 | I9: 0.2 | J9: 1 | K9: =ROUND(F9*G9*H9*I9*J9, 3) | L9: Bê tông C40 đá kê gối
B10: 1.4 | D10: - Bê tông lót đáy bệ mố M1 mác C10 (dày 10cm) | E10: m³ | F10: 1 | G10: 12.4 | H10: 4.9 | I10: 0.1 | J10: 1 | K10: =ROUND(F10*G10*H10*I10*J10, 3) | L10: Bê tông lót đáy bệ M1
B11: 1.5 | D11: - Bệ móng mố M2 chữ U (chiều cao h=2.0m) | E11: m³ | F11: 1 | G11: 13.5 | H11: 5.5 | I11: 2 | J11: 1 | K11: =ROUND(F11*G11*H11*I11*J11, 3) | L11: Bệ móng mố chữ U mác C30
B12: 1.6 | D12: - Thân mố M2, tường đỉnh & tường cánh chữ U | E12: m³ | F12: 1 | G12: 12.5 | H12: 1.8 | I12: 5.2 | J12: 0.594 | K12: =ROUND(F12*G12*H12*I12*J12, 3) | L12: Thân mố, tường đỉnh, cánh mố C30
B13: 1.7 | D13: - Đá kê gối C40 mố M2 (5 bệ kê gối) | E13: m³ | F13: 5 | G13: 0.5 | H13: 0.6 | I13: 0.183 | J13: 1 | K13: =ROUND(F13*G13*H13*I13*J13, 3) | L13: Bê tông C40 đá kê gối
B14: 1.8 | D14: - Bê tông lót đáy bệ mố M2 mác C10 (dày 10cm) | E14: m³ | F14: 1 | G14: 13.9 | H14: 5.9 | I14: 0.1 | J14: 1 | K14: =ROUND(F14*G14*H14*I14*J14, 3) | L14: Bê tông lót đáy bệ M2
B15: 1.9 | D15: - Cốt thép mố M1 & M2 (M1: 18.25T; M2: 22.70T) | E15: Tấn | F15: 1 | G15: 40.954 | H15: 1 | I15: 1 | J15: 1 | K15: =ROUND(F15*G15, 3) | L15: 40,954.12 kg thép CB400-V
B16: 1.10 | D16: - Ván khuôn mố M1 & M2 (thành bệ, thân mố, tường ngực) | E16: m² | F16: 1 | G16: 490.38 | H16: 1 | I16: 1 | J16: 1 | K16: =ROUND(F16*G16, 2) | L16: 490.38 m² ván khuôn thép
C17: Cộng Bê tông C30 Mố M1 & M2: | K17: =SUM(K7:K8)+SUM(K11:K12) | L17: 403.75 m³
B18: 2. TRỤ T1 & T2 TRÊN CẠN (2 THÂN OVAN, BÊ TÔNG C30/37)
B19: 2.1 | D19: - Bệ móng trụ T1 thân đặc (chiều cao h=2.5m) | E19: m³ | F19: 1 | G19: 12.3 | H19: 6 | I19: 2.5 | J19: 1 | K19: =ROUND(F19*G19*H19*I19*J19, 3) | L19: Bệ móng trụ T1 mác C30
B20: 2.2 | D20: - Thân trụ T1 (2 thân ovan, H=14.0m, F_ovan=7.15m²) | E20: m³ | F20: 2 | G20: 14 | H20: 1 | I20: 1 | J20: 7.15 | K20: =ROUND(F20*G20*J20, 3) | L20: 200.20 m³ thân trụ ovan T1
B21: 2.3 | D21: - Xà mũ trụ T1, tường tai & ụ chống xô | E21: m³ | F21: 1 | G21: 12 | H21: 2.2 | I21: 1.65 | J21: 1.666 | K21: =ROUND(F21*G21*H21*I21*J21, 3) | L21: 72.51 m³ xà mũ đúc tại chỗ
B22: 2.4 | D22: - Bê tông lót đáy bệ trụ T1 mác C10 (dày 10cm) | E22: m³ | F22: 1 | G22: 12.7 | H22: 6.4 | I22: 0.1 | J22: 1 | K22: =ROUND(F22*G22*H22*I22*J22, 3) | L22: Bê tông lót đáy bệ T1
B23: 2.5 | D23: - Bệ móng trụ T2 thân đặc (chiều cao h=2.5m) | E23: m³ | F23: 1 | G23: 12.3 | H23: 6 | I23: 2.5 | J23: 1 | K23: =ROUND(F23*G23*H23*I23*J23, 3) | L23: Bệ móng trụ T2 mác C30
B24: 2.6 | D24: - Thân trụ T2 (2 thân ovan, H=18.0m, F_ovan=7.15m²) | E24: m³ | F24: 2 | G24: 18 | H24: 1 | I24: 1 | J24: 7.15 | K24: =ROUND(F24*G24*J24, 3) | L24: 257.40 m³ thân trụ ovan T2
B25: 2.7 | D25: - Xà mũ trụ T2, tường tai & ụ chống xô | E25: m³ | F25: 1 | G25: 12 | H25: 2.2 | I25: 1.65 | J25: 1.666 | K25: =ROUND(F25*G25*H25*I25*J25, 3) | L25: 72.51 m³ xà mũ đúc tại chỗ
B26: 2.8 | D26: - Bê tông lót đáy bệ trụ T2 mác C10 (dày 10cm) | E26: m³ | F26: 1 | G26: 12.7 | H26: 6.4 | I26: 0.1 | J26: 1 | K26: =ROUND(F26*G26*H26*I26*J26, 3) | L26: Bê tông lót đáy bệ T2
B27: 2.9 | D27: - Cốt thép trụ T1 & T2 (T1: 58.42T; T2: 67.71T) | E27: Tấn | F27: 1 | G27: 126.127 | H27: 1 | I27: 1 | J27: 1 | K27: =ROUND(F27*G27, 3) | L27: 126,127.25 kg thép CB400-V
B28: 2.10 | D28: - Ván khuôn trụ T1 & T2 (bệ, thân ovan leo, xà mũ) | E28: m² | F28: 1 | G28: 1063.51 | H28: 1 | I28: 1 | J28: 1 | K28: =ROUND(F28*G28, 2) | L28: 1,063.51 m² ván khuôn thép
C29: Cộng Bê tông C30 Trụ T1 & T2: | K29: =SUM(K19:K21)+SUM(K23:K25) | L29: 1,015.22 m³
B30: 3. CỌC KHOAN NHỒI D1200MM ĐẠI TRÀ (26 CỌC, TỔNG DÀI L=872M)
B31: 3.1 | D31: - Cọc mố M1 (4 cọc x chiều sâu L=20.0m) | E31: m | F31: 4 | G31: 20 | H31: 1 | I31: 1 | J31: 1 | K31: =ROUND(F31*G31, 1) | L31: 80.0m cọc khoan nhồi M1
B32: 3.2 | D32: - Cọc trụ T1 (9 cọc x chiều sâu L=40.0m) | E32: m | F32: 9 | G32: 40 | H32: 1 | I32: 1 | J32: 1 | K32: =ROUND(F32*G32, 1) | L32: 360.0m cọc khoan nhồi T1
B33: 3.3 | D33: - Cọc trụ T2 (9 cọc x chiều sâu L=32.0m) | E33: m | F33: 9 | G33: 32 | H33: 1 | I33: 1 | J33: 1 | K33: =ROUND(F33*G33, 1) | L33: 288.0m cọc khoan nhồi T2
B34: 3.4 | D34: - Cọc mố M2 (4 cọc x chiều sâu L=36.0m) | E34: m | F34: 4 | G34: 36 | H34: 1 | I34: 1 | J34: 1 | K34: =ROUND(F34*G34, 1) | L34: 144.0m cọc khoan nhồi M2
B35: 3.5 | D35: - Bê tông cọc D1200 C30 mố M1 (hs nở thành k=1.02) | E35: m³ | F35: 4 | G35: 20 | H35: 0.6 | I35: 0.6 | J35: 3.2044 | K35: =ROUND(F35*G35*H35*I35*J35, 3) | L35: 92.34 m³ bê tông C30 rút tremie
B36: 3.6 | D36: - Bê tông cọc D1200 C30 trụ T1 (hs nở thành k=1.02) | E36: m³ | F36: 9 | G36: 40 | H36: 0.6 | I36: 0.6 | J36: 3.2044 | K36: =ROUND(F36*G36*H36*I36*J36, 3) | L36: 415.54 m³ bê tông C30 rút tremie
B37: 3.7 | D37: - Bê tông cọc D1200 C30 trụ T2 (hs nở thành k=1.02) | E37: m³ | F37: 9 | G37: 32 | H37: 0.6 | I37: 0.6 | J37: 3.2044 | K37: =ROUND(F37*G37*H37*I37*J37, 3) | L37: 332.43 m³ bê tông C30 rút tremie
B38: 3.8 | D38: - Bê tông cọc D1200 C30 mố M2 (hs nở thành k=1.02) | E38: m³ | F38: 4 | G38: 36 | H38: 0.6 | I38: 0.6 | J38: 3.2044 | K38: =ROUND(F38*G38*H38*I38*J38, 3) | L38: 166.23 m³ bê tông C30 rút tremie
B39: 3.9 | D39: - Bê tông đập đầu cọc (26 cọc x h=1.0m đập ngàm bệ) | E39: m³ | F39: 26 | G39: 1 | H39: 0.6 | I39: 0.6 | J39: 3.2436 | K39: =ROUND(F39*G39*H39*I39*J39, 3) | L39: 30.36 m³ đập đầu cọc
B40: 3.10 | D40: - Vữa mác 30Mpa lấp lòng ống siêu âm sonic | E40: m³ | F40: 1 | G40: 14.43 | H40: 1 | I40: 1 | J40: 1 | K40: =ROUND(F40*G40, 2) | L40: 14.43 m³ vữa lấp sonic
B41: 3.11 | D41: - Cốt thép cọc khoan nhồi D1200 (Thép chủ D28/D25, đai D16, D10) | E41: Tấn | F41: 1 | G41: 108.884 | H41: 1 | I41: 1 | J41: 1 | K41: =ROUND(F41*G41, 3) | L41: 108,884.17 kg thép CB400-V
B42: 3.12 | D42: - Ống siêu âm sonic thép M1 (D53.9/59.9mm) | E42: m | F42: 1 | G42: 2772 | H42: 1 | I42: 1 | J42: 1 | K42: =ROUND(F42*G42, 1) | L42: 2,772.0m ống siêu âm M1
...

Sheet 03_DIEN_GIAI_PHU_TRO
B2: BẢNG DIỄN GIẢI HÌNH HỌC CHI TIẾT KẾT CẤU PHỤ TRỢ (MISCELLANEOUS)
B3: Bản quá độ M1/M2, Gờ lan can BTCT, Lan can tay vịn thép mạ kẽm, Gối chậu 30 gối, Khe co giãn & Thoát nước
B5: STT | C5: Mã hiệu | D5: Bộ phận kết cấu & Diễn giải hình học chi tiết | E5: ĐVT | F5: n (Số lượng) | G5: Dài L (m) | H5: Rộng B (m) | I5: Cao/Dày H (m) | J5: Hệ số k / Diện tích F (m²) | K5: Khối lượng Bóc tách (Formula 365) | L5: Ghi chú & Ký hiệu CAD
B6: 1. BẢN QUÁ ĐỘ BTCT C25 (MỐ M1 & M2)
B7: 1.1 | D7: - Thân bản quá độ Mố M1 (L=4.0m, B=8.45m, d=0.30m, vát góc) | E7: m³ | F7: 1 | G7: 4 | H7: 8.45 | I7: 0.3 | J7: 3.775 | K7: =ROUND(F7*G7*H7*I7*J7, 3) | L7: 38.28 m³ bê tông C25 bản M1
B8: 1.2 | D8: - Bê tông lót đáy bản quá độ M1 mác C10 (dày 10cm) | E8: m³ | F8: 1 | G8: 4.4 | H8: 8.85 | I8: 0.1 | J8: 2.342 | K8: =ROUND(F8*G8*H8*I8*J8, 3) | L8: 9.12 m³ bê tông lót C10 M1
B9: 1.3 | D9: - Cốt thép bản quá độ M1 (BBS A1..A7: D10 đến D20) | E9: kg | F9: 1 | G9: 3964.44 | H9: 1 | I9: 1 | J9: 1 | K9: =ROUND(F9*G9, 2) | L9: 3,964.44 kg thép CB400-V
B10: 1.4 | D10: - Ván khuôn bản quá độ M1 (thành biên, đầu bản) | E10: m² | F10: 1 | G10: 18.15 | H10: 1 | I10: 1 | J10: 1 | K10: =ROUND(F10*G10, 2) | L10: 18.15 m² ván khuôn
B11: 1.5 | D11: - Thân bản quá độ Mố M2 (L=5.0m, B=8.45m, d=0.30m, vát góc) | E11: m³ | F11: 1 | G11: 5 | H11: 8.45 | I11: 0.3 | J11: 2.296 | K11: =ROUND(F11*G11*H11*I11*J11, 3) | L11: 29.10 m³ bê tông C25 bản M2
B12: 1.6 | D12: - Bê tông lót đáy bản quá độ M2 mác C10 (dày 10cm) | E12: m³ | F12: 1 | G12: 5.4 | H12: 8.85 | I12: 0.1 | J12: 1.427 | K12: =ROUND(F12*G12*H12*I12*J12, 3) | L12: 6.82 m³ bê tông lót C10 M2
B13: 1.7 | D13: - Cốt thép bản quá độ M2 (BBS A1..A7: D10 đến D22) | E13: kg | F13: 1 | G13: 5568.96 | H13: 1 | I13: 1 | J13: 1 | K13: =ROUND(F13*G13, 2) | L13: 5,568.96 kg thép CB400-V
B14: 1.8 | D14: - Ván khuôn bản quá độ M2 (thành biên, đầu bản) | E14: m² | F14: 1 | G14: 16.55 | H14: 1 | I14: 1 | J14: 1 | K14: =ROUND(F14*G14, 2) | L14: 16.55 m² ván khuôn
C15: Cộng Bê tông C25 Bản quá độ (M1 + M2): | K15: =K7+K11 | L15: 67.38 m³
B16: 2. GỜ LAN CAN BTCT C25 & BỆ CỘT ĐÈN (40 ĐỐT GỜ)
B17: 2.1 | D17: - Đốt gờ loại A1 (19 đốt x L=5.91m x F_mc=0.548m²) | E17: m³ | F17: 19 | G17: 5.91 | H17: 1 | I17: 1 | J17: 0.547 | K17: =ROUND(F18*G18*J18, 3) | L17: 61.42 m³ gờ lan can A1
B18: 2.2 | D18: - Đốt gờ loại A2 (1 đốt x L=4.12m x F_mc=0.548m²) | E18: m³ | F18: 1 | G18: 4.12 | H18: 1 | I18: 1 | J18: 0.55 | K18: =ROUND(F19*G19*J19, 3) | L18: 2.27 m³ gờ lan can A2
B19: 2.3 | D19: - Đốt gờ loại B1 (19 đốt x L=5.91m x F_mc=0.349m²) | E19: m³ | F19: 19 | G19: 5.91 | H19: 1 | I19: 1 | J19: 0.349 | K19: =ROUND(F20*G20*J20, 3) | L19: 39.15 m³ gờ lan can B1
B20: 2.4 | D20: - Đốt gờ loại B2 (1 đốt x L=4.12m x F_mc=0.349m²) | E20: m³ | F20: 1 | G20: 4.12 | H20: 1 | I20: 1 | J20: 0.351 | K20: =ROUND(F21*G21*J21, 3) | L20: 1.44 m³ gờ lan can B2
B21: 2.5 | D21: - Cốt thép gờ lan can (BBS G1..G8C: 10<D<=18 là 13.67T; D>18: 6.39T) | E21: kg | F21: 1 | G21: 20069.02 | H21: 1 | I21: 1 | J21: 1 | K21: =ROUND(F22*G22, 2) | L21: 20,069.02 kg thép CB400-V
B22: 2.6 | D22: - Ván khuôn gờ lan can 40 đốt (mặt trong, mặt ngoài, đỉnh) | E22: m² | F22: 1 | G22: 638.94 | H22: 1 | I22: 1 | J22: 1 | K22: =ROUND(F23*G23, 2) | L22: 638.94 m² ván khuôn thép
B23: 2.7 | D23: - Ống PVC D125 luồn cáp điện chiếu sáng | E23: m | F23: 1 | G23: 118.3 | H23: 1 | I23: 1 | J23: 1 | K23: =ROUND(F24*G24, 1) | L23: 118.3m ống nhựa PVC D125
C24: Cộng Bê tông Gờ lan can C25: | K24: =SUM(K18:K21) | L24: 104.28 m³
B25: 3. LAN CAN TAY VỊN THÉP MẠ KẼM & BU LÔNG NEO M22
B26: 3.1 | D26: - Thép ống lan can (Ống P1/P2 D114x3.5; H1/H2 D76x3.5; C1/C2) | E26: kg | F26: 1 | G26: 606.9 | H26: 1 | I26: 1 | J26: 1 | K26: =ROUND(F27*G27, 2) | L26: 606.90 kg thép ống mạ kẽm
B27: 3.2 | D27: - Thép bản định hình mạ kẽm chân cột & sườn gia cường (N1..N12) | E27: kg | F27: 1 | G27: 526.55 | H27: 1 | I27: 1 | J27: 1 | K27: =ROUND(F28*G28, 2) | L27: 526.55 kg thép bản mạ kẽm
B28: 3.3 | D28: - Bu lông neo chân cột M22 L=650mm | E28: kg | F28: 44 | G28: 1.94 | H28: 1 | I28: 1 | J28: 1 | K28: =ROUND(F29*G29, 2) | L28: 44 cái bu lông M22 = 85.36 kg
C29: Cộng Lan can thép mạ kẽm (kg): | K29: =SUM(K27:K29) | L29: 1,218.81 kg
B30: 4. GỐI CHẬU SUPER-T (15 GỐI B1 ĐƠN HƯỚNG & 15 GỐI B2 SONG HƯỚNG)
B31: 4.1 | D31: - Gối chậu đơn hướng B1 (390x560x110mm: M1: 5; P2: 5; M2: 5) | E31: Cái | F31: 15 | G31: 1 | H31: 1 | I31: 1 | J31: 1 | K31: =ROUND(F32, 0) | L31: 15 gối chậu B1
B32: 4.2 | D32: - Gối chậu song hướng B2 (620x327x110mm: P1: 10; P2: 5) | E32: Cái | F32: 15 | G32: 1 | H32: 1 | I32: 1 | J32: 1 | K32: =ROUND(F33, 0) | L32: 15 gối chậu B2
B33: 4.3 | D33: - Thép bản đệm gối mạ kẽm (t=25mm) | E33: kg | F33: 30 | G33: 49.59 | H33: 1 | I33: 1 | J33: 1 | K33: =ROUND(F34*G34, 2) | L33: 1,487.68 kg thép bản mạ kẽm
B34: 4.4 | D34: - Bu lông neo gối M20 (4 bu lông / gối) | E34: Bộ | F34: 30 | G34: 4 | H34: 1 | I34: 1 | J34: 1 | K34: =ROUND(F35*G35, 0) | L34: 120 bộ bu lông M20
B35: 4.5 | D35: - Vữa không co ngót đệm gối C40 (dày 25mm) | E35: m³ | F35: 30 | G35: 0.0194 | H35: 1 | I35: 1 | J35: 1 | K35: =ROUND(F36*G36, 3) | L35: 0.58 m³ vữa đệm gối
C36: Cộng Số lượng Gối chậu Super-T: | K36: =K32+K33 | L36: 30 Cái
B37: 5. KHE CO GIÃN RĂNG LƯỢC WD230 (MỐ M1 & M2, TỔNG DÀI L=24.5M)
B38: 5.1 | D38: - Chiều dài khe co giãn răng lược WD230 (2 khe x L=12.25m) | E38: m | F38: 2 | G38: 12.25 | H38: 1 | I38: 1 | J38: 1 | K38: =ROUND(F39*G39, 2) | L38: 24.50m khe co giãn
B39: 5.2 | D39: - Bê tông cốt liệu nhỏ không co ngót C40 hố chờ KCG | E39: m³ | F39: 2 | G39: 12.25 | H39: 0.4 | I39: 0.238 | J39: 1 | K39: =ROUND(F40*G40*H40*I40*J40, 3) | L39: 4.67 m³ bê tông C40
B40: 5.3 | D40: - Cốt thép neo KCG (BBS K1, K2, K3: D16mm) | E40: kg | F40: 2 | G40: 679.9 | H40: 1 | I40: 1 | J40: 1 | K40: =ROUND(F41*G41, 2) | L40: 1,359.80 kg thép D16 CB400-V
B41: 5.4 | D41: - Tấm thép mạ kẽm chắn rác (1266x350x4 & 1565x350x4) | E41: kg | F41: 2 | G41: 31.11 | H41: 1 | I41: 1 | J41: 1 | K41: =ROUND(F42*G42, 2) | L41: 62.23 kg tấm thép mạ kẽm
B42: 5.5 | D42: - Bu lông liên kết M16x180 & M12x60 | E42: Bộ | F42: 2 | G42: 131 | H42: 1 | I42: 1 | J42: 1 | K42: =ROUND(F43*G43, 0) | L42: 262 bộ bu lông neo
...

Sheet 04_DIEN_GIAI_DUONG_TU_NON
B2: BẢNG DIỄN GIẢI HÌNH HỌC CHI TIẾT ĐƯỜNG SAU MỐ, TỨ NÓN & KÈ GIA CỐ
B3: Kè tứ nón đá hộc xây, Tường chắn BT C15, Áo đường vuốt nối 10 lớp & Vật liệu hạt đắp lòng mố K98
B5: STT | C5: Mã hiệu | D5: Bộ phận kết cấu & Diễn giải hình học chi tiết | E5: ĐVT | F5: n (Số lượng) | G5: Dài L (m) | H5: Rộng B (m) | I5: Cao/Dày H (m) | J5: Hệ số k / Diện tích F (m²) | K5: Khối lượng Bóc tách (Formula 365) | L5: Ghi chú & Ký hiệu CAD
B6: 1. TỨ NÓN, KÈ ĐÁ HỘC XÂY VỮA VXM M100 & CHÂN KHAY (MỐ M1, M2)
B7: 1.1 | D7: - Mái kè tứ nón mố M1 (diện tích mái F=322.69m² x dày 30cm) | E7: m³ | F7: 1 | G7: 322.69 | H7: 0.3 | I7: 1 | J7: 1 | K7: =ROUND(F7*G7*H7*I7*J7, 3) | L7: 96.81 m³ đá hộc xây VXM M100 M1
B8: 1.2 | D8: - Mái kè tứ nón mố M2 (diện tích mái F=26.44m² x dày 30cm) | E8: m³ | F8: 1 | G8: 26.44 | H8: 0.3 | I8: 1 | J8: 1 | K8: =ROUND(F8*G8*H8*I8*J8, 3) | L8: 7.93 m³ đá hộc xây VXM M100 M2
B9: 1.3 | D9: - Đá dăm đệm dày 10cm dưới mái kè đá hộc (M1: 40.36m²; M2: 3.83m²) | E9: m² | F9: 1 | G9: 44.195 | H9: 1 | I9: 1 | J9: 1 | K9: =ROUND(F9*G9, 2) | L9: 44.20 m² lớp đệm lọc
B10: 1.4 | D10: - Chân khay đá hộc chống trượt mố M2 (0.5m x 0.8m x 10m) | E10: m³ | F10: 1 | G10: 10 | H10: 0.5 | I10: 0.8 | J10: 1 | K10: =ROUND(F10*G10*H10*I10*J10, 3) | L10: 4.00 m³ chân khay đá hộc
C11: Cộng Đá hộc xây vữa VXM M100 kè tứ nón: | K11: =K7+K8 | L11: 104.74 m³
B12: 2. TƯỜNG CHẮN BÊ TÔNG TRỌNG LỰC C15 (MỐ M2)
B13: 2.1 | D13: - Thân tường chắn bê tông C15 (L=24.5m, H_tb=4.5m, B_tb=1.05m) | E13: m³ | F13: 1 | G13: 24.5 | H13: 1.05 | I13: 4.5 | J13: 1 | K13: =ROUND(F13*G13*H13*I13*J13, 3) | L13: 115.88 m³ bê tông C15
B14: 2.2 | D14: - Ván khuôn tường chắn bê tông C15 (mặt trước, sau, đỉnh) | E14: m² | F14: 1 | G14: 194.032 | H14: 1 | I14: 1 | J14: 1 | K14: =ROUND(F14*G14, 2) | L14: 194.03 m² ván khuôn thép
B15: 2.3 | D15: - Bê tông đệm móng tường chắn C10 (L=24.5m x 1.5m x 0.10m) | E15: m³ | F15: 1 | G15: 24.5 | H15: 1.5 | I15: 0.1 | J15: 0.993 | K15: =ROUND(F15*G15*H15*I15*J15, 3) | L15: 3.65 m³ bê tông lót C10
B16: 2.4 | D16: - Ống thoát nước tường chắn PVC D90 | E16: m | F16: 1 | G16: 21.4 | H16: 1 | I16: 1 | J16: 1 | K16: =ROUND(F16*G16, 1) | L16: 21.4m ống thoát nước
B17: 2.5 | D17: - Quét Bitum 2 lớp mặt sau tường chắn | E17: m² | F17: 1 | G17: 119.2 | H17: 1 | I17: 1 | J17: 1 | K17: =ROUND(F17*G17, 2) | L17: 119.20 m² quét phòng nước
B18: 2.6 | D18: - Đắp đất hoàn trả hố móng tường chắn K90 | E18: m³ | F18: 1 | G18: 14.27 | H18: 1 | I18: 1 | J18: 1 | K18: =ROUND(F18*G18, 2) | L18: 14.27 m³ đắp hoàn trả
C19: Cộng Bê tông Tường chắn C15: | K19: =K13 | L19: 115.88 m³
B20: 3. KẾT CẤU ÁO ĐƯỜNG VUỐT NỐI 10M ĐẦU CẦU (MỐ M1 & M2, TỔNG S=387.97M²)
B21: 3.1 | D21: - Lớp hỗn hợp nhựa rỗng thoát nước 12.5 (dày 4cm) | E21: m² | F21: 2 | G21: 193.9825 | H21: 1 | I21: 1 | J21: 1 | K21: =ROUND(F21*G21, 2) | L21: 387.97 m² lớp mặt trên
B22: 3.2 | D22: - Tưới nhựa dính bám polyme 0.5 kg/m² | E22: m² | F22: 2 | G22: 193.9825 | H22: 1 | I22: 1 | J22: 1 | K22: =ROUND(F22*G22, 2) | L22: 387.97 m² tưới dính bám
B23: 3.3 | D23: - Bê tông nhựa chặt BTNC 19 (dày 7cm) | E23: m² | F23: 2 | G23: 193.9825 | H23: 1 | I23: 1 | J23: 1 | K23: =ROUND(F23*G23, 2) | L23: 387.97 m² BTNC 19
B24: 3.4 | D24: - Tưới nhựa dính bám 0.5 kg/m² | E24: m² | F24: 2 | G24: 193.9825 | H24: 1 | I24: 1 | J24: 1 | K24: =ROUND(F24*G24, 2) | L24: 387.97 m² tưới dính bám
B25: 3.5 | D25: - Hỗn hợp đá chặt gia cố nhựa nóng 25 (dày 8cm) | E25: m³ | F25: 2 | G25: 193.9825 | H25: 0.08 | I25: 1 | J25: 1 | K25: =ROUND(F25*G25*H25, 2) | L25: 31.04 m³ đá đen gia cố
B26: 3.6 | D26: - Tưới nhựa thấm bám tiêu chuẩn 1.0 kg/m² | E26: m² | F26: 2 | G26: 193.9825 | H26: 1 | I26: 1 | J26: 1 | K26: =ROUND(F26*G26, 2) | L26: 387.97 m² tưới thấm bám
B27: 3.7 | D27: - Cấp phối đá dăm gia cố xi măng 5% (dày 14cm) | E27: m³ | F27: 1 | G27: 53.46 | H27: 1 | I27: 1 | J27: 1 | K27: =ROUND(F27*G27, 2) | L27: 53.46 m³ móng bán cứng
B28: 3.8 | D28: - Lớp móng dưới CPĐD loại 1 (dày 30cm) | E28: m³ | F28: 1 | G28: 82.76 | H28: 1 | I28: 1 | J28: 1 | K28: =ROUND(F28*G28, 2) | L28: 82.76 m³ móng dưới CPĐD
B29: 3.9 | D29: - Đắp đất nền đường K98 dày 30cm & K95 | E29: m³ | F29: 1 | G29: 117.68 | H29: 1 | I29: 1 | J29: 1 | K29: =ROUND(F29*G29, 2) | L29: 117.68 m³ đắp nền K95/K98
C30: Cộng Diện tích Áo đường vuốt nối 10m đầu cầu: | K30: =K21 | L30: 387.97 m²
B31: 4. VẬT LIỆU DẠNG HẠT THOÁT NƯỚC GIẢM TẢI ĐẮP LÒNG MỐ K98
B32: 4.1 | D32: - Vật liệu hạt chọn lọc thoát nước đắp lòng mố M1 | E32: m³ | F32: 1 | G32: 194.369 | H32: 1 | I32: 1 | J32: 1 | K32: =ROUND(F32*G32, 2) | L32: 194.37 m³ lòng mố M1
B33: 4.2 | D33: - Vật liệu hạt chọn lọc thoát nước đắp lòng mố M2 | E33: m³ | F33: 1 | G33: 818.586 | H33: 1 | I33: 1 | J33: 1 | K33: =ROUND(F33*G33, 2) | L33: 818.59 m³ lòng mố M2
C34: Cộng Vật liệu hạt đắp lòng mố K98: | K34: =SUM(K32:K33) | L34: 1,012.96 m³
I36: ĐÁ HỘC XÂY VỮA M100 (M3): | J36: =K11
I37: TƯỜNG CHẮN BÊ TÔNG C15 (M3): | J37: =K19
I38: ÁO ĐƯỜNG VUỐT NỐI (M2): | J38: =K30
I39: VẬT LIỆU HẠT ĐẮP LÒNG MỐ (M3): | J39: =K34

Sheet 05_DIEN_GIAI_BPTC_CON
B2: BẢNG DIỄN GIẢI HÌNH HỌC CHI TIẾT BIỆN PHÁP THI CÔNG & CÔNG TRÌNH PHỤ TRỢ
B3: Bệ đúc dầm Super-T, Đường công vụ DCV6/DCV6A, Xe lao dầm 130T & Đà giáo sàn công tác mố trụ
B5: STT | C5: Mã hiệu | D5: Bộ phận kết cấu & Diễn giải hình học chi tiết | E5: ĐVT | F5: n (Số lượng) | G5: Dài L (m) | H5: Rộng B (m) | I5: Cao/Dày H (m) | J5: Hệ số k / Diện tích F (m²) | K5: Khối lượng Bóc tách (Formula 365) | L5: Ghi chú & Ký hiệu CAD
B6: 1. BỆ ĐÚC DẦM SUPER-T 38.2M TẠI BÃI ĐÚC (04 BỆ ĐÚC)
B7: 1.1 | D7: - Đào đất hố móng bệ đúc dầm (4 bệ x 40m x 2.2m x 0.35m) | E7: m³ | F7: 4 | G7: 40 | H7: 2.2 | I7: 0.35 | J7: 1 | K7: =ROUND(F7*G7*H7*I7*J7, 3) | L7: 123.60 m³ đào đất bãi đúc
B8: 1.2 | D8: - Đầm chặt đất nền bệ đúc dầm | E8: m² | F8: 4 | G8: 40.5 | H8: 1 | I8: 1 | J8: 1 | K8: =ROUND(F8*G8, 2) | L8: 162.00 m² đầm nền
B9: 1.3 | D9: - Đá dăm đệm bệ đúc dày 10cm | E9: m³ | F9: 4 | G9: 25.38 | H9: 1 | I9: 1 | J9: 1 | K9: =ROUND(F9*G9, 2) | L9: 101.52 m³ đá dăm
B10: 1.4 | D10: - Bê tông bệ đúc dầm C20 (thân bệ dày 30cm & đầu bệ) | E10: m³ | F10: 4 | G10: 17.1 | H10: 1 | I10: 1 | J10: 1 | K10: =ROUND(F10*G10, 2) | L10: 68.40 m³ bê tông C20
B11: 1.5 | D11: - Cốt thép bệ đúc dầm D20 (thép lưới & neo đầu bệ) | E11: Tấn | F11: 4 | G11: 1.619 | H11: 1 | I11: 1 | J11: 1 | K11: =ROUND(F11*G11, 3) | L11: 6.477 Tấn thép D20
B12: 1.6 | D12: - Thép hình kê đáy dầm 2U120 & I200 | E12: Tấn | F12: 4 | G12: 1.015 | H12: 1 | I12: 1 | J12: 1 | K12: =ROUND(F12*G12, 3) | L12: 4.060 Tấn thép hình kê
B13: 1.7 | D13: - Ván khuôn bệ đúc dầm (đáy dầm, thành dầm & ván khuôn đệm) | E13: m² | F13: 4 | G13: 115.93 | H13: 1 | I13: 1 | J13: 1 | K13: =ROUND(F13*G13, 2) | L13: 463.70 m² ván khuôn bãi đúc
C14: Cộng Bê tông Bệ đúc dầm C20: | K14: =K10 | L14: 68.40 m³
B15: 2. ĐƯỜNG CÔNG VỤ TIẾP CẬN THI CÔNG DCV6 & DCV6A
B16: 2.1 | D16: - Đào đất nền đường công vụ DCV6 (tiếp cận M1 & T1, 10 cọc) | E16: m³ | F16: 1 | G16: 2860.5 | H16: 1 | I16: 1 | J16: 1 | K16: =ROUND(F16*G16, 2) | L16: Đào nền đường DCV6
B17: 2.2 | D17: - Đắp đất nền đường công vụ DCV6 | E17: m³ | F17: 1 | G17: 412.3 | H17: 1 | I17: 1 | J17: 1 | K17: =ROUND(F17*G17, 2) | L17: Đắp nền đường DCV6
B18: 2.3 | D18: - Mặt đường cấp phối đá dăm loại II dày 20cm DCV6 | E18: m³ | F18: 1 | G18: 345 | H18: 1 | I18: 1 | J18: 1 | K18: =ROUND(F18*G18, 2) | L18: Mặt đường cấp phối DCV6
B19: 2.4 | D19: - Đào đất nền đường công vụ DCV6A (tiếp cận T2 & M2, 6 cọc) | E19: m³ | F19: 1 | G19: 1940.2 | H19: 1 | I19: 1 | J19: 1 | K19: =ROUND(F19*G19, 2) | L19: Đào nền đường DCV6A
B20: 2.5 | D20: - Mặt đường cấp phối đá dăm loại II dày 20cm DCV6A | E20: m³ | F20: 1 | G20: 280 | H20: 1 | I20: 1 | J20: 1 | K20: =ROUND(F20*G20, 2) | L20: Mặt đường cấp phối DCV6A
C21: Cộng Khối lượng Đào nền đường công vụ: | K21: =K16+K19 | L21: 4,800.70 m³
B22: 3. GIÁ LAO DẦM 130T & HỆ RAY LAO DẦM P43
B23: 3.1 | D23: - Giá lao dầm 130T (hệ giàn thép 10 đốt dầm D1-D10) | E23: Tấn | F23: 1 | G23: 78.883 | H23: 1 | I23: 1 | J23: 1 | K23: =ROUND(F23*G23, 3) | L23: 78.883 Tấn giá lao dầm
B24: 3.2 | D24: - Ray dẫn hướng P43 đường lao đầu cầu (108m x 44.6 kg/m) | E24: Tấn | F24: 1 | G24: 4.817 | H24: 1 | I24: 1 | J24: 1 | K24: =ROUND(F24*G24, 3) | L24: 4.817 Tấn ray P43
B25: 3.3 | D25: - Ray dẫn hướng P43 trên nhịp (160m + 25m) | E25: Tấn | F25: 1 | G25: 8.251 | H25: 1 | I25: 1 | J25: 1 | K25: =ROUND(F25*G25, 3) | L25: 8.251 Tấn ray P43 trên nhịp
B26: 3.4 | D26: - Tà vẹt gỗ 18x20x200cm kê ray | E26: Cái | F26: 1 | G26: 268 | H26: 1 | I26: 1 | J26: 1 | K26: =ROUND(F26*G26, 0) | L26: 268 cái tà vẹt gỗ
B27: 3.5 | D27: - Xe goòng vận chuyển dầm từ bãi đúc ra vị trí lao | E27: Xe | F27: 2 | G27: 1 | H27: 1 | I27: 1 | J27: 1 | K27: =ROUND(F27, 0) | L27: 2 xe goòng chở dầm
C28: Cộng Kết cấu thép Lao dầm (Tấn): | K28: =SUM(K23:K25) | L28: 91.951 Tấn
B29: 4. HỆ ĐÀ GIÁO XÀ MŨ & SÀN CÔNG TÁC MỐ TRỤ
B30: 4.1 | D30: - Hệ dầm thép đỡ xà mũ trụ T1 & T2 (Dầm I600, I300, giằng U100) | E30: Tấn | F30: 1 | G30: 34.55 | H30: 1 | I30: 1 | J30: 1 | K30: =ROUND(F30*G30, 3) | L30: 34.55 Tấn đà giáo chịu lực
B31: 4.2 | D31: - Sàn công tác an toàn thi công thân mố M1, M2 | E31: Tấn | F31: 1 | G31: 1.25 | H31: 1 | I31: 1 | J31: 1 | K31: =ROUND(F31*G31, 3) | L31: 1.25 Tấn sàn thao tác
B32: 4.3 | D32: - Sàn công tác an toàn thi công thân trụ ovan T1, T2 (H=14m, 18m) | E32: Tấn | F32: 1 | G32: 2.85 | H32: 1 | I32: 1 | J32: 1 | K32: =ROUND(F32*G32, 3) | L32: 2.85 Tấn giáo leo an toàn
B33: 4.4 | D33: - Xe đúc gờ lan can di động & sàn thao tác BMC | E33: Tấn | F33: 1 | G33: 4.5 | H33: 1 | I33: 1 | J33: 1 | K33: =ROUND(F33*G33, 3) | L33: 4.50 Tấn xe đúc gờ
C34: Cộng Thép đà giáo sàn công tác (Tấn): | K34: =SUM(K30:K33) | L34: 43.150 Tấn

Sheet 06_MASTER_BOQ_TIEN_LUONG
B2: BẢNG TIÊN LƯỢNG TỔNG HỢP TOÀN BỘ CÔNG TRÌNH (MASTER BILL OF QUANTITIES)
B3: Phân cấp WBS chuẩn Bộ GTVT / Bộ Xây dựng | Liên kết động 100% từ 5 Sheet Diễn giải Hình học
B5: STT | C5: Mã hiệu ĐM | D5: Hạng mục công việc / Cấu kiện | E5: Quy cách vật liệu / Tiêu chuẩn kỹ thuật | F5: ĐVT | G5: Khối lượng Thiết kế (365 Dynamic Formula) | H5: Ghi chú phân hệ & Sheet nguồn
B6: A. PHẦN I: KẾT CẤU PHẦN TRÊN (SUPERSTRUCTURE)
B7: 1 | C7: AF.22110 | D7: Bê tông dầm chủ Super-T 38.2m (15 phiến) | E7: Bê tông C45/50 | F7: m³ | G7: ='01_DIEN_GIAI_SUPER_T'!K11 | H7: Sheet 01_DIEN_GIAI_SUPER_T
B8: 2 | C8: AF.61110 | D8: Cáp DƯL 15.2mm kéo trước trong dầm chủ | E8: ASTM A416 Grade 270 | F8: Tấn | G8: ='01_DIEN_GIAI_SUPER_T'!K16 | H8: Sheet 01_DIEN_GIAI_SUPER_T
B9: 3 | C9: AF.61120 | D9: Cốt thép thường thân dầm Super-T (BBS 23 mã) | E9: CB400-V (D<=18 & D>18) | F9: Tấn | G9: ='01_DIEN_GIAI_SUPER_T'!K21 | H9: Sheet 01_DIEN_GIAI_SUPER_T
B10: 4 | C10: AF.81110 | D10: Ván khuôn dầm chủ Super-T 38.2m | E10: Ván khuôn thép định hình | F10: m² | G10: ='01_DIEN_GIAI_SUPER_T'!K27 | H10: Sheet 01_DIEN_GIAI_SUPER_T
B11: 5 | C11: AF.22120 | D11: Bê tông dầm ngang đúc tại chỗ | E11: Bê tông C35/45 | F11: m³ | G11: ='01_DIEN_GIAI_SUPER_T'!K34 | H11: Sheet 01_DIEN_GIAI_SUPER_T
B12: 6 | C12: AF.22130 | D12: Bê tông bản mặt cầu & bản liên tục nhiệt | E12: Bê tông C35/45 | F12: m³ | G12: ='01_DIEN_GIAI_SUPER_T'!K43 | H12: Sheet 01_DIEN_GIAI_SUPER_T
B13: 7 | C13: AF.61130 | D13: Cốt thép dầm ngang, BMC & bản liên tục nhiệt | E13: CB400-V | F13: Tấn | G13: =('01_DIEN_GIAI_SUPER_T'!K31+'01_DIEN_GIAI_SUPER_T'!K41)/1000 | H13: Sheet 01_DIEN_GIAI_SUPER_T
B14: 8 | C14: AF.22140 | D14: Bê tông tấm ván khuôn đúc sẵn (510 tấm) | E14: Bê tông C25/30 | F14: m³ | G14: ='01_DIEN_GIAI_SUPER_T'!K48 | H14: Sheet 01_DIEN_GIAI_SUPER_T
B15: 9 | C15: AD.21110 | D15: Bê tông nhựa chặt C16 mặt cầu dày 7cm | E15: BTN C16 & Chống thấm | F15: m² | G15: ='01_DIEN_GIAI_SUPER_T'!K53 | H15: Sheet 01_DIEN_GIAI_SUPER_T
B16: B. PHẦN II: KẾT CẤU PHẦN DƯỚI (SUBSTRUCTURE)
B17: 10 | C17: AF.21110 | D17: Bê tông Mố M1 & M2 (Bệ, thân, tường đỉnh, cánh) | E17: Bê tông C30/37 | F17: m³ | G17: ='02_DIEN_GIAI_HA_BO'!K17 | H17: Sheet 02_DIEN_GIAI_HA_BO
B18: 11 | C18: AF.61210 | D18: Cốt thép Mố M1 & M2 | E18: CB400-V | F18: Tấn | G18: ='02_DIEN_GIAI_HA_BO'!K15 | H18: Sheet 02_DIEN_GIAI_HA_BO
B19: 12 | C19: AF.21120 | D19: Bê tông Trụ T1 & T2 (Bệ trụ, thân ovan, xà mũ) | E19: Bê tông C30/37 | F19: m³ | G19: ='02_DIEN_GIAI_HA_BO'!K30 | H19: Sheet 02_DIEN_GIAI_HA_BO
B20: 13 | C20: AF.61220 | D20: Cốt thép Trụ T1 & T2 | E20: CB400-V | F20: Tấn | G20: ='02_DIEN_GIAI_HA_BO'!K29 | H20: Sheet 02_DIEN_GIAI_HA_BO
B21: 14 | C21: AC.11110 | D21: Khoan tạo lỗ & Bê tông cọc khoan nhồi D1200mm | E21: Bê tông C30/37 rút tremie (26 cọc) | F21: m³ | G21: ='02_DIEN_GIAI_HA_BO'!K47 | H21: Sheet 02_DIEN_GIAI_HA_BO
B22: 15 | C22: AF.61230 | D22: Cốt thép cọc khoan nhồi D1200mm | E22: CB400-V | F22: Tấn | G22: ='02_DIEN_GIAI_HA_BO'!K41 | H22: Sheet 02_DIEN_GIAI_HA_BO
B23: C. PHẦN III: KẾT CẤU PHỤ TRỢ (MISCELLANEOUS)
B24: 16 | C24: AF.21130 | D24: Bê tông bản quá độ mố M1 & M2 | E24: Bê tông C25/30 | F24: m³ | G24: ='03_DIEN_GIAI_PHU_TRO'!K15 | H24: Sheet 03_DIEN_GIAI_PHU_TRO
B25: 17 | C25: AF.21140 | D25: Bê tông gờ lan can | E25: Bê tông C25/30 | F25: m³ | G25: ='03_DIEN_GIAI_PHU_TRO'!K25 | H25: Sheet 03_DIEN_GIAI_PHU_TRO
B26: 18 | C26: AF.61310 | D26: Cốt thép bản quá độ & gờ lan can | E26: CB400-V | F26: Tấn | G26: =('03_DIEN_GIAI_PHU_TRO'!K9+'03_DIEN_GIAI_PHU_TRO'!K13+'03_DIEN_GIAI_PHU_TRO'!K22)/1000 | H26: Sheet 03_DIEN_GIAI_PHU_TRO
B27: 19 | C27: AG.11110 | D27: Gối chậu Super-T đơn hướng & song hướng | E27: Thép đúc & PTFE (30 gối) | F27: Cái | G27: ='03_DIEN_GIAI_PHU_TRO'!K37 | H27: Sheet 03_DIEN_GIAI_PHU_TRO
B28: 20 | C28: AG.21110 | D28: Khe co giãn răng lược WD230 | E28: Thép mạ kẽm (2 khe x 12.25m) | F28: m | G28: ='03_DIEN_GIAI_PHU_TRO'!K44 | H28: Sheet 03_DIEN_GIAI_PHU_TRO
B29: 21 | C29: AG.31110 | D29: Hè gang thu nước & hệ thống thoát nước | E29: Gang xám & uPVC D150 (24 bộ) | F29: Bộ | G29: ='03_DIEN_GIAI_PHU_TRO'!K52 | H29: Sheet 03_DIEN_GIAI_PHU_TRO
B30: D. PHẦN IV: ĐƯỜNG SAU MỐ, TỨ NÓN & GIA CỐ
B31: 22 | C31: AL.11110 | D31: Đá hộc xây vữa VXM M100 kè tứ nón | E31: Đá hộc VXM M100 | F31: m³ | G31: ='04_DIEN_GIAI_DUONG_TU_NON'!K11 | H31: Sheet 04_DIEN_GIAI_DUONG_TU_NON
B32: 23 | C32: AF.11110 | D32: Tường chắn bê tông trọng lực C15 | E32: Bê tông C15 | F32: m³ | G32: ='04_DIEN_GIAI_DUONG_TU_NON'!K19 | H32: Sheet 04_DIEN_GIAI_DUONG_TU_NON
B33: 24 | C33: AD.11110 | D33: Áo đường vuốt nối 10m đầu cầu | E33: BTN rỗng 12.5 & BTNC 19 | F33: m² | G33: ='04_DIEN_GIAI_DUONG_TU_NON'!K30 | H33: Sheet 04_DIEN_GIAI_DUONG_TU_NON
B34: 25 | C34: AB.11110 | D34: Vật liệu dạng hạt chọn lọc đắp lòng mố K98 | E34: Hạt chọn lọc đầm nén K98 | F34: m³ | G34: ='04_DIEN_GIAI_DUONG_TU_NON'!K34 | H34: Sheet 04_DIEN_GIAI_DUONG_TU_NON
B35: E. PHẦN V: BIỆN PHÁP THI CÔNG & PHỤ TRỢ CÔNG TRƯỜNG
B36: 26 | C36: BPTC-01 | D36: Bệ đúc dầm Super-T tại bãi đúc (04 bệ đúc) | E36: Bê tông C20/25 & thép bệ đúc | F36: Bệ | G36: 4 | H36: Sheet 05_DIEN_GIAI_BPTC_CON
B37: 27 | C37: BPTC-02 | D37: Đường công vụ thi công tiếp cận cầu DCV6 & 6A | E37: Đào nền đường công vụ tiếp cận cầu | F37: m³ | G37: ='05_DIEN_GIAI_BPTC_CON'!K21 | H37: Sheet 05_DIEN_GIAI_BPTC_CON
B38: 28 | C38: BPTC-03 | D38: Giá lao dầm 130T & Hệ ray lao dầm P43 | E38: Kết cấu thép giàn lao dầm | F38: Tấn | G38: ='05_DIEN_GIAI_BPTC_CON'!K28 | H38: Sheet 05_DIEN_GIAI_BPTC_CON
F45: TỔNG KHỐI LƯỢNG BÊ TÔNG TOÀN CẦU (M3): | G45: =G7+G11+G12+G14+G17+G19+G21+G24+G25+G32
F46: TỔNG CỐT THÉP THƯỜNG TOÀN CẦU (TẤN): | G46: =G9+G13+G18+G20+G22+G26
F47: TỔNG DIỆN TÍCH VÁN KHUÔN TOÀN CẦU (M2): | G47: =G10+'02_DIEN_GIAI_HA_BO'!K16+'02_DIEN_GIAI_HA_BO'!K28+'03_DIEN_GIAI_PHU_TRO'!K10+'03_DIEN_GIAI_PHU_TRO'!K14+'03_DIEN_GIAI_PHU_TRO'!K23+'04_DIEN_GIAI_DUONG_TU_NON'!K14
