Workbook

Sheet TIEN_DO_THI_CONG_WBS
B2: DỰ ÁN: CAO TỐC TUYÊN QUANG - HÀ GIANG (GIAI ĐOẠN 1) - ĐOẠN QUA TỈNH HÀ GIANG | N2: Ngày khởi công | R2: 46096 | V2: Hoàn thành (tính toán) | Z2: =MAX($J$8:$J$42) | AD2: Tổng thời gian (ngày) | AH2: =Z2-$R$2+1
B3: BẢNG KẾ HOẠCH TIẾN ĐỘ WBS, ĐIỀU PHỐI NHÂN CÔNG & BIỂU ĐỒ GANTT CPM - CẦU KM19+529.080 | N3: Hạn hoàn thành (mục tiêu) | R3: 46386 | V3: Dự phòng so với hạn (ngày) | Z3: =$R$3-Z2 | AD3: Trạng thái | AH3: =IF(Z2<=$R$3,"ĐẠT","TRỄ")
B4: Định mức ngày công TT 12/2021/TT-BXD, Luật Xây dựng số 135/2025/QH15 & NĐ 207/2026/NĐ-CP (Cột đỏ: Đường găng CPM) | N4: Gantt: 1=thanh 2=nhân công 3=ca | R4: 1
A5: Mã WBS | B5: Danh mục công tác thi công | C5: Khối lượng | D5: ĐVT | E5: Định mức (công/ĐVT) | F5: Tổng công (công) | G5: Tổ đội (người) | H5: Thời gian Duration (ngày) | I5: Ngày bắt đầu Start | J5: Ngày hoàn thành Finish | K5: Quan hệ logic Predecessors | L5: Đường găng CPM | M5: ="T"&1 | N5: ="T"&2 | O5: ="T"&3 | P5: ="T"&4 | Q5: ="T"&5 | R5: ="T"&6 | S5: ="T"&7 | T5: ="T"&8 | U5: ="T"&9 | V5: ="T"&10 | W5: ="T"&11 | X5: ="T"&12 | Y5: ="T"&13 | Z5: ="T"&14 | AA5: ="T"&15 | AB5: ="T"&16 | AC5: ="T"&17 | AD5: ="T"&18 | AE5: ="T"&19 | AF5: ="T"&20 | AG5: ="T"&21 | AH5: ="T"&22 | AI5: ="T"&23 | AJ5: ="T"&24 | AK5: ="T"&25 | AL5: ="T"&26 | AM5: ="T"&27 | AN5: ="T"&28 | AO5: ="T"&29 | AP5: ="T"&30 | AQ5: ="T"&31 | AR5: ="T"&32 | AS5: ="T"&33 | AT5: ="T"&34 | AU5: ="T"&35 | AV5: ="T"&36 | AW5: ="T"&37 | AX5: ="T"&38 | AY5: ="T"&39 | AZ5: ="T"&40 | BA5: ="T"&41 | BB5: ="T"&42 | BC5: ="T"&43 | BD5: ="T"&44 | BF5: Đường găng (công thức)
M6: =$R$2+7*0 | N6: =$R$2+7*1 | O6: =$R$2+7*2 | P6: =$R$2+7*3 | Q6: =$R$2+7*4 | R6: =$R$2+7*5 | S6: =$R$2+7*6 | T6: =$R$2+7*7 | U6: =$R$2+7*8 | V6: =$R$2+7*9 | W6: =$R$2+7*10 | X6: =$R$2+7*11 | Y6: =$R$2+7*12 | Z6: =$R$2+7*13 | AA6: =$R$2+7*14 | AB6: =$R$2+7*15 | AC6: =$R$2+7*16 | AD6: =$R$2+7*17 | AE6: =$R$2+7*18 | AF6: =$R$2+7*19 | AG6: =$R$2+7*20 | AH6: =$R$2+7*21 | AI6: =$R$2+7*22 | AJ6: =$R$2+7*23 | AK6: =$R$2+7*24 | AL6: =$R$2+7*25 | AM6: =$R$2+7*26 | AN6: =$R$2+7*27 | AO6: =$R$2+7*28 | AP6: =$R$2+7*29 | AQ6: =$R$2+7*30 | AR6: =$R$2+7*31 | AS6: =$R$2+7*32 | AT6: =$R$2+7*33 | AU6: =$R$2+7*34 | AV6: =$R$2+7*35 | AW6: =$R$2+7*36 | AX6: =$R$2+7*37 | AY6: =$R$2+7*38 | AZ6: =$R$2+7*39 | BA6: =$R$2+7*40 | BB6: =$R$2+7*41 | BC6: =$R$2+7*42 | BD6: =$R$2+7*43 | BF6: LF | BG6: LS | BH6: TF
A7: 1.0
A8: 1.1 | B8: Bàn giao tim mốc VN2000, cao độ quốc gia Hòn Dấu & tim mốc cầu | C8: 1 | D8: Điểm | E8: 12 | F8: =C8*E8 | G8: 6 | H8: =ROUNDUP(F8/G8, 0) | I8: =$R$2 | J8: =I8+H8-1 | K8: - | L8: =IF(BH8=0,"YES","NO") | M8: =IF(AND($I8<=M$6+6,$J8>=M$6),IF($R$4=1,"█",IF($R$4=2,$G8,$G8*2)),"") | N8: =IF(AND($I8<=N$6+6,$J8>=N$6),IF($R$4=1,"█",IF($R$4=2,$G8,$G8*2)),"") | O8: =IF(AND($I8<=O$6+6,$J8>=O$6),IF($R$4=1,"█",IF($R$4=2,$G8,$G8*2)),"") | P8: =IF(AND($I8<=P$6+6,$J8>=P$6),IF($R$4=1,"█",IF($R$4=2,$G8,$G8*2)),"") | Q8: =IF(AND($I8<=Q$6+6,$J8>=Q$6),IF($R$4=1,"█",IF($R$4=2,$G8,$G8*2)),"") | R8: =IF(AND($I8<=R$6+6,$J8>=R$6),IF($R$4=1,"█",IF($R$4=2,$G8,$G8*2)),"") | S8: =IF(AND($I8<=S$6+6,$J8>=S$6),IF($R$4=1,"█",IF($R$4=2,$G8,$G8*2)),"") | T8: =IF(AND($I8<=T$6+6,$J8>=T$6),IF($R$4=1,"█",IF($R$4=2,$G8,$G8*2)),"") | ... BD8: =IF(AND($I8<=BD$6+6,$J8>=BD$6),IF($R$4=1,"█",IF($R$4=2,$G8,$G8*2)),"") | BF8: =BG9-1-0 | BG8: =BF8-H8+1 | BH8: =BG8-I8
A9: 1.2 | B9: Rà phá bom mìn, dọn dẹp mặt bằng thi công & dựng lán trại | C9: 12500 | D9: m2 | E9: 0.02 | F9: =C9*E9 | G9: 10 | H9: =ROUNDUP(F9/G9, 0) | I9: =J8+1+0 | J9: =I9+H9-1 | K9: 1.1FS | L9: =IF(BH9=0,"YES","NO") | M9: =IF(AND($I9<=M$6+6,$J9>=M$6),IF($R$4=1,"█",IF($R$4=2,$G9,$G9*2)),"") | N9: =IF(AND($I9<=N$6+6,$J9>=N$6),IF($R$4=1,"█",IF($R$4=2,$G9,$G9*2)),"") | O9: =IF(AND($I9<=O$6+6,$J9>=O$6),IF($R$4=1,"█",IF($R$4=2,$G9,$G9*2)),"") | P9: =IF(AND($I9<=P$6+6,$J9>=P$6),IF($R$4=1,"█",IF($R$4=2,$G9,$G9*2)),"") | Q9: =IF(AND($I9<=Q$6+6,$J9>=Q$6),IF($R$4=1,"█",IF($R$4=2,$G9,$G9*2)),"") | R9: =IF(AND($I9<=R$6+6,$J9>=R$6),IF($R$4=1,"█",IF($R$4=2,$G9,$G9*2)),"") | S9: =IF(AND($I9<=S$6+6,$J9>=S$6),IF($R$4=1,"█",IF($R$4=2,$G9,$G9*2)),"") | T9: =IF(AND($I9<=T$6+6,$J9>=T$6),IF($R$4=1,"█",IF($R$4=2,$G9,$G9*2)),"") | ... BD9: =IF(AND($I9<=BD$6+6,$J9>=BD$6),IF($R$4=1,"█",IF($R$4=2,$G9,$G9*2)),"") | BF9: =BG10-1-0 | BG9: =BF9-H9+1 | BH9: =BG9-I9
A10: 1.3 | B10: Thi công đường công vụ nhánh 6 & nhánh 6A tiếp cận mố trụ | C10: 825 | D10: m3 | E10: 0.08 | F10: =C10*E10 | G10: 12 | H10: =ROUNDUP(F10/G10, 0) | I10: =J9+1+0 | J10: =I10+H10-1 | K10: 1.2FS | L10: =IF(BH10=0,"YES","NO") | M10: =IF(AND($I10<=M$6+6,$J10>=M$6),IF($R$4=1,"█",IF($R$4=2,$G10,$G10*2)),"") | N10: =IF(AND($I10<=N$6+6,$J10>=N$6),IF($R$4=1,"█",IF($R$4=2,$G10,$G10*2)),"") | O10: =IF(AND($I10<=O$6+6,$J10>=O$6),IF($R$4=1,"█",IF($R$4=2,$G10,$G10*2)),"") | P10: =IF(AND($I10<=P$6+6,$J10>=P$6),IF($R$4=1,"█",IF($R$4=2,$G10,$G10*2)),"") | Q10: =IF(AND($I10<=Q$6+6,$J10>=Q$6),IF($R$4=1,"█",IF($R$4=2,$G10,$G10*2)),"") | R10: =IF(AND($I10<=R$6+6,$J10>=R$6),IF($R$4=1,"█",IF($R$4=2,$G10,$G10*2)),"") | S10: =IF(AND($I10<=S$6+6,$J10>=S$6),IF($R$4=1,"█",IF($R$4=2,$G10,$G10*2)),"") | T10: =IF(AND($I10<=T$6+6,$J10>=T$6),IF($R$4=1,"█",IF($R$4=2,$G10,$G10*2)),"") | ... BD10: =IF(AND($I10<=BD$6+6,$J10>=BD$6),IF($R$4=1,"█",IF($R$4=2,$G10,$G10*2)),"") | BF10: =MIN(BG11-(3)+H10-1,BG13-1-0) | BG10: =BF10-H10+1 | BH10: =BG10-I10
A11: 1.4 | B11: Xây dựng bãi đúc dầm Super-T, bệ đúc cáp căng & trạm trộn BTXM | C11: 1 | D11: Hệ | E11: 180 | F11: =C11*E11 | G11: 15 | H11: =ROUNDUP(F11/G11, 0) | I11: =I10+3 | J11: =I11+H11-1 | K11: 1.3SS+3d | L11: =IF(BH11=0,"YES","NO") | M11: =IF(AND($I11<=M$6+6,$J11>=M$6),IF($R$4=1,"█",IF($R$4=2,$G11,$G11*2)),"") | N11: =IF(AND($I11<=N$6+6,$J11>=N$6),IF($R$4=1,"█",IF($R$4=2,$G11,$G11*2)),"") | O11: =IF(AND($I11<=O$6+6,$J11>=O$6),IF($R$4=1,"█",IF($R$4=2,$G11,$G11*2)),"") | P11: =IF(AND($I11<=P$6+6,$J11>=P$6),IF($R$4=1,"█",IF($R$4=2,$G11,$G11*2)),"") | Q11: =IF(AND($I11<=Q$6+6,$J11>=Q$6),IF($R$4=1,"█",IF($R$4=2,$G11,$G11*2)),"") | R11: =IF(AND($I11<=R$6+6,$J11>=R$6),IF($R$4=1,"█",IF($R$4=2,$G11,$G11*2)),"") | S11: =IF(AND($I11<=S$6+6,$J11>=S$6),IF($R$4=1,"█",IF($R$4=2,$G11,$G11*2)),"") | T11: =IF(AND($I11<=T$6+6,$J11>=T$6),IF($R$4=1,"█",IF($R$4=2,$G11,$G11*2)),"") | ... BD11: =IF(AND($I11<=BD$6+6,$J11>=BD$6),IF($R$4=1,"█",IF($R$4=2,$G11,$G11*2)),"") | BF11: =BG27-1-0 | BG11: =BF11-H11+1 | BH11: =BG11-I11
A12: 2.0
A13: 2.1 | B13: Khoan thăm dò hang Karst sâu 5m vào đá liền khối dưới mũi cọc | C13: 26 | D13: Lỗ | E13: 12 | F13: =C13*E13 | G13: 8 | H13: =ROUNDUP(F13/G13, 0) | I13: =J10+1+0 | J13: =I13+H13-1 | K13: 1.3FS | L13: =IF(BH13=0,"YES","NO") | M13: =IF(AND($I13<=M$6+6,$J13>=M$6),IF($R$4=1,"█",IF($R$4=2,$G13,$G13*2)),"") | N13: =IF(AND($I13<=N$6+6,$J13>=N$6),IF($R$4=1,"█",IF($R$4=2,$G13,$G13*2)),"") | O13: =IF(AND($I13<=O$6+6,$J13>=O$6),IF($R$4=1,"█",IF($R$4=2,$G13,$G13*2)),"") | P13: =IF(AND($I13<=P$6+6,$J13>=P$6),IF($R$4=1,"█",IF($R$4=2,$G13,$G13*2)),"") | Q13: =IF(AND($I13<=Q$6+6,$J13>=Q$6),IF($R$4=1,"█",IF($R$4=2,$G13,$G13*2)),"") | R13: =IF(AND($I13<=R$6+6,$J13>=R$6),IF($R$4=1,"█",IF($R$4=2,$G13,$G13*2)),"") | S13: =IF(AND($I13<=S$6+6,$J13>=S$6),IF($R$4=1,"█",IF($R$4=2,$G13,$G13*2)),"") | T13: =IF(AND($I13<=T$6+6,$J13>=T$6),IF($R$4=1,"█",IF($R$4=2,$G13,$G13*2)),"") | ... BD13: =IF(AND($I13<=BD$6+6,$J13>=BD$6),IF($R$4=1,"█",IF($R$4=2,$G13,$G13*2)),"") | BF13: =BG14-1-0 | BG13: =BF13-H13+1 | BH13: =BG13-I13
A14: 2.2 | B14: Khoan cọc nhồi D1200mm M1 (3 cọc L=20m) & đổ bê tông C30 | C14: =QS_DIEN_GIAI_CHI_TIET!J8 | D14: m | E14: 0.75 | F14: =C14*E14 | G14: 10 | H14: =ROUNDUP(F14/G14, 0) | I14: =J13+1+0 | J14: =I14+H14-1 | K14: 2.1FS | L14: =IF(BH14=0,"YES","NO") | M14: =IF(AND($I14<=M$6+6,$J14>=M$6),IF($R$4=1,"█",IF($R$4=2,$G14,$G14*2)),"") | N14: =IF(AND($I14<=N$6+6,$J14>=N$6),IF($R$4=1,"█",IF($R$4=2,$G14,$G14*2)),"") | O14: =IF(AND($I14<=O$6+6,$J14>=O$6),IF($R$4=1,"█",IF($R$4=2,$G14,$G14*2)),"") | P14: =IF(AND($I14<=P$6+6,$J14>=P$6),IF($R$4=1,"█",IF($R$4=2,$G14,$G14*2)),"") | Q14: =IF(AND($I14<=Q$6+6,$J14>=Q$6),IF($R$4=1,"█",IF($R$4=2,$G14,$G14*2)),"") | R14: =IF(AND($I14<=R$6+6,$J14>=R$6),IF($R$4=1,"█",IF($R$4=2,$G14,$G14*2)),"") | S14: =IF(AND($I14<=S$6+6,$J14>=S$6),IF($R$4=1,"█",IF($R$4=2,$G14,$G14*2)),"") | T14: =IF(AND($I14<=T$6+6,$J14>=T$6),IF($R$4=1,"█",IF($R$4=2,$G14,$G14*2)),"") | ... BD14: =IF(AND($I14<=BD$6+6,$J14>=BD$6),IF($R$4=1,"█",IF($R$4=2,$G14,$G14*2)),"") | BF14: =BG15-(4)+H14-1 | BG14: =BF14-H14+1 | BH14: =BG14-I14
A15: 2.3 | B15: Khoan cọc nhồi D1200mm Trụ T1 (8 cọc L=40m) & đổ bê tông C30 | C15: =QS_DIEN_GIAI_CHI_TIET!J9 | D15: m | E15: 0.75 | F15: =C15*E15 | G15: 16 | H15: =ROUNDUP(F15/G15, 0) | I15: =I14+4 | J15: =I15+H15-1 | K15: 2.2SS+4d | L15: =IF(BH15=0,"YES","NO") | M15: =IF(AND($I15<=M$6+6,$J15>=M$6),IF($R$4=1,"█",IF($R$4=2,$G15,$G15*2)),"") | N15: =IF(AND($I15<=N$6+6,$J15>=N$6),IF($R$4=1,"█",IF($R$4=2,$G15,$G15*2)),"") | O15: =IF(AND($I15<=O$6+6,$J15>=O$6),IF($R$4=1,"█",IF($R$4=2,$G15,$G15*2)),"") | P15: =IF(AND($I15<=P$6+6,$J15>=P$6),IF($R$4=1,"█",IF($R$4=2,$G15,$G15*2)),"") | Q15: =IF(AND($I15<=Q$6+6,$J15>=Q$6),IF($R$4=1,"█",IF($R$4=2,$G15,$G15*2)),"") | R15: =IF(AND($I15<=R$6+6,$J15>=R$6),IF($R$4=1,"█",IF($R$4=2,$G15,$G15*2)),"") | S15: =IF(AND($I15<=S$6+6,$J15>=S$6),IF($R$4=1,"█",IF($R$4=2,$G15,$G15*2)),"") | T15: =IF(AND($I15<=T$6+6,$J15>=T$6),IF($R$4=1,"█",IF($R$4=2,$G15,$G15*2)),"") | ... BD15: =IF(AND($I15<=BD$6+6,$J15>=BD$6),IF($R$4=1,"█",IF($R$4=2,$G15,$G15*2)),"") | BF15: =BG16-(8)+H15-1 | BG15: =BF15-H15+1 | BH15: =BG15-I15
A16: 2.4 | B16: Khoan cọc nhồi D1200mm Trụ T2 (8 cọc L=30m) & đổ bê tông C30 | C16: =QS_DIEN_GIAI_CHI_TIET!J10 | D16: m | E16: 0.75 | F16: =C16*E16 | G16: 14 | H16: =ROUNDUP(F16/G16, 0) | I16: =I15+8 | J16: =I16+H16-1 | K16: 2.3SS+8d | L16: =IF(BH16=0,"YES","NO") | M16: =IF(AND($I16<=M$6+6,$J16>=M$6),IF($R$4=1,"█",IF($R$4=2,$G16,$G16*2)),"") | N16: =IF(AND($I16<=N$6+6,$J16>=N$6),IF($R$4=1,"█",IF($R$4=2,$G16,$G16*2)),"") | O16: =IF(AND($I16<=O$6+6,$J16>=O$6),IF($R$4=1,"█",IF($R$4=2,$G16,$G16*2)),"") | P16: =IF(AND($I16<=P$6+6,$J16>=P$6),IF($R$4=1,"█",IF($R$4=2,$G16,$G16*2)),"") | Q16: =IF(AND($I16<=Q$6+6,$J16>=Q$6),IF($R$4=1,"█",IF($R$4=2,$G16,$G16*2)),"") | R16: =IF(AND($I16<=R$6+6,$J16>=R$6),IF($R$4=1,"█",IF($R$4=2,$G16,$G16*2)),"") | S16: =IF(AND($I16<=S$6+6,$J16>=S$6),IF($R$4=1,"█",IF($R$4=2,$G16,$G16*2)),"") | T16: =IF(AND($I16<=T$6+6,$J16>=T$6),IF($R$4=1,"█",IF($R$4=2,$G16,$G16*2)),"") | ... BD16: =IF(AND($I16<=BD$6+6,$J16>=BD$6),IF($R$4=1,"█",IF($R$4=2,$G16,$G16*2)),"") | BF16: =MIN(BG17-(7)+H16-1,BG18-1-0) | BG16: =BF16-H16+1 | BH16: =BG16-I16
A17: 2.5 | B17: Khoan cọc nhồi D1200mm M2 (7 cọc L=36m) & đổ bê tông C30 | C17: =QS_DIEN_GIAI_CHI_TIET!J11 | D17: m | E17: 0.75 | F17: =C17*E17 | G17: 14 | H17: =ROUNDUP(F17/G17, 0) | I17: =I16+7 | J17: =I17+H17-1 | K17: 2.4SS+7d | L17: =IF(BH17=0,"YES","NO") | M17: =IF(AND($I17<=M$6+6,$J17>=M$6),IF($R$4=1,"█",IF($R$4=2,$G17,$G17*2)),"") | N17: =IF(AND($I17<=N$6+6,$J17>=N$6),IF($R$4=1,"█",IF($R$4=2,$G17,$G17*2)),"") | O17: =IF(AND($I17<=O$6+6,$J17>=O$6),IF($R$4=1,"█",IF($R$4=2,$G17,$G17*2)),"") | P17: =IF(AND($I17<=P$6+6,$J17>=P$6),IF($R$4=1,"█",IF($R$4=2,$G17,$G17*2)),"") | Q17: =IF(AND($I17<=Q$6+6,$J17>=Q$6),IF($R$4=1,"█",IF($R$4=2,$G17,$G17*2)),"") | R17: =IF(AND($I17<=R$6+6,$J17>=R$6),IF($R$4=1,"█",IF($R$4=2,$G17,$G17*2)),"") | S17: =IF(AND($I17<=S$6+6,$J17>=S$6),IF($R$4=1,"█",IF($R$4=2,$G17,$G17*2)),"") | T17: =IF(AND($I17<=T$6+6,$J17>=T$6),IF($R$4=1,"█",IF($R$4=2,$G17,$G17*2)),"") | ... BD17: =IF(AND($I17<=BD$6+6,$J17>=BD$6),IF($R$4=1,"█",IF($R$4=2,$G17,$G17*2)),"") | BF17: =BG18-1-0 | BG17: =BF17-H17+1 | BH17: =BG17-I17
A18: 2.6 | B18: Thí nghiệm siêu âm 156 mặt cắt, khoan kiểm tra mũi cọc & thử tải PDA | C18: 1 | D18: Gói | E18: 48 | F18: =C18*E18 | G18: 6 | H18: =ROUNDUP(F18/G18, 0) | I18: =MAX(J16+1+0,J17+1+0) | J18: =I18+H18-1 | K18: 2.4FS,2.5FS | L18: =IF(BH18=0,"YES","NO") | M18: =IF(AND($I18<=M$6+6,$J18>=M$6),IF($R$4=1,"█",IF($R$4=2,$G18,$G18*2)),"") | N18: =IF(AND($I18<=N$6+6,$J18>=N$6),IF($R$4=1,"█",IF($R$4=2,$G18,$G18*2)),"") | O18: =IF(AND($I18<=O$6+6,$J18>=O$6),IF($R$4=1,"█",IF($R$4=2,$G18,$G18*2)),"") | P18: =IF(AND($I18<=P$6+6,$J18>=P$6),IF($R$4=1,"█",IF($R$4=2,$G18,$G18*2)),"") | Q18: =IF(AND($I18<=Q$6+6,$J18>=Q$6),IF($R$4=1,"█",IF($R$4=2,$G18,$G18*2)),"") | R18: =IF(AND($I18<=R$6+6,$J18>=R$6),IF($R$4=1,"█",IF($R$4=2,$G18,$G18*2)),"") | S18: =IF(AND($I18<=S$6+6,$J18>=S$6),IF($R$4=1,"█",IF($R$4=2,$G18,$G18*2)),"") | T18: =IF(AND($I18<=T$6+6,$J18>=T$6),IF($R$4=1,"█",IF($R$4=2,$G18,$G18*2)),"") | ... BD18: =IF(AND($I18<=BD$6+6,$J18>=BD$6),IF($R$4=1,"█",IF($R$4=2,$G18,$G18*2)),"") | BF18: =BG20-1-0 | BG18: =BF18-H18+1 | BH18: =BG18-I18
A19: 3.0
A20: 3.1 | B20: Đào hố móng, đập đầu 26 cọc nhồi & đổ bê tông lót đáy bệ mác C10 | C20: 26 | D20: Cọc | E20: 2.5 | F20: =C20*E20 | G20: 10 | H20: =ROUNDUP(F20/G20, 0) | I20: =J18+1+0 | J20: =I20+H20-1 | K20: 2.6FS | L20: =IF(BH20=0,"YES","NO") | M20: =IF(AND($I20<=M$6+6,$J20>=M$6),IF($R$4=1,"█",IF($R$4=2,$G20,$G20*2)),"") | N20: =IF(AND($I20<=N$6+6,$J20>=N$6),IF($R$4=1,"█",IF($R$4=2,$G20,$G20*2)),"") | O20: =IF(AND($I20<=O$6+6,$J20>=O$6),IF($R$4=1,"█",IF($R$4=2,$G20,$G20*2)),"") | P20: =IF(AND($I20<=P$6+6,$J20>=P$6),IF($R$4=1,"█",IF($R$4=2,$G20,$G20*2)),"") | Q20: =IF(AND($I20<=Q$6+6,$J20>=Q$6),IF($R$4=1,"█",IF($R$4=2,$G20,$G20*2)),"") | R20: =IF(AND($I20<=R$6+6,$J20>=R$6),IF($R$4=1,"█",IF($R$4=2,$G20,$G20*2)),"") | S20: =IF(AND($I20<=S$6+6,$J20>=S$6),IF($R$4=1,"█",IF($R$4=2,$G20,$G20*2)),"") | T20: =IF(AND($I20<=T$6+6,$J20>=T$6),IF($R$4=1,"█",IF($R$4=2,$G20,$G20*2)),"") | ... BD20: =IF(AND($I20<=BD$6+6,$J20>=BD$6),IF($R$4=1,"█",IF($R$4=2,$G20,$G20*2)),"") | BF20: =MIN(BG21-1-0,BG22-1-2) | BG20: =BF20-H20+1 | BH20: =BG20-I20
A21: 3.2 | B21: Gia công lắp dựng cốt thép, ván khuôn & đổ bê tông bệ móng mố M1, M2 | C21: =QS_DIEN_GIAI_CHI_TIET!J38 | D21: m3 | E21: 0.45 | F21: =C21*E21 | G21: 16 | H21: =ROUNDUP(F21/G21, 0) | I21: =J20+1+0 | J21: =I21+H21-1 | K21: 3.1FS | L21: =IF(BH21=0,"YES","NO") | M21: =IF(AND($I21<=M$6+6,$J21>=M$6),IF($R$4=1,"█",IF($R$4=2,$G21,$G21*2)),"") | N21: =IF(AND($I21<=N$6+6,$J21>=N$6),IF($R$4=1,"█",IF($R$4=2,$G21,$G21*2)),"") | O21: =IF(AND($I21<=O$6+6,$J21>=O$6),IF($R$4=1,"█",IF($R$4=2,$G21,$G21*2)),"") | P21: =IF(AND($I21<=P$6+6,$J21>=P$6),IF($R$4=1,"█",IF($R$4=2,$G21,$G21*2)),"") | Q21: =IF(AND($I21<=Q$6+6,$J21>=Q$6),IF($R$4=1,"█",IF($R$4=2,$G21,$G21*2)),"") | R21: =IF(AND($I21<=R$6+6,$J21>=R$6),IF($R$4=1,"█",IF($R$4=2,$G21,$G21*2)),"") | S21: =IF(AND($I21<=S$6+6,$J21>=S$6),IF($R$4=1,"█",IF($R$4=2,$G21,$G21*2)),"") | T21: =IF(AND($I21<=T$6+6,$J21>=T$6),IF($R$4=1,"█",IF($R$4=2,$G21,$G21*2)),"") | ... BD21: =IF(AND($I21<=BD$6+6,$J21>=BD$6),IF($R$4=1,"█",IF($R$4=2,$G21,$G21*2)),"") | BF21: =BG24-1-0 | BG21: =BF21-H21+1 | BH21: =BG21-I21
A22: 3.3 | B22: Gia công lắp dựng cốt thép, ván khuôn & đổ bê tông bệ trụ T1, T2 | C22: =QS_DIEN_GIAI_CHI_TIET!J39 | D22: m3 | E22: 0.42 | F22: =C22*E22 | G22: 18 | H22: =ROUNDUP(F22/G22, 0) | I22: =J20+1+2 | J22: =I22+H22-1 | K22: 3.1FS+2d | L22: =IF(BH22=0,"YES","NO") | M22: =IF(AND($I22<=M$6+6,$J22>=M$6),IF($R$4=1,"█",IF($R$4=2,$G22,$G22*2)),"") | N22: =IF(AND($I22<=N$6+6,$J22>=N$6),IF($R$4=1,"█",IF($R$4=2,$G22,$G22*2)),"") | O22: =IF(AND($I22<=O$6+6,$J22>=O$6),IF($R$4=1,"█",IF($R$4=2,$G22,$G22*2)),"") | P22: =IF(AND($I22<=P$6+6,$J22>=P$6),IF($R$4=1,"█",IF($R$4=2,$G22,$G22*2)),"") | Q22: =IF(AND($I22<=Q$6+6,$J22>=Q$6),IF($R$4=1,"█",IF($R$4=2,$G22,$G22*2)),"") | R22: =IF(AND($I22<=R$6+6,$J22>=R$6),IF($R$4=1,"█",IF($R$4=2,$G22,$G22*2)),"") | S22: =IF(AND($I22<=S$6+6,$J22>=S$6),IF($R$4=1,"█",IF($R$4=2,$G22,$G22*2)),"") | T22: =IF(AND($I22<=T$6+6,$J22>=T$6),IF($R$4=1,"█",IF($R$4=2,$G22,$G22*2)),"") | ... BD22: =IF(AND($I22<=BD$6+6,$J22>=BD$6),IF($R$4=1,"█",IF($R$4=2,$G22,$G22*2)),"") | BF22: =BG23-1-0 | BG22: =BF22-H22+1 | BH22: =BG22-I22
A23: 3.4 | B23: Thi công thân đặc trụ T1, T2 (H=14.5m & 11.4m) bê tông C30 | C23: =QS_DIEN_GIAI_CHI_TIET!J47 | D23: m3 | E23: 0.55 | F23: =C23*E23 | G23: 18 | H23: =ROUNDUP(F23/G23, 0) | I23: =J22+1+0 | J23: =I23+H23-1 | K23: 3.3FS | L23: =IF(BH23=0,"YES","NO") | M23: =IF(AND($I23<=M$6+6,$J23>=M$6),IF($R$4=1,"█",IF($R$4=2,$G23,$G23*2)),"") | N23: =IF(AND($I23<=N$6+6,$J23>=N$6),IF($R$4=1,"█",IF($R$4=2,$G23,$G23*2)),"") | O23: =IF(AND($I23<=O$6+6,$J23>=O$6),IF($R$4=1,"█",IF($R$4=2,$G23,$G23*2)),"") | P23: =IF(AND($I23<=P$6+6,$J23>=P$6),IF($R$4=1,"█",IF($R$4=2,$G23,$G23*2)),"") | Q23: =IF(AND($I23<=Q$6+6,$J23>=Q$6),IF($R$4=1,"█",IF($R$4=2,$G23,$G23*2)),"") | R23: =IF(AND($I23<=R$6+6,$J23>=R$6),IF($R$4=1,"█",IF($R$4=2,$G23,$G23*2)),"") | S23: =IF(AND($I23<=S$6+6,$J23>=S$6),IF($R$4=1,"█",IF($R$4=2,$G23,$G23*2)),"") | T23: =IF(AND($I23<=T$6+6,$J23>=T$6),IF($R$4=1,"█",IF($R$4=2,$G23,$G23*2)),"") | ... BD23: =IF(AND($I23<=BD$6+6,$J23>=BD$6),IF($R$4=1,"█",IF($R$4=2,$G23,$G23*2)),"") | BF23: =BG25-1-0 | BG23: =BF23-H23+1 | BH23: =BG23-I23
A24: 3.5 | B24: Thi công thân mố chân dê M1 và mố chữ U M2 bê tông C30 | C24: =QS_DIEN_GIAI_CHI_TIET!J42 | D24: m3 | E24: 0.52 | F24: =C24*E24 | G24: 14 | H24: =ROUNDUP(F24/G24, 0) | I24: =J21+1+0 | J24: =I24+H24-1 | K24: 3.2FS | L24: =IF(BH24=0,"YES","NO") | M24: =IF(AND($I24<=M$6+6,$J24>=M$6),IF($R$4=1,"█",IF($R$4=2,$G24,$G24*2)),"") | N24: =IF(AND($I24<=N$6+6,$J24>=N$6),IF($R$4=1,"█",IF($R$4=2,$G24,$G24*2)),"") | O24: =IF(AND($I24<=O$6+6,$J24>=O$6),IF($R$4=1,"█",IF($R$4=2,$G24,$G24*2)),"") | P24: =IF(AND($I24<=P$6+6,$J24>=P$6),IF($R$4=1,"█",IF($R$4=2,$G24,$G24*2)),"") | Q24: =IF(AND($I24<=Q$6+6,$J24>=Q$6),IF($R$4=1,"█",IF($R$4=2,$G24,$G24*2)),"") | R24: =IF(AND($I24<=R$6+6,$J24>=R$6),IF($R$4=1,"█",IF($R$4=2,$G24,$G24*2)),"") | S24: =IF(AND($I24<=S$6+6,$J24>=S$6),IF($R$4=1,"█",IF($R$4=2,$G24,$G24*2)),"") | T24: =IF(AND($I24<=T$6+6,$J24>=T$6),IF($R$4=1,"█",IF($R$4=2,$G24,$G24*2)),"") | ... BD24: =IF(AND($I24<=BD$6+6,$J24>=BD$6),IF($R$4=1,"█",IF($R$4=2,$G24,$G24*2)),"") | BF24: =MAX($J$8:$J$42) | BG24: =BF24-H24+1 | BH24: =BG24-I24
A25: 3.6 | B25: Thi công xà mũ trụ T1, T2, đá kê gối & khối chống xô | C25: =QS_DIEN_GIAI_CHI_TIET!J51 | D25: m3 | E25: 0.65 | F25: =C25*E25 | G25: 14 | H25: =ROUNDUP(F25/G25, 0) | I25: =J23+1+0 | J25: =I25+H25-1 | K25: 3.4FS | L25: =IF(BH25=0,"YES","NO") | M25: =IF(AND($I25<=M$6+6,$J25>=M$6),IF($R$4=1,"█",IF($R$4=2,$G25,$G25*2)),"") | N25: =IF(AND($I25<=N$6+6,$J25>=N$6),IF($R$4=1,"█",IF($R$4=2,$G25,$G25*2)),"") | O25: =IF(AND($I25<=O$6+6,$J25>=O$6),IF($R$4=1,"█",IF($R$4=2,$G25,$G25*2)),"") | P25: =IF(AND($I25<=P$6+6,$J25>=P$6),IF($R$4=1,"█",IF($R$4=2,$G25,$G25*2)),"") | Q25: =IF(AND($I25<=Q$6+6,$J25>=Q$6),IF($R$4=1,"█",IF($R$4=2,$G25,$G25*2)),"") | R25: =IF(AND($I25<=R$6+6,$J25>=R$6),IF($R$4=1,"█",IF($R$4=2,$G25,$G25*2)),"") | S25: =IF(AND($I25<=S$6+6,$J25>=S$6),IF($R$4=1,"█",IF($R$4=2,$G25,$G25*2)),"") | T25: =IF(AND($I25<=T$6+6,$J25>=T$6),IF($R$4=1,"█",IF($R$4=2,$G25,$G25*2)),"") | ... BD25: =IF(AND($I25<=BD$6+6,$J25>=BD$6),IF($R$4=1,"█",IF($R$4=2,$G25,$G25*2)),"") | BF25: =BG30-1-0 | BG25: =BF25-H25+1 | BH25: =BG25-I25
A26: 4.0
A27: 4.1 | B27: Gia công cốt thép, luồn cáp DUL 15.2mm 15 phiến dầm tại bãi đúc | C27: 15 | D27: Phiến | E27: 28 | F27: =C27*E27 | G27: 16 | H27: =ROUNDUP(F27/G27, 0) | I27: =J11+1+0 | J27: =I27+H27-1 | K27: 1.4FS | L27: =IF(BH27=0,"YES","NO") | M27: =IF(AND($I27<=M$6+6,$J27>=M$6),IF($R$4=1,"█",IF($R$4=2,$G27,$G27*2)),"") | N27: =IF(AND($I27<=N$6+6,$J27>=N$6),IF($R$4=1,"█",IF($R$4=2,$G27,$G27*2)),"") | O27: =IF(AND($I27<=O$6+6,$J27>=O$6),IF($R$4=1,"█",IF($R$4=2,$G27,$G27*2)),"") | P27: =IF(AND($I27<=P$6+6,$J27>=P$6),IF($R$4=1,"█",IF($R$4=2,$G27,$G27*2)),"") | Q27: =IF(AND($I27<=Q$6+6,$J27>=Q$6),IF($R$4=1,"█",IF($R$4=2,$G27,$G27*2)),"") | R27: =IF(AND($I27<=R$6+6,$J27>=R$6),IF($R$4=1,"█",IF($R$4=2,$G27,$G27*2)),"") | S27: =IF(AND($I27<=S$6+6,$J27>=S$6),IF($R$4=1,"█",IF($R$4=2,$G27,$G27*2)),"") | T27: =IF(AND($I27<=T$6+6,$J27>=T$6),IF($R$4=1,"█",IF($R$4=2,$G27,$G27*2)),"") | ... BD27: =IF(AND($I27<=BD$6+6,$J27>=BD$6),IF($R$4=1,"█",IF($R$4=2,$G27,$G27*2)),"") | BF27: =BG28-1-0 | BG27: =BF27-H27+1 | BH27: =BG27-I27
A28: 4.2 | B28: Đổ bê tông C45 15 phiến dầm Super-T (bảo dưỡng đạt cường độ R28) | C28: =QS_DIEN_GIAI_CHI_TIET!J57 | D28: m3 | E28: 0.65 | F28: =C28*E28 | G28: 16 | H28: =ROUNDUP(F28/G28, 0) | I28: =J27+1+0 | J28: =I28+H28-1 | K28: 4.1FS | L28: =IF(BH28=0,"YES","NO") | M28: =IF(AND($I28<=M$6+6,$J28>=M$6),IF($R$4=1,"█",IF($R$4=2,$G28,$G28*2)),"") | N28: =IF(AND($I28<=N$6+6,$J28>=N$6),IF($R$4=1,"█",IF($R$4=2,$G28,$G28*2)),"") | O28: =IF(AND($I28<=O$6+6,$J28>=O$6),IF($R$4=1,"█",IF($R$4=2,$G28,$G28*2)),"") | P28: =IF(AND($I28<=P$6+6,$J28>=P$6),IF($R$4=1,"█",IF($R$4=2,$G28,$G28*2)),"") | Q28: =IF(AND($I28<=Q$6+6,$J28>=Q$6),IF($R$4=1,"█",IF($R$4=2,$G28,$G28*2)),"") | R28: =IF(AND($I28<=R$6+6,$J28>=R$6),IF($R$4=1,"█",IF($R$4=2,$G28,$G28*2)),"") | S28: =IF(AND($I28<=S$6+6,$J28>=S$6),IF($R$4=1,"█",IF($R$4=2,$G28,$G28*2)),"") | T28: =IF(AND($I28<=T$6+6,$J28>=T$6),IF($R$4=1,"█",IF($R$4=2,$G28,$G28*2)),"") | ... BD28: =IF(AND($I28<=BD$6+6,$J28>=BD$6),IF($R$4=1,"█",IF($R$4=2,$G28,$G28*2)),"") | BF28: =BG29-1-0 | BG28: =BF28-H28+1 | BH28: =BG28-I28
A29: 4.3 | B29: Căng kéo cáp DUL tao xoắn 15.2mm & bơm vữa ống gen dầm | C29: 15 | D29: Phiến | E29: 4 | F29: =C29*E29 | G29: 8 | H29: =ROUNDUP(F29/G29, 0) | I29: =J28+1+0 | J29: =I29+H29-1 | K29: 4.2FS | L29: =IF(BH29=0,"YES","NO") | M29: =IF(AND($I29<=M$6+6,$J29>=M$6),IF($R$4=1,"█",IF($R$4=2,$G29,$G29*2)),"") | N29: =IF(AND($I29<=N$6+6,$J29>=N$6),IF($R$4=1,"█",IF($R$4=2,$G29,$G29*2)),"") | O29: =IF(AND($I29<=O$6+6,$J29>=O$6),IF($R$4=1,"█",IF($R$4=2,$G29,$G29*2)),"") | P29: =IF(AND($I29<=P$6+6,$J29>=P$6),IF($R$4=1,"█",IF($R$4=2,$G29,$G29*2)),"") | Q29: =IF(AND($I29<=Q$6+6,$J29>=Q$6),IF($R$4=1,"█",IF($R$4=2,$G29,$G29*2)),"") | R29: =IF(AND($I29<=R$6+6,$J29>=R$6),IF($R$4=1,"█",IF($R$4=2,$G29,$G29*2)),"") | S29: =IF(AND($I29<=S$6+6,$J29>=S$6),IF($R$4=1,"█",IF($R$4=2,$G29,$G29*2)),"") | T29: =IF(AND($I29<=T$6+6,$J29>=T$6),IF($R$4=1,"█",IF($R$4=2,$G29,$G29*2)),"") | ... BD29: =IF(AND($I29<=BD$6+6,$J29>=BD$6),IF($R$4=1,"█",IF($R$4=2,$G29,$G29*2)),"") | BF29: =BG31-1-0 | BG29: =BF29-H29+1 | BH29: =BG29-I29
A30: 4.4 | B30: Lắp đặt 30 gối chậu cao su đơn/song hướng mố trụ | C30: 30 | D30: Cái | E30: 1.2 | F30: =C30*E30 | G30: 6 | H30: =ROUNDUP(F30/G30, 0) | I30: =J25+1+0 | J30: =I30+H30-1 | K30: 3.6FS | L30: =IF(BH30=0,"YES","NO") | M30: =IF(AND($I30<=M$6+6,$J30>=M$6),IF($R$4=1,"█",IF($R$4=2,$G30,$G30*2)),"") | N30: =IF(AND($I30<=N$6+6,$J30>=N$6),IF($R$4=1,"█",IF($R$4=2,$G30,$G30*2)),"") | O30: =IF(AND($I30<=O$6+6,$J30>=O$6),IF($R$4=1,"█",IF($R$4=2,$G30,$G30*2)),"") | P30: =IF(AND($I30<=P$6+6,$J30>=P$6),IF($R$4=1,"█",IF($R$4=2,$G30,$G30*2)),"") | Q30: =IF(AND($I30<=Q$6+6,$J30>=Q$6),IF($R$4=1,"█",IF($R$4=2,$G30,$G30*2)),"") | R30: =IF(AND($I30<=R$6+6,$J30>=R$6),IF($R$4=1,"█",IF($R$4=2,$G30,$G30*2)),"") | S30: =IF(AND($I30<=S$6+6,$J30>=S$6),IF($R$4=1,"█",IF($R$4=2,$G30,$G30*2)),"") | T30: =IF(AND($I30<=T$6+6,$J30>=T$6),IF($R$4=1,"█",IF($R$4=2,$G30,$G30*2)),"") | ... BD30: =IF(AND($I30<=BD$6+6,$J30>=BD$6),IF($R$4=1,"█",IF($R$4=2,$G30,$G30*2)),"") | BF30: =BG31-1-0 | BG30: =BF30-H30+1 | BH30: =BG30-I30
A31: 4.5 | B31: Lắp đặt đường ray P43, vận chuyển & lao lắp 15 phiến dầm Super-T | C31: 15 | D31: Phiến | E31: 5 | F31: =C31*E31 | G31: 12 | H31: =ROUNDUP(F31/G31, 0) | I31: =MAX(J29+1+0,J30+1+0) | J31: =I31+H31-1 | K31: 4.3FS,4.4FS | L31: =IF(BH31=0,"YES","NO") | M31: =IF(AND($I31<=M$6+6,$J31>=M$6),IF($R$4=1,"█",IF($R$4=2,$G31,$G31*2)),"") | N31: =IF(AND($I31<=N$6+6,$J31>=N$6),IF($R$4=1,"█",IF($R$4=2,$G31,$G31*2)),"") | O31: =IF(AND($I31<=O$6+6,$J31>=O$6),IF($R$4=1,"█",IF($R$4=2,$G31,$G31*2)),"") | P31: =IF(AND($I31<=P$6+6,$J31>=P$6),IF($R$4=1,"█",IF($R$4=2,$G31,$G31*2)),"") | Q31: =IF(AND($I31<=Q$6+6,$J31>=Q$6),IF($R$4=1,"█",IF($R$4=2,$G31,$G31*2)),"") | R31: =IF(AND($I31<=R$6+6,$J31>=R$6),IF($R$4=1,"█",IF($R$4=2,$G31,$G31*2)),"") | S31: =IF(AND($I31<=S$6+6,$J31>=S$6),IF($R$4=1,"█",IF($R$4=2,$G31,$G31*2)),"") | T31: =IF(AND($I31<=T$6+6,$J31>=T$6),IF($R$4=1,"█",IF($R$4=2,$G31,$G31*2)),"") | ... BD31: =IF(AND($I31<=BD$6+6,$J31>=BD$6),IF($R$4=1,"█",IF($R$4=2,$G31,$G31*2)),"") | BF31: =BG33-1-0 | BG31: =BF31-H31+1 | BH31: =BG31-I31
A32: 5.0
A33: 5.1 | B33: Đổ bê tông dầm ngang mố, dầm ngang trụ và bản liên tục nhiệt C35 | C33: =QS_DIEN_GIAI_CHI_TIET!J68 | D33: m3 | E33: 0.85 | F33: =C33*E33 | G33: 12 | H33: =ROUNDUP(F33/G33, 0) | I33: =J31+1+0 | J33: =I33+H33-1 | K33: 4.5FS | L33: =IF(BH33=0,"YES","NO") | M33: =IF(AND($I33<=M$6+6,$J33>=M$6),IF($R$4=1,"█",IF($R$4=2,$G33,$G33*2)),"") | N33: =IF(AND($I33<=N$6+6,$J33>=N$6),IF($R$4=1,"█",IF($R$4=2,$G33,$G33*2)),"") | O33: =IF(AND($I33<=O$6+6,$J33>=O$6),IF($R$4=1,"█",IF($R$4=2,$G33,$G33*2)),"") | P33: =IF(AND($I33<=P$6+6,$J33>=P$6),IF($R$4=1,"█",IF($R$4=2,$G33,$G33*2)),"") | Q33: =IF(AND($I33<=Q$6+6,$J33>=Q$6),IF($R$4=1,"█",IF($R$4=2,$G33,$G33*2)),"") | R33: =IF(AND($I33<=R$6+6,$J33>=R$6),IF($R$4=1,"█",IF($R$4=2,$G33,$G33*2)),"") | S33: =IF(AND($I33<=S$6+6,$J33>=S$6),IF($R$4=1,"█",IF($R$4=2,$G33,$G33*2)),"") | T33: =IF(AND($I33<=T$6+6,$J33>=T$6),IF($R$4=1,"█",IF($R$4=2,$G33,$G33*2)),"") | ... BD33: =IF(AND($I33<=BD$6+6,$J33>=BD$6),IF($R$4=1,"█",IF($R$4=2,$G33,$G33*2)),"") | BF33: =MIN(BG34-1-0,BG36-1-0) | BG33: =BF33-H33+1 | BH33: =BG33-I33
A34: 5.2 | B34: Lắp đặt 510 tấm ván khuôn đúc sẵn & lắp cốt thép bản mặt cầu C35 | C34: =QS_DIEN_GIAI_CHI_TIET!J72 | D34: Tấm | E34: 0.08 | F34: =C34*E34 | G34: 14 | H34: =ROUNDUP(F34/G34, 0) | I34: =J33+1+0 | J34: =I34+H34-1 | K34: 5.1FS | L34: =IF(BH34=0,"YES","NO") | M34: =IF(AND($I34<=M$6+6,$J34>=M$6),IF($R$4=1,"█",IF($R$4=2,$G34,$G34*2)),"") | N34: =IF(AND($I34<=N$6+6,$J34>=N$6),IF($R$4=1,"█",IF($R$4=2,$G34,$G34*2)),"") | O34: =IF(AND($I34<=O$6+6,$J34>=O$6),IF($R$4=1,"█",IF($R$4=2,$G34,$G34*2)),"") | P34: =IF(AND($I34<=P$6+6,$J34>=P$6),IF($R$4=1,"█",IF($R$4=2,$G34,$G34*2)),"") | Q34: =IF(AND($I34<=Q$6+6,$J34>=Q$6),IF($R$4=1,"█",IF($R$4=2,$G34,$G34*2)),"") | R34: =IF(AND($I34<=R$6+6,$J34>=R$6),IF($R$4=1,"█",IF($R$4=2,$G34,$G34*2)),"") | S34: =IF(AND($I34<=S$6+6,$J34>=S$6),IF($R$4=1,"█",IF($R$4=2,$G34,$G34*2)),"") | T34: =IF(AND($I34<=T$6+6,$J34>=T$6),IF($R$4=1,"█",IF($R$4=2,$G34,$G34*2)),"") | ... BD34: =IF(AND($I34<=BD$6+6,$J34>=BD$6),IF($R$4=1,"█",IF($R$4=2,$G34,$G34*2)),"") | BF34: =BG35-1-0 | BG34: =BF34-H34+1 | BH34: =BG34-I34
A35: 5.3 | B35: Đổ bê tông bản mặt cầu tại chỗ C35 (dày tối thiểu 180mm) | C35: =QS_DIEN_GIAI_CHI_TIET!J74 | D35: m3 | E35: 0.45 | F35: =C35*E35 | G35: 18 | H35: =ROUNDUP(F35/G35, 0) | I35: =J34+1+0 | J35: =I35+H35-1 | K35: 5.2FS | L35: =IF(BH35=0,"YES","NO") | M35: =IF(AND($I35<=M$6+6,$J35>=M$6),IF($R$4=1,"█",IF($R$4=2,$G35,$G35*2)),"") | N35: =IF(AND($I35<=N$6+6,$J35>=N$6),IF($R$4=1,"█",IF($R$4=2,$G35,$G35*2)),"") | O35: =IF(AND($I35<=O$6+6,$J35>=O$6),IF($R$4=1,"█",IF($R$4=2,$G35,$G35*2)),"") | P35: =IF(AND($I35<=P$6+6,$J35>=P$6),IF($R$4=1,"█",IF($R$4=2,$G35,$G35*2)),"") | Q35: =IF(AND($I35<=Q$6+6,$J35>=Q$6),IF($R$4=1,"█",IF($R$4=2,$G35,$G35*2)),"") | R35: =IF(AND($I35<=R$6+6,$J35>=R$6),IF($R$4=1,"█",IF($R$4=2,$G35,$G35*2)),"") | S35: =IF(AND($I35<=S$6+6,$J35>=S$6),IF($R$4=1,"█",IF($R$4=2,$G35,$G35*2)),"") | T35: =IF(AND($I35<=T$6+6,$J35>=T$6),IF($R$4=1,"█",IF($R$4=2,$G35,$G35*2)),"") | ... BD35: =IF(AND($I35<=BD$6+6,$J35>=BD$6),IF($R$4=1,"█",IF($R$4=2,$G35,$G35*2)),"") | BF35: =MIN(BG37-1-0,BG38-1-0) | BG35: =BF35-H35+1 | BH35: =BG35-I35
A36: 5.4 | B36: Đổ bê tông bản quá độ C25 sau 2 mố & đắp đất chọn lọc K98 | C36: 2 | D36: Bản | E36: 24 | F36: =C36*E36 | G36: 10 | H36: =ROUNDUP(F36/G36, 0) | I36: =J33+1+0 | J36: =I36+H36-1 | K36: 5.1FS | L36: =IF(BH36=0,"YES","NO") | M36: =IF(AND($I36<=M$6+6,$J36>=M$6),IF($R$4=1,"█",IF($R$4=2,$G36,$G36*2)),"") | N36: =IF(AND($I36<=N$6+6,$J36>=N$6),IF($R$4=1,"█",IF($R$4=2,$G36,$G36*2)),"") | O36: =IF(AND($I36<=O$6+6,$J36>=O$6),IF($R$4=1,"█",IF($R$4=2,$G36,$G36*2)),"") | P36: =IF(AND($I36<=P$6+6,$J36>=P$6),IF($R$4=1,"█",IF($R$4=2,$G36,$G36*2)),"") | Q36: =IF(AND($I36<=Q$6+6,$J36>=Q$6),IF($R$4=1,"█",IF($R$4=2,$G36,$G36*2)),"") | R36: =IF(AND($I36<=R$6+6,$J36>=R$6),IF($R$4=1,"█",IF($R$4=2,$G36,$G36*2)),"") | S36: =IF(AND($I36<=S$6+6,$J36>=S$6),IF($R$4=1,"█",IF($R$4=2,$G36,$G36*2)),"") | T36: =IF(AND($I36<=T$6+6,$J36>=T$6),IF($R$4=1,"█",IF($R$4=2,$G36,$G36*2)),"") | ... BD36: =IF(AND($I36<=BD$6+6,$J36>=BD$6),IF($R$4=1,"█",IF($R$4=2,$G36,$G36*2)),"") | BF36: =MAX($J$8:$J$42) | BG36: =BF36-H36+1 | BH36: =BG36-I36
A37: 5.5 | B37: Lắp đặt khe co giãn răng lược thép D=100mm & ống thoát nước PVC D150 | C37: 2 | D37: Bộ | E37: 18 | F37: =C37*E37 | G37: 6 | H37: =ROUNDUP(F37/G37, 0) | I37: =J35+1+0 | J37: =I37+H37-1 | K37: 5.3FS | L37: =IF(BH37=0,"YES","NO") | M37: =IF(AND($I37<=M$6+6,$J37>=M$6),IF($R$4=1,"█",IF($R$4=2,$G37,$G37*2)),"") | N37: =IF(AND($I37<=N$6+6,$J37>=N$6),IF($R$4=1,"█",IF($R$4=2,$G37,$G37*2)),"") | O37: =IF(AND($I37<=O$6+6,$J37>=O$6),IF($R$4=1,"█",IF($R$4=2,$G37,$G37*2)),"") | P37: =IF(AND($I37<=P$6+6,$J37>=P$6),IF($R$4=1,"█",IF($R$4=2,$G37,$G37*2)),"") | Q37: =IF(AND($I37<=Q$6+6,$J37>=Q$6),IF($R$4=1,"█",IF($R$4=2,$G37,$G37*2)),"") | R37: =IF(AND($I37<=R$6+6,$J37>=R$6),IF($R$4=1,"█",IF($R$4=2,$G37,$G37*2)),"") | S37: =IF(AND($I37<=S$6+6,$J37>=S$6),IF($R$4=1,"█",IF($R$4=2,$G37,$G37*2)),"") | T37: =IF(AND($I37<=T$6+6,$J37>=T$6),IF($R$4=1,"█",IF($R$4=2,$G37,$G37*2)),"") | ... BD37: =IF(AND($I37<=BD$6+6,$J37>=BD$6),IF($R$4=1,"█",IF($R$4=2,$G37,$G37*2)),"") | BF37: =BG39-1-0 | BG37: =BF37-H37+1 | BH37: =BG37-I37
A38: 5.6 | B38: Đổ bê tông gờ lan can C25 & lắp dựng tay vịn thép mạ kẽm | C38: 260.8 | D38: m | E38: 0.35 | F38: =C38*E38 | G38: 10 | H38: =ROUNDUP(F38/G38, 0) | I38: =J35+1+0 | J38: =I38+H38-1 | K38: 5.3FS | L38: =IF(BH38=0,"YES","NO") | M38: =IF(AND($I38<=M$6+6,$J38>=M$6),IF($R$4=1,"█",IF($R$4=2,$G38,$G38*2)),"") | N38: =IF(AND($I38<=N$6+6,$J38>=N$6),IF($R$4=1,"█",IF($R$4=2,$G38,$G38*2)),"") | O38: =IF(AND($I38<=O$6+6,$J38>=O$6),IF($R$4=1,"█",IF($R$4=2,$G38,$G38*2)),"") | P38: =IF(AND($I38<=P$6+6,$J38>=P$6),IF($R$4=1,"█",IF($R$4=2,$G38,$G38*2)),"") | Q38: =IF(AND($I38<=Q$6+6,$J38>=Q$6),IF($R$4=1,"█",IF($R$4=2,$G38,$G38*2)),"") | R38: =IF(AND($I38<=R$6+6,$J38>=R$6),IF($R$4=1,"█",IF($R$4=2,$G38,$G38*2)),"") | S38: =IF(AND($I38<=S$6+6,$J38>=S$6),IF($R$4=1,"█",IF($R$4=2,$G38,$G38*2)),"") | T38: =IF(AND($I38<=T$6+6,$J38>=T$6),IF($R$4=1,"█",IF($R$4=2,$G38,$G38*2)),"") | ... BD38: =IF(AND($I38<=BD$6+6,$J38>=BD$6),IF($R$4=1,"█",IF($R$4=2,$G38,$G38*2)),"") | BF38: =MAX($J$8:$J$42) | BG38: =BF38-H38+1 | BH38: =BG38-I38
A39: 5.7 | B39: Phun lớp màng chống thấm & thảm bê tông nhựa C16 mặt cầu dày 7cm | C39: =QS_DIEN_GIAI_CHI_TIET!J87 | D39: m2 | E39: 0.04 | F39: =C39*E39 | G39: 12 | H39: =ROUNDUP(F39/G39, 0) | I39: =J37+1+0 | J39: =I39+H39-1 | K39: 5.5FS | L39: =IF(BH39=0,"YES","NO") | M39: =IF(AND($I39<=M$6+6,$J39>=M$6),IF($R$4=1,"█",IF($R$4=2,$G39,$G39*2)),"") | N39: =IF(AND($I39<=N$6+6,$J39>=N$6),IF($R$4=1,"█",IF($R$4=2,$G39,$G39*2)),"") | O39: =IF(AND($I39<=O$6+6,$J39>=O$6),IF($R$4=1,"█",IF($R$4=2,$G39,$G39*2)),"") | P39: =IF(AND($I39<=P$6+6,$J39>=P$6),IF($R$4=1,"█",IF($R$4=2,$G39,$G39*2)),"") | Q39: =IF(AND($I39<=Q$6+6,$J39>=Q$6),IF($R$4=1,"█",IF($R$4=2,$G39,$G39*2)),"") | R39: =IF(AND($I39<=R$6+6,$J39>=R$6),IF($R$4=1,"█",IF($R$4=2,$G39,$G39*2)),"") | S39: =IF(AND($I39<=S$6+6,$J39>=S$6),IF($R$4=1,"█",IF($R$4=2,$G39,$G39*2)),"") | T39: =IF(AND($I39<=T$6+6,$J39>=T$6),IF($R$4=1,"█",IF($R$4=2,$G39,$G39*2)),"") | ... BD39: =IF(AND($I39<=BD$6+6,$J39>=BD$6),IF($R$4=1,"█",IF($R$4=2,$G39,$G39*2)),"") | BF39: =BG41-1-0 | BG39: =BF39-H39+1 | BH39: =BG39-I39
A40: 6.0
A41: 6.1 | B41: Thử tải tĩnh/động cầu bằng đoàn xe tải nặng, đo dao động & võng dầm | C41: 1 | D41: Gói | E41: 32 | F41: =C41*E41 | G41: 8 | H41: =ROUNDUP(F41/G41, 0) | I41: =J39+1+0 | J41: =I41+H41-1 | K41: 5.7FS | L41: =IF(BH41=0,"YES","NO") | M41: =IF(AND($I41<=M$6+6,$J41>=M$6),IF($R$4=1,"█",IF($R$4=2,$G41,$G41*2)),"") | N41: =IF(AND($I41<=N$6+6,$J41>=N$6),IF($R$4=1,"█",IF($R$4=2,$G41,$G41*2)),"") | O41: =IF(AND($I41<=O$6+6,$J41>=O$6),IF($R$4=1,"█",IF($R$4=2,$G41,$G41*2)),"") | P41: =IF(AND($I41<=P$6+6,$J41>=P$6),IF($R$4=1,"█",IF($R$4=2,$G41,$G41*2)),"") | Q41: =IF(AND($I41<=Q$6+6,$J41>=Q$6),IF($R$4=1,"█",IF($R$4=2,$G41,$G41*2)),"") | R41: =IF(AND($I41<=R$6+6,$J41>=R$6),IF($R$4=1,"█",IF($R$4=2,$G41,$G41*2)),"") | S41: =IF(AND($I41<=S$6+6,$J41>=S$6),IF($R$4=1,"█",IF($R$4=2,$G41,$G41*2)),"") | T41: =IF(AND($I41<=T$6+6,$J41>=T$6),IF($R$4=1,"█",IF($R$4=2,$G41,$G41*2)),"") | ... BD41: =IF(AND($I41<=BD$6+6,$J41>=BD$6),IF($R$4=1,"█",IF($R$4=2,$G41,$G41*2)),"") | BF41: =BG42-1-0 | BG41: =BF41-H41+1 | BH41: =BG41-I41
...

Sheet QS_DIEN_GIAI_CHI_TIET
B2: DỰ ÁN: CAO TỐC TUYÊN QUANG - HÀ GIANG (GIAI ĐOẠN 1) - ĐOẠN QUA TỈNH HÀ GIANG
B3: BẢNG DIỄN GIẢI TIÊN LƯỢNG KHỐI LƯỢNG HÌNH HỌC CHI TIẾT - CẦU KM19+529.080
B4: Tuân thủ nghiêm ngặt nguyên tắc 100% công thức động: Khối lượng = Dài x Rộng x Cao x Số lượng x Hệ số (CẤM SỐ CHẾT)
A5: TT | B5: Mã hiệu | C5: Nội dung công tác & Diễn giải hình học cấu kiện | D5: ĐVT | E5: Số lượng (Cấu kiện) | F5: Dài (m) | G5: Rộng (m) | H5: Cao / Dày (m) | I5: Hệ số hình học | J5: Khối lượng (Công thức) | K5: Đơn giá (VNĐ) | L5: Thành tiền (VNĐ)
A6: PHẦN I: THI CÔNG CỌC KHOAN NHỒI D1200MM & THÍ NGHIỆM KIỂM SOÁT
A7: 1 | B7: AC.11111 | C7: Khoan tạo lỗ cọc khoan nhồi D1200mm vào đất và đá gốc (26 cọc) | D7: m | J7: =SUM(J8:J11) | K7: 2850000 | L7: =J7*K7
C8: - Cọc mố M1: 3 cọc chiều sâu L=20.0m | D8: m | E8: 3 | F8: 20 | G8: 1 | H8: 1 | I8: 1 | J8: =E8*F8*G8*H8*I8
C9: - Cọc trụ T1: 8 cọc chiều sâu L=40.0m | D9: m | E9: 8 | F9: 40 | G9: 1 | H9: 1 | I9: 1 | J9: =E9*F9*G9*H9*I9
C10: - Cọc trụ T2: 8 cọc chiều sâu L=30.0m | D10: m | E10: 8 | F10: 30 | G10: 1 | H10: 1 | I10: 1 | J10: =E10*F10*G10*H10*I10
C11: - Cọc mố M2: 7 cọc chiều sâu L=36.0m | D11: m | E11: 7 | F11: 36 | G11: 1 | H11: 1 | I11: 1 | J11: =E11*F11*G11*H11*I11
A12: 2 | B12: AC.12111 | C12: Hạ và nhổ ống vách thép dẫn hướng D1300mm d=8mm (luân chuyển) | D12: m | J12: =SUM(J13:J16) | K12: 1450000 | L12: =J12*K12
C13: - Ống vách thép cọc mố M1 (3 cọc x 6m) | D13: m | E13: 3 | F13: 6 | G13: 1 | H13: 1 | I13: 1 | J13: =E13*F13*G13*H13*I13
C14: - Ống vách thép cọc trụ T1 (8 cọc x 6m) | D14: m | E14: 8 | F14: 6 | G14: 1 | H14: 1 | I14: 1 | J14: =E14*F14*G14*H14*I14
C15: - Ống vách thép cọc trụ T2 (8 cọc x 6m) | D15: m | E15: 8 | F15: 6 | G15: 1 | H15: 1 | I15: 1 | J15: =E15*F15*G15*H15*I15
C16: - Ống vách thép cọc mố M2 (7 cọc x 6m) | D16: m | E16: 7 | F16: 6 | G16: 1 | H16: 1 | I16: 1 | J16: =E16*F16*G16*H16*I16
A17: 3 | B17: AF.21111 | C17: Bê tông cọc khoan nhồi C30/37 đổ bằng phương pháp rút ống tremie | D17: m3 | J17: =SUM(J18:J21) | K17: 1650000 | L17: =J17*K17
C18: - Bê tông 3 cọc mố M1 (L=20m, D=1.2m, hs nở thành 1.12) | D18: m3 | E18: 3 | F18: 20 | G18: 0.6 | H18: 0.6 | I18: 3.5186 | J18: =E18*F18*G18*H18*I18
C19: - Bê tông 8 cọc trụ T1 (L=40m, D=1.2m, hs nở thành 1.12) | D19: m3 | E19: 8 | F19: 40 | G19: 0.6 | H19: 0.6 | I19: 3.5186 | J19: =E19*F19*G19*H19*I19
C20: - Bê tông 8 cọc trụ T2 (L=30m, D=1.2m, hs nở thành 1.12) | D20: m3 | E20: 8 | F20: 30 | G20: 0.6 | H20: 0.6 | I20: 3.5186 | J20: =E20*F20*G20*H20*I20
C21: - Bê tông 7 cọc mố M2 (L=36m, D=1.2m, hs nở thành 1.12) | D21: m3 | E21: 7 | F21: 36 | G21: 0.6 | H21: 0.6 | I21: 3.5186 | J21: =E21*F21*G21*H21*I21
A22: 4 | B22: AF.61111 | C22: Cốt thép cọc khoan nhồi D1200mm (Thép chủ D25, đai D16, D10) | D22: Tấn | J22: 108.76599 | K22: 18500000 | L22: =J22*K22
C23: - Cốt thép cọc mố M1 (3 cọc x 5.889 tấn/cọc) | D23: Tấn | E23: 3 | F23: 5.889 | G23: 1 | H23: 1 | I23: 1 | J23: =E23*F23*G23*H23*I23
C24: - Cốt thép cọc trụ T1 (8 cọc x 4.845 tấn/cọc) | D24: Tấn | E24: 8 | F24: 4.845 | G24: 1 | H24: 1 | I24: 1 | J24: =E24*F24*G24*H24*I24
C25: - Cốt thép cọc trụ T2 (8 cọc x 3.687 tấn/cọc) | D25: Tấn | E25: 8 | F25: 3.687 | G25: 1 | H25: 1 | I25: 1 | J25: =E25*F25*G25*H25*I25
C26: - Cốt thép cọc mố M2 (7 cọc x 4.721 tấn/cọc) | D26: Tấn | E26: 7 | F26: 4.721 | G26: 1 | H26: 1 | I26: 1 | J26: =E26*F26*G26*H26*I26
A27: 5 | B27: AC.13111 | C27: Đập đầu cọc khoan nhồi nhô lên đáy bệ ngàm vào kết cấu | D27: m3 | J27: =SUM(J28:J28) | K27: 550000 | L27: =J27*K27
C28: - Đập đầu 26 cọc khoan nhồi (chiều cao đập h=1.0m) | D28: m3 | E28: 26 | F28: 1 | G28: 0.6 | H28: 0.6 | I28: 3.1416 | J28: =E28*F28*G28*H28*I28
A29: 6 | B29: TN.11111 | C29: Thí nghiệm kiểm soát cọc (Siêu âm 156 mặt cắt, PDA 9434kN, lấy lõi 4 cọc) | D29: Gói | J29: =SUM(J30:J30) | K29: 450000000 | L29: =J29*K29
C30: - Gói thí nghiệm siêu âm 100% cọc, nén động PDA trụ T1 & khoan lấy lõi | D30: Gói | E30: 1 | F30: 1 | G30: 1 | H30: 1 | I30: 1 | J30: =E30*F30*G30*H30*I30
A31: PHẦN II: KẾT CẤU PHẦN DƯỚI (BỆ, THÂN, XÀ MŨ MỐ M1, M2 & TRỤ T1, T2)
A32: 7 | B32: AB.11111 | C32: Đào đất đá hố móng bệ mố M1, M2 và bệ trụ T1, T2 (Link Sheet Đào Đắp) | D32: m3 | J32: =SUM(J33:J33) | K32: 145000 | L32: =J32*K32
C33: - Đào đất đá hố móng bệ mố M1,M2 & bệ trụ T1,T2 → =KHOI_LUONG_DAO_DAP!F21 | D33: m3 | E33: 1 | F33: 1 | G33: 1 | H33: 1 | I33: 1 | J33: 6245
A34: 8 | B34: AF.11111 | C34: Bê tông lót đáy bệ móng mác C10 dày 10cm | D34: m3 | J34: =SUM(J35:J38) | K34: 1150000 | L34: =J34*K34
C35: - Lớp bê tông lót đáy bệ mố M1 chân dê | D35: m3 | E35: 1 | F35: 12.5 | G35: 6 | H35: 0.1 | I35: 1 | J35: =E35*F35*G35*H35*I35
C36: - Lớp bê tông lót đáy bệ mố M2 chữ U | D36: m3 | E36: 1 | F36: 14 | G36: 6.5 | H36: 0.1 | I36: 1 | J36: =E36*F36*G36*H36*I36
C37: - Lớp bê tông lót đáy bệ trụ T1 | D37: m3 | E37: 1 | F37: 13 | G37: 6.5 | H37: 0.1 | I37: 1 | J37: =E37*F37*G37*H37*I37
C38: - Lớp bê tông lót đáy bệ trụ T2 | D38: m3 | E38: 1 | F38: 13 | G38: 6.5 | H38: 0.1 | I38: 1 | J38: =E38*F38*G38*H38*I38
A39: 9 | B39: AF.12111 | C39: Bê tông bệ móng mố M1, M2 và bệ trụ T1, T2 mác C30 | D39: m3 | J39: =SUM(J40:J43) | K39: 1480000 | L39: =J39*K39
C40: - Bệ móng mố M1 chân dê (chiều cao bệ h=2.0m) | D40: m3 | E40: 1 | F40: 12 | G40: 5.5 | H40: 2 | I40: 1.1287 | J40: =E40*F40*G40*H40*I40
C41: - Bệ móng mố M2 chữ U (chiều cao bệ h=2.0m) | D41: m3 | E41: 1 | F41: 13.5 | G41: 5.5 | H41: 2 | I41: 1.0033 | J41: =E41*F41*G41*H41*I41
...
