Workbook

Sheet 01_TienDo_CaMay_Master
A1: DỰ ÁN: CỐNG HỘP TUYẾN A5 - KHU ĐÔ THỊ THỂ THAO QUỐC TẾ HÀ NỘI
A2: BẢNG TÍNH TOÁN CA XE, CA MÁY & TIẾN ĐỘ THI CÔNG TOÀN TUYẾN A5 (L = 2,170 M - 63 HỐ GA)
A3: MỐC TIẾN ĐỘ THI CÔNG TOÀN TUYẾN: TỪ 05/09/2026 ĐẾN 12/11/2026 (69 NGÀY) - 2 CA/NGÀY (20H/NGÀY) - 3 MŨI THI CÔNG ĐỒNG THỜI
B4: Chế độ ca: | C4: 2 ca/ngày (20 giờ/ngày) | F4: Phân đoạn thi công: | G4: 3 mũi song song (Cống 2x2: 385m, Cống 3x3: 560m, Cống đôi 2x(3x3): 1,225m) | K4: Định mức áp dụng: | L4: Vincons_ĐMGK_02-01 Hạ tầng giao thông
A6: STT | B6: Mã ĐM | C6: Nội dung công việc thi công cống hộp | D6: ĐVT | E6: Khối lượng thiết kế | F6: Định mức Vincons (ĐVT/ca) | G6: Tổng số ca máy (ca) | H6: Năng xuất ngày | I6: Thời gian (ngày) | J6: Ngày BĐ | K6: Ngày KT | L6: Số ca/ngày | M6: Số máy huy động/ngày | N6: Chủng loại MMTB & Ghi chú | O6: NC bố trí (người) | P6: 46270 | Q6: =P6+1 -> 46271 | R6: =Q6+1 -> 46272 | S6: =R6+1 -> 46273 | T6: =S6+1 -> 46274 | U6: =T6+1 -> 46275 | V6: =U6+1 -> 46276 | W6: =V6+1 -> 46277 | X6: =W6+1 -> 46278 | ... CF6: =CE6+1 -> 46338
P7: T7 | Q7: CN | R7: T2 | S7: T3 | T7: T4 | U7: T5 | V7: T6 | W7: T7 | X7: CN | Y7: T2 | Z7: T3 | AA7: T4 | AB7: T5 | AC7: T6 | AD7: T7 | AE7: CN | AF7: T2 | AG7: T3 | AH7: T4 | AI7: T5 | AJ7: T6 | AK7: T7 | AL7: CN | AM7: T2 | AN7: T3 | AO7: T4 | AP7: T5 | AQ7: T6 | AR7: T7 | AS7: CN | AT7: T2 | AU7: T3 | AV7: T4 | AW7: T5 | AX7: T6 | AY7: T7 | AZ7: CN | BA7: T2 | BB7: T3 | BC7: T4 | BD7: T5 | BE7: T6 | BF7: T7 | BG7: CN | BH7: T2 | BI7: T3 | BJ7: T4 | BK7: T5 | BL7: T6 | BM7: T7 | BN7: CN | BO7: T2 | BP7: T3 | BQ7: T4 | BR7: T5 | BS7: T6 | BT7: T7 | BU7: CN | BV7: T2 | BW7: T3 | BX7: T4 | BY7: T5 | BZ7: T6 | CA7: T7 | CB7: CN | CC7: T2 | CD7: T3 | CE7: T4 | CF7: T5
A8: 1 | B8: ĐM-16 | C8: Đào đất hố móng cống hộp 3 mũi (H_tb = 3.5m) | D8: m3 | E8: 73800 | F8: 401.07 | G8: =IF(F8>0,ROUND(E8/F8,1),0) -> 184 | H8: =IF(I8>0,ROUND(E8/I8,1),0) -> 2460 | I8: =K8-J8+1 -> 30 | J8: 46270 | K8: 46299 | L8: 2 | M8: =IF(AND(G8>0,I8>0,L8>0),ROUNDUP(G8/(I8*L8),2),0) -> 3.07 | N8: Máy xúc PC200 - PC300 | O8: 24 | P8: =IF(AND($J8<=P$6,$K8>=P$6),$M8,"") -> 3.07 | Q8: =IF(AND($J8<=Q$6,$K8>=Q$6),$M8,"") -> 3.07 | R8: =IF(AND($J8<=R$6,$K8>=R$6),$M8,"") -> 3.07 | S8: =IF(AND($J8<=S$6,$K8>=S$6),$M8,"") -> 3.07 | T8: =IF(AND($J8<=T$6,$K8>=T$6),$M8,"") -> 3.07 | U8: =IF(AND($J8<=U$6,$K8>=U$6),$M8,"") -> 3.07 | V8: =IF(AND($J8<=V$6,$K8>=V$6),$M8,"") -> 3.07 | W8: =IF(AND($J8<=W$6,$K8>=W$6),$M8,"") -> 3.07 | ... CF8: =IF(AND($J8<=CF$6,$K8>=CF$6),$M8,"")
A9: 2 | B9: ĐM-15 | C9: Đào hố móng 63 hố ga thu nước & đấu nối | D9: m3 | E9: 12650 | F9: 313.55 | G9: =IF(F9>0,ROUND(E9/F9,1),0) -> 40.3 | H9: =IF(I9>0,ROUND(E9/I9,1),0) -> 550 | I9: =K9-J9+1 -> 23 | J9: 46273 | K9: 46295 | L9: 2 | M9: =IF(AND(G9>0,I9>0,L9>0),ROUNDUP(G9/(I9*L9),2),0) -> 0.88 | N9: Máy xúc PC200 | O9: 12 | P9: =IF(AND($J9<=P$6,$K9>=P$6),$M9,"") | Q9: =IF(AND($J9<=Q$6,$K9>=Q$6),$M9,"") | R9: =IF(AND($J9<=R$6,$K9>=R$6),$M9,"") | S9: =IF(AND($J9<=S$6,$K9>=S$6),$M9,"") -> 0.88 | T9: =IF(AND($J9<=T$6,$K9>=T$6),$M9,"") -> 0.88 | U9: =IF(AND($J9<=U$6,$K9>=U$6),$M9,"") -> 0.88 | V9: =IF(AND($J9<=V$6,$K9>=V$6),$M9,"") -> 0.88 | W9: =IF(AND($J9<=W$6,$K9>=W$6),$M9,"") -> 0.88 | ... CF9: =IF(AND($J9<=CF$6,$K9>=CF$6),$M9,"")
A10: 3 | B10: ĐM-29 | C10: Vận chuyển đất đào cự ly <5km (bãi thải/đắp) | D10: m3 | E10: 86450 | F10: 571.43 | G10: =IF(F10>0,ROUND(E10/F10,1),0) -> 151.3 | H10: =IF(I10>0,ROUND(E10/I10,1),0) -> 2881.7 | I10: =K10-J10+1 -> 30 | J10: 46270 | K10: 46299 | L10: 2 | M10: =IF(AND(G10>0,I10>0,L10>0),ROUNDUP(G10/(I10*L10),2),0) -> 2.53 | N10: Ô tô tự đổ Howo 18 m3 | O10: 10 | P10: =IF(AND($J10<=P$6,$K10>=P$6),$M10,"") -> 2.53 | Q10: =IF(AND($J10<=Q$6,$K10>=Q$6),$M10,"") -> 2.53 | R10: =IF(AND($J10<=R$6,$K10>=R$6),$M10,"") -> 2.53 | S10: =IF(AND($J10<=S$6,$K10>=S$6),$M10,"") -> 2.53 | T10: =IF(AND($J10<=T$6,$K10>=T$6),$M10,"") -> 2.53 | U10: =IF(AND($J10<=U$6,$K10>=U$6),$M10,"") -> 2.53 | V10: =IF(AND($J10<=V$6,$K10>=V$6),$M10,"") -> 2.53 | W10: =IF(AND($J10<=W$6,$K10>=W$6),$M10,"") -> 2.53 | ... CF10: =IF(AND($J10<=CF$6,$K10>=CF$6),$M10,"")
A11: 4 | B11: ĐM-BOM | C11: Bơm hạ mực nước ngầm & chống ngập móng | D11: ca | E11: 138 | F11: 1 | G11: =E11 -> 138 | H11: =IF(I11>0,ROUND(E11/I11,1),0) -> 2 | I11: =K11-J11+1 -> 69 | J11: 46270 | K11: 46338 | L11: 2 | M11: =IF(AND(G11>0,I11>0,L11>0),ROUNDUP(G11/(I11*L11),2),0) -> 1 | N11: Máy bơm nước d80-d100 | O11: 4 | P11: =IF(AND($J11<=P$6,$K11>=P$6),$M11,"") -> 1 | Q11: =IF(AND($J11<=Q$6,$K11>=Q$6),$M11,"") -> 1 | R11: =IF(AND($J11<=R$6,$K11>=R$6),$M11,"") -> 1 | S11: =IF(AND($J11<=S$6,$K11>=S$6),$M11,"") -> 1 | T11: =IF(AND($J11<=T$6,$K11>=T$6),$M11,"") -> 1 | U11: =IF(AND($J11<=U$6,$K11>=U$6),$M11,"") -> 1 | V11: =IF(AND($J11<=V$6,$K11>=V$6),$M11,"") -> 1 | W11: =IF(AND($J11<=W$6,$K11>=W$6),$M11,"") -> 1 | ... CF11: =IF(AND($J11<=CF$6,$K11>=CF$6),$M11,"") -> 1
A12: 5 | B12: ĐM-53 | C12: Đệm cát / đá dăm 4x6 lót móng cống | D12: m3 | E12: 1250 | F12: 150 | G12: =IF(F12>0,ROUND(E12/F12,1),0) -> 8.3 | H12: =IF(I12>0,ROUND(E12/I12,1),0) -> 43.1 | I12: =K12-J12+1 -> 29 | J12: 46275 | K12: 46303 | L12: 2 | M12: =IF(AND(G12>0,I12>0,L12>0),ROUNDUP(G12/(I12*L12),2),0) -> 0.15 | N12: Đầm cóc + đầm bàn | O12: 12 | P12: =IF(AND($J12<=P$6,$K12>=P$6),$M12,"") | Q12: =IF(AND($J12<=Q$6,$K12>=Q$6),$M12,"") | R12: =IF(AND($J12<=R$6,$K12>=R$6),$M12,"") | S12: =IF(AND($J12<=S$6,$K12>=S$6),$M12,"") | T12: =IF(AND($J12<=T$6,$K12>=T$6),$M12,"") | U12: =IF(AND($J12<=U$6,$K12>=U$6),$M12,"") -> 0.15 | V12: =IF(AND($J12<=V$6,$K12>=V$6),$M12,"") -> 0.15 | W12: =IF(AND($J12<=W$6,$K12>=W$6),$M12,"") -> 0.15 | ... CF12: =IF(AND($J12<=CF$6,$K12>=CF$6),$M12,"")
A13: 6 | B13: ĐM-37 | C13: Bê tông lót móng M100# dày 50mm | D13: m3 | E13: 592.4 | F13: 45 | G13: =IF(F13>0,ROUND(E13/F13,1),0) -> 13.2 | H13: =IF(I13>0,ROUND(E13/I13,1),0) -> 19.1 | I13: =K13-J13+1 -> 31 | J13: 46277 | K13: 46307 | L13: 2 | M13: =IF(AND(G13>0,I13>0,L13>0),ROUNDUP(G13/(I13*L13),2),0) -> 0.22 | N13: Xe bồn + đầm bàn | O13: 16 | P13: =IF(AND($J13<=P$6,$K13>=P$6),$M13,"") | Q13: =IF(AND($J13<=Q$6,$K13>=Q$6),$M13,"") | R13: =IF(AND($J13<=R$6,$K13>=R$6),$M13,"") | S13: =IF(AND($J13<=S$6,$K13>=S$6),$M13,"") | T13: =IF(AND($J13<=T$6,$K13>=T$6),$M13,"") | U13: =IF(AND($J13<=U$6,$K13>=U$6),$M13,"") | V13: =IF(AND($J13<=V$6,$K13>=V$6),$M13,"") | W13: =IF(AND($J13<=W$6,$K13>=W$6),$M13,"") -> 0.22 | ... CF13: =IF(AND($J13<=CF$6,$K13>=CF$6),$M13,"")
A14: 7 | B14: ĐM-CT | C14: Gia công & lắp dựng cốt thép cống hộp B20 | D14: tấn | E14: 753.36 | F14: 12 | G14: =IF(F14>0,ROUND(E14/F14,1),0) -> 62.8 | H14: =IF(I14>0,ROUND(E14/I14,1),0) -> 18.4 | I14: =K14-J14+1 -> 41 | J14: 46281 | K14: 46321 | L14: 2 | M14: =IF(AND(G14>0,I14>0,L14>0),ROUNDUP(G14/(I14*L14),2),0) -> 0.77 | N14: Cần cẩu 25T & Máy uốn cắt | O14: 60 | P14: =IF(AND($J14<=P$6,$K14>=P$6),$M14,"") | Q14: =IF(AND($J14<=Q$6,$K14>=Q$6),$M14,"") | R14: =IF(AND($J14<=R$6,$K14>=R$6),$M14,"") | S14: =IF(AND($J14<=S$6,$K14>=S$6),$M14,"") | T14: =IF(AND($J14<=T$6,$K14>=T$6),$M14,"") | U14: =IF(AND($J14<=U$6,$K14>=U$6),$M14,"") | V14: =IF(AND($J14<=V$6,$K14>=V$6),$M14,"") | W14: =IF(AND($J14<=W$6,$K14>=W$6),$M14,"") | ... CF14: =IF(AND($J14<=CF$6,$K14>=CF$6),$M14,"")
A15: 8 | B15: ĐM-VK | C15: Lắp dựng ván khuôn thép/phủ phim thân cống | D15: m2 | E15: 44940.7 | F15: 450 | G15: =IF(F15>0,ROUND(E15/F15,1),0) -> 99.9 | H15: =IF(I15>0,ROUND(E15/I15,1),0) -> 1096.1 | I15: =K15-J15+1 -> 41 | J15: 46283 | K15: 46323 | L15: 2 | M15: =IF(AND(G15>0,I15>0,L15>0),ROUNDUP(G15/(I15*L15),2),0) -> 1.22 | N15: Cần cẩu 15T & Dàn giáo | O15: 70 | P15: =IF(AND($J15<=P$6,$K15>=P$6),$M15,"") | Q15: =IF(AND($J15<=Q$6,$K15>=Q$6),$M15,"") | R15: =IF(AND($J15<=R$6,$K15>=R$6),$M15,"") | S15: =IF(AND($J15<=S$6,$K15>=S$6),$M15,"") | T15: =IF(AND($J15<=T$6,$K15>=T$6),$M15,"") | U15: =IF(AND($J15<=U$6,$K15>=U$6),$M15,"") | V15: =IF(AND($J15<=V$6,$K15>=V$6),$M15,"") | W15: =IF(AND($J15<=W$6,$K15>=W$6),$M15,"") | ... CF15: =IF(AND($J15<=CF$6,$K15>=CF$6),$M15,"")
A16: 9 | B16: ĐM-BT | C16: Đổ bê tông thân cống B20 (đáy, vách, nắp) | D16: m3 | E16: 11870 | F16: 150 | G16: =IF(F16>0,ROUND(E16/F16,1),0) -> 79.1 | H16: =IF(I16>0,ROUND(E16/I16,1),0) -> 282.6 | I16: =K16-J16+1 -> 42 | J16: 46285 | K16: 46326 | L16: 2 | M16: =IF(AND(G16>0,I16>0,L16>0),ROUNDUP(G16/(I16*L16),2),0) -> 0.95 | N16: Máy bơm cần 37-43m + đầm | O16: 40 | P16: =IF(AND($J16<=P$6,$K16>=P$6),$M16,"") | Q16: =IF(AND($J16<=Q$6,$K16>=Q$6),$M16,"") | R16: =IF(AND($J16<=R$6,$K16>=R$6),$M16,"") | S16: =IF(AND($J16<=S$6,$K16>=S$6),$M16,"") | T16: =IF(AND($J16<=T$6,$K16>=T$6),$M16,"") | U16: =IF(AND($J16<=U$6,$K16>=U$6),$M16,"") | V16: =IF(AND($J16<=V$6,$K16>=V$6),$M16,"") | W16: =IF(AND($J16<=W$6,$K16>=W$6),$M16,"") | ... CF16: =IF(AND($J16<=CF$6,$K16>=CF$6),$M16,"")
A17: 10 | B17: ĐM-VCBT | C17: Vận chuyển bê tông thương phẩm B20 trạm trộn | D17: m3 | E17: 11870 | F17: 45 | G17: =IF(F17>0,ROUND(E17/F17,1),0) -> 263.8 | H17: =IF(I17>0,ROUND(E17/I17,1),0) -> 282.6 | I17: =K17-J17+1 -> 42 | J17: 46285 | K17: 46326 | L17: 2 | M17: =IF(AND(G17>0,I17>0,L17>0),ROUNDUP(G17/(I17*L17),2),0) -> 3.15 | N17: Xe bồn 8-10m3 (6 xe) | O17: 12 | P17: =IF(AND($J17<=P$6,$K17>=P$6),$M17,"") | Q17: =IF(AND($J17<=Q$6,$K17>=Q$6),$M17,"") | R17: =IF(AND($J17<=R$6,$K17>=R$6),$M17,"") | S17: =IF(AND($J17<=S$6,$K17>=S$6),$M17,"") | T17: =IF(AND($J17<=T$6,$K17>=T$6),$M17,"") | U17: =IF(AND($J17<=U$6,$K17>=U$6),$M17,"") | V17: =IF(AND($J17<=V$6,$K17>=V$6),$M17,"") | W17: =IF(AND($J17<=W$6,$K17>=W$6),$M17,"") | ... CF17: =IF(AND($J17<=CF$6,$K17>=CF$6),$M17,"")
A18: 11 | B18: ĐM-46 | C18: Bê tông & cốt thép 63 hố ga BTCT | D18: m3 | E18: 409.5 | F18: 25 | G18: =IF(F18>0,ROUND(E18/F18,1),0) -> 16.4 | H18: =IF(I18>0,ROUND(E18/I18,1),0) -> 13.2 | I18: =K18-J18+1 -> 31 | J18: 46290 | K18: 46320 | L18: 2 | M18: =IF(AND(G18>0,I18>0,L18>0),ROUNDUP(G18/(I18*L18),2),0) -> 0.27 | N18: Xe bồn + đầm bàn | O18: 22 | P18: =IF(AND($J18<=P$6,$K18>=P$6),$M18,"") | Q18: =IF(AND($J18<=Q$6,$K18>=Q$6),$M18,"") | R18: =IF(AND($J18<=R$6,$K18>=R$6),$M18,"") | S18: =IF(AND($J18<=S$6,$K18>=S$6),$M18,"") | T18: =IF(AND($J18<=T$6,$K18>=T$6),$M18,"") | U18: =IF(AND($J18<=U$6,$K18>=U$6),$M18,"") | V18: =IF(AND($J18<=V$6,$K18>=V$6),$M18,"") | W18: =IF(AND($J18<=W$6,$K18>=W$6),$M18,"") | ... CF18: =IF(AND($J18<=CF$6,$K18>=CF$6),$M18,"")
A19: 12 | B19: ĐM-25 | C19: Máy xúc lốp PC140 cẩu lắp & đầm cóc mang cống | D19: md | E19: 2170 | F19: 100 | G19: =IF(F19>0,ROUND(E19/F19,1),0) -> 21.7 | H19: =IF(I19>0,ROUND(E19/I19,1),0) -> 51.7 | I19: =K19-J19+1 -> 42 | J19: 46285 | K19: 46326 | L19: 2 | M19: =IF(AND(G19>0,I19>0,L19>0),ROUNDUP(G19/(I19*L19),2),0) -> 0.26 | N19: Máy xúc lốp PC140 | O19: 8 | P19: =IF(AND($J19<=P$6,$K19>=P$6),$M19,"") | Q19: =IF(AND($J19<=Q$6,$K19>=Q$6),$M19,"") | R19: =IF(AND($J19<=R$6,$K19>=R$6),$M19,"") | S19: =IF(AND($J19<=S$6,$K19>=S$6),$M19,"") | T19: =IF(AND($J19<=T$6,$K19>=T$6),$M19,"") | U19: =IF(AND($J19<=U$6,$K19>=U$6),$M19,"") | V19: =IF(AND($J19<=V$6,$K19>=V$6),$M19,"") | W19: =IF(AND($J19<=W$6,$K19>=W$6),$M19,"") | ... CF19: =IF(AND($J19<=CF$6,$K19>=CF$6),$M19,"")
A20: 13 | B20: ĐM-17 | C20: Đắp cát/đất K95 hoàn trả mang cống | D20: m3 | E20: 54200 | F20: 255 | G20: =IF(F20>0,ROUND(E20/F20,1),0) -> 212.5 | H20: =IF(I20>0,ROUND(E20/I20,1),0) -> 2463.6 | I20: =K20-J20+1 -> 22 | J20: 46315 | K20: 46336 | L20: 2 | M20: =IF(AND(G20>0,I20>0,L20>0),ROUNDUP(G20/(I20*L20),2),0) -> 4.83 | N20: Đầm cóc + xúc lật mang cống | O20: 28 | P20: =IF(AND($J20<=P$6,$K20>=P$6),$M20,"") | Q20: =IF(AND($J20<=Q$6,$K20>=Q$6),$M20,"") | R20: =IF(AND($J20<=R$6,$K20>=R$6),$M20,"") | S20: =IF(AND($J20<=S$6,$K20>=S$6),$M20,"") | T20: =IF(AND($J20<=T$6,$K20>=T$6),$M20,"") | U20: =IF(AND($J20<=U$6,$K20>=U$6),$M20,"") | V20: =IF(AND($J20<=V$6,$K20>=V$6),$M20,"") | W20: =IF(AND($J20<=W$6,$K20>=W$6),$M20,"") | ... CF20: =IF(AND($J20<=CF$6,$K20>=CF$6),$M20,"")
A21: 14 | B21: ĐM-ỦI | C21: Máy ủi D3-D5 san gạt hoàn trả đỉnh móng | D21: m3 | E21: 54200 | F21: 1425 | G21: =IF(F21>0,ROUND(E21/F21,1),0) -> 38 | H21: =IF(I21>0,ROUND(E21/I21,1),0) -> 2463.6 | I21: =K21-J21+1 -> 22 | J21: 46315 | K21: 46336 | L21: 2 | M21: =IF(AND(G21>0,I21>0,L21>0),ROUNDUP(G21/(I21*L21),2),0) -> 0.87 | N21: Máy ủi bánh xích D3-D5 | O21: 4 | P21: =IF(AND($J21<=P$6,$K21>=P$6),$M21,"") | Q21: =IF(AND($J21<=Q$6,$K21>=Q$6),$M21,"") | R21: =IF(AND($J21<=R$6,$K21>=R$6),$M21,"") | S21: =IF(AND($J21<=S$6,$K21>=S$6),$M21,"") | T21: =IF(AND($J21<=T$6,$K21>=T$6),$M21,"") | U21: =IF(AND($J21<=U$6,$K21>=U$6),$M21,"") | V21: =IF(AND($J21<=V$6,$K21>=V$6),$M21,"") | W21: =IF(AND($J21<=W$6,$K21>=W$6),$M21,"") | ... CF21: =IF(AND($J21<=CF$6,$K21>=CF$6),$M21,"")
A22: 15 | B22: ĐM-LU | C22: Máy lu rung 12-16T đầm nén K95 hoàn trả | D22: m3 | E22: 54200 | F22: 255 | G22: =IF(F22>0,ROUND(E22/F22,1),0) -> 212.5 | H22: =IF(I22>0,ROUND(E22/I22,1),0) -> 2463.6 | I22: =K22-J22+1 -> 22 | J22: 46316 | K22: 46337 | L22: 2 | M22: =IF(AND(G22>0,I22>0,L22>0),ROUNDUP(G22/(I22*L22),2),0) -> 4.83 | N22: Máy lu rung 12T - 16T | O22: 12 | P22: =IF(AND($J22<=P$6,$K22>=P$6),$M22,"") | Q22: =IF(AND($J22<=Q$6,$K22>=Q$6),$M22,"") | R22: =IF(AND($J22<=R$6,$K22>=R$6),$M22,"") | S22: =IF(AND($J22<=S$6,$K22>=S$6),$M22,"") | T22: =IF(AND($J22<=T$6,$K22>=T$6),$M22,"") | U22: =IF(AND($J22<=U$6,$K22>=U$6),$M22,"") | V22: =IF(AND($J22<=V$6,$K22>=V$6),$M22,"") | W22: =IF(AND($J22<=W$6,$K22>=W$6),$M22,"") | ... CF22: =IF(AND($J22<=CF$6,$K22>=CF$6),$M22,"")
A23: 16 | B23: ĐM-DAU | C23: Xe téc cấp dầu lưu động 9m3 phục vụ máy móc | D23: ca | E23: 138 | F23: 1 | G23: =E23 -> 138 | H23: =IF(I23>0,ROUND(E23/I23,1),0) -> 2 | I23: =K23-J23+1 -> 69 | J23: 46270 | K23: 46338 | L23: 2 | M23: =IF(AND(G23>0,I23>0,L23>0),ROUNDUP(G23/(I23*L23),2),0) -> 1 | N23: Xe téc cấp dầu 9 m3 | O23: 2 | P23: =IF(AND($J23<=P$6,$K23>=P$6),$M23,"") -> 1 | Q23: =IF(AND($J23<=Q$6,$K23>=Q$6),$M23,"") -> 1 | R23: =IF(AND($J23<=R$6,$K23>=R$6),$M23,"") -> 1 | S23: =IF(AND($J23<=S$6,$K23>=S$6),$M23,"") -> 1 | T23: =IF(AND($J23<=T$6,$K23>=T$6),$M23,"") -> 1 | U23: =IF(AND($J23<=U$6,$K23>=U$6),$M23,"") -> 1 | V23: =IF(AND($J23<=V$6,$K23>=V$6),$M23,"") -> 1 | W23: =IF(AND($J23<=W$6,$K23>=W$6),$M23,"") -> 1 | ... CF23: =IF(AND($J23<=CF$6,$K23>=CF$6),$M23,"") -> 1
A24: 17 | B24: ĐM-ĐIỆN | C24: Máy phát điện 3 pha công nghiệp 25-45kVA | D24: ca | E24: 138 | F24: 1 | G24: =E24 -> 138 | H24: =IF(I24>0,ROUND(E24/I24,1),0) -> 2 | I24: =K24-J24+1 -> 69 | J24: 46270 | K24: 46338 | L24: 2 | M24: =IF(AND(G24>0,I24>0,L24>0),ROUNDUP(G24/(I24*L24),2),0) -> 1 | N24: Máy phát điện 25-45kVA | O24: 2 | P24: =IF(AND($J24<=P$6,$K24>=P$6),$M24,"") -> 1 | Q24: =IF(AND($J24<=Q$6,$K24>=Q$6),$M24,"") -> 1 | R24: =IF(AND($J24<=R$6,$K24>=R$6),$M24,"") -> 1 | S24: =IF(AND($J24<=S$6,$K24>=S$6),$M24,"") -> 1 | T24: =IF(AND($J24<=T$6,$K24>=T$6),$M24,"") -> 1 | U24: =IF(AND($J24<=U$6,$K24>=U$6),$M24,"") -> 1 | V24: =IF(AND($J24<=V$6,$K24>=V$6),$M24,"") -> 1 | W24: =IF(AND($J24<=W$6,$K24>=W$6),$M24,"") -> 1 | ... CF24: =IF(AND($J24<=CF$6,$K24>=CF$6),$M24,"") -> 1
C26: TỔNG NHÂN CÔNG TRÊN CÔNG TRƯỜNG TUYẾN A5 (Người/ngày) | P26: =SUMPRODUCT(($J$8:$J$24<=P$6)*($K$8:$K$24>=P$6)*$O$8:$O$24) -> 42 | Q26: =SUMPRODUCT(($J$8:$J$24<=Q$6)*($K$8:$K$24>=Q$6)*$O$8:$O$24) -> 42 | R26: =SUMPRODUCT(($J$8:$J$24<=R$6)*($K$8:$K$24>=R$6)*$O$8:$O$24) -> 42 | S26: =SUMPRODUCT(($J$8:$J$24<=S$6)*($K$8:$K$24>=S$6)*$O$8:$O$24) -> 54 | T26: =SUMPRODUCT(($J$8:$J$24<=T$6)*($K$8:$K$24>=T$6)*$O$8:$O$24) -> 54 | U26: =SUMPRODUCT(($J$8:$J$24<=U$6)*($K$8:$K$24>=U$6)*$O$8:$O$24) -> 66 | V26: =SUMPRODUCT(($J$8:$J$24<=V$6)*($K$8:$K$24>=V$6)*$O$8:$O$24) -> 66 | W26: =SUMPRODUCT(($J$8:$J$24<=W$6)*($K$8:$K$24>=W$6)*$O$8:$O$24) -> 82 | ... CF26: =SUMPRODUCT(($J$8:$J$24<=CF$6)*($K$8:$K$24>=CF$6)*$O$8:$O$24) -> 8
C28: BẢNG TỔNG HỢP CA MÁY & SỐ PHƯƠNG TIỆN HUY ĐỘNG THEO NGÀY (CÔNG TRƯỜNG A5)
A29: Mã | C29: Chủng loại phương tiện / Thiết bị | D29: ĐVT | E29: ĐM dầu (l/ca) | F29: Max máy | G29: Nhiệm vụ thi công trên tuyến A5 | P29: =P6 -> 46270 | Q29: =Q6 -> 46271 | R29: =R6 -> 46272 | S29: =S6 -> 46273 | T29: =T6 -> 46274 | U29: =U6 -> 46275 | V29: =V6 -> 46276 | W29: =W6 -> 46277 | ... CF29: =CF6 -> 46338
A30: M1 | C30: Máy xúc bánh xích PC200 - PC300 | D30: cái | E30: 89.6 | F30: 8 | G30: Đào móng, đào ga, xúc mang cống | P30: =IF(AND($J$8<=P$6,$K$8>=P$6),8,IF(AND($J$20<=P$6,$K$20>=P$6),4,0)) -> 8 | Q30: =IF(AND($J$8<=Q$6,$K$8>=Q$6),8,IF(AND($J$20<=Q$6,$K$20>=Q$6),4,0)) -> 8 | R30: =IF(AND($J$8<=R$6,$K$8>=R$6),8,IF(AND($J$20<=R$6,$K$20>=R$6),4,0)) -> 8 | S30: =IF(AND($J$8<=S$6,$K$8>=S$6),8,IF(AND($J$20<=S$6,$K$20>=S$6),4,0)) -> 8 | T30: =IF(AND($J$8<=T$6,$K$8>=T$6),8,IF(AND($J$20<=T$6,$K$20>=T$6),4,0)) -> 8 | U30: =IF(AND($J$8<=U$6,$K$8>=U$6),8,IF(AND($J$20<=U$6,$K$20>=U$6),4,0)) -> 8 | V30: =IF(AND($J$8<=V$6,$K$8>=V$6),8,IF(AND($J$20<=V$6,$K$20>=V$6),4,0)) -> 8 | W30: =IF(AND($J$8<=W$6,$K$8>=W$6),8,IF(AND($J$20<=W$6,$K$20>=W$6),4,0)) -> 8 | ... CF30: =IF(AND($J$8<=CF$6,$K$8>=CF$6),8,IF(AND($J$20<=CF$6,$K$20>=CF$6),4,0)) -> 0
A31: M7 | C31: Ô tô tự đổ 18 m3 | D31: xe | E31: 26 | F31: 5 | G31: Vận chuyển đất đào cự ly <5km | P31: =IF(AND($J$10<=P$6,$K$10>=P$6),5,IF(AND($J$20<=P$6,$K$20>=P$6),4,0)) -> 5 | Q31: =IF(AND($J$10<=Q$6,$K$10>=Q$6),5,IF(AND($J$20<=Q$6,$K$20>=Q$6),4,0)) -> 5 | R31: =IF(AND($J$10<=R$6,$K$10>=R$6),5,IF(AND($J$20<=R$6,$K$20>=R$6),4,0)) -> 5 | S31: =IF(AND($J$10<=S$6,$K$10>=S$6),5,IF(AND($J$20<=S$6,$K$20>=S$6),4,0)) -> 5 | T31: =IF(AND($J$10<=T$6,$K$10>=T$6),5,IF(AND($J$20<=T$6,$K$20>=T$6),4,0)) -> 5 | U31: =IF(AND($J$10<=U$6,$K$10>=U$6),5,IF(AND($J$20<=U$6,$K$20>=U$6),4,0)) -> 5 | V31: =IF(AND($J$10<=V$6,$K$10>=V$6),5,IF(AND($J$20<=V$6,$K$20>=V$6),4,0)) -> 5 | W31: =IF(AND($J$10<=W$6,$K$10>=W$6),5,IF(AND($J$20<=W$6,$K$20>=W$6),4,0)) -> 5 | ... CF31: =IF(AND($J$10<=CF$6,$K$10>=CF$6),5,IF(AND($J$20<=CF$6,$K$20>=CF$6),4,0)) -> 0
A32: M5 | C32: Máy lu rung 12T - 16T | D32: cái | E32: 44 | F32: 6 | G32: Đầm nén K95 mang cống và đỉnh cống | P32: =IF(AND($J$22<=P$6,$K$22>=P$6),6,0) -> 0 | Q32: =IF(AND($J$22<=Q$6,$K$22>=Q$6),6,0) -> 0 | R32: =IF(AND($J$22<=R$6,$K$22>=R$6),6,0) -> 0 | S32: =IF(AND($J$22<=S$6,$K$22>=S$6),6,0) -> 0 | T32: =IF(AND($J$22<=T$6,$K$22>=T$6),6,0) -> 0 | U32: =IF(AND($J$22<=U$6,$K$22>=U$6),6,0) -> 0 | V32: =IF(AND($J$22<=V$6,$K$22>=V$6),6,0) -> 0 | W32: =IF(AND($J$22<=W$6,$K$22>=W$6),6,0) -> 0 | ... CF32: =IF(AND($J$22<=CF$6,$K$22>=CF$6),6,0) -> 0
A33: M3 | C33: Máy ủi bánh xích D3 - D5 | D33: cái | E33: 124 | F33: 2 | G33: San gạt hoàn trả hố móng cống | P33: =IF(AND($J$21<=P$6,$K$21>=P$6),2,0) -> 0 | Q33: =IF(AND($J$21<=Q$6,$K$21>=Q$6),2,0) -> 0 | R33: =IF(AND($J$21<=R$6,$K$21>=R$6),2,0) -> 0 | S33: =IF(AND($J$21<=S$6,$K$21>=S$6),2,0) -> 0 | T33: =IF(AND($J$21<=T$6,$K$21>=T$6),2,0) -> 0 | U33: =IF(AND($J$21<=U$6,$K$21>=U$6),2,0) -> 0 | V33: =IF(AND($J$21<=V$6,$K$21>=V$6),2,0) -> 0 | W33: =IF(AND($J$21<=W$6,$K$21>=W$6),2,0) -> 0 | ... CF33: =IF(AND($J$21<=CF$6,$K$21>=CF$6),2,0) -> 0
A34: MC | C34: Cần cẩu 25T & Cẩu tự hành 15T | D34: cái | E34: 28 | F34: 3 | G34: Hạ ván khuôn, cẩu lắp cốt thép | P34: =IF(OR(AND($J$14<=P$6,$K$14>=P$6),AND($J$15<=P$6,$K$15>=P$6)),3,0) -> 0 | Q34: =IF(OR(AND($J$14<=Q$6,$K$14>=Q$6),AND($J$15<=Q$6,$K$15>=Q$6)),3,0) -> 0 | R34: =IF(OR(AND($J$14<=R$6,$K$14>=R$6),AND($J$15<=R$6,$K$15>=R$6)),3,0) -> 0 | S34: =IF(OR(AND($J$14<=S$6,$K$14>=S$6),AND($J$15<=S$6,$K$15>=S$6)),3,0) -> 0 | T34: =IF(OR(AND($J$14<=T$6,$K$14>=T$6),AND($J$15<=T$6,$K$15>=T$6)),3,0) -> 0 | U34: =IF(OR(AND($J$14<=U$6,$K$14>=U$6),AND($J$15<=U$6,$K$15>=U$6)),3,0) -> 0 | V34: =IF(OR(AND($J$14<=V$6,$K$14>=V$6),AND($J$15<=V$6,$K$15>=V$6)),3,0) -> 0 | W34: =IF(OR(AND($J$14<=W$6,$K$14>=W$6),AND($J$15<=W$6,$K$15>=W$6)),3,0) -> 0 | ... CF34: =IF(OR(AND($J$14<=CF$6,$K$14>=CF$6),AND($J$15<=CF$6,$K$15>=CF$6)),3,0) -> 0
A35: MB | C35: Máy bơm bê tông cần 37 - 43m | D35: cái | E35: 65 | F35: 2 | G35: Đổ bê tông thân cống B20 & hố ga | P35: =IF(AND($J$16<=P$6,$K$16>=P$6),2,0) -> 0 | Q35: =IF(AND($J$16<=Q$6,$K$16>=Q$6),2,0) -> 0 | R35: =IF(AND($J$16<=R$6,$K$16>=R$6),2,0) -> 0 | S35: =IF(AND($J$16<=S$6,$K$16>=S$6),2,0) -> 0 | T35: =IF(AND($J$16<=T$6,$K$16>=T$6),2,0) -> 0 | U35: =IF(AND($J$16<=U$6,$K$16>=U$6),2,0) -> 0 | V35: =IF(AND($J$16<=V$6,$K$16>=V$6),2,0) -> 0 | W35: =IF(AND($J$16<=W$6,$K$16>=W$6),2,0) -> 0 | ... CF35: =IF(AND($J$16<=CF$6,$K$16>=CF$6),2,0) -> 0
A36: XB | C36: Xe bồn vận chuyển bê tông 8-10m3 | D36: xe | E36: 42 | F36: 6 | G36: Chở bê tông từ trạm trộn về công trường | P36: =IF(AND($J$17<=P$6,$K$17>=P$6),6,0) -> 0 | Q36: =IF(AND($J$17<=Q$6,$K$17>=Q$6),6,0) -> 0 | R36: =IF(AND($J$17<=R$6,$K$17>=R$6),6,0) -> 0 | S36: =IF(AND($J$17<=S$6,$K$17>=S$6),6,0) -> 0 | T36: =IF(AND($J$17<=T$6,$K$17>=T$6),6,0) -> 0 | U36: =IF(AND($J$17<=U$6,$K$17>=U$6),6,0) -> 0 | V36: =IF(AND($J$17<=V$6,$K$17>=V$6),6,0) -> 0 | W36: =IF(AND($J$17<=W$6,$K$17>=W$6),6,0) -> 0 | ... CF36: =IF(AND($J$17<=CF$6,$K$17>=CF$6),6,0) -> 0
A37: M8 | C37: Máy xúc bánh lốp PC140 | D37: cái | E37: 64 | F37: 1 | G37: Cẩu lắp, đầm cóc mang cống | P37: =IF(AND($J$19<=P$6,$K$19>=P$6),1,0) -> 0 | Q37: =IF(AND($J$19<=Q$6,$K$19>=Q$6),1,0) -> 0 | R37: =IF(AND($J$19<=R$6,$K$19>=R$6),1,0) -> 0 | S37: =IF(AND($J$19<=S$6,$K$19>=S$6),1,0) -> 0 | T37: =IF(AND($J$19<=T$6,$K$19>=T$6),1,0) -> 0 | U37: =IF(AND($J$19<=U$6,$K$19>=U$6),1,0) -> 0 | V37: =IF(AND($J$19<=V$6,$K$19>=V$6),1,0) -> 0 | W37: =IF(AND($J$19<=W$6,$K$19>=W$6),1,0) -> 0 | ... CF37: =IF(AND($J$19<=CF$6,$K$19>=CF$6),1,0) -> 0
A38: BP | C38: Máy bơm nước hố móng d80-d100 | D38: cái | E38: 14 | F38: 2 | G38: Bơm hạ mực nước ngầm 24/7 | P38: =IF(AND($J$11<=P$6,$K$11>=P$6),2,0) -> 2 | Q38: =IF(AND($J$11<=Q$6,$K$11>=Q$6),2,0) -> 2 | R38: =IF(AND($J$11<=R$6,$K$11>=R$6),2,0) -> 2 | S38: =IF(AND($J$11<=S$6,$K$11>=S$6),2,0) -> 2 | T38: =IF(AND($J$11<=T$6,$K$11>=T$6),2,0) -> 2 | U38: =IF(AND($J$11<=U$6,$K$11>=U$6),2,0) -> 2 | V38: =IF(AND($J$11<=V$6,$K$11>=V$6),2,0) -> 2 | W38: =IF(AND($J$11<=W$6,$K$11>=W$6),2,0) -> 2 | ... CF38: =IF(AND($J$11<=CF$6,$K$11>=CF$6),2,0) -> 2
A39: MP1 | C39: Xe téc cấp dầu lưu động 9m3 | D39: xe | E39: 44 | F39: 1 | G39: Cấp dầu lưu động 2 ca/ngày | P39: =IF(AND($J$23<=P$6,$K$23>=P$6),1,0) -> 1 | Q39: =IF(AND($J$23<=Q$6,$K$23>=Q$6),1,0) -> 1 | R39: =IF(AND($J$23<=R$6,$K$23>=R$6),1,0) -> 1 | S39: =IF(AND($J$23<=S$6,$K$23>=S$6),1,0) -> 1 | T39: =IF(AND($J$23<=T$6,$K$23>=T$6),1,0) -> 1 | U39: =IF(AND($J$23<=U$6,$K$23>=U$6),1,0) -> 1 | V39: =IF(AND($J$23<=V$6,$K$23>=V$6),1,0) -> 1 | W39: =IF(AND($J$23<=W$6,$K$23>=W$6),1,0) -> 1 | ... CF39: =IF(AND($J$23<=CF$6,$K$23>=CF$6),1,0) -> 1
A40: MP2 | C40: Máy phát điện 3 pha 25-45kVA | D40: cái | E40: 28 | F40: 2 | G40: Chiếu sáng ban đêm 2 ca | P40: =IF(AND($J$24<=P$6,$K$24>=P$6),2,0) -> 2 | Q40: =IF(AND($J$24<=Q$6,$K$24>=Q$6),2,0) -> 2 | R40: =IF(AND($J$24<=R$6,$K$24>=R$6),2,0) -> 2 | S40: =IF(AND($J$24<=S$6,$K$24>=S$6),2,0) -> 2 | T40: =IF(AND($J$24<=T$6,$K$24>=T$6),2,0) -> 2 | U40: =IF(AND($J$24<=U$6,$K$24>=U$6),2,0) -> 2 | V40: =IF(AND($J$24<=V$6,$K$24>=V$6),2,0) -> 2 | W40: =IF(AND($J$24<=W$6,$K$24>=W$6),2,0) -> 2 | ... CF40: =IF(AND($J$24<=CF$6,$K$24>=CF$6),2,0) -> 2
C42: BẢNG TÍNH DẦU DIEZEL TIÊU THỤ THEO TIẾN ĐỘ THI CÔNG TUYẾN A5 (Lít/ngày)
C43: TỔNG SỐ LÍT DẦU DIEZEL TIÊU THỤ / NGÀY | P43: =SUM(P44:P54) -> 1949.6 | Q43: =SUM(Q44:Q54) -> 1949.6 | R43: =SUM(R44:R54) -> 1949.6 | S43: =SUM(S44:S54) -> 1949.6 | T43: =SUM(T44:T54) -> 1949.6 | U43: =SUM(U44:U54) -> 1949.6 | V43: =SUM(V44:V54) -> 1949.6 | W43: =SUM(W44:W54) -> 1949.6 | ... CF43: =SUM(CF44:CF54) -> 256
A44: M1 | C44: Nhiên liệu dầu Diezel cho máy M1 | D44: Lít | E44: 89.6 | P44: =P30*$E44*2 -> 1433.6 | Q44: =Q30*$E44*2 -> 1433.6 | R44: =R30*$E44*2 -> 1433.6 | S44: =S30*$E44*2 -> 1433.6 | T44: =T30*$E44*2 -> 1433.6 | U44: =U30*$E44*2 -> 1433.6 | V44: =V30*$E44*2 -> 1433.6 | W44: =W30*$E44*2 -> 1433.6 | ... CF44: =CF30*$E44*2 -> 0
...

Sheet 02_TongHop_CaXe_CaMay_MMTB
A1: BẢNG TỔNG HỢP CA XE, CA MÁY THI CÔNG TOÀN TUYẾN CỐNG HỘP A5
A3: STT | B3: Mã máy | C3: Tên phương tiện / Thiết bị thi công | D3: ĐVT | E3: Định mức dầu (lít/ca) | F3: Tổng số ca máy (ca) | G3: Số máy huy động Max | H3: Số ngày làm việc | I3: Tổng lít dầu tiêu thụ (lít) | J3: Nhiệm vụ thi công trên công trường A5
A4: 1 | B4: M1 | C4: Máy xúc bánh xích PC200 - PC300 | D4: cái | E4: 89.6 | F4: 224.3 | G4: ='01_TienDo_CaMay_Master'!G8+'01_TienDo_CaMay_Master'!G9+'01_TienDo_CaMay_Master'!G20 -> 436.8 | H4: 16 | I4: =ROUND(F4*G4,1) -> 97974.2 | J4: Đào hố móng cống, đào hố ga, xúc đắp hoàn trả K95
A5: 2 | B5: M7 | C5: Ô tô tự đổ 16 - 18 tấn | D5: xe | E5: 26 | F5: 151.3 | G5: ='01_TienDo_CaMay_Master'!G10 -> 151.3 | H5: 16 | I5: =ROUND(F5*G5,1) -> 22891.7 | J5: Vận chuyển đất đào cự ly <5km ra bãi thải/bãi đắp
A6: 3 | B6: M5 | C6: Máy lu rung bánh thép & lốp 12T - 16T | D6: cái | E6: 44 | F6: 212.5 | G6: ='01_TienDo_CaMay_Master'!G22 -> 212.5 | H6: 18 | I6: =ROUND(F6*G6,1) -> 45156.3 | J6: Đầm nén cát/đất K95 hoàn trả mang cống và đỉnh cống
A7: 4 | B7: M3 | C7: Máy ủi bánh xích D3 - D5 | D7: cái | E7: 124 | F7: 38 | G7: ='01_TienDo_CaMay_Master'!G21 -> 38 | H7: 18 | I7: =ROUND(F7*G7,1) -> 1444 | J7: San gạt đất hoàn trả hố móng cống, tạo mặt bằng
A8: 5 | B8: MC | C8: Cần cẩu 25T & Cẩu tự hành 15T | D8: cái | E8: 28 | F8: 162.7 | G8: ='01_TienDo_CaMay_Master'!G14+'01_TienDo_CaMay_Master'!G15 -> 162.7 | H8: 22 | I8: =ROUND(F8*G8,1) -> 26471.3 | J8: Cẩu lắp ván khuôn cống, hạ cốt thép, hỗ trợ đúc cống
A9: 6 | B9: MB | C9: Máy bơm bê tông cần 37 - 43m | D9: cái | E9: 65 | F9: 79.6 | G9: ='01_TienDo_CaMay_Master'!G16 -> 79.1 | H9: 22 | I9: =ROUND(F9*G9,1) -> 6296.4 | J9: Bơm bê tông thân cống B20 (đáy, vách, nắp) & hố ga
A10: 7 | B10: XB | C10: Xe bồn vận chuyển bê tông thương phẩm 8-10m3 | D10: xe | E10: 42 | F10: 263.8 | G10: ='01_TienDo_CaMay_Master'!G17 -> 263.8 | H10: 22 | I10: =ROUND(F10*G10,1) -> 69590.4 | J10: Chở bê tông từ trạm trộn thương phẩm đến công trường
A11: 8 | B11: M8 | C11: Máy xúc bánh lốp PC140 | D11: cái | E11: 64 | F11: 21.7 | G11: ='01_TienDo_CaMay_Master'!G19 -> 21.7 | H11: 22 | I11: =ROUND(F11*G11,1) -> 470.9 | J11: Trung chuyển vật tư, cẩu lắp và đầm cóc mang cống
A12: 9 | B12: BP | C12: Máy bơm nước hố móng d80-d100 | D12: cái | E12: 14 | F12: 138 | G12: ='01_TienDo_CaMay_Master'!G11 -> 138 | H12: 36 | I12: =ROUND(F12*G12,1) -> 19044 | J12: Bơm hút hạ mực nước ngầm, chống ngập hố móng 24/7
A13: 10 | B13: MP1 | C13: Xe téc cấp dầu lưu động 9m3 | D13: xe | E13: 44 | F13: 138 | G13: ='01_TienDo_CaMay_Master'!G23 -> 138 | H13: 36 | I13: =ROUND(F13*G13,1) -> 19044 | J13: Cấp phát dầu Diezel trực tiếp cho máy móc 2 ca/ngày
A14: 11 | B14: MP2 | C14: Máy phát điện 3 pha công nghiệp 25-45kVA | D14: cái | E14: 28 | F14: 138 | G14: ='01_TienDo_CaMay_Master'!G24 -> 138 | H14: 36 | I14: =ROUND(F14*G14,1) -> 19044 | J14: Cấp điện thi công ca đêm & vận hành máy đầm, máy bơm
C15: TỔNG CỘNG TOÀN CÔNG TRÌNH CỐNG HỘP A5 | F15: =SUM(F4:F14) -> 1567.9 | G15: =SUM(G4:G14) -> 1779.9 | I15: =SUM(I4:I14) -> 327427.2

Sheet 03_KeHoach_Dau_Diezel
A1: KẾ HOẠCH CẤP DẦU DIEZEL CHO MÁY MÓC THI CÔNG TUYẾN A5 (TỪ 05/09/2026 ĐẾN 12/11/2026)
A3: STT | B3: Chủng loại thiết bị | C3: Định mức (lít/ca) | D3: Tổng số ca máy | E3: Tổng nhu cầu dầu (Lít) | F3: Kỳ 1 (05/9 - 20/9) | G3: Kỳ 2 (21/9 - 10/10) | H3: Kỳ 3 (11/10 - 31/10) | I3: Kỳ 4 (01/11 - 12/11)
A4: 1 | B4: Máy xúc bánh xích PC200 - PC300 | C4: 89.6 | D4: ='02_TongHop_CaXe_CaMay_MMTB'!G4 -> 436.8 | E4: =ROUND(C4*D4,1) -> 39137.3 | F4: =E4*0.25 -> 9784.325 | G4: =E4*0.4 -> 15654.92 | H4: =E4*0.25 -> 9784.325 | I4: =E4*0.1 -> 3913.73
A5: 2 | B5: Ô tô tự đổ 16 - 18 tấn | C5: 26 | D5: ='02_TongHop_CaXe_CaMay_MMTB'!G5 -> 151.3 | E5: =ROUND(C5*D5,1) -> 3933.8 | F5: =E5*0.35 -> 1376.83 | G5: =E5*0.5 -> 1966.9 | H5: =E5*0.15 -> 590.07 | I5: =E5*0 -> 0
A6: 3 | B6: Máy lu rung 12T - 16T | C6: 44 | D6: ='02_TongHop_CaXe_CaMay_MMTB'!G6 -> 212.5 | E6: =ROUND(C6*D6,1) -> 9350 | F6: =E6*0 -> 0 | G6: =E6*0.1 -> 935 | H6: =E6*0.5 -> 4675 | I6: =E6*0.4 -> 3740
A7: 4 | B7: Máy ủi bánh xích D3 - D5 | C7: 124 | D7: ='02_TongHop_CaXe_CaMay_MMTB'!G7 -> 38 | E7: =ROUND(C7*D7,1) -> 4712 | F7: =E7*0 -> 0 | G7: =E7*0.1 -> 471.2 | H7: =E7*0.5 -> 2356 | I7: =E7*0.4 -> 1884.8
A8: 5 | B8: Cần cẩu 25T & Cẩu tự hành 15T | C8: 28 | D8: ='02_TongHop_CaXe_CaMay_MMTB'!G8 -> 162.7 | E8: =ROUND(C8*D8,1) -> 4555.6 | F8: =E8*0.1 -> 455.56 | G8: =E8*0.45 -> 2050.02 | H8: =E8*0.35 -> 1594.46 | I8: =E8*0.1 -> 455.56
A9: 6 | B9: Máy bơm bê tông cần 37 - 43m | C9: 65 | D9: ='02_TongHop_CaXe_CaMay_MMTB'!G9 -> 79.1 | E9: =ROUND(C9*D9,1) -> 5141.5 | F9: =E9*0.05 -> 257.075 | G9: =E9*0.45 -> 2313.675 | H9: =E9*0.4 -> 2056.6 | I9: =E9*0.1 -> 514.15
A10: 7 | B10: Xe bồn vận chuyển bê tông 8-10m3 | C10: 42 | D10: ='02_TongHop_CaXe_CaMay_MMTB'!G10 -> 263.8 | E10: =ROUND(C10*D10,1) -> 11079.6 | F10: =E10*0.05 -> 553.98 | G10: =E10*0.45 -> 4985.82 | H10: =E10*0.4 -> 4431.84 | I10: =E10*0.1 -> 1107.96
A11: 8 | B11: Máy xúc bánh lốp PC140 | C11: 64 | D11: ='02_TongHop_CaXe_CaMay_MMTB'!G11 -> 21.7 | E11: =ROUND(C11*D11,1) -> 1388.8 | F11: =E11*0 -> 0 | G11: =E11*0.45 -> 624.96 | H11: =E11*0.45 -> 624.96 | I11: =E11*0.1 -> 138.88
A12: 9 | B12: Máy bơm nước hố móng | C12: 14 | D12: ='02_TongHop_CaXe_CaMay_MMTB'!G12 -> 138 | E12: =ROUND(C12*D12,1) -> 1932 | F12: =E12*0.2 -> 386.4 | G12: =E12*0.3 -> 579.6 | H12: =E12*0.3 -> 579.6 | I12: =E12*0.2 -> 386.4
A13: 10 | B13: Xe téc cấp dầu lưu động 9m3 | C13: 44 | D13: ='02_TongHop_CaXe_CaMay_MMTB'!G13 -> 138 | E13: =ROUND(C13*D13,1) -> 6072 | F13: =E13*0.2 -> 1214.4 | G13: =E13*0.3 -> 1821.6 | H13: =E13*0.3 -> 1821.6 | I13: =E13*0.2 -> 1214.4
A14: 11 | B14: Máy phát điện 3 pha 25-45kVA | C14: 28 | D14: ='02_TongHop_CaXe_CaMay_MMTB'!G14 -> 138 | E14: =ROUND(C14*D14,1) -> 3864 | F14: =E14*0.2 -> 772.8 | G14: =E14*0.3 -> 1159.2 | H14: =E14*0.3 -> 1159.2 | I14: =E14*0.2 -> 772.8
B15: TỔNG SỐ LÍT DẦU DIEZEL CẦN CUNG CẤP (LÍT) | D15: =SUM(D4:D14) -> 1779.9 | E15: =SUM(E4:E14) -> 91166.6 | F15: =SUM(F4:F14) -> 14801.37 | G15: =SUM(G4:G14) -> 32562.895 | H15: =SUM(H4:H14) -> 29673.655 | I15: =SUM(I4:I14) -> 14128.68

Sheet 04_KeHoach_NhanLuc_3_Mui
A1: BẢNG PHÂN BỔ NHÂN LỰC THI CÔNG 3 MŨI CỐNG HỘP TUYẾN A5
A3: STT | B3: Tổ đội / Bộ phận thi công | C3: Mũi 1 (Cống 2x2, L=385m) | D3: Mũi 2 (Cống 3x3, L=560m) | E3: Mũi 3 (Cống đôi 2x(3x3), L=1225m) | F3: Tổ cơ giới & Phục vụ | G3: Tổng nhân lực (người) | H3: Ghi chú bố trí ca kíp
A4: 1 | B4: Thợ gia công & lắp dựng cốt thép CB300/CB400 | C4: 12 | D4: 18 | E4: 30 | F4: 0 | G4: =SUM(C4:F4) -> 60 | H4: Gia công tại bãi + buộc lồng thép hố móng
A5: 2 | B5: Thợ lắp dựng & tháo dỡ ván khuôn thép/phim | C5: 14 | D5: 20 | E5: 36 | F5: 0 | G5: =SUM(C5:F5) -> 70 | H5: Ghép ván khuôn đáy, vách, bản nắp cống
A6: 3 | B6: Công nhân đổ bê tông & đầm dùi/đầm bàn B20 | C6: 8 | D6: 12 | E6: 20 | F6: 0 | G6: =SUM(C6:F6) -> 40 | H6: Đổ bê tông theo từng đốt 11.3m
A7: 4 | B7: Thợ thi công 63 hố ga thu nước & đấu nối | C7: 4 | D7: 6 | E7: 12 | F7: 0 | G7: =SUM(C7:F7) -> 22 | H7: Đúc ga, lắp nắp ga thu nước
A8: 5 | B8: Công nhân đắp đất/cát hoàn trả mang cống K95 | C8: 6 | D8: 8 | E8: 14 | F8: 0 | G8: =SUM(C8:F8) -> 28 | H8: Đầm cóc mang cống & lu lèn
A9: 6 | B9: Lái máy xúc bánh xích PC200 - PC300 | C9: 0 | D9: 0 | E9: 0 | F9: 16 | G9: =SUM(C9:F9) -> 16 | H9: 8 máy xúc x 2 tài/máy (2 ca)
A10: 7 | B10: Lái ô tô tự đổ 18 m3 | C10: 0 | D10: 0 | E10: 0 | F10: 10 | G10: =SUM(C10:F10) -> 10 | H10: 5 xe x 2 tài/xe
A11: 8 | B11: Lái máy lu rung 12-16T | C11: 0 | D11: 0 | E11: 0 | F11: 12 | G11: =SUM(C11:F11) -> 12 | H11: 6 máy lu x 2 tài/máy
A12: 9 | B12: Lái cần cẩu 25T & Cẩu tự hành 15T | C12: 0 | D12: 0 | E12: 0 | F12: 6 | G12: =SUM(C12:F12) -> 6 | H12: 3 cẩu x 2 tài/cẩu
A13: 10 | B13: Lái máy ủi, xúc lốp, xe cấp dầu, máy phát điện | C13: 0 | D13: 0 | E13: 0 | F13: 10 | G13: =SUM(C13:F13) -> 10 | H13: Vận hành thiết bị phụ trợ 2 ca
A14: 11 | B14: Chỉ huy trưởng, kỹ sư hiện trường, KCS/QA/QC | C14: 3 | D14: 3 | E14: 5 | F14: 5 | G14: =SUM(C14:F14) -> 16 | H14: Giám sát kỹ thuật 24/7
B15: TỔNG NHÂN LỰC TOÀN CÔNG TRƯỜNG A5 (NGƯỜI) | C15: =SUM(C4:C14) -> 47 | D15: =SUM(D4:D14) -> 67 | E15: =SUM(E4:E14) -> 117 | F15: =SUM(F4:F14) -> 59 | G15: =SUM(G4:G14) -> 290

Sheet 05_DoiChieu_BocTach_A5
A1: BẢNG ĐỐI CHIẾU KHỐI LƯỢNG THỰC TẾ HỒ SƠ CỐNG HỘP TUYẾN A5
A3: STT | B3: Hạng mục cống hộp Tuyến A5 | C3: Quy cách (BxH) | D3: Chiều dài L (m) | E3: Bê tông thân B20 (m3) | F3: Bê tông lót M100 (m3) | G3: Ván khuôn tiếp xúc (m2) | H3: Cốt thép CB300/CB400 (tấn)
A4: 1 | B4: Đoạn 1 - Tuyến cống đơn 2.0x2.0m (12 ga) | C4: 2.0 x 2.0 m | D4: 385 | E4: 897.05 | F4: 51.98 | G4: 4747.05 | H4: 80.73
A5: 2 | B5: Đoạn 2 - Tuyến cống đơn 3.0x3.0m (17 ga) | C5: 3.0 x 3.0 m | D5: 560 | E5: 2287.6 | F5: 106.4 | G5: 9861.6 | H5: 154.84
A6: 3 | B6: Đoạn 3 - Tuyến cống đôi 2x(3.0x3.0m) (37 ga) | C6: 2 x (3.0 x 3.0) m | D6: 1225 | E6: 8685.25 | F6: 434.88 | G6: 30331 | H6: 517.8
B7: TỔNG CỘNG TOÀN TUYẾN A5 (100%) | D7: =SUM(D4:D6) -> 2170 | E7: =SUM(E4:E6) -> 11869.9 | F7: =SUM(F4:F6) -> 593.26 | G7: =SUM(G4:G6) -> 44939.65 | H7: =SUM(H4:H6) -> 753.37
