Workbook

Sheet PHAN_TICH_VAT_TU_WBS
B2: DỰ ÁN: CAO TỐC TUYÊN QUANG - HÀ GIANG (GIAI ĐOẠN 1) - CẦU KM19+529.080
B3: BẢNG PHÂN TÍCH ĐỊNH MỨC HAO PHÍ VẬT LIỆU CHO TỪNG HẠNG MỤC CÔNG TÁC WBS
B4: Chi tiết sắt thép từng loại đường kính Ø, xi măng, cát, đá, cáp DƯL (Theo Định mức Thông tư 12/2021/TT-BXD)
A5: TT | B5: Mã định mức | C5: Hạng mục công tác WBS | D5: Khối lượng công tác | E5: ĐVT công tác | F5: Tên quy cách vật tư cấu thành | G5: ĐVT vật tư | H5: Định mức cho 1 ĐVT | I5: Hao phí vật tư hạng mục | J5: Tiêu chuẩn kỹ thuật áp dụng
A6: 1 | B6: AC.11111 | C6: Khoan tạo lỗ cọc khoan nhồi D1200mm (26 cọc L=20m-40m) | D6: =QS_DIEN_GIAI_CHI_TIET!J7 | E6: m
C7: • Bột sét Bentonite tạo vách khoan | F7: Bột sét Bentonite tạo vách khoan | G7: Tấn | H7: 0.045 | I7: =D6*H7 | J7: TCVN 9395:2012
C8: • Nước sạch thi công khoan cọc | F8: Nước sạch thi công khoan cọc | G8: m3 | H8: 0.25 | I8: =D6*H8 | J8: TCVN 4506:2012
A9: 2 | B9: AC.12111 | C9: Hạ và nhổ ống vách thép dẫn hướng D1300mm d=8mm | D9: =QS_DIEN_GIAI_CHI_TIET!J12 | E9: m
C10: • Ống vách thép dẫn hướng D1300 d=8mm (khấu hao) | F10: Ống vách thép dẫn hướng D1300 d=8mm (khấu hao) | G10: Tấn | H10: 0.052 | I10: =D9*H10 | J10: TCVN 9395:2012
A11: 3 | B11: AF.21111 | C11: Bê tông cọc khoan nhồi C30/37 đổ bằng ống Tremie | D11: =QS_DIEN_GIAI_CHI_TIET!J17 | E11: m3
C12: • Xi măng PCB40 cọc khoan nhồi | F12: Xi măng PCB40 cọc khoan nhồi | G12: kg | H12: 395 | I12: =D11*H12 | J12: TCVN 6260:2020
C13: • Cát vàng hạt trung Mk>=2.0 | F13: Cát vàng hạt trung Mk>=2.0 | G13: m3 | H13: 0.47 | I13: =D11*H13 | J13: TCVN 7570:2006
C14: • Đá dăm 1x2 sạch chọn lọc | F14: Đá dăm 1x2 sạch chọn lọc | G14: m3 | H14: 0.83 | I14: =D11*H14 | J14: TCVN 7570:2006
C15: • Nước sạch trộn bê tông | F15: Nước sạch trộn bê tông | G15: Lít | H15: 185 | I15: =D11*H15 | J15: TCVN 4506:2012
C16: • Phụ gia hoá dẻo chậm đông kết | F16: Phụ gia hoá dẻo chậm đông kết | G16: kg | H16: 4.2 | I16: =D11*H16 | J16: ASTM C494 Type G
A17: 4 | B17: AF.61111 | C17: Cốt thép cọc khoan nhồi D1200mm (Lồng thép) | D17: =QS_DIEN_GIAI_CHI_TIET!J22 | E17: Tấn
C18: • Thép chủ cọc nhồi vằn Ø25 (CB500-V) | F18: Thép chủ cọc nhồi vằn Ø25 (CB500-V) | G18: Tấn | H18: 0.785 | I18: =D17*H18 | J18: TCVN 1651:2018
C19: • Thép đai tăng cường vằn Ø16 (CB400-V) | F19: Thép đai tăng cường vằn Ø16 (CB400-V) | G19: Tấn | H19: 0.12 | I19: =D17*H19 | J19: TCVN 1651:2018
C20: • Thép đai xoắn liên tục tròn trơn Ø10 (CB240-T) | F20: Thép đai xoắn liên tục tròn trơn Ø10 (CB240-T) | G20: Tấn | H20: 0.095 | I20: =D17*H20 | J20: TCVN 1651:2018
C21: • Ống siêu âm cọc nhồi thép Ø60x2 | F21: Ống siêu âm cọc nhồi thép Ø60x2 | G21: m | H21: 36.5 | I21: =D17*H21 | J21: ASTM A53 / TCVN 9395
C22: • Dây thép buộc 1 ly | F22: Dây thép buộc 1 ly | G22: kg | H22: 15 | I22: =D17*H22 | J22: TCVN 1651:2018
C23: • Que hàn điện E42/E50 | F23: Que hàn điện E42/E50 | G23: kg | H23: 8 | I23: =D17*H23 | J23: TCVN 3223:2000
A24: 5 | B24: AF.11111 | C24: Bê tông lót đáy bệ móng mác C10 dày 10cm | D24: =QS_DIEN_GIAI_CHI_TIET!J34 | E24: m3
C25: • Xi măng PCB40 lót móng | F25: Xi măng PCB40 lót móng | G25: kg | H25: 240 | I25: =D24*H25 | J25: TCVN 6260:2020
C26: • Cát vàng xây dựng | F26: Cát vàng xây dựng | G26: m3 | H26: 0.51 | I26: =D24*H26 | J26: TCVN 7570:2006
C27: • Đá dăm 1x2 | F27: Đá dăm 1x2 | G27: m3 | H27: 0.87 | I27: =D24*H27 | J27: TCVN 7570:2006
C28: • Nước sạch trộn bê tông | F28: Nước sạch trộn bê tông | G28: Lít | H28: 175 | I28: =D24*H28 | J28: TCVN 4506:2012
A29: 6 | B29: AF.12111 | C29: Bê tông bệ móng mố M1, M2 và bệ trụ T1, T2 mác C30 | D29: =QS_DIEN_GIAI_CHI_TIET!J39 | E29: m3
C30: • Xi măng PCB40 bệ móng | F30: Xi măng PCB40 bệ móng | G30: kg | H30: 385 | I30: =D29*H30 | J30: TCVN 6260:2020
C31: • Cát vàng sàng rửa Mk>=2.0 | F31: Cát vàng sàng rửa Mk>=2.0 | G31: m3 | H31: 0.46 | I31: =D29*H31 | J31: TCVN 7570:2006
C32: • Đá dăm 1x2 sạch | F32: Đá dăm 1x2 sạch | G32: m3 | H32: 0.84 | I32: =D29*H32 | J32: TCVN 7570:2006
C33: • Nước sạch trộn bê tông | F33: Nước sạch trộn bê tông | G33: Lít | H33: 180 | I33: =D29*H33 | J33: TCVN 4506:2012
C34: • Phụ gia siêu dẻo giảm nước | F34: Phụ gia siêu dẻo giảm nước | G34: kg | H34: 3.8 | I34: =D29*H34 | J34: ASTM C494 Type F
A35: 7 | B35: AF.12211 | C35: Bê tông thân mố chân dê M1 và mố chữ U M2 mác C30 | D35: =QS_DIEN_GIAI_CHI_TIET!J44 | E35: m3
C36: • Xi măng PCB40 thân mố | F36: Xi măng PCB40 thân mố | G36: kg | H36: 385 | I36: =D35*H36 | J36: TCVN 6260:2020
C37: • Cát vàng sàng rửa Mk>=2.0 | F37: Cát vàng sàng rửa Mk>=2.0 | G37: m3 | H37: 0.46 | I37: =D35*H37 | J37: TCVN 7570:2006
C38: • Đá dăm 1x2 sạch | F38: Đá dăm 1x2 sạch | G38: m3 | H38: 0.84 | I38: =D35*H38 | J38: TCVN 7570:2006
C39: • Nước sạch trộn bê tông | F39: Nước sạch trộn bê tông | G39: Lít | H39: 180 | I39: =D35*H39 | J39: TCVN 4506:2012
C40: • Phụ gia siêu dẻo giảm nước | F40: Phụ gia siêu dẻo giảm nước | G40: kg | H40: 3.8 | I40: =D35*H40 | J40: ASTM C494 Type F
A41: 8 | B41: AF.12311 | C41: Bê tông tường cánh và tường đỉnh mố M1, M2 mác C30 | D41: =QS_DIEN_GIAI_CHI_TIET!J47 | E41: m3
...

Sheet QS_DIEN_GIAI_CHI_TIET
B2: DỰ ÁN: CAO TỐC TUYÊN QUANG - HÀ GIANG (GIAI ĐOẠN 1) - ĐOẠN QUA TỈNH HÀ GIANG
B3: BẢNG DIỄN GIẢI TIÊN LƯỢNG KHỐI LƯỢNG HÌNH HỌC CHI TIẾT - CẦU KM19+529.080
B4: Tuân thủ nghiêm ngặt nguyên tắc 100% công thức động: Khối lượng = Dài x Rộng x Cao x Số lượng x Hệ số (CẤM SỐ CHẾT)
A5: TT | B5: Mã hiệu | C5: Nội dung công tác & Diễn giải hình học cấu kiện | D5: ĐVT | E5: Số lượng (Cấu kiện) | F5: Dài (m) | G5: Rộng (m) | H5: Cao / Dày (m) | I5: Hệ số hình học | J5: Khối lượng (Công thức) | K5: Đơn giá (VNĐ) | L5: Thành tiền (VNĐ)
A6: PHẦN I: THI CÔNG CỌC KHOAN NHỒI D1200MM & THÍ NGHIỆM KIỂM SOÁT
A7: 1 | B7: AC.11111 | C7: Khoan tạo lỗ cọc khoan nhồi D1200mm vào đất và đá gốc (26 cọc) | D7: m | J7: =SUM(J8:J11) | K7: 2850000 | L7: =J7*K7
C8: - Cọc mố M1: 3 cọc chiều sâu L=20.0m | D8: m | E8: 3 | F8: 20 | G8: 1 | H8: 1 | I8: 1 | J8: =E8*F8*G8*H8*I8
C9: - Cọc trụ T1: 8 cọc chiều sâu L=40.0m | D9: m | E9: 8 | F9: 40 | G9: 1 | H9: 1 | I9: 1 | J9: =E9*F9*G9*H9*I9
C10: - Cọc trụ T2: 8 cọc chiều sâu L=30.0m | D10: m | E10: 8 | F10: 30 | G10: 1 | H10: 1 | I10: 1 | J10: =E10*F10*G10*H10*I10
C11: - Cọc mố M2: 7 cọc chiều sâu L=36.0m | D11: m | E11: 7 | F11: 36 | G11: 1 | H11: 1 | I11: 1 | J11: =E11*F11*G11*H11*I11
A12: 2 | B12: AC.12111 | C12: Hạ và nhổ ống vách thép dẫn hướng D1300mm d=8mm (luân chuyển) | D12: m | J12: =SUM(J13:J16) | K12: 1450000 | L12: =J12*K12
C13: - Ống vách thép cọc mố M1 (3 cọc x 6m) | D13: m | E13: 3 | F13: 6 | G13: 1 | H13: 1 | I13: 1 | J13: =E13*F13*G13*H13*I13
C14: - Ống vách thép cọc trụ T1 (8 cọc x 6m) | D14: m | E14: 8 | F14: 6 | G14: 1 | H14: 1 | I14: 1 | J14: =E14*F14*G14*H14*I14
C15: - Ống vách thép cọc trụ T2 (8 cọc x 6m) | D15: m | E15: 8 | F15: 6 | G15: 1 | H15: 1 | I15: 1 | J15: =E15*F15*G15*H15*I15
C16: - Ống vách thép cọc mố M2 (7 cọc x 6m) | D16: m | E16: 7 | F16: 6 | G16: 1 | H16: 1 | I16: 1 | J16: =E16*F16*G16*H16*I16
A17: 3 | B17: AF.21111 | C17: Bê tông cọc khoan nhồi C30/37 đổ bằng phương pháp rút ống tremie | D17: m3 | J17: =SUM(J18:J21) | K17: 1650000 | L17: =J17*K17
C18: - Bê tông 3 cọc mố M1 (L=20m, D=1.2m, hs nở thành 1.12) | D18: m3 | E18: 3 | F18: 20 | G18: 0.6 | H18: 0.6 | I18: 3.5186 | J18: =E18*F18*G18*H18*I18
C19: - Bê tông 8 cọc trụ T1 (L=40m, D=1.2m, hs nở thành 1.12) | D19: m3 | E19: 8 | F19: 40 | G19: 0.6 | H19: 0.6 | I19: 3.5186 | J19: =E19*F19*G19*H19*I19
C20: - Bê tông 8 cọc trụ T2 (L=30m, D=1.2m, hs nở thành 1.12) | D20: m3 | E20: 8 | F20: 30 | G20: 0.6 | H20: 0.6 | I20: 3.5186 | J20: =E20*F20*G20*H20*I20
C21: - Bê tông 7 cọc mố M2 (L=36m, D=1.2m, hs nở thành 1.12) | D21: m3 | E21: 7 | F21: 36 | G21: 0.6 | H21: 0.6 | I21: 3.5186 | J21: =E21*F21*G21*H21*I21
A22: 4 | B22: AF.61111 | C22: Cốt thép cọc khoan nhồi D1200mm (Thép chủ D25, đai D16, D10) | D22: Tấn | J22: 108.76599 | K22: 18500000 | L22: =J22*K22
C23: - Cốt thép cọc mố M1 (3 cọc x 5.889 tấn/cọc) | D23: Tấn | E23: 3 | F23: 5.889 | G23: 1 | H23: 1 | I23: 1 | J23: =E23*F23*G23*H23*I23
C24: - Cốt thép cọc trụ T1 (8 cọc x 4.845 tấn/cọc) | D24: Tấn | E24: 8 | F24: 4.845 | G24: 1 | H24: 1 | I24: 1 | J24: =E24*F24*G24*H24*I24
C25: - Cốt thép cọc trụ T2 (8 cọc x 3.687 tấn/cọc) | D25: Tấn | E25: 8 | F25: 3.687 | G25: 1 | H25: 1 | I25: 1 | J25: =E25*F25*G25*H25*I25
C26: - Cốt thép cọc mố M2 (7 cọc x 4.721 tấn/cọc) | D26: Tấn | E26: 7 | F26: 4.721 | G26: 1 | H26: 1 | I26: 1 | J26: =E26*F26*G26*H26*I26
A27: 5 | B27: AC.13111 | C27: Đập đầu cọc khoan nhồi nhô lên đáy bệ ngàm vào kết cấu | D27: m3 | J27: =SUM(J28:J28) | K27: 550000 | L27: =J27*K27
C28: - Đập đầu 26 cọc khoan nhồi (chiều cao đập h=1.0m) | D28: m3 | E28: 26 | F28: 1 | G28: 0.6 | H28: 0.6 | I28: 3.1416 | J28: =E28*F28*G28*H28*I28
A29: 6 | B29: TN.11111 | C29: Thí nghiệm kiểm soát cọc (Siêu âm 156 mặt cắt, PDA 9434kN, lấy lõi 4 cọc) | D29: Gói | J29: =SUM(J30:J30) | K29: 450000000 | L29: =J29*K29
C30: - Gói thí nghiệm siêu âm 100% cọc, nén động PDA trụ T1 & khoan lấy lõi | D30: Gói | E30: 1 | F30: 1 | G30: 1 | H30: 1 | I30: 1 | J30: =E30*F30*G30*H30*I30
A31: PHẦN II: KẾT CẤU PHẦN DƯỚI (BỆ, THÂN, XÀ MŨ MỐ M1, M2 & TRỤ T1, T2)
A32: 7 | B32: AB.11111 | C32: Đào đất đá hố móng bệ mố M1, M2 và bệ trụ T1, T2 (Link Sheet Đào Đắp) | D32: m3 | J32: =SUM(J33:J33) | K32: 145000 | L32: =J32*K32
C33: - Đào đất đá hố móng bệ mố M1,M2 & bệ trụ T1,T2 → =KHOI_LUONG_DAO_DAP!F21 | D33: m3 | E33: 1 | F33: 1 | G33: 1 | H33: 1 | I33: 1 | J33: 6245
A34: 8 | B34: AF.11111 | C34: Bê tông lót đáy bệ móng mác C10 dày 10cm | D34: m3 | J34: =SUM(J35:J38) | K34: 1150000 | L34: =J34*K34
C35: - Lớp bê tông lót đáy bệ mố M1 chân dê | D35: m3 | E35: 1 | F35: 12.5 | G35: 6 | H35: 0.1 | I35: 1 | J35: =E35*F35*G35*H35*I35
C36: - Lớp bê tông lót đáy bệ mố M2 chữ U | D36: m3 | E36: 1 | F36: 14 | G36: 6.5 | H36: 0.1 | I36: 1 | J36: =E36*F36*G36*H36*I36
C37: - Lớp bê tông lót đáy bệ trụ T1 | D37: m3 | E37: 1 | F37: 13 | G37: 6.5 | H37: 0.1 | I37: 1 | J37: =E37*F37*G37*H37*I37
C38: - Lớp bê tông lót đáy bệ trụ T2 | D38: m3 | E38: 1 | F38: 13 | G38: 6.5 | H38: 0.1 | I38: 1 | J38: =E38*F38*G38*H38*I38
A39: 9 | B39: AF.12111 | C39: Bê tông bệ móng mố M1, M2 và bệ trụ T1, T2 mác C30 | D39: m3 | J39: =SUM(J40:J43) | K39: 1480000 | L39: =J39*K39
C40: - Bệ móng mố M1 chân dê (chiều cao bệ h=2.0m) | D40: m3 | E40: 1 | F40: 12 | G40: 5.5 | H40: 2 | I40: 1.1287 | J40: =E40*F40*G40*H40*I40
C41: - Bệ móng mố M2 chữ U (chiều cao bệ h=2.0m) | D41: m3 | E41: 1 | F41: 13.5 | G41: 5.5 | H41: 2 | I41: 1.0033 | J41: =E41*F41*G41*H41*I41
...
