Workbook

Sheet TONG_HOP_VAT_TU_TOAN_BO
B2: DỰ ÁN: CAO TỐC TUYÊN QUANG - HÀ GIANG (GIAI ĐOẠN 1) - CẦU KM19+529.080
B3: BẢNG TỔNG HỢP NHU CẦU VẬT TƯ TOÀN CÔNG TRÌNH & KẾ HOẠCH CUNG ỨNG (BOM)
B4: Tổng hợp tự động 100% công thức (=SUMIF) từ bảng phân rã WBS; Kế hoạch phân bổ theo 4 giai đoạn thi công
A5: TT | B5: Tên chủng loại vật tư | C5: Tiêu chuẩn kỹ thuật | D5: ĐVT | E5: Hao phí định mức lý thuyết | F5: Tỷ lệ hao hụt TT12 (%) | G5: Tổng nhu cầu cung ứng (BOM) | H5: GĐ 1: Cọc nhồi | I5: GĐ 2: Mố & Trụ | J5: GĐ 3: Dầm & Mặt cầu | K5: GĐ 4: Hoàn thiện
B6: I. SẮT THÉP CÁC LOẠI (CỐT THÉP, CÁP DỰ ỨNG LỰC & PHỤ KIỆN)
A7: 1 | B7: Thép đai tròn trơn Ø10 (CB240-T) | C7: TCVN 1651:2018 | D7: Tấn | E7: =SUMIF(PHAN_TICH_VAT_TU_WBS!$F$6:$F$140, "*Ø10*", PHAN_TICH_VAT_TU_WBS!$I$6:$I$140) | F7: 0.015 | G7: =E7*(1+F7) | H7: =G7*0.4 | I7: =G7*0.2 | J7: =G7*0.4 | K7: =G7*0.0
A8: 2 | B8: Thép cốt vằn Ø12 (CB400-V) | C8: TCVN 1651:2018 | D8: Tấn | E8: =SUMIF(PHAN_TICH_VAT_TU_WBS!$F$6:$F$140, "*Ø12*", PHAN_TICH_VAT_TU_WBS!$I$6:$I$140)/1000 | F8: 0.015 | G8: =E8*(1+F8) | H8: =G8*0.0 | I8: =G8*0.0 | J8: =G8*0.0 | K8: =G8*1.0
A9: 3 | B9: Thép bản cánh & mặt cầu vằn Ø14 (CB400-V) | C9: TCVN 1651:2018 | D9: Tấn | E9: =SUMIF(PHAN_TICH_VAT_TU_WBS!$F$6:$F$140, "*Ø14*", PHAN_TICH_VAT_TU_WBS!$I$6:$I$140) | F9: 0.015 | G9: =E9*(1+F9) | H9: =G9*0.0 | I9: =G9*0.0 | J9: =G9*1.0 | K9: =G9*0.0
A10: 4 | B10: Thép đai & sườn dầm vằn Ø16 (CB400-V) | C10: TCVN 1651:2018 | D10: Tấn | E10: =SUMIF(PHAN_TICH_VAT_TU_WBS!$F$6:$F$140, "*Ø16*", PHAN_TICH_VAT_TU_WBS!$I$6:$I$140) | F10: 0.015 | G10: =E10*(1+F10) | H10: =G10*0.25 | I10: =G10*0.15 | J10: =G10*0.5 | K10: =G10*0.1
A11: 5 | B11: Thép phân bố bệ móng vằn Ø20 (CB500-V) | C11: TCVN 1651:2018 | D11: Tấn | E11: =SUMIF(PHAN_TICH_VAT_TU_WBS!$F$6:$F$140, "*Ø20*", PHAN_TICH_VAT_TU_WBS!$I$6:$I$140) | F11: 0.015 | G11: =E11*(1+F11) | H11: =G11*0.0 | I11: =G11*1.0 | J11: =G11*0.0 | K11: =G11*0.0
A12: 6 | B12: Thép chủ cọc khoan nhồi vằn Ø25 (CB500-V) | C12: TCVN 1651:2018 | D12: Tấn | E12: =SUMIF(PHAN_TICH_VAT_TU_WBS!$F$6:$F$140, "*Ø25*", PHAN_TICH_VAT_TU_WBS!$I$6:$I$140) | F12: 0.015 | G12: =E12*(1+F12) | H12: =G12*1.0 | I12: =G12*0.0 | J12: =G12*0.0 | K12: =G12*0.0
A13: 7 | B13: Thép thân mố & xà mũ vằn Ø28 (CB500-V) | C13: TCVN 1651:2018 | D13: Tấn | E13: =SUMIF(PHAN_TICH_VAT_TU_WBS!$F$6:$F$140, "*Ø28*", PHAN_TICH_VAT_TU_WBS!$I$6:$I$140) | F13: 0.015 | G13: =E13*(1+F13) | H13: =G13*0.0 | I13: =G13*1.0 | J13: =G13*0.0 | K13: =G13*0.0
A14: 8 | B14: Thép bệ móng & thân trụ vằn Ø32 (CB500-V) | C14: TCVN 1651:2018 | D14: Tấn | E14: =SUMIF(PHAN_TICH_VAT_TU_WBS!$F$6:$F$140, "*Ø32*", PHAN_TICH_VAT_TU_WBS!$I$6:$I$140) | F14: 0.015 | G14: =E14*(1+F14) | H14: =G14*0.0 | I14: =G14*1.0 | J14: =G14*0.0 | K14: =G14*0.0
A15: 9 | B15: Cáp dự ứng lực tao 15.2mm Grade 270 | C15: ASTM A416 Gr270 | D15: Tấn | E15: =SUMIF(PHAN_TICH_VAT_TU_WBS!$F$6:$F$140, "*Cáp dự ứng lực*", PHAN_TICH_VAT_TU_WBS!$I$6:$I$140) | F15: 0.015 | G15: =E15*(1+F15) | H15: =G15*0.0 | I15: =G15*0.0 | J15: =G15*1.0 | K15: =G15*0.0
A16: 10 | B16: Bộ neo chùm dự ứng lực công tác | C16: TCVN 11823:2017 | D16: Bộ | E16: =SUMIF(PHAN_TICH_VAT_TU_WBS!$F$6:$F$140, "*Bộ neo chùm*", PHAN_TICH_VAT_TU_WBS!$I$6:$I$140) | F16: 0.01 | G16: =E16*(1+F16) | H16: =G16*0.0 | I16: =G16*0.0 | J16: =G16*1.0 | K16: =G16*0.0
A17: 11 | B17: Ống ghen tôn mạ kẽm luồn cáp DƯL | C17: TCVN 11823:2017 | D17: m | E17: =SUMIF(PHAN_TICH_VAT_TU_WBS!$F$6:$F$140, "*Ống ghen tôn*", PHAN_TICH_VAT_TU_WBS!$I$6:$I$140) | F17: 0.02 | G17: =E17*(1+F17) | H17: =G17*0.0 | I17: =G17*0.0 | J17: =G17*1.0 | K17: =G17*0.0
A18: 12 | B18: Ống siêu âm cọc nhồi thép Ø60x2 | C18: ASTM A53 / TCVN 9395 | D18: m | E18: =SUMIF(PHAN_TICH_VAT_TU_WBS!$F$6:$F$140, "*Ống siêu âm*", PHAN_TICH_VAT_TU_WBS!$I$6:$I$140) | F18: 0.01 | G18: =E18*(1+F18) | H18: =G18*1.0 | I18: =G18*0.0 | J18: =G18*0.0 | K18: =G18*0.0
A19: 13 | B19: Ống vách thép dẫn hướng D1300 d=8mm | C19: TCVN 9395:2012 | D19: Tấn | E19: =SUMIF(PHAN_TICH_VAT_TU_WBS!$F$6:$F$140, "*Ống vách thép*", PHAN_TICH_VAT_TU_WBS!$I$6:$I$140) | F19: 0.02 | G19: =E19*(1+F19) | H19: =G19*1.0 | I19: =G19*0.0 | J19: =G19*0.0 | K19: =G19*0.0
A20: 14 | B20: Tay vịn lan can thép mạ kẽm nhúng nóng Ø114 | C20: TCVN 11823:2017 | D20: m | E20: =SUMIF(PHAN_TICH_VAT_TU_WBS!$F$6:$F$140, "*Tay vịn*", PHAN_TICH_VAT_TU_WBS!$I$6:$I$140) | F20: 0.02 | G20: =E20*(1+F20) | H20: =G20*0.0 | I20: =G20*0.0 | J20: =G20*0.0 | K20: =G20*1.0
A21: 15 | B21: Thép tấm khe co giãn răng lược D=100mm | C21: TCVN 11823:2017 | D21: m | E21: =SUMIF(PHAN_TICH_VAT_TU_WBS!$F$6:$F$140, "*Thép tấm răng lược*", PHAN_TICH_VAT_TU_WBS!$I$6:$I$140) | F21: 0.01 | G21: =E21*(1+F21) | H21: =G21*0.0 | I21: =G21*0.0 | J21: =G21*0.0 | K21: =G21*1.0
A22: 16 | B22: Dây thép buộc 1 ly | C22: TCVN 1651:2018 | D22: kg | E22: =SUMIF(PHAN_TICH_VAT_TU_WBS!$F$6:$F$140, "*Dây thép buộc*", PHAN_TICH_VAT_TU_WBS!$I$6:$I$140) | F22: 0.03 | G22: =E22*(1+F22) | H22: =G22*0.35 | I22: =G22*0.25 | J22: =G22*0.35 | K22: =G22*0.05
A23: 17 | B23: Que hàn điện E42/E50 | C23: TCVN 3223:2000 | D23: kg | E23: =SUMIF(PHAN_TICH_VAT_TU_WBS!$F$6:$F$140, "*Que hàn điện*", PHAN_TICH_VAT_TU_WBS!$I$6:$I$140) | F23: 0.03 | G23: =E23*(1+F23) | H23: =G23*0.5 | I23: =G23*0.3 | J23: =G23*0.2 | K23: =G23*0.0
B24: II. KHOÁNG XÂY DỰNG & CẤP PHỐI BÊ TÔNG
A25: 18 | B25: Xi măng PCB40 (quy đổi Tấn) | C25: TCVN 6260:2020 | D25: Tấn | E25: =SUMIF(PHAN_TICH_VAT_TU_WBS!$F$6:$F$140, "*Xi măng PCB40*", PHAN_TICH_VAT_TU_WBS!$I$6:$I$140)/1000 | F25: 0.01 | G25: =E25*(1+F25) | H25: =G25*0.25 | I25: =G25*0.3 | J25: =G25*0.4 | K25: =G25*0.05
A26: 19 | B26: Cát vàng sàng rửa đúc bê tông (Mk >= 2.0) | C26: TCVN 7570:2006 | D26: m3 | E26: =SUMIF(PHAN_TICH_VAT_TU_WBS!$F$6:$F$140, "*Cát vàng*", PHAN_TICH_VAT_TU_WBS!$I$6:$I$140) | F26: 0.025 | G26: =E26*(1+F26) | H26: =G26*0.25 | I26: =G26*0.3 | J26: =G26*0.4 | K26: =G26*0.05
A27: 20 | B27: Đá dăm 1x2 sạch chọn lọc | C27: TCVN 7570:2006 | D27: m3 | E27: =SUMIF(PHAN_TICH_VAT_TU_WBS!$F$6:$F$140, "*Đá dăm 1x2*", PHAN_TICH_VAT_TU_WBS!$I$6:$I$140) | F27: 0.025 | G27: =E27*(1+F27) | H27: =G27*0.25 | I27: =G27*0.3 | J27: =G27*0.4 | K27: =G27*0.05
A28: 21 | B28: Đá hộc 20x30cm kè tứ nón mố | C28: TCVN 11823:2017 | D28: m3 | E28: =SUMIF(PHAN_TICH_VAT_TU_WBS!$F$6:$F$140, "*Đá hộc*", PHAN_TICH_VAT_TU_WBS!$I$6:$I$140) | F28: 0.02 | G28: =E28*(1+F28) | H28: =G28*0.0 | I28: =G28*0.0 | J28: =G28*0.0 | K28: =G28*1.0
A29: 22 | B29: Đất đắp nền đường sau mố K98 | C29: TCVN 9436:2012 | D29: m3 | E29: =SUMIF(PHAN_TICH_VAT_TU_WBS!$F$6:$F$140, "*Đất đắp*", PHAN_TICH_VAT_TU_WBS!$I$6:$I$140) | F29: 0.03 | G29: =E29*(1+F29) | H29: =G29*0.0 | I29: =G29*0.0 | J29: =G29*0.0 | K29: =G29*1.0
A30: 23 | B30: Nước sạch thi công & dưỡng hộ (quy đổi m3) | C30: TCVN 4506:2012 | D30: m3 | E30: =SUMIF(PHAN_TICH_VAT_TU_WBS!$F$6:$F$140, "*Nước sạch*", PHAN_TICH_VAT_TU_WBS!$I$6:$I$140)/1000 | F30: 0.02 | G30: =E30*(1+F30) | H30: =G30*0.25 | I30: =G30*0.3 | J30: =G30*0.4 | K30: =G30*0.05
B31: III. PHỤ GIA VÀ HÓA CHẤT XÂY DỰNG
A32: 24 | B32: Phụ gia siêu dẻo Polycarboxylate thế hệ 3 | C32: ASTM C494 Type F/G | D32: kg | E32: =SUMIF(PHAN_TICH_VAT_TU_WBS!$F$6:$F$140, "*Phụ gia siêu dẻo*", PHAN_TICH_VAT_TU_WBS!$I$6:$I$140) | F32: 0.01 | G32: =E32*(1+F32) | H32: =G32*0.0 | I32: =G32*0.3 | J32: =G32*0.7 | K32: =G32*0.0
A33: 25 | B33: Phụ gia hoá dẻo chậm đông kết | C33: ASTM C494 Type G | D33: kg | E33: =SUMIF(PHAN_TICH_VAT_TU_WBS!$F$6:$F$140, "*Phụ gia hoá dẻo*", PHAN_TICH_VAT_TU_WBS!$I$6:$I$140) | F33: 0.01 | G33: =E33*(1+F33) | H33: =G33*1.0 | I33: =G33*0.0 | J33: =G33*0.0 | K33: =G33*0.0
A34: 26 | B34: Vữa rót không co ngót bơm ghen SikaGrout 214-11 | C34: ASTM C1107 | D34: kg | E34: =SUMIF(PHAN_TICH_VAT_TU_WBS!$F$6:$F$140, "*Vữa không co ngót*", PHAN_TICH_VAT_TU_WBS!$I$6:$I$140) | F34: 0.015 | G34: =E34*(1+F34) | H34: =G34*0.0 | I34: =G34*0.0 | J34: =G34*1.0 | K34: =G34*0.0
A35: 27 | B35: Bột sét Bentonite tạo vách cọc khoan nhồi | C35: TCVN 9395:2012 | D35: Tấn | E35: =SUMIF(PHAN_TICH_VAT_TU_WBS!$F$6:$F$140, "*Bentonite*", PHAN_TICH_VAT_TU_WBS!$I$6:$I$140)/1000 | F35: 0.02 | G35: =E35*(1+F35) | H35: =G35*1.0 | I35: =G35*0.0 | J35: =G35*0.0 | K35: =G35*0.0
B36: IV. PHỤ KIỆN & VẬT LIỆU HOÀN THIỆN CẦU
A37: 28 | B37: Gối chậu cao su cốt bản thép chịu lực | C37: TCVN 11823:2017 | D37: Cái | E37: =SUMIF(PHAN_TICH_VAT_TU_WBS!$F$6:$F$140, "*Gối chậu*", PHAN_TICH_VAT_TU_WBS!$I$6:$I$140) | F37: 0 | G37: =E37*(1+F37) | H37: =G37*0.0 | I37: =G37*0.0 | J37: =G37*1.0 | K37: =G37*0.0
A38: 29 | B38: Màng / Sơn chống thấm mặt cầu Polymer cải tiến | C38: TCVN 11823:2017 | D38: m2 | E38: =SUMIF(PHAN_TICH_VAT_TU_WBS!$F$6:$F$140, "*Màng chống thấm*", PHAN_TICH_VAT_TU_WBS!$I$6:$I$140) | F38: 0.02 | G38: =E38*(1+F38) | H38: =G38*0.0 | I38: =G38*0.0 | J38: =G38*0.0 | K38: =G38*1.0
A39: 30 | B39: Bê tông nhựa chặt C12.5 rải nóng | C39: TCVN 8819:2011 | D39: Tấn | E39: =SUMIF(PHAN_TICH_VAT_TU_WBS!$F$6:$F$140, "*Bê tông nhựa*", PHAN_TICH_VAT_TU_WBS!$I$6:$I$140) | F39: 0.025 | G39: =E39*(1+F39) | H39: =G39*0.0 | I39: =G39*0.0 | J39: =G39*0.0 | K39: =G39*1.0
A40: 31 | B40: Vải địa kỹ thuật không dệt lọc ngược | C40: TCVN 9865:2013 | D40: m2 | E40: =SUMIF(PHAN_TICH_VAT_TU_WBS!$F$6:$F$140, "*Vải địa*", PHAN_TICH_VAT_TU_WBS!$I$6:$I$140) | F40: 0.03 | G40: =E40*(1+F40) | H40: =G40*0.0 | I40: =G40*0.0 | J40: =G40*0.0 | K40: =G40*1.0
A41: 32 | B41: Phễu gang thu nước mặt cầu có lưới chắn | C41: TCVN 11823:2017 | D41: Bộ | E41: =SUMIF(PHAN_TICH_VAT_TU_WBS!$F$6:$F$140, "*Phễu gang*", PHAN_TICH_VAT_TU_WBS!$I$6:$I$140) | F41: 0 | G41: =E41*(1+F41) | H41: =G41*0.0 | I41: =G41*0.0 | J41: =G41*0.0 | K41: =G41*1.0
...

Sheet PHAN_TICH_VAT_TU_WBS
B2: DỰ ÁN: CAO TỐC TUYÊN QUANG - HÀ GIANG (GIAI ĐOẠN 1) - CẦU KM19+529.080
B3: BẢNG PHÂN TÍCH ĐỊNH MỨC HAO PHÍ VẬT LIỆU CHO TỪNG HẠNG MỤC CÔNG TÁC WBS
B4: Chi tiết sắt thép từng loại đường kính Ø, xi măng, cát, đá, cáp DƯL (Theo Định mức Thông tư 12/2021/TT-BXD)
A5: TT | B5: Mã định mức | C5: Hạng mục công tác WBS | D5: Khối lượng công tác | E5: ĐVT công tác | F5: Tên quy cách vật tư cấu thành | G5: ĐVT vật tư | H5: Định mức cho 1 ĐVT | I5: Hao phí vật tư hạng mục | J5: Tiêu chuẩn kỹ thuật áp dụng
A6: 1 | B6: AC.11111 | C6: Khoan tạo lỗ cọc khoan nhồi D1200mm (26 cọc L=20m-40m) | D6: 872 | E6: m
C7: • Bột sét Bentonite tạo vách khoan | F7: Bột sét Bentonite tạo vách khoan | G7: Tấn | H7: 0.045 | I7: =D6*H7 | J7: TCVN 9395:2012
C8: • Nước sạch thi công khoan cọc | F8: Nước sạch thi công khoan cọc | G8: m3 | H8: 0.25 | I8: =D6*H8 | J8: TCVN 4506:2012
A9: 2 | B9: AC.12111 | C9: Hạ và nhổ ống vách thép dẫn hướng D1300mm d=8mm | D9: 156 | E9: m
C10: • Ống vách thép dẫn hướng D1300 d=8mm (khấu hao) | F10: Ống vách thép dẫn hướng D1300 d=8mm (khấu hao) | G10: Tấn | H10: 0.052 | I10: =D9*H10 | J10: TCVN 9395:2012
A11: 3 | B11: AF.21111 | C11: Bê tông cọc khoan nhồi C30/37 đổ bằng ống Tremie | D11: 1104.5589 | E11: m3
C12: • Xi măng PCB40 cọc khoan nhồi | F12: Xi măng PCB40 cọc khoan nhồi | G12: kg | H12: 395 | I12: =D11*H12 | J12: TCVN 6260:2020
C13: • Cát vàng hạt trung Mk>=2.0 | F13: Cát vàng hạt trung Mk>=2.0 | G13: m3 | H13: 0.47 | I13: =D11*H13 | J13: TCVN 7570:2006
C14: • Đá dăm 1x2 sạch chọn lọc | F14: Đá dăm 1x2 sạch chọn lọc | G14: m3 | H14: 0.83 | I14: =D11*H14 | J14: TCVN 7570:2006
C15: • Nước sạch trộn bê tông | F15: Nước sạch trộn bê tông | G15: Lít | H15: 185 | I15: =D11*H15 | J15: TCVN 4506:2012
C16: • Phụ gia hoá dẻo chậm đông kết | F16: Phụ gia hoá dẻo chậm đông kết | G16: kg | H16: 4.2 | I16: =D11*H16 | J16: ASTM C494 Type G
A17: 4 | B17: AF.61111 | C17: Cốt thép cọc khoan nhồi D1200mm (Lồng thép) | D17: 108.76599 | E17: Tấn
C18: • Thép chủ cọc nhồi vằn Ø25 (CB500-V) | F18: Thép chủ cọc nhồi vằn Ø25 (CB500-V) | G18: Tấn | H18: 0.785 | I18: =D17*H18 | J18: TCVN 1651:2018
C19: • Thép đai tăng cường vằn Ø16 (CB400-V) | F19: Thép đai tăng cường vằn Ø16 (CB400-V) | G19: Tấn | H19: 0.12 | I19: =D17*H19 | J19: TCVN 1651:2018
C20: • Thép đai xoắn liên tục tròn trơn Ø10 (CB240-T) | F20: Thép đai xoắn liên tục tròn trơn Ø10 (CB240-T) | G20: Tấn | H20: 0.095 | I20: =D17*H20 | J20: TCVN 1651:2018
C21: • Ống siêu âm cọc nhồi thép Ø60x2 | F21: Ống siêu âm cọc nhồi thép Ø60x2 | G21: m | H21: 36.5 | I21: =D17*H21 | J21: ASTM A53 / TCVN 9395
C22: • Dây thép buộc 1 ly | F22: Dây thép buộc 1 ly | G22: kg | H22: 15 | I22: =D17*H22 | J22: TCVN 1651:2018
C23: • Que hàn điện E42/E50 | F23: Que hàn điện E42/E50 | G23: kg | H23: 8 | I23: =D17*H23 | J23: TCVN 3223:2000
A24: 5 | B24: AF.11111 | C24: Bê tông lót đáy bệ móng mác C10 dày 10cm | D24: 33.5 | E24: m3
C25: • Xi măng PCB40 lót móng | F25: Xi măng PCB40 lót móng | G25: kg | H25: 240 | I25: =D24*H25 | J25: TCVN 6260:2020
C26: • Cát vàng xây dựng | F26: Cát vàng xây dựng | G26: m3 | H26: 0.51 | I26: =D24*H26 | J26: TCVN 7570:2006
C27: • Đá dăm 1x2 | F27: Đá dăm 1x2 | G27: m3 | H27: 0.87 | I27: =D24*H27 | J27: TCVN 7570:2006
C28: • Nước sạch trộn bê tông | F28: Nước sạch trộn bê tông | G28: Lít | H28: 175 | I28: =D24*H28 | J28: TCVN 4506:2012
A29: 6 | B29: AF.12111 | C29: Bê tông bệ móng mố M1, M2 và bệ trụ T1, T2 mác C30 | D29: 666.97845 | E29: m3
C30: • Xi măng PCB40 bệ móng | F30: Xi măng PCB40 bệ móng | G30: kg | H30: 385 | I30: =D29*H30 | J30: TCVN 6260:2020
C31: • Cát vàng sàng rửa Mk>=2.0 | F31: Cát vàng sàng rửa Mk>=2.0 | G31: m3 | H31: 0.46 | I31: =D29*H31 | J31: TCVN 7570:2006
C32: • Đá dăm 1x2 sạch | F32: Đá dăm 1x2 sạch | G32: m3 | H32: 0.84 | I32: =D29*H32 | J32: TCVN 7570:2006
C33: • Nước sạch trộn bê tông | F33: Nước sạch trộn bê tông | G33: Lít | H33: 180 | I33: =D29*H33 | J33: TCVN 4506:2012
C34: • Phụ gia siêu dẻo giảm nước | F34: Phụ gia siêu dẻo giảm nước | G34: kg | H34: 3.8 | I34: =D29*H34 | J34: ASTM C494 Type F
A35: 7 | B35: AF.12211 | C35: Bê tông thân mố chân dê M1 và mố chữ U M2 mác C30 | D35: 169.2 | E35: m3
C36: • Xi măng PCB40 thân mố | F36: Xi măng PCB40 thân mố | G36: kg | H36: 385 | I36: =D35*H36 | J36: TCVN 6260:2020
C37: • Cát vàng sàng rửa Mk>=2.0 | F37: Cát vàng sàng rửa Mk>=2.0 | G37: m3 | H37: 0.46 | I37: =D35*H37 | J37: TCVN 7570:2006
C38: • Đá dăm 1x2 sạch | F38: Đá dăm 1x2 sạch | G38: m3 | H38: 0.84 | I38: =D35*H38 | J38: TCVN 7570:2006
C39: • Nước sạch trộn bê tông | F39: Nước sạch trộn bê tông | G39: Lít | H39: 180 | I39: =D35*H39 | J39: TCVN 4506:2012
C40: • Phụ gia siêu dẻo giảm nước | F40: Phụ gia siêu dẻo giảm nước | G40: kg | H40: 3.8 | I40: =D35*H40 | J40: ASTM C494 Type F
A41: 8 | B41: AF.12311 | C41: Bê tông tường cánh và tường đỉnh mố M1, M2 mác C30 | D41: 48.91425 | E41: m3
...

Sheet CUNG_UNG_4_GIAI_DOAN
A1: DỰ ÁN: CAO TỐC TUYÊN QUANG - HÀ GIANG (GIAI ĐOẠN 1) — GÓI THẦU SỐ 09-XL
A2: KẾ HOẠCH CUNG ỨNG VÀ DỰ TRỮ VẬT TƯ THEO 4 GIAI ĐOÀN THI CÔNG — CẦU KM19+529.080
A3: Phù hợp tiến độ CPM đường găng; Đảm bảo không bị gián đoạn thi công do thời tiết vùng cao
A5: STT | B5: Chủng loại vật tư chính | C5: ĐVT | D5: Tổng nhu cầu công trình | E5: Giai đoạn 1: Móng cọc & Bệ móng | F5: Giai đoạn 2: Thân mố, Thân trụ & Đúc dầm Super-T | G5: Giai đoạn 3: Lao dầm & Bản mặt cầu | H5: Giai đoạn 4: Khe co giãn & Hoàn thiện | I5: Quy định dự trữ kho an toàn
A6: 1 | B6: Xi măng PCB40 | C6: Tấn | D6: =TONG_HOP_VAT_TU_TOAN_BO!G23 | E6: =D6*0.35 | F6: =D6*0.35 | G6: =D6*0.20 | H6: =D6*0.10 | I6: Tồn kho tối thiểu 50 tấn tại trạm trộn
A7: 2 | B7: Cát vàng bê tông | C7: m3 | D7: =TONG_HOP_VAT_TU_TOAN_BO!G24 | E7: =D7*0.35 | F7: =D7*0.35 | G7: =D7*0.20 | H7: =D7*0.10 | I7: Dự trữ bãi chứa 100 m3 chống mưa lũ
A8: 3 | B8: Đá dăm 1x2 bê tông | C8: m3 | D8: =TONG_HOP_VAT_TU_TOAN_BO!G25 | E8: =D8*0.35 | F8: =D8*0.35 | G8: =D8*0.20 | H8: =D8*0.10 | I8: Dự trữ bãi chứa 150 m3 sàng sạch
A9: 4 | B9: Cốt thép CB400-V (các Ø) | C9: kg | D9: =TONG_HOP_VAT_TU_TOAN_BO!G10 | E9: =D9*0.40 | F9: =D9*0.35 | G9: =D9*0.20 | H9: =D9*0.05 | I9: Gia công sẵn lồng cọc & dầm tại bãi
A10: 5 | B10: Cáp DƯL tao xoắn 15.2mm | C10: kg | D10: =TONG_HOP_VAT_TU_TOAN_BO!G11 | E10: 0 | F10: =D10*0.80 | G10: =D10*0.20 | H10: 0 | I10: Bảo quản phòng khô, tra mỡ bảo vệ
A11: 6 | B11: Ván khuôn thép định hình | C11: m2 | D11: 1500 | E11: 600 | F11: 600 | G11: 300 | H11: 0 | I11: Luân chuyển tuần hoàn thân trụ & dầm
A12: 7 | B12: Gối chậu cao su (30 bộ) | C12: Bộ | D12: 30 | E12: 0 | F12: 10 | G12: 20 | H12: 0 | I12: Nhập đủ lô trước khi đúc dầm nhịp 1
A13: 8 | B13: Khe co giãn răng lược (2 bộ) | C13: Bộ | D13: 2 | E13: 0 | F13: 0 | G13: 0 | H13: 2 | I13: Gia công chuẩn theo bản vẽ cơ khí
A14: 9 | B14: Bê tông nhựa C16 mặt cầu | C14: Tấn | D14: =TONG_HOP_VAT_TU_TOAN_BO!G32 | E14: 0 | F14: 0 | G14: 0 | H14: =D14 | I14: Trạm trộn thảm liên tục trong 2 ngày
