Workbook

Sheet TONG_HOP_1M
A1: BẢNG TỔNG HỢP KHỐI LƯỢNG BÊ TÔNG, VÁN KHUÔN, CỐT THÉP CHO 1M DÀI CỐNG HỘP
A2: Dự án: Tuyến A5 - Khu đô thị Thể thao Quốc tế Hà Nội | Đơn vị thi công: Vincons
A3: Tiêu chuẩn tính toán: TCVN 1651:2018 | Hồ sơ bản vẽ: OLP_SD_KC_HT_CH_06 đến CH_26
A5: STT | B5: HẠNG MỤC / QUY CÁCH CỐNG | C5: THÔNG THỦY (BxH) (m) | D5: PHỦ BÌ (BxH) (m) | E5: BÊ TÔNG THÂN B20 (m3/m) | F5: BÊ TÔNG LÓT M100 (m3/m) | G5: VÁN KHUÔN TIẾP XÚC (m2/m) | H5: THÉP DƯỚI ĐƯỜNG (kg/m) | I5: THÉP VỈA HÈ (kg/m) | J5: THÉP TRUNG BÌNH (kg/m) | K5: HÀM LƯỢNG THÉP (kg/m3 BT) | L5: GHI CHÚ
A6: 1 | B6: Cống hộp đơn 2.0x2.0m | C6: 2.0 x 2.0 | D6: 2.5 x 2.5 | E6: =CONG_DON_2X2!H15 | F6: =CONG_DON_2X2!H18 | G6: =CONG_DON_2X2!H28 | H6: =CONG_DON_2X2!H44 | I6: =CONG_DON_2X2!H45 | J6: =AVERAGE(H6:I6) | K6: =J6/E6 | L6: Bản vẽ CH_06-08 (11 đoạn)
A7: 2 | B7: Cống hộp đơn 3.0x3.0m | C7: 3.0 x 3.0 | D7: 3.6 x 3.6 | E7: =CONG_DON_3X3!H15 | F7: =CONG_DON_3X3!H18 | G7: =CONG_DON_3X3!H28 | H7: =CONG_DON_3X3!H44 | I7: =CONG_DON_3X3!H45 | J7: =AVERAGE(H7:I7) | K7: =J7/E7 | L7: Bản vẽ CH_10-12 (16 đoạn)
A8: 3 | B8: Cống hộp đôi 2x(3.0x3.0m) | C8: 2 x (3.0 x 3.0) | D8: 6.9 x 3.6 | E8: =CONG_DOI_2X3X3!H15 | F8: =CONG_DOI_2X3X3!H18 | G8: =CONG_DOI_2X3X3!H28 | H8: =CONG_DOI_2X3X3!H48 | I8: =CONG_DOI_2X3X3!H49 | J8: =AVERAGE(H8:I8) | K8: =J8/E8 | L8: Bản vẽ CH_13-15 (35 đoạn)
B9: GIÁ TRỊ TRUNG BÌNH CỘNG (3 LOẠI) | C9: - | D9: - | E9: =AVERAGE(E6:E8) | F9: =AVERAGE(F6:F8) | G9: =AVERAGE(G6:G8) | H9: =AVERAGE(H6:H8) | I9: =AVERAGE(I6:I8) | J9: =AVERAGE(J6:J8) | K9: =J9/E9 | L9: Trung bình số học đơn giản
A10: ★ | B10: TRUNG BÌNH TRỌNG SỐ TOÀN TUYẾN A5 (THEO CHIỀU DÀI) | C10: L_tong = 2,170m | D10: 100% | E10: =(385*E6 + 560*E7 + 1225*E8)/2170 | F10: =(385*F6 + 560*F7 + 1225*F8)/2170 | G10: =(385*G6 + 560*G7 + 1225*G8)/2170 | H10: =(385*H6 + 560*H7 + 1225*H8)/2170 | I10: =(385*I6 + 560*I7 + 1225*I8)/2170 | J10: =(385*J6 + 560*J7 + 1225*J8)/2170 | K10: =J10/E10 | L10: Tỷ trọng: 2x2 (18%), 3x3 (26%), 2x(3x3) (56%)
B12: GHI CHÚ KỸ THUẬT & QUY ƯỚC ĐO BÓC:
B13: 1. Bê tông thân cống: Cấp độ bền B20 (tương đương Mác 250# theo TCVN 5574:2018). Thể tích tính bao gồm cả 4 nách vát góc tăng cường.
B14: 2. Bê tông lót móng: Chiều dày 50mm, Mác 100#, mở rộng mỗi bên 100mm so với mép ngoài đáy cống.
B15: 3. Ván khuôn: Diện tích bề mặt tiếp xúc thực tế của 2 vách ngoài, 2 vách trong, đáy bản nắp trong, các nách vát và ván khuôn đầu đốt cống chặn khe co giãn.
B16: 4. Cốt thép: Thép d < 10mm dùng CB240-T, thép d >= 10mm dùng CB500-V. Trọng lượng tính toán theo TCVN 1651:2018.
B17: 5. Tải trọng: Bản vẽ phân biệt 2 cấp tải trọng nắp cống: Dưới đường (400kN / HL93, cốt thép dày a100-a125) và Trên vỉa hè (125kN, cốt thép a250).
B18: 6. Thép khe co giãn: Dowel bar d22 L=1000mm bọc ống PVC bôi mỡ bitum tại các vị trí khe co giãn (chu kỳ 11.7m) đã được phân bổ bình quân cho 1m dài.

Sheet CONG_DON_2X2
A1: BÓC TÁCH KHỐI LƯỢNG CỐNG HỘP ĐƠN 2.0x2.0M
A2: Hồ sơ bản vẽ: OLP_SD_KC_HT_CH_06 & CH_07 | Chiều dài đốt cống điển hình L = 11.3m
A4: I. KÍCH THƯỚC HÌNH HỌC & ĐO BÓC BÊ TÔNG
A5: STT | B5: CẤU KIỆN / THÀNH PHẦN | C5: SỐ LƯỢNG | D5: DÀI (m) | E5: RỘNG (m) | F5: CAO/DÀY (m) | G5: HỆ SỐ VÁT | H5: THỂ TÍCH (m3)
A6: 1 | B6: Hình hộp ngoại vi cống (phủ bì) | C6: 1 | D6: 1 | E6: 2.5 | F6: 2.5 | G6: 1 | H6: =C6*D6*E6*F6*G6
A7: 2 | B7: Trừ khoang thông thủy (1 khoang) | C7: 1 | D7: 1 | E7: 2 | F7: 2 | G7: -1 | H7: =C7*D7*E7*F7*G7
A8: 3 | B8: Cộng nách vát góc (4 nách) | C8: 4 | D8: 1 | E8: 0.2 | F8: 0.2 | G8: 0.5 | H8: =C8*D8*E8*F8*G8
B9: TỔNG THỂ TÍCH BÊ TÔNG THÂN CỐNG B20 (1M DÀI) | H9: =SUM(H6:H8)
A10: 4 | B10: Bê tông lót M100 dày 50mm (nhô 100mm mỗi bên) | C10: 1 | D10: 1 | E10: 2.7 | F10: 0.05 | G10: 1 | H10: =C10*D10*E10*F10*G10
B12: QUY ĐỔI KHỐI LƯỢNG CHO ĐỐT CỐNG & 1M DÀI:
B13: - Chiều dài đốt cống điển hình L (m): | E13: 11.3
B14: - Thể tích bê tông thân cho 01 đốt cống 11.3m (m3): | E14: =H9*E13
B15: - BÊ TÔNG THÂN CỐNG B20 CHO 1M DÀI (m3/m): | H15: =H9
B16: - Thể tích bê tông lót cho 01 đốt cống 11.3m (m3): | E16: =H10*E13
B18: - BÊ TÔNG LÓT M100 CHO 1M DÀI (m3/m): | H18: =H10
A20: II. ĐO BÓC VÁN KHUÔN TIẾP XÚC (m2)
A21: STT | B21: VỊ TRÍ VÁN KHUÔN | C21: SỐ LƯỢNG | D21: DÀI (m) | E21: RỘNG/CAO (m) | F21: HỆ SỐ | G21: GHI CHÚ | H21: DIỆN TÍCH (m2)
A22: 1 | B22: Vách ngoài 2 bên cống | C22: 2 | D22: 1 | E22: 2.5 | F22: 1 | G22: 2 mặt thành biên ngoài | H22: =C22*D22*E22*F22
A23: 2 | B23: Vách trong khoang cống (1 khoang) | C23: 2 | D23: 1 | E23: 1.6 | F23: 1 | G23: Thành bên trong (phần phẳng) | H23: =C23*D23*E23*F23
A24: 3 | B24: Đáy bản nắp trong (1 khoang) | C24: 1 | D24: 1 | E24: 1.6 | F24: 1 | G24: Đáy nắp phẳng trong khoang | H24: =C24*D24*E24*F24
A25: 4 | B25: Vát nách cống (4 nách) | C25: 4 | D25: 1 | E25: 0.28284271 | F25: 1 | G25: Mặt nghiêng nách cống | H25: =C25*D25*E25*F25
A26: 5 | B26: Đầu đốt cống chặn khe co giãn (phân bổ) | C26: 1 | D26: 1 | E26: =H9/11.3 | F26: 1 | G26: Phân bổ trên đốt 11.3m | H26: =C26*D26*E26*F26
B28: TỔNG DIỆN TÍCH VÁN KHUÔN CHO 1M DÀI CỐNG (m2/m) | H28: =SUM(H22:H26)
A30: III. BẢNG THỐNG KÊ CỐT THÉP CHI TIẾT (BBS) & QUY ĐỔI 1M DÀI
A31: SỐ HIỆU | B31: LOẠI THÉP / VỊ TRÍ | C31: ĐƯỜNG KÍNH (mm) | D31: SỐ LƯỢNG (thanh) | E31: DÀI 1 THANH (m) | F31: TỔNG DÀI ĐỐT (m) | G31: TRỌNG LƯỢNG ĐƠN VỊ (kg/m) | H31: TỔNG TRỌNG LƯỢNG ĐỐT (kg) | I31: QUY ĐỔI 1M DÀI (kg/m) | J31: GHI CHÚ
A32: 1 | B32: Thép ngang nắp/đáy (Dưới đường a100) | C32: 12 | D32: 226 | E32: 2.82 | F32: =D32*E32 | G32: 0.888 | H32: =F32*G32 | I32: =H32/11.3 | J32: Dưới đường (2x113 thanh)
A33: 1a | B33: Thép ngang nắp/đáy (Vỉa hè a250) | C33: 12 | D33: 90 | E33: 2.92 | F33: =D33*E33 | G33: 0.888 | H33: =F33*G33 | I33: =H33/11.3 | J33: Vỉa hè (2x45 thanh)
A34: 2 | B34: Thép thành biên (Dưới đường a125) | C34: 12 | D34: 180 | E34: 2.84 | F34: =D34*E34 | G34: 0.888 | H34: =F34*G34 | I34: =H34/11.3 | J34: Dưới đường (2x90 thanh)
A35: 2a | B35: Thép thành biên (Vỉa hè a250) | C35: 12 | D35: 90 | E35: 2.84 | F35: =D35*E35 | G35: 0.888 | H35: =F35*G35 | I35: =H35/11.3 | J35: Vỉa hè (2x45 thanh)
A36: 3 | B36: Thép gia cường 4 nách vát góc | C36: 12 | D36: 180 | E36: 1.32 | F36: =D36*E36 | G36: 0.888 | H36: =F36*G36 | I36: =H36/11.3 | J36: Dùng chung (4x45 thanh a250)
A37: 4 | B37: Thép dọc cống phân bố a200 | C37: 10 | D37: 96 | E37: 11.7 | F37: =D37*E37 | G37: 0.617 | H37: =F37*G37 | I37: =H37/11.3 | J37: Dùng chung (96 thanh suốt đốt)
A38: 5 | B38: Thép dowel bar khe co giãn | C38: 22 | D38: 20 | E38: 1 | F38: =D38*E38 | G38: 2.984 | H38: =F38*G38 | I38: =H38/11.3 | J38: Dùng chung (bọc PVC bôi mỡ)
B40: TỔNG KHỐI LƯỢNG THÉP - KỊCH BẢN DƯỚI ĐƯỜNG (HL93) | H40: =SUMIF(J32:J38, "<>*Vỉa hè*", H32:H38) | I40: =H40/11.3 | J40: kg/m dài cống dưới đường
B41: TỔNG KHỐI LƯỢNG THÉP - KỊCH BẢN TRÊN VỈA HÈ (125kN) | H41: =SUMIF(J32:J38, "<>*Dưới đường*", H32:H38) | I41: =H41/11.3 | J41: kg/m dài cống trên vỉa hè
B43: GIÁ TRỊ QUY ĐỔI 1M DÀI PHỤC VỤ LINK SHEET TỔNG HỢP:
B44: THÉP DƯỚI ĐƯỜNG (kg/m): | H44: =I40
B45: THÉP TRÊN VỈA HÈ (kg/m): | H45: =I41

Sheet CONG_DON_3X3
A1: BÓC TÁCH KHỐI LƯỢNG CỐNG HỘP ĐƠN 3.0x3.0M
A2: Hồ sơ bản vẽ: OLP_SD_KC_HT_CH_10 & CH_11 | Chiều dài đốt cống điển hình L = 11.3m
A4: I. KÍCH THƯỚC HÌNH HỌC & ĐO BÓC BÊ TÔNG
A5: STT | B5: CẤU KIỆN / THÀNH PHẦN | C5: SỐ LƯỢNG | D5: DÀI (m) | E5: RỘNG (m) | F5: CAO/DÀY (m) | G5: HỆ SỐ VÁT | H5: THỂ TÍCH (m3)
A6: 1 | B6: Hình hộp ngoại vi cống (phủ bì) | C6: 1 | D6: 1 | E6: 3.6 | F6: 3.6 | G6: 1 | H6: =C6*D6*E6*F6*G6
A7: 2 | B7: Trừ khoang thông thủy (1 khoang) | C7: 1 | D7: 1 | E7: 3 | F7: 3 | G7: -1 | H7: =C7*D7*E7*F7*G7
A8: 3 | B8: Cộng nách vát góc (4 nách) | C8: 4 | D8: 1 | E8: 0.25 | F8: 0.25 | G8: 0.5 | H8: =C8*D8*E8*F8*G8
B9: TỔNG THỂ TÍCH BÊ TÔNG THÂN CỐNG B20 (1M DÀI) | H9: =SUM(H6:H8)
A10: 4 | B10: Bê tông lót M100 dày 50mm (nhô 100mm mỗi bên) | C10: 1 | D10: 1 | E10: 3.8 | F10: 0.05 | G10: 1 | H10: =C10*D10*E10*F10*G10
B12: QUY ĐỔI KHỐI LƯỢNG CHO ĐỐT CỐNG & 1M DÀI:
B13: - Chiều dài đốt cống điển hình L (m): | E13: 11.3
B14: - Thể tích bê tông thân cho 01 đốt cống 11.3m (m3): | E14: =H9*E13
B15: - BÊ TÔNG THÂN CỐNG B20 CHO 1M DÀI (m3/m): | H15: =H9
B16: - Thể tích bê tông lót cho 01 đốt cống 11.3m (m3): | E16: =H10*E13
B18: - BÊ TÔNG LÓT M100 CHO 1M DÀI (m3/m): | H18: =H10
A20: II. ĐO BÓC VÁN KHUÔN TIẾP XÚC (m2)
A21: STT | B21: VỊ TRÍ VÁN KHUÔN | C21: SỐ LƯỢNG | D21: DÀI (m) | E21: RỘNG/CAO (m) | F21: HỆ SỐ | G21: GHI CHÚ | H21: DIỆN TÍCH (m2)
A22: 1 | B22: Vách ngoài 2 bên cống | C22: 2 | D22: 1 | E22: 3.6 | F22: 1 | G22: 2 mặt thành biên ngoài | H22: =C22*D22*E22*F22
A23: 2 | B23: Vách trong khoang cống (1 khoang) | C23: 2 | D23: 1 | E23: 2.5 | F23: 1 | G23: Thành bên trong (phần phẳng) | H23: =C23*D23*E23*F23
A24: 3 | B24: Đáy bản nắp trong (1 khoang) | C24: 1 | D24: 1 | E24: 2.5 | F24: 1 | G24: Đáy nắp phẳng trong khoang | H24: =C24*D24*E24*F24
A25: 4 | B25: Vát nách cống (4 nách) | C25: 4 | D25: 1 | E25: 0.35355339 | F25: 1 | G25: Mặt nghiêng nách cống | H25: =C25*D25*E25*F25
A26: 5 | B26: Đầu đốt cống chặn khe co giãn (phân bổ) | C26: 1 | D26: 1 | E26: =H9/11.3 | F26: 1 | G26: Phân bổ trên đốt 11.3m | H26: =C26*D26*E26*F26
B28: TỔNG DIỆN TÍCH VÁN KHUÔN CHO 1M DÀI CỐNG (m2/m) | H28: =SUM(H22:H26)
A30: III. BẢNG THỐNG KÊ CỐT THÉP CHI TIẾT (BBS) & QUY ĐỔI 1M DÀI
A31: SỐ HIỆU | B31: LOẠI THÉP / VỊ TRÍ | C31: ĐƯỜNG KÍNH (mm) | D31: SỐ LƯỢNG (thanh) | E31: DÀI 1 THANH (m) | F31: TỔNG DÀI ĐỐT (m) | G31: TRỌNG LƯỢNG ĐƠN VỊ (kg/m) | H31: TỔNG TRỌNG LƯỢNG ĐỐT (kg) | I31: QUY ĐỔI 1M DÀI (kg/m) | J31: GHI CHÚ
A32: 1 | B32: Thép ngang nắp/đáy (Dưới đường a125) | C32: 14 | D32: 180 | E32: 3.9 | F32: =D32*E32 | G32: 1.208 | H32: =F32*G32 | I32: =H32/11.3 | J32: Dưới đường (2x90 thanh)
A33: 1a | B33: Thép ngang nắp/đáy (Vỉa hè a250) | C33: 14 | D33: 90 | E33: 3.9 | F33: =D33*E33 | G33: 1.208 | H33: =F33*G33 | I33: =H33/11.3 | J33: Vỉa hè (2x45 thanh)
A34: 2 | B34: Thép thành biên (Dưới đường a125) | C34: 14 | D34: 180 | E34: 3.9 | F34: =D34*E34 | G34: 1.208 | H34: =F34*G34 | I34: =H34/11.3 | J34: Dưới đường (2x90 thanh)
A35: 2a | B35: Thép thành biên (Vỉa hè a250) | C35: 14 | D35: 90 | E35: 3.9 | F35: =D35*E35 | G35: 1.208 | H35: =F35*G35 | I35: =H35/11.3 | J35: Vỉa hè (2x45 thanh)
A36: 3 | B36: Thép gia cường 4 nách vát góc | C36: 14 | D36: 180 | E36: 1.95 | F36: =D36*E36 | G36: 1.208 | H36: =F36*G36 | I36: =H36/11.3 | J36: Dùng chung (4x45 thanh a250)
A37: 4 | B37: Thép dọc cống phân bố a200 | C37: 10 | D37: 136 | E37: 11.7 | F37: =D37*E37 | G37: 0.617 | H37: =F37*G37 | I37: =H37/11.3 | J37: Dùng chung (136 thanh suốt đốt)
A38: 5 | B38: Thép dowel bar khe co giãn | C38: 22 | D38: 28 | E38: 1 | F38: =D38*E38 | G38: 2.984 | H38: =F38*G38 | I38: =H38/11.3 | J38: Dùng chung (bọc PVC bôi mỡ)
B40: TỔNG KHỐI LƯỢNG THÉP - KỊCH BẢN DƯỚI ĐƯỜNG (HL93) | H40: =SUMIF(J32:J38, "<>*Vỉa hè*", H32:H38) | I40: =H40/11.3 | J40: kg/m dài cống dưới đường
B41: TỔNG KHỐI LƯỢNG THÉP - KỊCH BẢN TRÊN VỈA HÈ (125kN) | H41: =SUMIF(J32:J38, "<>*Dưới đường*", H32:H38) | I41: =H41/11.3 | J41: kg/m dài cống trên vỉa hè
B43: GIÁ TRỊ QUY ĐỔI 1M DÀI PHỤC VỤ LINK SHEET TỔNG HỢP:
B44: THÉP DƯỚI ĐƯỜNG (kg/m): | H44: =I40
B45: THÉP TRÊN VỈA HÈ (kg/m): | H45: =I41

Sheet CONG_DOI_2X3X3
A1: BÓC TÁCH KHỐI LƯỢNG CỐNG HỘP ĐÔI 2x(3.0x3.0M)
A2: Hồ sơ bản vẽ: OLP_SD_KC_HT_CH_13, 14 & CH_15 | Chiều dài đốt cống điển hình L = 11.3m
A4: I. KÍCH THƯỚC HÌNH HỌC & ĐO BÓC BÊ TÔNG
A5: STT | B5: CẤU KIỆN / THÀNH PHẦN | C5: SỐ LƯỢNG | D5: DÀI (m) | E5: RỘNG (m) | F5: CAO/DÀY (m) | G5: HỆ SỐ VÁT | H5: THỂ TÍCH (m3)
A6: 1 | B6: Hình hộp ngoại vi cống (phủ bì) | C6: 1 | D6: 1 | E6: 6.9 | F6: 3.6 | G6: 1 | H6: =C6*D6*E6*F6*G6
A7: 2 | B7: Trừ khoang thông thủy (2 khoang) | C7: 2 | D7: 1 | E7: 3 | F7: 3 | G7: -1 | H7: =C7*D7*E7*F7*G7
A8: 3 | B8: Cộng nách vát góc (8 nách) | C8: 8 | D8: 1 | E8: 0.25 | F8: 0.25 | G8: 0.5 | H8: =C8*D8*E8*F8*G8
B9: TỔNG THỂ TÍCH BÊ TÔNG THÂN CỐNG B20 (1M DÀI) | H9: =SUM(H6:H8)
A10: 4 | B10: Bê tông lót M100 dày 50mm (nhô 100mm mỗi bên) | C10: 1 | D10: 1 | E10: 7.1 | F10: 0.05 | G10: 1 | H10: =C10*D10*E10*F10*G10
B12: QUY ĐỔI KHỐI LƯỢNG CHO ĐỐT CỐNG & 1M DÀI:
B13: - Chiều dài đốt cống điển hình L (m): | E13: 11.3
B14: - Thể tích bê tông thân cho 01 đốt cống 11.3m (m3): | E14: =H9*E13
B15: - BÊ TÔNG THÂN CỐNG B20 CHO 1M DÀI (m3/m): | H15: =H9
B16: - Thể tích bê tông lót cho 01 đốt cống 11.3m (m3): | E16: =H10*E13
B18: - BÊ TÔNG LÓT M100 CHO 1M DÀI (m3/m): | H18: =H10
A20: II. ĐO BÓC VÁN KHUÔN TIẾP XÚC (m2)
A21: STT | B21: VỊ TRÍ VÁN KHUÔN | C21: SỐ LƯỢNG | D21: DÀI (m) | E21: RỘNG/CAO (m) | F21: HỆ SỐ | G21: GHI CHÚ | H21: DIỆN TÍCH (m2)
A22: 1 | B22: Vách ngoài 2 bên cống | C22: 2 | D22: 1 | E22: 3.6 | F22: 1 | G22: 2 mặt thành biên ngoài | H22: =C22*D22*E22*F22
A23: 2 | B23: Vách trong khoang cống (2 khoang) | C23: 4 | D23: 1 | E23: 2.5 | F23: 1 | G23: Thành bên trong (phần phẳng) | H23: =C23*D23*E23*F23
A24: 3 | B24: Đáy bản nắp trong (2 khoang) | C24: 2 | D24: 1 | E24: 2.5 | F24: 1 | G24: Đáy nắp phẳng trong khoang | H24: =C24*D24*E24*F24
A25: 4 | B25: Vát nách cống (8 nách) | C25: 8 | D25: 1 | E25: 0.35355339 | F25: 1 | G25: Mặt nghiêng nách cống | H25: =C25*D25*E25*F25
A26: 5 | B26: Đầu đốt cống chặn khe co giãn (phân bổ) | C26: 1 | D26: 1 | E26: =H9/11.3 | F26: 1 | G26: Phân bổ trên đốt 11.3m | H26: =C26*D26*E26*F26
B28: TỔNG DIỆN TÍCH VÁN KHUÔN CHO 1M DÀI CỐNG (m2/m) | H28: =SUM(H22:H26)
A30: III. BẢNG THỐNG KÊ CỐT THÉP CHI TIẾT (BBS) & QUY ĐỔI 1M DÀI
A31: SỐ HIỆU | B31: LOẠI THÉP / VỊ TRÍ | C31: ĐƯỜNG KÍNH (mm) | D31: SỐ LƯỢNG (thanh) | E31: DÀI 1 THANH (m) | F31: TỔNG DÀI ĐỐT (m) | G31: TRỌNG LƯỢNG ĐƠN VỊ (kg/m) | H31: TỔNG TRỌNG LƯỢNG ĐỐT (kg) | I31: QUY ĐỔI 1M DÀI (kg/m) | J31: GHI CHÚ
A32: 1 | B32: Thép ngang nắp/đáy 2 khoang (Dưới đường a125) | C32: 14 | D32: 180 | E32: 9.37 | F32: =D32*E32 | G32: 1.208 | H32: =F32*G32 | I32: =H32/11.3 | J32: Dưới đường (2x90 thanh)
A33: 1a | B33: Thép ngang nắp/đáy 2 khoang (Vỉa hè a250) | C33: 14 | D33: 90 | E33: 9.37 | F33: =D33*E33 | G33: 1.208 | H33: =F33*G33 | I33: =H33/11.3 | J33: Vỉa hè (2x45 thanh)
A34: 2 | B34: Thép vách biên ngoài (Dưới đường a125) | C34: 14 | D34: 180 | E34: 4.02 | F34: =D34*E34 | G34: 1.208 | H34: =F34*G34 | I34: =H34/11.3 | J34: Dưới đường (2x90 thanh)
A35: 2a | B35: Thép vách biên ngoài (Vỉa hè a250) | C35: 14 | D35: 90 | E35: 4.02 | F35: =D35*E35 | G35: 1.208 | H35: =F35*G35 | I35: =H35/11.3 | J35: Vỉa hè (2x45 thanh)
A36: 3 | B36: Thép vách giữa ngăn đôi | C36: 14 | D36: 90 | E36: 3.9 | F36: =D36*E36 | G36: 1.208 | H36: =F36*G36 | I36: =H36/11.3 | J36: Dùng chung (2x45 thanh a250)
A37: 4 | B37: Thép nách vát góc ngoài | C37: 14 | D37: 180 | E37: 2 | F37: =D37*E37 | G37: 1.208 | H37: =F37*G37 | I37: =H37/11.3 | J37: Dùng chung (4x45 thanh a250)
A38: 4a | B38: Thép nách vát góc trong vách giữa | C38: 14 | D38: 90 | E38: 1.95 | F38: =D38*E38 | G38: 1.208 | H38: =F38*G38 | I38: =H38/11.3 | J38: Dùng chung (2x45 thanh a250)
A39: 5 | B39: Thép dọc cống phân bố a200 | C39: 10 | D39: 234 | E39: 11.7 | F39: =D39*E39 | G39: 0.617 | H39: =F39*G39 | I39: =H39/11.3 | J39: Dùng chung (234 thanh suốt đốt)
A40: 6 | B40: Thép đai C liên kết vách giữa | C40: 10 | D40: 114 | E40: 0.92 | F40: =D40*E40 | G40: 0.617 | H40: =F40*G40 | I40: =H40/11.3 | J40: Dùng chung (114 thanh a600)
A41: 7 | B41: Thép móc đai nách | C41: 6 | D41: 228 | E41: 0.35 | F41: =D41*E41 | G41: 0.222 | H41: =F41*G41 | I41: =H41/11.3 | J41: Dùng chung (3x76 thanh a600)
A42: 8 | B42: Thép dowel bar khe co giãn | C42: 22 | D42: 42 | E42: 1 | F42: =D42*E42 | G42: 2.984 | H42: =F42*G42 | I42: =H42/11.3 | J42: Dùng chung (bọc PVC bôi mỡ)
B44: TỔNG KHỐI LƯỢNG THÉP - KỊCH BẢN DƯỚI ĐƯỜNG (HL93) | H44: =SUMIF(J32:J42, "<>*Vỉa hè*", H32:H42) | I44: =H44/11.3 | J44: kg/m dài cống dưới đường
B45: TỔNG KHỐI LƯỢNG THÉP - KỊCH BẢN TRÊN VỈA HÈ (125kN) | H45: =SUMIF(J32:J42, "<>*Dưới đường*", H32:H42) | I45: =H45/11.3 | J45: kg/m dài cống trên vỉa hè
B47: GIÁ TRỊ QUY ĐỔI 1M DÀI PHỤC VỤ LINK SHEET TỔNG HỢP:
B48: THÉP DƯỚI ĐƯỜNG (kg/m): | H48: =I44
...

Sheet THONG_KE_TUYEN_A5
A1: BẢNG THỐNG KÊ PHÂN ĐOẠN CỐNG HỘP & CHIỀU CAO CỔ GA TUYẾN A5
A2: Trích xuất từ các bản vẽ: OLP_SD_KC_HT_CH_23, CH_24, CH_25, CH_26
A4: STT | B4: PHẠM VI ĐOẠN TUYẾN | C4: SỐ HIỆU GA BẮT ĐẦU - KẾT THÚC | D4: SỐ LƯỢNG GA | E4: QUY CÁCH CỐNG (BxH) | F4: CHIỀU DÀI DỰ KIẾN (m) | G4: TỶ TRỌNG (%) | H4: CAO ĐỘ ĐÁY THAY ĐỔI (m) | I4: BẢN VẼ CHI TIẾT
A5: 1 | B5: Đoạn 1 - Tuyến cống đơn 2x2 | C5: T5-a17 đến T5-a28 | D5: 12 | E5: 2.0 x 2.0 m | F5: 385 | G5: =F5/$F$8 | H5: +3.58m đến +3.47m | I5: CH_06 đến CH_08, CH_23
A6: 2 | B6: Đoạn 2 - Tuyến cống đơn 3x3 | C6: T5-a1 đến T5-a16, T5-a54 | D6: 17 | E6: 3.0 x 3.0 m | F6: 560 | G6: =F6/$F$8 | H6: +4.67m đến +4.58m | I6: CH_10 đến CH_12, CH_24
A7: 3 | B7: Đoạn 3 - Tuyến cống đôi 2x(3x3) | C7: T5-a53.1 đến T5-a90, T5-a119 | D7: 37 | E7: 2x(3.0 x 3.0) m | F7: 1225 | G7: =F7/$F$8 | H7: +5.11m đến +4.07m | I7: CH_13 đến CH_15, CH_25-26
B8: TỔNG CỘNG TOÀN TUYẾN A5 | C8: - | D8: =SUM(D5:D7) | E8: - | F8: =SUM(F5:F7) | G8: =SUM(G5:G7) | H8: - | I8: Hồ sơ Shop Drawing Tuyến A5
