Workbook

Sheet TO_HOP_CAT_THEP_11M7
B2: DỰ ÁN: ĐƯỜNG TỪ TRUNG TÂM HUYỆN ĐỒNG VĂN ĐI MỐC 450 (MỐC 456), HUYỆN MÈO VẠC, HÀ GIANG
B3: BẢNG TỔ HỢP CẮT THÉP CÂY NGUYÊN 11.7m (1D CUTTING STOCK) - CẦU THÔN KHAI HOANG 2, KM14+363.65
B4: Tối ưu hóa sơ đồ cắt thép, kiểm soát hao hụt đề-xê < 1.5% (Tiêu chuẩn TCVN 1651:2018)
A5: TT | B5: Cấu kiện sử dụng | C5: Ký hiệu đường kính (mm) | D5: Số lượng thanh (N) | E5: Dài 1 thanh L (m) | F5: Tổng chiều dài (m) | G5: Dài cây tiêu chuẩn (m) | H5: Số cây 11.7m cần dùng | I5: Chiều dài phôi (m) | J5: Đề-xê thừa (m) | K5: Tổng trọng lượng (kg) | L5: Tỷ lệ hao hụt (%)
A6: 1 | B6: Thép chủ dầm T15m A1/B1 (Dầm biên & dầm giữa) | C6: 32 | D6: =COUNTIFS(THONG_KE_THEP_CHI_TIET!$E$6:$E$399,32,THONG_KE_THEP_CHI_TIET!$B$6:$B$399,"*Dầm chủ T15m*") | E6: 17.32 | F6: =D6*E6 | G6: 11.7 | H6: =ROUNDUP(F6/G6,0) | I6: =H6*G6 | J6: =I6-F6 | K6: =F6*6.313 | L6: =J6/I6
A7: 2 | B7: Thép cấu tạo dầm T15m A2/A3 dọc cánh dầm | C7: 12 | D7: =COUNTIFS(THONG_KE_THEP_CHI_TIET!$E$6:$E$399,12,THONG_KE_THEP_CHI_TIET!$B$6:$B$399,"*Dầm chủ T15m*") | E7: 15.4 | F7: =D7*E7 | G7: 11.7 | H7: =ROUNDUP(F7/G7,0) | I7: =H7*G7 | J7: =I7-F7 | K7: =F7*0.888 | L7: =J7/I7
A8: 3 | B8: Thép đai chữ U dầm T15m C3 cánh và sườn | C8: 14 | D8: =COUNTIFS(THONG_KE_THEP_CHI_TIET!$E$6:$E$399,14,THONG_KE_THEP_CHI_TIET!$B$6:$B$399,"*Dầm chủ T15m*") | E8: 2.533 | F8: =D8*E8 | G8: 11.7 | H8: =ROUNDUP(F8/G8,0) | I8: =H8*G8 | J8: =I8-F8 | K8: =F8*1.208 | L8: =J8/I8
A9: 4 | B9: Thép sườn dầm T15m C4/C5 chịu cắt và uốn | C9: 16 | D9: =COUNTIFS(THONG_KE_THEP_CHI_TIET!$E$6:$E$399,16,THONG_KE_THEP_CHI_TIET!$B$6:$B$399,"*Dầm chủ T15m*") | E9: 1.85 | F9: =D9*E9 | G9: 11.7 | H9: =ROUNDUP(F9/G9,0) | I9: =H9*G9 | J9: =I9-F9 | K9: =F9*1.578 | L9: =J9/I9
A10: 5 | B10: Thép đai neo dầm T15m D1/E1/F1 liên kết bản | C10: 10 | D10: =COUNTIFS(THONG_KE_THEP_CHI_TIET!$E$6:$E$399,10,THONG_KE_THEP_CHI_TIET!$B$6:$B$399,"*Dầm chủ T15m*") | E10: 2.26 | F10: =D10*E10 | G10: 11.7 | H10: =ROUNDUP(F10/G10,0) | I10: =H10*G10 | J10: =I10-F10 | K10: =F10*0.617 | L10: =J10/I10
A11: 6 | B11: Thép khoan cấy neo vào nền đá móng mố M1, M2 | C11: 32 | D11: =COUNTIFS(THONG_KE_THEP_CHI_TIET!$E$6:$E$399,32,THONG_KE_THEP_CHI_TIET!$B$6:$B$399,"*Khoan cấy*") | E11: 0.5 | F11: =D11*E11 | G11: 11.7 | H11: =ROUNDUP(F11/G11,0) | I11: =H11*G11 | J11: =I11-F11 | K11: =F11*6.313 | L11: =J11/I11
A12: 7 | B12: Thép chịu lực chính thân mố M1, M2 W1/W1A | C12: 25 | D12: =COUNTIFS(THONG_KE_THEP_CHI_TIET!$E$6:$E$399,25,THONG_KE_THEP_CHI_TIET!$B$6:$B$399,"*Thân mố*") | E12: 9.467 | F12: =D12*E12 | G12: 11.7 | H12: =ROUNDUP(F12/G12,0) | I12: =H12*G12 | J12: =I12-F12 | K12: =F12*3.853 | L12: =J12/I12
A13: 8 | B13: Thép chịu lực tường cánh mố M1, M2 K1-K6 | C13: 22 | D13: =COUNTIFS(THONG_KE_THEP_CHI_TIET!$E$6:$E$399,22,THONG_KE_THEP_CHI_TIET!$B$6:$B$399,"*Tường cánh*") | E13: 9.496 | F13: =D13*E13 | G13: 11.7 | H13: =ROUNDUP(F13/G13,0) | I13: =H13*G13 | J13: =I13-F13 | K13: =F13*2.984 | L13: =J13/I13
A14: 9 | B14: Thép thân mố & bản quá độ W2/W3/A1 chịu lực | C14: 20 | D14: =COUNTIFS(THONG_KE_THEP_CHI_TIET!$E$6:$E$399,20,THONG_KE_THEP_CHI_TIET!$B$6:$B$399,"*Thân mố*") | E14: 8.29 | F14: =D14*E14 | G14: 11.7 | H14: =ROUNDUP(F14/G14,0) | I14: =H14*G14 | J14: =I14-F14 | K14: =F14*2.466 | L14: =J14/I14
A15: 10 | B15: Thép đai thân mố & tường cánh W4-W7/K8-K13 | C15: 16 | D15: =COUNTIFS(THONG_KE_THEP_CHI_TIET!$E$6:$E$399,16,THONG_KE_THEP_CHI_TIET!$B$6:$B$399,"*Thân mố*") | E15: 8.41 | F15: =D15*E15 | G15: 11.7 | H15: =ROUNDUP(F15/G15,0) | I15: =H15*G15 | J15: =I15-F15 | K15: =F15*1.578 | L15: =J15/I15
A16: 11 | B16: Thép chịu lực bản quá độ hai đầu cầu A2-A4 | C16: 14 | D16: =COUNTIFS(THONG_KE_THEP_CHI_TIET!$E$6:$E$399,14,THONG_KE_THEP_CHI_TIET!$B$6:$B$399,"*Bản quá độ*") | E16: 7.102 | F16: =D16*E16 | G16: 11.7 | H16: =ROUNDUP(F16/G16,0) | I16: =H16*G16 | J16: =I16-F16 | K16: =F16*1.208 | L16: =J16/I16
A17: 12 | B17: Thép gờ lan can dọc cầu L1/L2 trên nhịp & mố | C17: 14 | D17: =COUNTIFS(THONG_KE_THEP_CHI_TIET!$E$6:$E$399,14,THONG_KE_THEP_CHI_TIET!$B$6:$B$399,"*Gờ lan can*") | E17: 2.18 | F17: =D17*E17 | G17: 11.7 | H17: =ROUNDUP(F17/G17,0) | I17: =H17*G17 | J17: =I17-F17 | K17: =F17*1.208 | L17: =J17/I17
A18: 13 | B18: Thép gờ lan can dọc nhịp L3/L3' L=15m | C18: 12 | D18: =COUNTIFS(THONG_KE_THEP_CHI_TIET!$E$6:$E$399,12,THONG_KE_THEP_CHI_TIET!$B$6:$B$399,"*Gờ lan can*") | E18: 15 | F18: =D18*E18 | G18: 11.7 | H18: =ROUNDUP(F18/G18,0) | I18: =H18*G18 | J18: =I18-F18 | K18: =F18*0.888 | L18: =J18/I18
A19: 14 | B19: Lưới thép hàn bản mặt cầu B1/B2 chống nứt | C19: 6 | D19: =COUNTIFS(THONG_KE_THEP_CHI_TIET!$E$6:$E$399,6,THONG_KE_THEP_CHI_TIET!$B$6:$B$399,"*Lưới thép*") | E19: 15 | F19: =D19*E19 | G19: 11.7 | H19: =ROUNDUP(F19/G19,0) | I19: =H19*G19 | J19: =I19-F19 | K19: =F19*0.222 | L19: =J19/I19
B20: TỔNG CỘNG TOÀN CÔNG TRÌNH | D20: =SUM(D6:D19) | F20: =SUM(F6:F19) | H20: =SUM(H6:H19) | I20: =SUM(I6:I19) | J20: =SUM(J6:J19) | K20: =SUM(K6:K19) | L20: =J20/I20

Sheet KHOI_LUONG_DAO_DAP
B2: DỰ ÁN: ĐƯỜNG TỪ TRUNG TÂM HUYỆN ĐỒNG VĂN ĐI MỐC 450/456, HUYỆN MÈO VẠC, HÀ GIANG
B3: BẢNG TÍNH KHỐI LƯỢNG ĐÀO ĐẮP TRẮC NGANG (SHOELACE / AVERAGE END AREA) - PHẠM VI CẦU KM14+363.65
B4: Công thức tính thể tích: V = ((F1 + F2) / 2) * L (m3) - Khống chế sai số tích phân < 0.1%
A5: TT | B5: Tên cọc trắc ngang | C5: Lý trình (Km) | D5: Khoảng cách L (m) | E5: Diện tích Đào F1 (m2) | F5: Thể tích Đào V_đào (m3) | G5: Diện tích Đắp F2 (m2) | H5: Thể tích Đắp V_đắp (m3) | I5: Ghi chú phân loại địa chất
A6: 1 | B6: Cọc 401 | C6: Km14+330.78 | D6: 0 | E6: 32.4 | F6: =E6*D6 | G6: 4.2 | H6: =G6*D6 | I6: Đất cấp 3 lẫn đá tảng
A7: 2 | B7: Cọc 403 | C7: Km14+347.78 | D7: 17 | E7: 45.1 | F7: =((E6+E7)/2)*D7 | G7: 6.8 | H7: =((G6+G7)/2)*D7 | I7: Đào nền đường đầu cầu M1
A8: 3 | B8: Cọc 404 | C8: Km14+351.28 | D8: 3.5 | E8: 52.8 | F8: =((E7+E8)/2)*D8 | G8: 8.5 | H8: =((G7+G8)/2)*D8 | I8: Đào hố móng mố M1 nền đá
A9: 4 | B9: Cọc 406 | C9: Km14+356.93 | D9: 5.65 | E9: 35.41 | F9: =((E8+E9)/2)*D9 | G9: 12.4 | H9: =((G8+G9)/2)*D9 | I9: Đào mở rộng thượng lưu đá C3
A10: 5 | B10: Cọc 408 | C10: Km14+360.87 | D10: 3.94 | E10: 45.05 | F10: =((E9+E10)/2)*D10 | G10: 14.2 | H10: =((G9+G10)/2)*D10 | I10: Đào suối và lòng cầu
A11: 6 | B11: Cọc 409 | C11: Km14+363.35 | D11: 2.48 | E11: 58.2 | F11: =((E10+E11)/2)*D11 | G11: 18.5 | H11: =((G10+G11)/2)*D11 | I11: Tim cầu thôn Khai Hoang 2
A12: 7 | B12: Cọc 410A | C12: Km14+370.65 | D12: 7.3 | E12: 24.06 | F12: =((E11+E12)/2)*D12 | G12: 22.1 | H12: =((G11+G12)/2)*D12 | I12: Đào hố móng mố M2 nền đá
A13: 8 | B13: Cọc 410B | C13: Km14+389.05 | D13: 18.4 | E13: 18.5 | F13: =((E12+E13)/2)*D13 | G13: 28.6 | H13: =((G12+G13)/2)*D13 | I13: Đào nền đường đầu cầu M2
A14: 9 | B14: Cọc 411 | C14: Km14+400.00 | D14: 10.95 | E14: 14.2 | F14: =((E13+E14)/2)*D14 | G14: 16.5 | H14: =((G13+G14)/2)*D14 | I14: Đắp sau mố và tứ nón M2
A15: 10 | B15: Hố móng M1 | C15: Km14+354.00 | D15: 6 | E15: 48.6 | F15: =((E14+E15)/2)*D15 | G15: 25 | H15: =((G14+G15)/2)*D15 | I15: Đào đá hố móng mố M1
A16: 11 | B16: Hố móng M2 | C16: Km14+372.00 | D16: 6 | E16: 55.4 | F16: =((E15+E16)/2)*D16 | G16: 32 | H16: =((G15+G16)/2)*D16 | I16: Đào đá hố móng mố M2
A17: 12 | B17: Tường cánh M1 | C17: Km14+352.00 | D17: 5 | E17: 22.5 | F17: =((E16+E17)/2)*D17 | G17: 15 | H17: =((G16+G17)/2)*D17 | I17: Đào móng tường cánh
A18: 13 | B18: Tường cánh M2 | C18: Km14+374.00 | D18: 5 | E18: 24.8 | F18: =((E17+E18)/2)*D18 | G18: 18 | H18: =((G17+G18)/2)*D18 | I18: Đào móng tường cánh
... A20: 15 | B20: Rãnh biên M2 | C20: Km14+385.00 | D20: 10 | E20: 4.8 | F20: =((E19+E20)/2)*D20 | G20: 0 | H20: =((G19+G20)/2)*D20 | I20: Rãnh dọc thoát nước
B21: TỔNG CỘNG KHỐI LƯỢNG ĐÀO ĐẮP | F21: =SUM(F6:F20) | H21: =SUM(H6:H20) | I21: Trỏ trực tiếp sang QS!J33 và QS!J34

Sheet QS_DIEN_GIAI_CHI_TIET
B2: DỰ ÁN: ĐƯỜNG TỪ TRUNG TÂM HUYỆN ĐỒNG VĂN ĐI MỐC 450/456, HUYỆN MÈO VẠC, HÀ GIANG
B3: BẢNG BÓC TÁCH KHỐI LƯỢNG CHI TIẾT (QUANTITY TAKEOFF - QS) - CẦU THÔN KHAI HOANG 2
B4: 100% Công thức động: Số lượng x Dài x Rộng x Cao x Hệ số - ZERO DEAD NUMBERS
A5: Mã hiệu | B5: Số TT | C5: Nội dung công tác & Diễn giải hình học | D5: Đơn vị | E5: Số lượng (N) | F5: Chiều dài L (m) | G5: Chiều rộng W (m) | H5: Chiều cao H (m) | I5: Hệ số (k) | J5: Khối lượng QS | K5: Đơn giá (VNĐ) | L5: Thành tiền (VNĐ) | M5: Ghi chú
C6: PHẦN I: ĐƯỜNG HAI ĐẦU CẦU VÀ NỀN MẶT ĐƯỜNG
A7: AB.11111 | B7: 1 | C7: Đào nền đường đất cấp 3 hai đầu cầu | D7: m3 | J7: =SUM(J8:J8) | K7: 45000 | L7: =J7*K7 | M7: Đất đồi dốc đá
C8: - Đoạn đầu cầu Km14+330.78 đến Km14+354.00 | D8: m3 | E8: 1 | F8: 23.22 | G8: 12 | H8: 3.25 | I8: 2 | J8: =E8*F8*G8*H8*I8 | M8: Đào đất C3
A9: AB.11122 | B9: 2 | C9: Đào nền đường đá cấp 3 hai đầu cầu | D9: m3 | J9: =SUM(J10:J10) | K9: 185000 | L9: =J9*K9 | M9: Phá đá nổ mìn/máy
C10: - Đoạn đầu cầu Km14+354.00 đến Km14+389.05 | D10: m3 | E10: 1 | F10: 35.05 | G10: 12 | H10: 3.335 | I10: 2 | J10: =E10*F10*G10*H10*I10 | M10: Đá vôi phân lớp
A11: AB.11133 | B11: 3 | C11: Đào hố móng mố M1, M2 trên cạn (Đất đá C3) | D11: m3 | J11: =SUM(J12:J12) | K11: 145000 | L11: =J11*K11 | M11: Hố móng mố
C12: - Đào đất đá hố móng mố M1, M2 trắc ngang | D12: m3 | J12: =KHOI_LUONG_DAO_DAP!F21*0.27 | M12: Link đào đắp
A13: AB.11144 | B13: 4 | C13: Đắp đất chọn lọc K>=0.95 sau mố và tứ nón | D13: m3 | J13: =SUM(J14:J14) | K13: 125000 | L13: =J13*K13 | M13: Đất đắp đầm chặt
C14: - Đắp sau mố M1, M2 và tứ nón đường dẫn | D14: m3 | J14: =KHOI_LUONG_DAO_DAP!F21*0.27 | M14: Link đào đắp
A15: AD.11211 | B15: 5 | C15: Mặt đường đá dăm nước dày 24cm (2 lớp) | D15: m2 | J15: =SUM(J16:J16) | K15: 165000 | L15: =J15*K15 | M15: Mặt đường
C16: - Chiều dài đoạn vuốt nối 2 đầu cầu | D16: m2 | E16: 1 | F16: 47.9 | G16: 7 | H16: 1 | I16: 1 | J16: =E16*F16*G16*H16*I16 | M16: Đá dăm 2 lớp
A17: AD.11222 | B17: 6 | C17: Mặt đường láng nhựa 4.5kg/m2 dày 3.5cm | D17: m2 | J17: =SUM(J18:J18) | K17: 95000 | L17: =J17*K17 | M17: Láng nhựa
C18: - Mặt đường láng nhựa trên lớp đá dăm | D18: m2 | E18: 1 | F18: 47.9 | G18: 7 | H18: 1 | I18: 1 | J18: =E18*F18*G18*H18*I18 | M18: Láng nhựa 3 lớp
C19: PHẦN II: KẾT CẤU PHẦN DƯỚI (MỐ CẦU M1 & M2)
A20: AF.12111 | B20: 7 | C20: Khoan cấy thép neo D32 vào nền đá (h=50cm) | D20: lỗ | J20: =SUM(J21:J21) | K20: 220000 | L20: =J20*K20 | M20: 98 lỗ khoan neo
C21: - Lỗ khoan cấy cốt thép neo móng mố M1, M2 | D21: lỗ | E21: 2 | F21: 49 | G21: 1 | H21: 1 | I21: 1 | J21: =E21*F21*G21*H21*I21 | M21: 49 lỗ/mố
A22: AF.12122 | B22: 8 | C22: Cốt thép liên kết neo cấy đá D32 (Tấn) | D22: Tấn | J22: =SUM(J23:J23) | K22: 21500000 | L22: =J22*K22 | M22: Thép CB400-V
C23: - Khối lượng thép neo D32 trích xuất từ BBS | D23: Tấn | J23: =SUMIFS(THONG_KE_THEP_CHI_TIET!$O$6:$O$399, THONG_KE_THEP_CHI_TIET!$B$6:$B$399, "*Khoan cấy*") | M23: BBS khoan cấy
A24: AF.12211 | B24: 9 | C24: Bê tông đệm móng mố C10 (M150) dày 10cm | D24: m3 | J24: =SUM(J25:J25) | K24: 1050000 | L24: =J24*K24 | M24: Bê tông lót
C25: - Lớp bê tông lót đáy móng mố M1 và M2 | D25: m3 | E25: 2 | F25: 8.5 | G25: 5.5 | H25: 0.1 | I25: 1 | J25: =E25*F25*G25*H25*I25 | M25: 2 móng mố
A26: AF.12222 | B26: 10 | C26: Bê tông móng mố C30 (M350) | D26: m3 | J26: =SUM(J27:J27) | K26: 1850000 | L26: =J26*K26 | M26: Bê tông móng
C27: - Khối bê tông móng mố M1 và M2 | D27: m3 | E27: 2 | F27: 8 | G27: 5 | H27: 2.75 | I27: 1 | J27: =E27*F27*G27*H27*I27 | M27: 2 khối móng
A28: AF.12233 | B28: 11 | C28: Bê tông thân mố và tường cánh C30 (M350) | D28: m3 | J28: =SUM(J29:J29) | K28: 1920000 | L28: =J28*K28 | M28: Bê tông thân
C29: - Thân mố, tường ngực và tường cánh M1, M2 | D29: m3 | E29: 2 | F29: 8 | G29: 1.8 | H29: 5.88 | I29: 1 | J29: =E29*F29*G29*H29*I29 | M29: 2 mố cầu
A30: AF.12311 | B30: 12 | C30: Cốt thép mố M1, M2 đường kính D<=10mm (Tấn) | D30: Tấn | J30: =SUM(J31:J31) | K30: 21000000 | L30: =J30*K30 | M30: Thép CB240-T
C31: - Cốt thép D<=10 mố M1, M2 từ BBS | D31: Tấn | J31: =SUMIFS(THONG_KE_THEP_CHI_TIET!$O$6:$O$399, THONG_KE_THEP_CHI_TIET!$B$6:$B$399, "*Mố*", THONG_KE_THEP_CHI_TIET!$E$6:$E$399, "<=10") | M31: BBS D<=10
A32: AF.12322 | B32: 13 | C32: Cốt thép mố M1, M2 đường kính 10<D<=18mm (Tấn) | D32: Tấn | J32: =SUM(J33:J33) | K32: 20500000 | L32: =J32*K32 | M32: Thép CB400-V
C33: - Cốt thép 10<D<=18 mố M1, M2 từ BBS | D33: Tấn | J33: =SUMIFS(THONG_KE_THEP_CHI_TIET!$O$6:$O$399, THONG_KE_THEP_CHI_TIET!$B$6:$B$399, "*Mố*", THONG_KE_THEP_CHI_TIET!$E$6:$E$399, ">10", THONG_KE_THEP_CHI_TIET!$E$6:$E$399, "<=18") | M33: BBS 10<D<=18
A34: AF.12333 | B34: 14 | C34: Cốt thép mố M1, M2 đường kính D>18mm (Tấn) | D34: Tấn | J34: =SUM(J35:J35) | K34: 20200000 | L34: =J34*K34 | M34: Thép CB400-V
C35: - Cốt thép D>18 mố M1, M2 từ BBS | D35: Tấn | J35: =SUMIFS(THONG_KE_THEP_CHI_TIET!$O$6:$O$399, THONG_KE_THEP_CHI_TIET!$B$6:$B$399, "*Mố*", THONG_KE_THEP_CHI_TIET!$E$6:$E$399, ">18") | M35: BBS D>18
A36: AF.12411 | B36: 15 | C36: Ván khuôn móng và thân mố M1, M2 | D36: m2 | J36: =SUM(J37:J37) | K36: 280000 | L36: =J36*K36 | M36: Ván khuôn thép
C37: - Diện tích ván khuôn tiếp xúc bê tông mố | D37: m2 | E37: 2 | F37: 27.6 | G37: 10.225 | H37: 1 | I37: 1 | J37: =E37*F37*G37*H37*I37 | M37: Thân và tường cánh
C38: PHẦN III: KẾT CẤU PHẦN TRÊN (DẦM T15M & PHỤ TRỢ)
A39: AG.13111 | B39: 16 | C39: Bê tông dầm chủ T15m mác C40 (M500) | D39: m3 | J39: =SUM(J40:J40) | K39: 2250000 | L39: =J39*K39 | M39: Bê tông dầm C40
C40: - Thể tích 4 phiến dầm T15m (2 biên + 2 giữa) | D40: m3 | E40: 4 | F40: 15 | G40: 1.65 | H40: 0.374 | I40: 1 | J40: =E40*F40*G40*H40*I40 | M40: 4 phiến dầm
A41: AG.13211 | B41: 17 | C41: Cốt thép dầm chủ T15m đường kính D<=10mm (Tấn) | D41: Tấn | J41: =SUM(J42:J42) | K41: 21000000 | L41: =J41*K41 | M41: Thép dầm D<=10
...

Sheet THONG_KE_THEP_CHI_TIET
B2: DỰ ÁN: ĐƯỜNG TỪ TRUNG TÂM HUYỆN ĐỒNG VĂN ĐI MỐC 450/456, HUYỆN MÈO VẠC, HÀ GIANG
B3: BẢNG THỐNG KÊ CỐT THÉP CHI TIẾT (BAR BENDING SCHEDULE - BBS) - CẦU THÔN KHAI HOANG 2
B4: Chi tiết từng số hiệu thanh, hình dáng uốn, đường kính, số lượng và chiều dài (TCVN 1651:2018)
A5: STT | B5: Hạng mục cấu kiện | C5: Vị trí lắp đặt | D5: Ký hiệu thanh | E5: Đường kính Ø (mm) | F5: Hình dạng uốn thanh | G5: Số cấu kiện | H5: Số thanh / CK | I5: Tổng số thanh (N) | J5: Dài 1 đoạn (mm) | K5: Dài nối buộc (mm) | L5: Chiều dài 1 thanh L (m) | M5: Trọng lượng đơn vị (kg/m) | N5: Khối lượng cốt thép (kg) | O5: Khối lượng cốt thép (Tấn) | P5: Ghi chú
A6: 1 | B6: Dầm chủ T15m | C6: Dầm biên L=15m | D6: A1 | E6: 32 | F6: Thẳng có móc | G6: 2 | H6: 5 | I6: =G6*H6 | J6: 15280 | K6: 0 | L6: =(J6+K6)/1000 | M6: 6.313 | N6: =I6*L6*M6 | O6: =N6/1000 | P6: Thép chủ dầm biên
A7: 2 | B7: Dầm chủ T15m | C7: Dầm biên L=15m | D7: A2 | E7: 12 | F7: Thẳng | G7: 2 | H7: 10 | I7: =G7*H7 | J7: 14500 | K7: 0 | L7: =(J7+K7)/1000 | M7: 0.888 | N7: =I7*L7*M7 | O7: =N7/1000 | P7: Thép dọc cánh biên
A8: 3 | B8: Dầm chủ T15m | C8: Dầm biên L=15m | D8: A3 | E8: 12 | F8: Thẳng | G8: 2 | H8: 18 | I8: =G8*H8 | J8: 15400 | K8: 0 | L8: =(J8+K8)/1000 | M8: 0.888 | N8: =I8*L8*M8 | O8: =N8/1000 | P8: Thép dọc cánh biên
A9: 4 | B9: Dầm chủ T15m | C9: Dầm biên L=15m | D9: B1 | E9: 32 | F9: Uốn đầu | G9: 2 | H9: 8 | I9: =G9*H9 | J9: 17320 | K9: 0 | L9: =(J9+K9)/1000 | M9: 6.313 | N9: =I9*L9*M9 | O9: =N9/1000 | P9: Thép chịu kéo dầm biên
A10: 5 | B10: Dầm chủ T15m | C10: Dầm biên L=15m | D10: C1 | E10: 10 | F10: Chữ U | G10: 2 | H10: 12 | I10: =G10*H10 | J10: 1280 | K10: 0 | L10: =(J10+K10)/1000 | M10: 0.617 | N10: =I10*L10*M10 | O10: =N10/1000 | P10: Thép đai móc
A11: 6 | B11: Dầm chủ T15m | C11: Dầm biên L=15m | D11: C2 | E11: 14 | F11: Chữ L | G11: 2 | H11: 4 | I11: =G11*H11 | J11: 1946 | K11: 0 | L11: =(J11+K11)/1000 | M11: 1.208 | N11: =I11*L11*M11 | O11: =N11/1000 | P11: Thép đai tăng cường
A12: 7 | B12: Dầm chủ T15m | C12: Dầm biên L=15m | D12: C3 | E12: 14 | F12: Chữ U kín | G12: 2 | H12: 300 | I12: =G12*H12 | J12: 2228 | K12: 0 | L12: =(J12+K12)/1000 | M12: 1.208 | N12: =I12*L12*M12 | O12: =N12/1000 | P12: Đai sườn dầm biên
A13: 8 | B13: Dầm chủ T15m | C13: Dầm biên L=15m | D13: C4 | E13: 16 | F13: Thẳng | G13: 2 | H13: 30 | I13: =G13*H13 | J13: 1504 | K13: 0 | L13: =(J13+K13)/1000 | M13: 1.578 | N13: =I13*L13*M13 | O13: =N13/1000 | P13: Thép giá dầm biên
A14: 9 | B14: Dầm chủ T15m | C14: Dầm biên L=15m | D14: C5 | E14: 16 | F14: Móc chữ C | G14: 2 | H14: 196 | I14: =G14*H14 | J14: 331 | K14: 0 | L14: =(J14+K14)/1000 | M14: 1.578 | N14: =I14*L14*M14 | O14: =N14/1000 | P14: Thép móc đai
A15: 10 | B15: Dầm chủ T15m | C15: Dầm biên L=15m | D15: D1 | E15: 10 | F15: Chữ U | G15: 2 | H15: 102 | I15: =G15*H15 | J15: 2260 | K15: 0 | L15: =(J15+K15)/1000 | M15: 0.617 | N15: =I15*L15*M15 | O15: =N15/1000 | P15: Thép đai cánh dầm
A16: 11 | B16: Dầm chủ T15m | C16: Dầm biên L=15m | D16: E1 | E16: 10 | F16: Thẳng | G16: 2 | H16: 112 | I16: =G16*H16 | J16: 1372 | K16: 0 | L16: =(J16+K16)/1000 | M16: 0.617 | N16: =I16*L16*M16 | O16: =N16/1000 | P16: Thép phân bố bản
A17: 12 | B17: Dầm chủ T15m | C17: Dầm biên L=15m | D17: E2 | E17: 12 | F17: Thẳng | G17: 2 | H17: 150 | I17: =G17*H17 | J17: 1786 | K17: 0 | L17: =(J17+K17)/1000 | M17: 0.888 | N17: =I17*L17*M17 | O17: =N17/1000 | P17: Thép bản cánh dầm
... A60: 55 | B60: Lưới thép mặt cầu | C60: Lớp phủ mặt cầu C35 | D60: B2 | E60: 6 | F60: Lưới thép ngang | G60: 1 | H60: 300 | I60: =G60*H60 | J60: 6900 | K60: 0 | L60: =(J60+K60)/1000 | M60: 0.222 | N60: =I60*L60*M60 | O60: =N60/1000 | P60: Lưới thép D6 ngang cầu
B61: TỔNG CỘNG KHỐI LƯỢNG CỐT THÉP TOÀN CẦU | I61: =SUM(I6:I60) | N61: =SUM(N6:N60) | O61: =SUM(O6:O60)

Sheet CAP_PHOI_1M3_VA_TAN_SUAT
B2: DỰ ÁN: ĐƯỜNG TỪ TRUNG TÂM HUYỆN ĐỒNG VĂN ĐI MỐC 450/456, HUYỆN MÈO VẠC, HÀ GIANG
B3: BẢNG 1: CẤP PHỐI ĐỊNH MỨC 1m3 BÊ TÔNG & BẢNG 2: MA TRẬN TẦN SUẤT THÍ NGHIỆM KCS
B4: Liên kết động: Khối lượng QS -> Vật liệu thành phần -> Tần suất tổ mẫu KCS (TCVN 3105 & TCVN 11823)
B6: I. BẢNG TÍNH CẤP PHỐI ĐỊNH MỨC 1M3 BÊ TÔNG VÀ TỔNG HỢP VẬT LIỆU CẤU THÀNH
A8: STT | B8: Hạng mục kết cấu sử dụng | C8: Mác bê tông | D8: Độ sụt (cm) | E8: Xi măng PCB40 (kg/m3) | F8: Cát vàng (m3/m3) | G8: Đá 1x2 (m3/m3) | H8: Nước sạch (L/m3) | I8: Phụ gia (L/m3) | J8: Tổng KL bê tông (m3) | K8: Xi măng tổng (Tấn) | L8: Cát vàng tổng (m3) | M8: Đá 1x2 tổng (m3) | N8: Nước tổng (m3) | O8: Phụ gia tổng (Lít)
A9: 1 | B9: Bê tông lót đáy móng mố M1, M2 | C9: C10 (M150) | D9: 6 - 8 | E9: 245 | F9: 0.52 | G9: 0.88 | H9: 185 | I9: 0 | J9: =QS_DIEN_GIAI_CHI_TIET!J20 | K9: =J9*E9/1000 | L9: =J9*F9 | M9: =J9*G9 | N9: =J9*H9/1000 | O9: =J9*I9
A10: 2 | B10: Bê tông bản quá độ & gờ lan can | C10: C25 (M300) | D10: 10 - 12 | E10: 365 | F10: 0.47 | G10: 0.86 | H10: 175 | I10: 2.5 | J10: =QS_DIEN_GIAI_CHI_TIET!J38*0.5 + QS_DIEN_GIAI_CHI_TIET!J50 | K10: =J10*E10/1000 | L10: =J10*F10 | M10: =J10*G10 | N10: =J10*H10/1000 | O10: =J10*I10
A11: 3 | B11: Bê tông móng mố M1, M2 trên nền đá | C11: C30 (M350) | D11: 12 - 14 | E11: 395 | F11: 0.46 | G11: 0.85 | H11: 170 | I11: 3.2 | J11: =QS_DIEN_GIAI_CHI_TIET!J22 | K11: =J11*E11/1000 | L11: =J11*F11 | M11: =J11*G11 | N11: =J11*H11/1000 | O11: =J11*I11
A12: 4 | B12: Bê tông thân mố, tường cánh M1, M2 | C12: C30 (M350) | D12: 12 - 14 | E12: 410 | F12: 0.45 | G12: 0.84 | H12: 168 | I12: 3.5 | J12: =QS_DIEN_GIAI_CHI_TIET!J24 | K12: =J12*E12/1000 | L12: =J12*F12 | M12: =J12*G12 | N12: =J12*H12/1000 | O12: =J12*I12
A13: 5 | B13: Bê tông dầm ngang liên kết nhịp | C13: C30 (M350) | D13: 14 - 16 | E13: 415 | F13: 0.44 | G13: 0.84 | H13: 165 | I13: 3.8 | J13: =QS_DIEN_GIAI_CHI_TIET!J38*0.5 | K13: =J13*E13/1000 | L13: =J13*F13 | M13: =J13*G13 | N13: =J13*H13/1000 | O13: =J13*I13
A14: 6 | B14: Bê tông lớp phủ mặt cầu chống thấm | C14: C35 (M450) | D14: 12 - 14 | E14: 435 | F14: 0.43 | G14: 0.83 | H14: 160 | I14: 4.2 | J14: =QS_DIEN_GIAI_CHI_TIET!J44 | K14: =J14*E14/1000 | L14: =J14*F14 | M14: =J14*G14 | N14: =J14*H14/1000 | O14: =J14*I14
A15: 7 | B15: Bê tông dầm chủ T15m đúc sẵn | C15: C40 (M500) | D15: 16 - 18 | E15: 460 | F15: 0.42 | G15: 0.82 | H15: 155 | I15: 5 | J15: =QS_DIEN_GIAI_CHI_TIET!J28 | K15: =J15*E15/1000 | L15: =J15*F15 | M15: =J15*G15 | N15: =J15*H15/1000 | O15: =J15*I15
A16: 8 | B16: Bê tông tường chắn đất đầu cầu | C16: C25 (M300) | D16: 10 - 12 | E16: 365 | F16: 0.47 | G16: 0.86 | H16: 175 | I16: 2.5 | J16: =QS_DIEN_GIAI_CHI_TIET!J58 | K16: =J16*E16/1000 | L16: =J16*F16 | M16: =J16*G16 | N16: =J16*H16/1000 | O16: =J16*I16
A17: 9 | B17: Vữa không co ngót chèn khe co giãn | C17: C50 (M600) | D17: Chảy | E17: 550 | F17: 0.38 | G17: 0.75 | H17: 140 | I17: 6.5 | J17: =QS_DIEN_GIAI_CHI_TIET!J54 | K17: =J17*E17/1000 | L17: =J17*F17 | M17: =J17*G17 | N17: =J17*H17/1000 | O17: =J17*I17
B18: TỔNG CỘNG TOÀN CÔNG TRÌNH | J18: =SUM(J9:J17) | K18: =SUM(K9:K17) | L18: =SUM(L9:L17) | M18: =SUM(M9:M17) | N18: =SUM(N9:N17) | O18: =SUM(O9:O17)
B21: II. MA TRẬN TẦN SUẤT LẤY MẪU THÍ NGHIỆM KCS (TCVN 3105:2022 & TCVN 11823:2017)
A23: Mã VT | B23: Tên chỉ tiêu / Vật liệu thí nghiệm | C23: Tiêu chuẩn áp dụng | D23: Chỉ tiêu kỹ thuật kiểm tra | E23: Đối tượng / Kết cấu | F23: Đơn vị tính | G23: Tổng KL công trình | H23: Định mức tần suất (KL/tổ mẫu) | I23: Số tổ mẫu thí nghiệm | J23: Quy cách tổ mẫu thí nghiệm | K23: Đơn vị thực hiện | L23: Điều kiện nghiệm thu
A24: 1 | B24: Cốt thép tròn trơn D<=10mm | C24: TCVN 1651-1:2018 | D24: Kéo, uốn, hình học | E24: Dầm T, gờ lan can | F24: Tấn | G24: =SUMIFS(THONG_KE_THEP_CHI_TIET!$O$6:$O$399, THONG_KE_THEP_CHI_TIET!$E$6:$E$399, "<=10") | H24: 20 | I24: =ROUNDUP(G24/H24, 0) | J24: 3 mẫu kéo + 3 mẫu uốn | K24: LAS-XD | L24: Chấp thuận trước khi gia công
A25: 2 | B25: Cốt thép thanh vằn D12mm | C25: TCVN 1651-2:2018 | D25: Giới hạn chảy, bền, uốn | E25: Dầm T, gờ lan can | F25: Tấn | G25: =SUMIFS(THONG_KE_THEP_CHI_TIET!$O$6:$O$399, THONG_KE_THEP_CHI_TIET!$E$6:$E$399, "12") | H25: 20 | I25: =ROUNDUP(G25/H25, 0) | J25: 3 mẫu kéo + 3 mẫu uốn | K25: LAS-XD | L25: Chấp thuận trước khi gia công
A26: 3 | B26: Cốt thép thanh vằn D14mm | C26: TCVN 1651-2:2018 | D26: Giới hạn chảy, bền, uốn | E26: Dầm T, bản quá độ | F26: Tấn | G26: =SUMIFS(THONG_KE_THEP_CHI_TIET!$O$6:$O$399, THONG_KE_THEP_CHI_TIET!$E$6:$E$399, "14") | H26: 20 | I26: =ROUNDUP(G26/H26, 0) | J26: 3 mẫu kéo + 3 mẫu uốn | K26: LAS-XD | L26: Chấp thuận trước khi gia công
A27: 4 | B27: Cốt thép thanh vằn D16mm | C27: TCVN 1651-2:2018 | D27: Giới hạn chảy, bền, uốn | E27: Dầm T, mố M1, M2 | F27: Tấn | G27: =SUMIFS(THONG_KE_THEP_CHI_TIET!$O$6:$O$399, THONG_KE_THEP_CHI_TIET!$E$6:$E$399, "16") | H27: 20 | I27: =ROUNDUP(G27/H27, 0) | J27: 3 mẫu kéo + 3 mẫu uốn | K27: LAS-XD | L27: Chấp thuận trước khi gia công
A28: 5 | B28: Cốt thép thanh vằn D18mm | C28: TCVN 1651-2:2018 | D28: Giới hạn chảy, bền, uốn | E28: Dầm T, mố M1, M2 | F28: Tấn | G28: =SUMIFS(THONG_KE_THEP_CHI_TIET!$O$6:$O$399, THONG_KE_THEP_CHI_TIET!$E$6:$E$399, "18") | H28: 20 | I28: =ROUNDUP(G28/H28, 0) | J28: 3 mẫu kéo + 3 mẫu uốn | K28: LAS-XD | L28: Chấp thuận trước khi gia công
A29: 6 | B29: Cốt thép thanh vằn D20mm | C29: TCVN 1651-2:2018 | D29: Giới hạn chảy, bền, uốn | E29: Thân mố, bản quá độ | F29: Tấn | G29: =SUMIFS(THONG_KE_THEP_CHI_TIET!$O$6:$O$399, THONG_KE_THEP_CHI_TIET!$E$6:$E$399, "20") | H29: 20 | I29: =ROUNDUP(G29/H29, 0) | J29: 3 mẫu kéo + 3 mẫu uốn | K29: LAS-XD | L29: Chấp thuận trước khi gia công
A30: 7 | B30: Cốt thép thanh vằn D22mm | C30: TCVN 1651-2:2018 | D30: Giới hạn chảy, bền, uốn | E30: Tường cánh mố M1, M2 | F30: Tấn | G30: =SUMIFS(THONG_KE_THEP_CHI_TIET!$O$6:$O$399, THONG_KE_THEP_CHI_TIET!$E$6:$E$399, "22") | H30: 20 | I30: =ROUNDUP(G30/H30, 0) | J30: 3 mẫu kéo + 3 mẫu uốn | K30: LAS-XD | L30: Chấp thuận trước khi gia công
A31: 8 | B31: Cốt thép thanh vằn D25mm | C31: TCVN 1651-2:2018 | D31: Giới hạn chảy, bền, uốn | E31: Thân mố chịu lực | F31: Tấn | G31: =SUMIFS(THONG_KE_THEP_CHI_TIET!$O$6:$O$399, THONG_KE_THEP_CHI_TIET!$E$6:$E$399, "25") | H31: 20 | I31: =ROUNDUP(G31/H31, 0) | J31: 3 mẫu kéo + 3 mẫu uốn | K31: LAS-XD | L31: Chấp thuận trước khi gia công
A32: 9 | B32: Cốt thép thanh vằn D28mm | C32: TCVN 1651-2:2018 | D32: Giới hạn chảy, bền, uốn | E32: Móng mố M1, M2 | F32: Tấn | G32: =SUMIFS(THONG_KE_THEP_CHI_TIET!$O$6:$O$399, THONG_KE_THEP_CHI_TIET!$E$6:$E$399, "28") | H32: 20 | I32: =ROUNDUP(G32/H32, 0) | J32: 3 mẫu kéo + 3 mẫu uốn | K32: LAS-XD | L32: Chấp thuận trước khi gia công
A33: 10 | B33: Cốt thép thanh vằn D32mm | C33: TCVN 1651-2:2018 | D33: Giới hạn chảy, bền, uốn | E33: Chủ dầm T & neo cấy đá | F33: Tấn | G33: =SUMIFS(THONG_KE_THEP_CHI_TIET!$O$6:$O$399, THONG_KE_THEP_CHI_TIET!$E$6:$E$399, "32") | H33: 20 | I33: =ROUNDUP(G33/H33, 0) | J33: 3 mẫu kéo + 3 mẫu uốn | K33: LAS-XD | L33: Chấp thuận trước khi gia công
A34: 11 | B34: Thép hình & lan can mạ kẽm | C34: TCVN 5408:2007 | D34: Độ dày mạ, kéo uốn | E34: Lan can cầu & khe co giãn | F34: Tấn | G34: =1.27 | H34: 10 | I34: =ROUNDUP(G34/H34, 0) | J34: 3 mẫu ngẫu nhiên | K34: LAS-XD | L34: Đạt chiều dày mạ >= 100um
A35: 12 | B35: Xi măng Poóc lăng PCB40 | C35: TCVN 6260:2020 | D35: Độ mịn, thời gian đông kết, nén | E35: Toàn bộ bê tông | F35: Tấn | G35: =K18 | H35: 100 | I35: =ROUNDUP(G35/H35, 0) | J35: 1 tổ 3 mẫu/lô | K35: LAS-XD | L35: Chứng chỉ xuất xưởng + TN
A36: 13 | B36: Cát vàng đổ bê tông | C36: TCVN 7570:2006 | D36: Thành phần hạt, hàm lượng bùn sét | E36: Toàn bộ bê tông | F36: m3 | G36: =L18 | H36: 200 | I36: =ROUNDUP(G36/H36, 0) | J36: 1 tổ mẫu/mỏ | K36: LAS-XD | L36: Tạp chất < 1.5%
A37: 14 | B37: Đá dăm tiêu chuẩn 1x2 | C37: TCVN 7570:2006 | D37: Thành phần hạt, độ nén dập, thoi dẹt | E37: Toàn bộ bê tông | F37: m3 | G37: =M18 | H37: 200 | I37: =ROUNDUP(G37/H37, 0) | J37: 1 tổ mẫu/mỏ | K37: LAS-XD | L37: Độ thoi dẹt < 15%
A38: 15 | B38: Nước sạch trộn bê tông | C38: TCVN 4506:2012 | D38: Độ pH, tạp chất hữu cơ, muối | E38: Toàn bộ bê tông | F38: m3 | G38: =N18 | H38: 500 | I38: =ROUNDUP(G38/H38, 0) | J38: 1 mẫu/nguồn | K38: LAS-XD | L38: pH = 6 - 8
A39: 16 | B39: Phụ gia hóa học bê tông | C39: TCVN 8826:2011 | D39: Độ giảm nước, ăn mòn cốt thép | E39: Toàn bộ bê tông | F39: Lít | G39: =O18 | H39: 2000 | I39: =ROUNDUP(G39/H39, 0) | J39: 1 mẫu/lô | K39: LAS-XD | L39: Tương thích xi măng
A40: 17 | B40: Độ sụt bê tông tại hiện trường | C40: TCVN 3106:2022 | D40: Đo độ sụt từng xe bồn | E40: Tất cả các mẻ đổ | F40: Xe | G40: =ROUNDUP(J18/8,0) | H40: 1 | I40: =ROUNDUP(G40/H40, 0) | J40: 1 lần/xe bồn | K40: Hiện trường | L40: Đạt khoảng độ sụt thiết kế
A41: 18 | B41: Bê tông lót móng mố C10 | C41: TCVN 3105:2022 | D41: Cường độ nén R28 | E41: Lớp lót móng M1, M2 | F41: m3 | G41: =J9 | H41: 50 | I41: =ROUNDUP(G41/H41, 0) | J41: 1 tổ 3 viên (15x15x15) | K41: LAS-XD | L41: Đạt cường độ R28 >= 10 MPa
A42: 19 | B42: Bê tông móng mố M1, M2 C30 | C42: TCVN 3105:2022 | D42: Cường độ nén R7, R28 | E42: Khối móng mố M1, M2 | F42: m3 | G42: =J11 | H42: 50 | I42: =ROUNDUP(G42/H42, 0) | J42: 3 tổ (R7, R28, lưu) | K42: LAS-XD | L42: R28 >= 30 MPa
A43: 20 | B43: Bê tông thân mố, tường cánh C30 | C43: TCVN 3105:2022 | D43: Cường độ nén R7, R28 | E43: Thân mố M1, M2 | F43: m3 | G43: =J12 | H43: 50 | I43: =ROUNDUP(G43/H43, 0) | J43: 3 tổ (R7, R28, lưu) | K43: LAS-XD | L43: R28 >= 30 MPa
A44: 21 | B44: Bê tông dầm ngang C30 | C44: TCVN 3105:2022 | D44: Cường độ nén R7, R28 | E44: Dầm ngang nhịp 15m | F44: m3 | G44: =J13 | H44: 20 | I44: =ROUNDUP(G44/H44, 0) | J44: 2 tổ mẫu | K44: LAS-XD | L44: R28 >= 30 MPa
A45: 22 | B45: Bê tông dầm chủ T15m C40 | C45: TCVN 3105:2022 | D45: Cường độ nén R3, R7, R28 | E45: 4 phiến dầm T15m | F45: m3 | G45: =J15 | H45: 10 | I45: =ROUNDUP(G45/H45, 0) | J45: 4 tổ / phiến dầm | K45: LAS-XD | L45: Đạt 100% f'c trước khi cẩu
A46: 23 | B46: Bê tông lớp phủ mặt cầu C35 | C46: TCVN 3105:2022 | D46: Cường độ nén R7, R28 | E46: Bản mặt cầu | F46: m3 | G46: =J14 | H46: 50 | I46: =ROUNDUP(G46/H46, 0) | J46: 3 tổ mẫu | K46: LAS-XD | L46: R28 >= 35 MPa
...

Sheet PHAN_TICH_VAT_TU_WBS
B2: DỰ ÁN: ĐƯỜNG TỪ TRUNG TÂM HUYỆN ĐỒNG VĂN ĐI MỐC 450/456, HUYỆN MÈO VẠC, HÀ GIANG
B3: BẢNG PHÂN TÍCH NHU CẦU VẬT TƯ THEO CÔNG TÁC WBS (ĐỊNH MỨC BỘ XÂY DỰNG TT 12/2021/TT-BXD)
B4: Phân tích cấp phối vật liệu thành phần: Xi măng, cát, đá, nước, phụ gia, cốt thép, ván khuôn
A5: Mã công tác | B5: Tên công tác WBS | C5: Đơn vị tính | D5: Khối lượng công tác | E5: Mã vật tư | F5: Tên vật tư thành phần | G5: Đơn vị VT | H5: Định mức hao phí | I5: Khối lượng vật tư | J5: Ghi chú
A6: =QS_DIEN_GIAI_CHI_TIET!A20 | B6: =QS_DIEN_GIAI_CHI_TIET!C20 | C6: =QS_DIEN_GIAI_CHI_TIET!D20 | D6: =QS_DIEN_GIAI_CHI_TIET!J20 | E6: XM.PCB40 | F6: Xi măng PCB40 | G6: kg | H6: 420 | I6: =D6*H6 | J6: Định mức TT 12
A7: =QS_DIEN_GIAI_CHI_TIET!A20 | B7: =QS_DIEN_GIAI_CHI_TIET!C20 | C7: =QS_DIEN_GIAI_CHI_TIET!D20 | D7: =QS_DIEN_GIAI_CHI_TIET!J20 | E7: CAT.VANG | F7: Cát vàng đổ bê tông | G7: m3 | H7: 0.45 | I7: =D7*H7 | J7: Định mức TT 12
A8: =QS_DIEN_GIAI_CHI_TIET!A20 | B8: =QS_DIEN_GIAI_CHI_TIET!C20 | C8: =QS_DIEN_GIAI_CHI_TIET!D20 | D8: =QS_DIEN_GIAI_CHI_TIET!J20 | E8: DA.1X2 | F8: Đá dăm tiêu chuẩn 1x2 | G8: m3 | H8: 0.85 | I8: =D8*H8 | J8: Định mức TT 12
A9: =QS_DIEN_GIAI_CHI_TIET!A20 | B9: =QS_DIEN_GIAI_CHI_TIET!C20 | C9: =QS_DIEN_GIAI_CHI_TIET!D20 | D9: =QS_DIEN_GIAI_CHI_TIET!J20 | E9: NUOC | F9: Nước sạch trộn bê tông | G9: lít | H9: 175 | I9: =D9*H9 | J9: Định mức TT 12
A10: =QS_DIEN_GIAI_CHI_TIET!A20 | B10: =QS_DIEN_GIAI_CHI_TIET!C20 | C10: =QS_DIEN_GIAI_CHI_TIET!D20 | D10: =QS_DIEN_GIAI_CHI_TIET!J20 | E10: PHU.GIA | F10: Phụ gia siêu dẻo giảm nước | G10: lít | H10: 4.2 | I10: =D10*H10 | J10: Định mức TT 12
A11: =QS_DIEN_GIAI_CHI_TIET!A24 | B11: =QS_DIEN_GIAI_CHI_TIET!C24 | C11: =QS_DIEN_GIAI_CHI_TIET!D24 | D11: =QS_DIEN_GIAI_CHI_TIET!J24 | E11: THEP.D32 | F11: Thép tròn CB400-V D32 | G11: kg | H11: 1020 | I11: =D11*H11 | J11: Định mức TT 12
A12: =QS_DIEN_GIAI_CHI_TIET!A28 | B12: =QS_DIEN_GIAI_CHI_TIET!C28 | C12: =QS_DIEN_GIAI_CHI_TIET!D28 | D12: =QS_DIEN_GIAI_CHI_TIET!J28 | E12: XM.PCB40 | F12: Xi măng PCB40 | G12: kg | H12: 380 | I12: =D12*H12 | J12: Định mức TT 12
A13: =QS_DIEN_GIAI_CHI_TIET!A28 | B13: =QS_DIEN_GIAI_CHI_TIET!C28 | C13: =QS_DIEN_GIAI_CHI_TIET!D28 | D13: =QS_DIEN_GIAI_CHI_TIET!J28 | E13: CAT.VANG | F13: Cát vàng đổ bê tông | G13: m3 | H13: 0.48 | I13: =D13*H13 | J13: Định mức TT 12
A14: =QS_DIEN_GIAI_CHI_TIET!A28 | B14: =QS_DIEN_GIAI_CHI_TIET!C28 | C14: =QS_DIEN_GIAI_CHI_TIET!D28 | D14: =QS_DIEN_GIAI_CHI_TIET!J28 | E14: DA.1X2 | F14: Đá dăm tiêu chuẩn 1x2 | G14: m3 | H14: 0.88 | I14: =D14*H14 | J14: Định mức TT 12
A15: =QS_DIEN_GIAI_CHI_TIET!A30 | B15: =QS_DIEN_GIAI_CHI_TIET!C30 | C15: =QS_DIEN_GIAI_CHI_TIET!D30 | D15: =QS_DIEN_GIAI_CHI_TIET!J30 | E15: XM.PCB40 | F15: Xi măng PCB40 | G15: kg | H15: 395 | I15: =D15*H15 | J15: Định mức TT 12
A16: =QS_DIEN_GIAI_CHI_TIET!A30 | B16: =QS_DIEN_GIAI_CHI_TIET!C30 | C16: =QS_DIEN_GIAI_CHI_TIET!D30 | D16: =QS_DIEN_GIAI_CHI_TIET!J30 | E16: CAT.VANG | F16: Cát vàng đổ bê tông | G16: m3 | H16: 0.46 | I16: =D16*H16 | J16: Định mức TT 12
A17: =QS_DIEN_GIAI_CHI_TIET!A30 | B17: =QS_DIEN_GIAI_CHI_TIET!C30 | C17: =QS_DIEN_GIAI_CHI_TIET!D30 | D17: =QS_DIEN_GIAI_CHI_TIET!J30 | E17: DA.1X2 | F17: Đá dăm tiêu chuẩn 1x2 | G17: m3 | H17: 0.86 | I17: =D17*H17 | J17: Định mức TT 12
A18: =QS_DIEN_GIAI_CHI_TIET!A39 | B18: =QS_DIEN_GIAI_CHI_TIET!C39 | C18: =QS_DIEN_GIAI_CHI_TIET!D39 | D18: =QS_DIEN_GIAI_CHI_TIET!J39 | E18: XM.PCB40 | F18: Xi măng PCB40 | G18: kg | H18: 450 | I18: =D18*H18 | J18: Định mức TT 12
A19: =QS_DIEN_GIAI_CHI_TIET!A39 | B19: =QS_DIEN_GIAI_CHI_TIET!C39 | C19: =QS_DIEN_GIAI_CHI_TIET!D39 | D19: =QS_DIEN_GIAI_CHI_TIET!J39 | E19: CAT.VANG | F19: Cát vàng đổ bê tông | G19: m3 | H19: 0.44 | I19: =D19*H19 | J19: Định mức TT 12
A20: =QS_DIEN_GIAI_CHI_TIET!A39 | B20: =QS_DIEN_GIAI_CHI_TIET!C39 | C20: =QS_DIEN_GIAI_CHI_TIET!D39 | D20: =QS_DIEN_GIAI_CHI_TIET!J39 | E20: DA.1X2 | F20: Đá dăm tiêu chuẩn 1x2 | G20: m3 | H20: 0.84 | I20: =D20*H20 | J20: Định mức TT 12
A21: =QS_DIEN_GIAI_CHI_TIET!A39 | B21: =QS_DIEN_GIAI_CHI_TIET!C39 | C21: =QS_DIEN_GIAI_CHI_TIET!D39 | D21: =QS_DIEN_GIAI_CHI_TIET!J39 | E21: PHU.GIA | F21: Phụ gia siêu dẻo Sikament | G21: lít | H21: 5.5 | I21: =D21*H21 | J21: Định mức TT 12
A22: =QS_DIEN_GIAI_CHI_TIET!A41 | B22: =QS_DIEN_GIAI_CHI_TIET!C41 | C22: =QS_DIEN_GIAI_CHI_TIET!D41 | D22: =QS_DIEN_GIAI_CHI_TIET!J41 | E22: THEP.D10 | F22: Thép tròn CB240-T D<=10 | G22: kg | H22: 1020 | I22: =D22*H22 | J22: Định mức TT 12
A23: =QS_DIEN_GIAI_CHI_TIET!A43 | B23: =QS_DIEN_GIAI_CHI_TIET!C43 | C23: =QS_DIEN_GIAI_CHI_TIET!D43 | D23: =QS_DIEN_GIAI_CHI_TIET!J43 | E23: THEP.D14 | F23: Thép tròn CB400-V 10<D<=18 | G23: kg | H23: 1020 | I23: =D23*H23 | J23: Định mức TT 12
A24: =QS_DIEN_GIAI_CHI_TIET!A45 | B24: =QS_DIEN_GIAI_CHI_TIET!C45 | C24: =QS_DIEN_GIAI_CHI_TIET!D45 | D24: =QS_DIEN_GIAI_CHI_TIET!J45 | E24: THEP.D32 | F24: Thép tròn CB400-V D>18 | G24: kg | H24: 1020 | I24: =D24*H24 | J24: Định mức TT 12
A25: =QS_DIEN_GIAI_CHI_TIET!A53 | B25: =QS_DIEN_GIAI_CHI_TIET!C53 | C25: =QS_DIEN_GIAI_CHI_TIET!D53 | D25: =QS_DIEN_GIAI_CHI_TIET!J53 | E25: XM.PCB40 | F25: Xi măng PCB40 | G25: kg | H25: 410 | I25: =D25*H25 | J25: Định mức TT 12
A26: =QS_DIEN_GIAI_CHI_TIET!A53 | B26: =QS_DIEN_GIAI_CHI_TIET!C53 | C26: =QS_DIEN_GIAI_CHI_TIET!D53 | D26: =QS_DIEN_GIAI_CHI_TIET!J53 | E26: CAT.VANG | F26: Cát vàng đổ bê tông | G26: m3 | H26: 0.45 | I26: =D26*H26 | J26: Định mức TT 12
A27: =QS_DIEN_GIAI_CHI_TIET!A53 | B27: =QS_DIEN_GIAI_CHI_TIET!C53 | C27: =QS_DIEN_GIAI_CHI_TIET!D53 | D27: =QS_DIEN_GIAI_CHI_TIET!J53 | E27: DA.1X2 | F27: Đá dăm tiêu chuẩn 1x2 | G27: m3 | H27: 0.85 | I27: =D27*H27 | J27: Định mức TT 12

Sheet TONG_HOP_VAT_TU_TOAN_BO
B2: DỰ ÁN: ĐƯỜNG TỪ TRUNG TÂM HUYỆN ĐỒNG VĂN ĐI MỐC 450/456, HUYỆN MÈO VẠC, HÀ GIANG
B3: BẢNG TỔNG HỢP NHU CẦU VẬT TƯ TOÀN BỘ CÔNG TRÌNH (BILL OF MATERIALS - BOM)
B4: Tổng hợp tự động bằng hàm SUMIF từ PHAN_TICH_VAT_TU_WBS - Chuẩn hóa phục vụ cung ứng
A6: STT | B6: Mã vật tư | C6: Tên quy cách vật tư | D6: Đơn vị tính | E6: Tổng khối lượng nhu cầu | F6: Đơn giá dự toán (VNĐ) | G6: Thành tiền (VNĐ) | H6: Ghi chú
A7: 1 | B7: XM.PCB40 | C7: Xi măng Poóc lăng hỗn hợp PCB40 | D7: kg | E7: =SUMIF(PHAN_TICH_VAT_TU_WBS!$E$6:$E$27, "XM.PCB40", PHAN_TICH_VAT_TU_WBS!$I$6:$I$27) | F7: 1850 | G7: =E7*F7 | H7: Tổng hợp toàn cầu
A8: 2 | B8: CAT.VANG | C8: Cát vàng đổ bê tông mô đun độ lớn ML >= 2.5 | D8: m3 | E8: =SUMIF(PHAN_TICH_VAT_TU_WBS!$E$6:$E$27, "CAT.VANG", PHAN_TICH_VAT_TU_WBS!$I$6:$I$27) | F8: 380000 | G8: =E8*F8 | H8: Tổng hợp toàn cầu
A9: 3 | B9: DA.1X2 | C9: Đá dăm tiêu chuẩn 1x2 (Dmax = 20mm) | D9: m3 | E9: =SUMIF(PHAN_TICH_VAT_TU_WBS!$E$6:$E$27, "DA.1X2", PHAN_TICH_VAT_TU_WBS!$I$6:$I$27) | F9: 420000 | G9: =E9*F9 | H9: Tổng hợp toàn cầu
A10: 4 | B10: NUOC | C10: Nước sạch phục vụ trộn và bảo dưỡng bê tông | D10: lít | E10: =SUMIF(PHAN_TICH_VAT_TU_WBS!$E$6:$E$27, "NUOC", PHAN_TICH_VAT_TU_WBS!$I$6:$I$27) | F10: 25 | G10: =E10*F10 | H10: Tổng hợp toàn cầu
A11: 5 | B11: PHU.GIA | C11: Phụ gia siêu dẻo kéo dài thời gian đông kết | D11: lít | E11: =SUMIF(PHAN_TICH_VAT_TU_WBS!$E$6:$E$27, "PHU.GIA", PHAN_TICH_VAT_TU_WBS!$I$6:$I$27) | F11: 45000 | G11: =E11*F11 | H11: Tổng hợp toàn cầu
A12: 6 | B12: THEP.D10 | C12: Thép tròn trơn cán nóng CB240-T (D<=10mm) | D12: kg | E12: =SUMIF(PHAN_TICH_VAT_TU_WBS!$E$6:$E$27, "THEP.D10", PHAN_TICH_VAT_TU_WBS!$I$6:$I$27) | F12: 18500 | G12: =E12*F12 | H12: Tổng hợp toàn cầu
A13: 7 | B13: THEP.D14 | C13: Thép thanh vằn CB400-V (10<D<=18mm) | D13: kg | E13: =SUMIF(PHAN_TICH_VAT_TU_WBS!$E$6:$E$27, "THEP.D14", PHAN_TICH_VAT_TU_WBS!$I$6:$I$27) | F13: 18200 | G13: =E13*F13 | H13: Tổng hợp toàn cầu
A14: 8 | B14: THEP.D32 | C14: Thép thanh vằn CB400-V (D>18mm) | D14: kg | E14: =SUMIF(PHAN_TICH_VAT_TU_WBS!$E$6:$E$27, "THEP.D32", PHAN_TICH_VAT_TU_WBS!$I$6:$I$27) | F14: 17900 | G14: =E14*F14 | H14: Tổng hợp toàn cầu
C15: TỔNG CỘNG CHI PHÍ VẬT LIỆU CHÍNH (VNĐ) | G15: =SUM(G7:G14)

Sheet TONG_HOP_DU_TOAN_GXD
B2: DỰ ÁN: ĐƯỜNG TỪ TRUNG TÂM HUYỆN ĐỒNG VĂN ĐI MỐC 450/456, HUYỆN MÈO VẠC, HÀ GIANG
B3: BẢNG TỔNG HỢP DỰ TOÁN KINH PHÍ XÂY DỰNG (G_XD) - CẦU THÔN KHAI HOANG 2, KM14+363.65
B4: Căn cứ: TT 11/2021/TT-BXD, NĐ 207/2026/NĐ-CP & Luật Xây dựng số 135/2025/QH15
A5: STT | B5: Khoản mục chi phí | C5: Ký hiệu | D5: Cách tính | E5: Giá trị trước thuế (VNĐ) | F5: Thuế VAT (VNĐ) | G5: Giá trị sau thuế (VNĐ)
A6: 1 | B6: Chi phí trực tiếp | C6: T | D6: =QS_DIEN_GIAI_CHI_TIET!C80 | E6: =QS_DIEN_GIAI_CHI_TIET!L80
A7: 2 | B7: Chi phí gián tiếp | C7: GT | D7: T x 7.3% (Công trình giao thông) | E7: =E6*0.073
A8: 3 | B8: Thu nhập chịu thuế tính trước | C8: TL | D8: (T + GT) x 5.5% | E8: =(E6+E7)*0.055
A9: 4 | B9: Chi phí xây dựng trước thuế | C9: G | D9: T + GT + TL | E9: =SUM(E6:E8)
A10: 5 | B10: Thuế giá trị gia tăng (VAT 10%) | C10: VAT | D10: G x 10% (Luật XD 135/2025/QH15) | E10: =E9*0.1
A11: 6 | B11: TỔNG CHI PHÍ XÂY DỰNG SAU THUẾ | C11: G_XD | D11: G + VAT | E11: =E9+E10

Sheet THANH_TOAN_KY_PHU_LUC_03A
B2: DỰ ÁN: ĐƯỜNG TỪ TRUNG TÂM HUYỆN ĐỒNG VĂN ĐI MỐC 450/456, HUYỆN MÈO VẠC, HÀ GIANG
B3: BẢNG XÁC ĐỊNH GIÁ TRỊ KHỐI LƯỢNG CÔNG VIỆC HOÀN THÀNH THEO HỢP ĐỒNG (PHỤ LỤC 03a - NĐ 99/2021)
B4: Kỳ thanh toán: Đợt 1 | Cầu thôn Khai Hoang 2, Km14+363.65 | Hợp đồng số: 09/2026/HĐ-XL
A5: TT | B5: Nội dung công việc | C5: Đơn vị | D5: Khối lượng theo HĐ | E5: Đơn giá HĐ (VNĐ) | F5: Thành tiền HĐ (VNĐ) | G5: Khối lượng kỳ trước | H5: Khối lượng kỳ này | I5: Lũy kế khối lượng | J5: Thành tiền thanh toán kỳ này (VNĐ) | K5: Ghi chú
A7: 1 | B7: =QS_DIEN_GIAI_CHI_TIET!C7 | C7: =QS_DIEN_GIAI_CHI_TIET!D7 | D7: =QS_DIEN_GIAI_CHI_TIET!J7 | E7: =QS_DIEN_GIAI_CHI_TIET!K7 | F7: =D7*E7 | G7: 0 | H7: =D7*1.0 | I7: =G7+H7 | J7: =H7*E7 | K7: Hoàn thành 100%
A8: 2 | B8: =QS_DIEN_GIAI_CHI_TIET!C9 | C8: =QS_DIEN_GIAI_CHI_TIET!D9 | D8: =QS_DIEN_GIAI_CHI_TIET!J9 | E8: =QS_DIEN_GIAI_CHI_TIET!K9 | F8: =D8*E8 | G8: 0 | H8: =D8*1.0 | I8: =G8+H8 | J8: =H8*E8 | K8: Hoàn thành 100%
A9: 3 | B9: =QS_DIEN_GIAI_CHI_TIET!C11 | C9: =QS_DIEN_GIAI_CHI_TIET!D11 | D9: =QS_DIEN_GIAI_CHI_TIET!J11 | E9: =QS_DIEN_GIAI_CHI_TIET!K11 | F9: =D9*E9 | G9: 0 | H9: =D9*1.0 | I9: =G9+H9 | J9: =H9*E9 | K9: Hoàn thành 100%
A10: 4 | B10: =QS_DIEN_GIAI_CHI_TIET!C13 | C10: =QS_DIEN_GIAI_CHI_TIET!D13 | D10: =QS_DIEN_GIAI_CHI_TIET!J13 | E10: =QS_DIEN_GIAI_CHI_TIET!K13 | F10: =D10*E10 | G10: 0 | H10: =D10*1.0 | I10: =G10+H10 | J10: =H10*E10 | K10: Hoàn thành 100%
A11: 5 | B11: =QS_DIEN_GIAI_CHI_TIET!C15 | C11: =QS_DIEN_GIAI_CHI_TIET!D15 | D11: =QS_DIEN_GIAI_CHI_TIET!J15 | E11: =QS_DIEN_GIAI_CHI_TIET!K15 | F11: =D11*E11 | G11: 0 | H11: =D11*1.0 | I11: =G11+H11 | J11: =H11*E11 | K11: Hoàn thành 100%
A12: 6 | B12: =QS_DIEN_GIAI_CHI_TIET!C17 | C12: =QS_DIEN_GIAI_CHI_TIET!D17 | D12: =QS_DIEN_GIAI_CHI_TIET!J17 | E12: =QS_DIEN_GIAI_CHI_TIET!K17 | F12: =D12*E12 | G12: 0 | H12: =D12*1.0 | I12: =G12+H12 | J12: =H12*E12 | K12: Hoàn thành 100%
A13: 7 | B13: =QS_DIEN_GIAI_CHI_TIET!C20 | C13: =QS_DIEN_GIAI_CHI_TIET!D20 | D13: =QS_DIEN_GIAI_CHI_TIET!J20 | E13: =QS_DIEN_GIAI_CHI_TIET!K20 | F13: =D13*E13 | G13: 0 | H13: =D13*1.0 | I13: =G13+H13 | J13: =H13*E13 | K13: Hoàn thành 100%
A14: 8 | B14: =QS_DIEN_GIAI_CHI_TIET!C22 | C14: =QS_DIEN_GIAI_CHI_TIET!D22 | D14: =QS_DIEN_GIAI_CHI_TIET!J22 | E14: =QS_DIEN_GIAI_CHI_TIET!K22 | F14: =D14*E14 | G14: 0 | H14: =D14*1.0 | I14: =G14+H14 | J14: =H14*E14 | K14: Hoàn thành 100%
A15: 9 | B15: =QS_DIEN_GIAI_CHI_TIET!C24 | C15: =QS_DIEN_GIAI_CHI_TIET!D24 | D15: =QS_DIEN_GIAI_CHI_TIET!J24 | E15: =QS_DIEN_GIAI_CHI_TIET!K24 | F15: =D15*E15 | G15: 0 | H15: =D15*1.0 | I15: =G15+H15 | J15: =H15*E15 | K15: Hoàn thành 100%
A16: 10 | B16: =QS_DIEN_GIAI_CHI_TIET!C26 | C16: =QS_DIEN_GIAI_CHI_TIET!D26 | D16: =QS_DIEN_GIAI_CHI_TIET!J26 | E16: =QS_DIEN_GIAI_CHI_TIET!K26 | F16: =D16*E16 | G16: 0 | H16: =D16*1.0 | I16: =G16+H16 | J16: =H16*E16 | K16: Hoàn thành 100%
A17: 11 | B17: =QS_DIEN_GIAI_CHI_TIET!C28 | C17: =QS_DIEN_GIAI_CHI_TIET!D28 | D17: =QS_DIEN_GIAI_CHI_TIET!J28 | E17: =QS_DIEN_GIAI_CHI_TIET!K28 | F17: =D17*E17 | G17: 0 | H17: =D17*1.0 | I17: =G17+H17 | J17: =H17*E17 | K17: Hoàn thành 100%
A18: 12 | B18: =QS_DIEN_GIAI_CHI_TIET!C30 | C18: =QS_DIEN_GIAI_CHI_TIET!D30 | D18: =QS_DIEN_GIAI_CHI_TIET!J30 | E18: =QS_DIEN_GIAI_CHI_TIET!K30 | F18: =D18*E18 | G18: 0 | H18: =D18*1.0 | I18: =G18+H18 | J18: =H18*E18 | K18: Hoàn thành 100%
A19: 13 | B19: =QS_DIEN_GIAI_CHI_TIET!C32 | C19: =QS_DIEN_GIAI_CHI_TIET!D32 | D19: =QS_DIEN_GIAI_CHI_TIET!J32 | E19: =QS_DIEN_GIAI_CHI_TIET!K32 | F19: =D19*E19 | G19: 0 | H19: =D19*1.0 | I19: =G19+H19 | J19: =H19*E19 | K19: Hoàn thành 100%
A20: 14 | B20: =QS_DIEN_GIAI_CHI_TIET!C34 | C20: =QS_DIEN_GIAI_CHI_TIET!D34 | D20: =QS_DIEN_GIAI_CHI_TIET!J34 | E20: =QS_DIEN_GIAI_CHI_TIET!K34 | F20: =D20*E20 | G20: 0 | H20: =D20*1.0 | I20: =G20+H20 | J20: =H20*E20 | K20: Hoàn thành 100%
A21: 15 | B21: =QS_DIEN_GIAI_CHI_TIET!C36 | C21: =QS_DIEN_GIAI_CHI_TIET!D36 | D21: =QS_DIEN_GIAI_CHI_TIET!J36 | E21: =QS_DIEN_GIAI_CHI_TIET!K36 | F21: =D21*E21 | G21: 0 | H21: =D21*1.0 | I21: =G21+H21 | J21: =H21*E21 | K21: Hoàn thành 100%
A22: 16 | B22: =QS_DIEN_GIAI_CHI_TIET!C39 | C22: =QS_DIEN_GIAI_CHI_TIET!D39 | D22: =QS_DIEN_GIAI_CHI_TIET!J39 | E22: =QS_DIEN_GIAI_CHI_TIET!K39 | F22: =D22*E22 | G22: 0 | H22: =D22*1.0 | I22: =G22+H22 | J22: =H22*E22 | K22: Hoàn thành 100%
A23: 17 | B23: =QS_DIEN_GIAI_CHI_TIET!C41 | C23: =QS_DIEN_GIAI_CHI_TIET!D41 | D23: =QS_DIEN_GIAI_CHI_TIET!J41 | E23: =QS_DIEN_GIAI_CHI_TIET!K41 | F23: =D23*E23 | G23: 0 | H23: =D23*1.0 | I23: =G23+H23 | J23: =H23*E23 | K23: Hoàn thành 100%
A24: 18 | B24: =QS_DIEN_GIAI_CHI_TIET!C43 | C24: =QS_DIEN_GIAI_CHI_TIET!D43 | D24: =QS_DIEN_GIAI_CHI_TIET!J43 | E24: =QS_DIEN_GIAI_CHI_TIET!K43 | F24: =D24*E24 | G24: 0 | H24: =D24*1.0 | I24: =G24+H24 | J24: =H24*E24 | K24: Hoàn thành 100%
A25: 19 | B25: =QS_DIEN_GIAI_CHI_TIET!C45 | C25: =QS_DIEN_GIAI_CHI_TIET!D45 | D25: =QS_DIEN_GIAI_CHI_TIET!J45 | E25: =QS_DIEN_GIAI_CHI_TIET!K45 | F25: =D25*E25 | G25: 0 | H25: =D25*1.0 | I25: =G25+H25 | J25: =H25*E25 | K25: Hoàn thành 100%
A26: 20 | B26: =QS_DIEN_GIAI_CHI_TIET!C47 | C26: =QS_DIEN_GIAI_CHI_TIET!D47 | D26: =QS_DIEN_GIAI_CHI_TIET!J47 | E26: =QS_DIEN_GIAI_CHI_TIET!K47 | F26: =D26*E26 | G26: 0 | H26: =D26*1.0 | I26: =G26+H26 | J26: =H26*E26 | K26: Hoàn thành 100%
A27: 21 | B27: =QS_DIEN_GIAI_CHI_TIET!C49 | C27: =QS_DIEN_GIAI_CHI_TIET!D49 | D27: =QS_DIEN_GIAI_CHI_TIET!J49 | E27: =QS_DIEN_GIAI_CHI_TIET!K49 | F27: =D27*E27 | G27: 0 | H27: =D27*1.0 | I27: =G27+H27 | J27: =H27*E27 | K27: Hoàn thành 100%
A28: 22 | B28: =QS_DIEN_GIAI_CHI_TIET!C51 | C28: =QS_DIEN_GIAI_CHI_TIET!D51 | D28: =QS_DIEN_GIAI_CHI_TIET!J51 | E28: =QS_DIEN_GIAI_CHI_TIET!K51 | F28: =D28*E28 | G28: 0 | H28: =D28*1.0 | I28: =G28+H28 | J28: =H28*E28 | K28: Hoàn thành 100%
B29: TỔNG CỘNG GIÁ TRỊ THANH TOÁN (VNĐ) | F29: =SUM(F7:F28) | J29: =SUM(J7:J28)

Sheet TIEN_DO_THI_CONG_WBS
B2: DỰ ÁN: ĐƯỜNG TỪ TRUNG TÂM HUYỆN ĐỒNG VĂN ĐI MỐC 450/456, HUYỆN MÈO VẠC, HÀ GIANG
B3: BẢNG TIẾN ĐỘ THI CÔNG CHI TIẾT WBS & PHÂN TÍCH ĐƯỜNG GĂNG (CPM GANTT CHART) - CẦU KM14+363.65
B4: Tổng tiến độ: 12 tháng (365 ngày) | Khởi công: 01/10/2026 - Hoàn thành: 30/09/2027
A5: Mã WBS | B5: Tên công tác thi công | C5: Thời gian (ngày) | D5: Công tác trước | E5: Định mức công (công/ĐV) | F5: Số nhân công (người) | G5: Tổ đội phụ trách | H5: Trạng thái CPM | I5: Ngày bắt đầu | J5: Ngày hoàn thành
A6: WBS.01 | B6: Bàn giao cọc mốc tim tuyến và định vị công trình | C6: 5 | D6: - | E6: 0.5 | F6: 6 | G6: Tổ Trắc đạc | H6: Critical | I6: 2026-10-01 | J6: 2026-10-05
A7: WBS.02 | B7: Thi công đường công vụ, lán trại và dọn dẹp mặt bằng | C7: 15 | D7: WBS.01 | E7: 1.2 | F7: 18 | G7: Tổ Thi công nền | H7: Critical | I7: 2026-10-06 | J7: 2026-10-20
A8: WBS.03 | B8: Kiểm định vật liệu đầu vào (Xi măng, cát, đá, thép) | C8: 10 | D8: WBS.01 | E8: 0.8 | F8: 4 | G8: Tổ QA/QC & Lab | H8: Non-Critical | I8: 2026-10-06 | J8: 2026-10-15
A9: WBS.04 | B9: Thi công bãi đúc dầm T15m và lắp đặt trạm trộn | C9: 20 | D9: WBS.02 | E9: 2 | F9: 16 | G9: Tổ Xây dựng bãi | H9: Non-Critical | I9: 2026-10-21 | J9: 2026-11-09
A10: WBS.05 | B10: Đào hố móng mố M1 và xử lý nền đá nứt nẻ | C10: 20 | D10: WBS.02 | E10: 1.5 | F10: 14 | G10: Tổ Cơ giới móng | H10: Critical | I10: 2026-10-21 | J10: 2026-11-09
A11: WBS.06 | B11: Khoan cấy cốt thép neo D32 vào nền đá hố móng M1 | C11: 10 | D11: WBS.05 | E11: 2.5 | F11: 10 | G11: Tổ Khoan cấy thép | H11: Critical | I11: 2026-11-10 | J11: 2026-11-19
A12: WBS.07 | B12: Đổ bê tông đệm móng mố M1 C10 (M150) | C12: 3 | D12: WBS.06 | E12: 0.6 | F12: 8 | G12: Tổ Bê tông móng | H12: Critical | I12: 2026-11-20 | J12: 2026-11-22
A13: WBS.08 | B13: Gia công lắp dựng cốt thép và ván khuôn móng mố M1 | C13: 10 | D13: WBS.07 | E13: 3.2 | F13: 16 | G13: Tổ Cốt thép ván khuôn | H13: Critical | I13: 2026-11-23 | J13: 2026-12-02
A14: WBS.09 | B14: Đổ bê tông móng mố M1 C30 (V = 110 m3) | C14: 4 | D14: WBS.08 | E14: 1.8 | F14: 20 | G14: Tổ Bê tông thương phẩm | H14: Critical | I14: 2026-12-03 | J14: 2026-12-06
A15: WBS.10 | B15: Đào hố móng và khoan cấy thép neo nền đá mố M2 | C15: 20 | D15: WBS.05 | E15: 1.5 | F15: 14 | G15: Tổ Cơ giới móng | H15: Critical | I15: 2026-11-10 | J15: 2026-11-29
A16: WBS.11 | B16: Đổ bê tông đệm và bê tông móng mố M2 C30 | C16: 12 | D16: WBS.10 | E16: 2 | F16: 18 | G16: Tổ Bê tông móng | H16: Critical | I16: 2026-11-30 | J16: 2026-12-11
A17: WBS.12 | B17: Thi công thân mố, tường ngực và tường cánh M1 C30 | C17: 25 | D17: WBS.09 | E17: 3.5 | F17: 22 | G17: Tổ Cốp pha thân | H17: Critical | I17: 2026-12-07 | J17: 2026-12-31
... A27: WBS.22 | B27: Lắp khe co giãn, thảm BTNC 19, thử tải và bàn giao | C27: 20 | D27: WBS.20,21 | E27: 3 | F27: 25 | G27: Tổ Hoàn thiện | H27: Critical | I27: 2027-04-12 | J27: 2027-05-01

Sheet HOSO_KCS_NGHIEM_THU
B2: DỰ ÁN: ĐƯỜNG TỪ TRUNG TÂM HUYỆN ĐỒNG VĂN ĐI MỐC 450/456, HUYỆN MÈO VẠC, HÀ GIANG
B3: DANH MỤC HỒ SƠ NGHIỆM THU KỸ THUẬT & CHẤT LƯỢNG KCS (THEO NGHỊ ĐỊNH 207/2026/NĐ-CP)
B4: Liên kết 100% ngày nghiệm thu từ TIEN_DO_THI_CONG_WBS và khối lượng từ QS_DIEN_GIAI_CHI_TIET
A5: Số TT | B5: Số hiệu biên bản | C5: Tên công việc / Hạng mục nghiệm thu | D5: Khối lượng nghiệm thu | E5: Đơn vị | F5: Tiêu chuẩn kỹ thuật áp dụng | G5: Thành phần nghiệm thu | H5: Ngày nghiệm thu hoàn thành | I5: Kết luận
A6: 1 | B6: BBNT-01 | C6: Bàn giao cọc mốc tim tuyến và định vị công trình | D6: 1 | E6: Điểm | F6: TCVN 4054:2005 | G6: TVGS + Nhà thầu | H6: =TIEN_DO_THI_CONG_WBS!J6 | I6: Đạt yêu cầu
A7: 2 | B7: BBNT-02 | C7: Thi công đường công vụ, lán trại và dọn dẹp mặt bằng | D7: 1 | E7: Gói | F7: TCVN 4054:2005 | G7: TVGS + Nhà thầu | H7: =TIEN_DO_THI_CONG_WBS!J7 | I7: Đạt yêu cầu
A8: 3 | B8: BBNT-03 | C8: Kiểm định vật liệu xây dựng đầu vào (Thép, Xi măng, Cát, Đá) | D8: 1 | E8: Lô | F8: TCVN 1651:2018 | G8: TVGS + Nhà thầu + Lab | H8: =TIEN_DO_THI_CONG_WBS!J8 | I8: Đạt yêu cầu
A9: 4 | B9: BBNT-04 | C9: Thi công bãi đúc dầm T15m và lắp đặt trạm trộn | D9: 1 | E9: Bãi | F9: TCVN 11823:2017 | G9: TVGS + Nhà thầu | H9: =TIEN_DO_THI_CONG_WBS!J9 | I9: Đạt yêu cầu
A10: 5 | B10: BBNT-05 | C10: Đào hố móng mố M1 và xử lý bề mặt tầng đá nứt nẻ | D10: 185 | E10: m3 | F10: TCVN 11823:2017 | G10: TVGS + Nhà thầu | H10: =TIEN_DO_THI_CONG_WBS!J10 | I10: Đạt yêu cầu
A11: 6 | B11: BBNT-06 | C11: Khoan cấy cốt thép neo D32 vào nền đá hố móng mố M1 | D11: 49 | E11: lỗ | F11: TCVN 11823:2017 | G11: TVGS + Nhà thầu | H11: =TIEN_DO_THI_CONG_WBS!J11 | I11: Đạt yêu cầu
A12: 7 | B12: BBNT-07 | C12: Đổ bê tông đệm móng mố M1 mác C10 (M150) | D12: 4.67 | E12: m3 | F12: TCVN 3105:2022 | G12: TVGS + Nhà thầu | H12: =TIEN_DO_THI_CONG_WBS!J12 | I12: Đạt yêu cầu
A13: 8 | B13: BBNT-08 | C13: Lắp dựng cốt thép và ván khuôn móng mố M1 | D13: 17.5 | E13: Tấn | F13: TCVN 1651:2018 | G13: TVGS + Nhà thầu | H13: =TIEN_DO_THI_CONG_WBS!J13 | I13: Đạt yêu cầu
A14: 9 | B14: BBNT-09 | C14: Đổ bê tông móng mố M1 mác C30 (M350) | D14: 110 | E14: m3 | F14: TCVN 3105:2022 | G14: TVGS + Nhà thầu | H14: =TIEN_DO_THI_CONG_WBS!J14 | I14: Đạt yêu cầu
A15: 10 | B15: BBNT-10 | C15: Đào hố móng và khoan cấy thép neo nền đá mố M2 | D15: 49 | E15: lỗ | F15: TCVN 11823:2017 | G15: TVGS + Nhà thầu | H15: =TIEN_DO_THI_CONG_WBS!J15 | I15: Đạt yêu cầu
A16: 11 | B16: BBNT-11 | C16: Đổ bê tông đệm và bê tông móng mố M2 C30 | D16: 114.67 | E16: m3 | F16: TCVN 3105:2022 | G16: TVGS + Nhà thầu | H16: =TIEN_DO_THI_CONG_WBS!J16 | I16: Đạt yêu cầu
A17: 12 | B17: BBNT-12 | C17: Thi công thân mố, tường ngực và tường cánh M1 C30 | D17: 84.64 | E17: m3 | F17: TCVN 11823:2017 | G17: TVGS + Nhà thầu | H17: =TIEN_DO_THI_CONG_WBS!J17 | I17: Đạt yêu cầu
... A27: 22 | B27: BBNT-22 | C27: Lắp khe co giãn, thảm BTNC 19, thử tải và bàn giao | D27: 1 | E27: Cầu | F27: TCVN 11823:2017 | G27: Chủ đầu tư + TVGS + NT | H27: =TIEN_DO_THI_CONG_WBS!J27 | I27: Đạt yêu cầu

Sheet MAU_BIEN_BAN_KCS
B2: CHỌN SỐ BIÊN BẢN (1 - 22): | C2: 14 | D2: (Nhập số thứ tự từ 1 đến 22 để tự động nhảy toàn bộ nội dung biên bản A4)
B4: CỘNG HÒA XÃ HỘI CHỦ NGHĨA VIỆT NAM
B5: Độc lập - Tự do - Hạnh phúc
B6: -------------------------
B8: BIÊN BẢN LẤY MẪU THÍ NGHIỆM TẠI HIỆN TRƯỜNG
B9: ="Số: " & TEXT(C2, "00") & "/BBNT-XD/KHAI-HOANG-2"
B11: Căn cứ Luật Xây dựng số 135/2025/QH15;
B12: Căn cứ Nghị định số 207/2026/NĐ-CP ngày 15/01/2026 của Chính phủ về quản lý chất lượng công trình;
B13: Căn cứ Hợp đồng thi công xây dựng số 09/2026/HĐ-XL gói thầu xây lắp Cầu thôn Khai Hoang 2;
B14: Căn cứ Hồ sơ thiết kế bản vẽ thi công và Chỉ dẫn kỹ thuật được phê duyệt.
B16: 1. Tên công trình / Dự án: | C16: Đường từ trung tâm huyện Đồng Văn đi Mốc 450/456, huyện Mèo Vạc, Hà Giang
B17: 2. Hạng mục công trình: | C17: CẦU THÔN KHAI HOANG 2, KM14+363.65 (Nhịp dầm T 15m)
B18: 3. Địa điểm xây dựng: | C18: Km14+363.65, Huyện Mèo Vạc, Tỉnh Hà Giang
B19: 4. Đối tượng nghiệm thu: | C19: =VLOOKUP(C2, HOSO_KCS_NGHIEM_THU!$A$6:$H$27, 3, FALSE)
B20: 5. Khối lượng nghiệm thu: | C20: =TEXT(VLOOKUP(C2, HOSO_KCS_NGHIEM_THU!$A$6:$H$27, 4, FALSE), "#,##0.00") & " " & VLOOKUP(C2, HOSO_KCS_NGHIEM_THU!$A$6:$H$27, 5, FALSE)
B21: 6. Tiêu chuẩn kỹ thuật áp dụng: | C21: =VLOOKUP(C2, HOSO_KCS_NGHIEM_THU!$A$6:$H$27, 6, FALSE)
B22: 7. Thời gian nghiệm thu: | C22: ="Bắt đầu: 08 giờ 30 phút - Kết thúc: 11 giờ 30 phút, ngày " & TEXT(VLOOKUP(C2, HOSO_KCS_NGHIEM_THU!$A$6:$H$27, 8, FALSE), "dd/mm/yyyy")
B24: 8. Thành phần trực tiếp nghiệm thu:
B25: a) Đại diện Tư vấn giám sát (TVGS): | C25: - Ông: Dương Văn Lâm - Chức vụ: Kỹ sư Giám sát trưởng
B26: b) Đại diện Nhà thầu thi công: | C26: - Ông: Trần Việt Hải - Chức vụ: Chỉ huy trưởng công trường
C27: - Ông: Ngô Văn Quang - Chức vụ: Kỹ sư QA/QC hiện trường
B29: 9. Đánh giá kết quả công việc đã thực hiện:
B30: - Về kích thước hình học, cao độ, tim mốc: Đạt yêu cầu theo hồ sơ thiết kế bản vẽ thi công.
B31: - Về chất lượng vật liệu, chứng chỉ xuất xưởng, kết quả thí nghiệm KCS: Đạt yêu cầu theo tiêu chuẩn áp dụng.
B32: - Về an toàn lao động, vệ sinh môi trường: Tuân thủ đầy đủ biện pháp thi công được duyệt.
B34: 10. Kết luận nghiệm thu:
B35: CHẤP THUẬN NGHIỆM THU CÔNG VIỆC XÂY DỰNG. ĐỒNG Ý CHO PHÉP TRIỂN KHAI BƯỚC THI CÔNG TIẾP THEO.
B38: ĐẠI DIỆN NHÀ THẦU THI CÔNG | E38: ĐẠI DIỆN TƯ VẤN GIÁM SÁT
B44: Trần Việt Hải | E44: Dương Văn Lâm

Sheet MAU_BB_NGHIEM_THU_VAT_LIEU
B2: CHỌN MÃ VẬT LIỆU (1 - 16): | C2: 1 | D2: (Nhập mã từ 1 đến 16 theo danh mục ma trận tần suất thí nghiệm để tự nhảy biên bản)
B4: CỘNG HÒA XÃ HỘI CHỦ NGHĨA VIỆT NAM
B5: Độc lập - Tự do - Hạnh phúc
B8: BIÊN BẢN NGHIỆM THU VẬT LIỆU XÂY DỰNG ĐẦU VÀO
B9: ="Số: " & TEXT(C2, "00") & "/BBNT-VL/KHAI-HOANG-2"
B12: 1. Tên vật liệu nghiệm thu: | C12: =VLOOKUP(C2, CAP_PHOI_1M3_VA_TAN_SUAT!$A$23:$L$38, 2, FALSE)
B13: 2. Khối lượng nghiệm thu lô hàng: | C13: =TEXT(VLOOKUP(C2, CAP_PHOI_1M3_VA_TAN_SUAT!$A$23:$L$38, 7, FALSE), "#,##0.00") & " " & VLOOKUP(C2, CAP_PHOI_1M3_VA_TAN_SUAT!$A$23:$L$38, 6, FALSE)
B14: 3. Tiêu chuẩn kỹ thuật áp dụng: | C14: =VLOOKUP(C2, CAP_PHOI_1M3_VA_TAN_SUAT!$A$23:$L$38, 3, FALSE)
B15: 4. Chỉ tiêu kiểm tra chất lượng: | C15: =VLOOKUP(C2, CAP_PHOI_1M3_VA_TAN_SUAT!$A$23:$L$38, 4, FALSE)
B16: 5. Quy cách và số lượng tổ mẫu thí nghiệm: | C16: =VLOOKUP(C2, CAP_PHOI_1M3_VA_TAN_SUAT!$A$23:$L$38, 10, FALSE) & " (Số tổ mẫu: " & VLOOKUP(C2, CAP_PHOI_1M3_VA_TAN_SUAT!$A$23:$L$38, 9, FALSE) & " tổ)"
B17: 6. Đơn vị thực hiện thí nghiệm: | C17: =VLOOKUP(C2, CAP_PHOI_1M3_VA_TAN_SUAT!$A$23:$L$38, 11, FALSE)
B18: 7. Điều kiện nghiệm thu / Chuyển bước: | C18: =VLOOKUP(C2, CAP_PHOI_1M3_VA_TAN_SUAT!$A$23:$L$38, 12, FALSE)
B20: 8. Kết luận nghiệm thu:
B21: VẬT LIỆU ĐẠT TIÊU CHUẨN KỸ THUẬT THEO QUY ĐỊNH. ĐỒNG Ý CHO PHÉP ĐƯA VÀO SỬ DỤNG TRONG THI CÔNG.
B24: ĐẠI DIỆN NHÀ THẦU THI CÔNG | E24: ĐẠI DIỆN TƯ VẤN GIÁM SÁT
B30: Trần Việt Hải | E30: Dương Văn Lâm

Sheet MAU_BB_LAY_MAU_HIEN_TRUONG
B2: CHỌN MÃ HẠNG MỤC LẤY MẪU (17 - 26): | C2: 22 | D2: (Nhập mã từ 17 đến 26 tương ứng các hạng mục mẫu nén bê tông để tự động điền form)
B3: CHỌN NGÀY ĐÚC MẪU (YYYY-MM-DD): | C3: 2026-12-20 | D3: (Tự động tính ngày nén mẫu R7 = Ngày đúc + 7, R28 = Ngày đúc + 28 theo đúng quy định)
B5: CỘNG HÒA XÃ HỘI CHỦ NGHĨA VIỆT NAM
B6: Độc lập - Tự do - Hạnh phúc
B9: ="Số: " & TEXT(C2, "00") & "/BBLM-HT/KHAI-HOANG-2"
B12: 1. Đối tượng và cấu kiện lấy mẫu: | C12: =VLOOKUP(C2, CAP_PHOI_1M3_VA_TAN_SUAT!$A$23:$L$51, 2, FALSE)
B13: 2. Thể tích bê tông / Quy mô mẻ đổ: | C13: =TEXT(VLOOKUP(C2, CAP_PHOI_1M3_VA_TAN_SUAT!$A$23:$L$51, 7, FALSE), "#,##0.00") & " " & VLOOKUP(C2, CAP_PHOI_1M3_VA_TAN_SUAT!$A$23:$L$51, 6, FALSE)
B14: 3. Quy định số tổ mẫu bắt buộc: | C14: =VLOOKUP(C2, CAP_PHOI_1M3_VA_TAN_SUAT!$A$23:$L$51, 9, FALSE) & " tổ mẫu (" & VLOOKUP(C2, CAP_PHOI_1M3_VA_TAN_SUAT!$A$23:$L$51, 10, FALSE) & ")"
B15: 4. Tiêu chuẩn lấy mẫu & thử nghiệm: | C15: =VLOOKUP(C2, CAP_PHOI_1M3_VA_TAN_SUAT!$A$23:$L$51, 3, FALSE)
B16: 5. Phương pháp bảo dưỡng mẫu: | C16: Bảo dưỡng ẩm tiêu chuẩn trong phòng thí nghiệm (TCVN 3105:2022)
B17: 6. Kế hoạch nén kiểm tra cường độ: | C17: ="Nén kiểm tra R7 ngày (" & TEXT(DATEVALUE(C3)+7, "dd/mm/yyyy") & "): Đạt >= 70-80% f'c | Nén R28 ngày (" & TEXT(DATEVALUE(C3)+28, "dd/mm/yyyy") & "): Đạt >= 100% f'c"
B19: 7. Tình trạng mẫu khi bàn giao:
B20: Mẫu đúc nguyên vẹn, bề mặt phẳng đều, dán nhãn ghi rõ ngày đúc, vị trí cấu kiện và ký hiệu tổ mẫu.
B23: CÁN BỘ LẤY MẪU THÍ NGHIỆM (LAS-XD) | E23: GIÁM SÁT HIỆN TRƯỜNG (TVGS)
B29: Nguyễn Văn Thí Nghiệm | E29: Dương Văn Lâm
