Workbook

Sheet CAP_PHOI_1M3_VA_TAN_SUAT
B2: DỰ ÁN: CAO TỐC TUYÊN QUANG - HÀ GIANG (GIAI ĐOẠN 1) - CẦU KM19+529.080
B3: PHÂN TÍCH ĐỊNH MỨC CẤP PHỐI 1M³ BÊ TÔNG & MA TRẬN TẦN SUẤT THÍ NGHIỆM KCS
B4: Căn cứ: Định mức Thông tư 12/2021/TT-BXD, TCVN 4453:1995, TCVN 1651:2018, TCVN 6260:2020, TCVN 7570:2006, Nghị định 207/2026/NĐ-CP
B6: I. BẢNG PHÂN TÍCH ĐỊNH MỨC CẤP PHỐI CHO 1 M³ BÊ TÔNG CỦA TỪNG KẾT CẤU CÔNG TRÌNH
A8: TT | B8: Loại kết cấu công trình | C8: Mác thiết kế (f'c / Mác) | D8: Độ sụt yêu cầu (cm) | E8: Xi măng PCB40 (kg/m3) | F8: Cát vàng Mk>=2.5 (m3/m3) | G8: Đá dăm 1x2 (m3/m3) | H8: Nước sạch (lít/m3) | I8: Phụ gia (lít hoặc kg/m3) | J8: Tổng KL bê tông (m3) | K8: Tổng Xi măng (Tấn) | L8: Tổng Cát vàng (m3) | M8: Tổng Đá dăm 1x2 (m3) | N8: Tổng Nước (m3) | O8: Tổng Phụ gia (Lít/kg) | P8: Tiêu chuẩn & Yêu cầu kỹ thuật
A9: 1 | B9: Bê tông đệm móng mố, bệ trụ, bản quá độ | C9: C10 (Mác 150) | D9: 6 ± 2 | E9: 225 | F9: 0.51 | G9: 0.88 | H9: 185 | I9: 0 | J9: =QS_DIEN_GIAI_CHI_TIET!J34 | K9: =J9*E9/1000 | L9: =J9*F9 | M9: =J9*G9 | N9: =J9*H9/1000 | O9: =J9*I9 | P9: Đệm cách ly đáy móng, TCVN 4453
A10: 2 | B10: Bản quá độ sau mố & Gờ lan can, tấm đúc sẵn | C10: C25 (Mác 300) | D10: 10 ± 2 | E10: 350 | F10: 0.46 | G10: 0.86 | H10: 175 | I10: 2.8 | J10: =QS_DIEN_GIAI_CHI_TIET!J75*0.026 + 171.659 | K10: =J10*E10/1000 | L10: =J10*F10 | M10: =J10*G10 | N10: =J10*H10/1000 | O10: =J10*I10 | P10: Bản quá độ, gờ lan can C25
A11: 3 | B11: Bê tông Cọc khoan nhồi D1200mm (thi công Tremie) | C11: C30 (Mác 350) | D11: 18 ± 2 | E11: 410 | F11: 0.47 | G11: 0.84 | H11: 180 | I11: 4.1 | J11: =QS_DIEN_GIAI_CHI_TIET!J17 + QS_DIEN_GIAI_CHI_TIET!J27 | K11: =J11*E11/1000 | L11: =J11*F11 | M11: =J11*G11 | N11: =J11*H11/1000 | O11: =J11*I11 | P11: Đổ dưới nước ống tremie, đông kết chậm
A12: 4 | B12: Bê tông Bệ mố M1, M2; Thân mố; Tường cánh | C12: C30 (Mác 350) | D12: 12 ± 2 | E12: 385 | F12: 0.45 | G12: 0.85 | H12: 175 | I12: 3.5 | J12: =QS_DIEN_GIAI_CHI_TIET!J39*0.395 + QS_DIEN_GIAI_CHI_TIET!J44 + QS_DIEN_GIAI_CHI_TIET!J47 | K12: =J12*E12/1000 | L12: =J12*F12 | M12: =J12*G12 | N12: =J12*H12/1000 | O12: =J12*I12 | P12: Bê tông khối lớn mố M1, M2
A13: 5 | B13: Bê tông Bệ trụ T1, T2 & Thân trụ đặc | C13: C30 (Mác 350) | D13: 12 ± 2 | E13: 385 | F13: 0.45 | G13: 0.85 | H13: 175 | I13: 3.5 | J13: =QS_DIEN_GIAI_CHI_TIET!J50 + QS_DIEN_GIAI_CHI_TIET!J39*0.605 | K13: =J13*E13/1000 | L13: =J13*F13 | M13: =J13*G13 | N13: =J13*H13/1000 | O13: =J13*I13 | P13: Bê tông bệ trụ & thân trụ 2 thân
A14: 6 | B14: Bê tông Xà mũ trụ T1, T2 & Tường tai | C14: C35 (Mác 400) | D14: 14 ± 2 | E14: 430 | F14: 0.44 | G14: 0.85 | H14: 165 | I14: 4.3 | J14: =QS_DIEN_GIAI_CHI_TIET!J53 | K14: =J14*E14/1000 | L14: =J14*F14 | M14: =J14*G14 | N14: =J14*H14/1000 | O14: =J14*I14 | P14: Xà mũ trụ dự ứng lực ngang
A15: 7 | B15: Bê tông Bản mặt cầu, Dầm ngang, Liên tục nhiệt | C15: C35 (Mác 400) | D15: 14 ± 2 | E15: 430 | F15: 0.44 | G15: 0.85 | H15: 165 | I15: 4.3 | J15: =QS_DIEN_GIAI_CHI_TIET!J73 + QS_DIEN_GIAI_CHI_TIET!J77 + QS_DIEN_GIAI_CHI_TIET!J79 | K15: =J15*E15/1000 | L15: =J15*F15 | M15: =J15*G15 | N15: =J15*H15/1000 | O15: =J15*I15 | P15: Chống thấm tốt, co ngót thấp
A16: 8 | B16: Bê tông Dầm chủ Super-T đúc sẵn (15 phiến L=38.2m) | C16: C45 (Mác 550) | D16: 16 ± 2 | E16: 475 | F16: 0.42 | G16: 0.83 | H16: 150 | I16: 5.7 | J16: =QS_DIEN_GIAI_CHI_TIET!J62 | K16: =J16*E16/1000 | L16: =J16*F16 | M16: =J16*G16 | N16: =J16*H16/1000 | O16: =J16*I16 | P16: Cường độ sớm R kéo >= 85% f'c
A17: 9 | B17: Bê tông hạt nhỏ không co ngót chèn khe co giãn | C17: C40 (Mác 450) | D17: 12 ± 2 | E17: 450 | F17: 0.46 | G17: 0.8 | H17: 160 | I17: 4.5 | J17: =QS_DIEN_GIAI_CHI_TIET!J86 | K17: =J17*E17/1000 | L17: =J17*F17 | M17: =J17*G17 | N17: =J17*H17/1000 | O17: =J17*I17 | P17: Cốt liệu nhỏ, chống co ngót
A18: TỔNG CỘNG TOÀN CÔNG TRÌNH | J18: =SUM(J9:J17) | K18: =SUM(K9:K17) | L18: =SUM(L9:L17) | M18: =SUM(M9:M17) | N18: =SUM(N9:N17) | O18: =SUM(O9:O17) | P18: Tổng hợp cấp phối toàn dự án
B21: II. MA TRẬN QUY ĐỊNH TẦN SUẤT THÍ NGHIỆM VẬT LIỆU ĐẦU VÀO VÀ NGHIỆM THU KCS
B22: Quy định tần suất lấy mẫu kiểm soát chất lượng QA/QC theo Luật Xây dựng 135/2025/QH15, Nghị định 207/2026/NĐ-CP, TCVN 4453:1995, TCVN 1651:2018
A23: TT | B23: Tên vật liệu / Chỉ tiêu kiểm tra | C23: Tiêu chuẩn kỹ thuật áp dụng | D23: Chỉ tiêu kiểm tra bắt buộc | E23: Quy định tần suất lấy mẫu | F23: ĐVT vật tư | G23: Tổng KL công trình | H23: Định mức tần suất (KL/tổ mẫu) | I23: Số tổ mẫu thí nghiệm | J23: Quy cách tổ mẫu thí nghiệm | K23: Đơn vị thực hiện | L23: Điều kiện nghiệm thu (Hold Point)
A24: 1 | B24: Cốt thép tròn trơn Ø<=10mm (CB240-T) | C24: TCVN 1651-1:2018 | D24: Giới hạn chảy, độ bền kéo, độ giãn dài, uốn nguội | E24: <= 50 Tấn / lô / đường kính | F24: Tấn | G24: =SUMIFS(THONG_KE_THEP_CHI_TIET!$O$6:$O$399, THONG_KE_THEP_CHI_TIET!$E$6:$E$399, "<=10") | H24: 50 | I24: =ROUNDUP(G24/H24, 0) | J24: 3 thanh kéo + 3 thanh uốn | K24: LAS-XD hợp chuẩn | L24: Bắt buộc có KQTN trước khi gia công
A25: 2 | B25: Cốt thép thanh vằn Ø12mm (CB400-V) | C25: TCVN 1651-2:2018 | D25: Giới hạn chảy Re, độ bền kéo Rm, Rm/Re, uốn 180° | E25: <= 50 Tấn / lô / đường kính | F25: Tấn | G25: =SUMIFS(THONG_KE_THEP_CHI_TIET!$O$6:$O$399, THONG_KE_THEP_CHI_TIET!$E$6:$E$399, 12) | H25: 50 | I25: =ROUNDUP(G25/H25, 0) | J25: 3 thanh kéo + 3 thanh uốn | K25: LAS-XD hợp chuẩn | L25: Bắt buộc có KQTN trước khi gia công
A26: 3 | B26: Cốt thép thanh vằn Ø14mm (CB400-V) | C26: TCVN 1651-2:2018 | D26: Giới hạn chảy Re, độ bền kéo Rm, Rm/Re, uốn 180° | E26: <= 50 Tấn / lô / đường kính | F26: Tấn | G26: =SUMIFS(THONG_KE_THEP_CHI_TIET!$O$6:$O$399, THONG_KE_THEP_CHI_TIET!$E$6:$E$399, 14) | H26: 50 | I26: =ROUNDUP(G26/H26, 0) | J26: 3 thanh kéo + 3 thanh uốn | K26: LAS-XD hợp chuẩn | L26: Bắt buộc có KQTN trước khi gia công
A27: 4 | B27: Cốt thép thanh vằn Ø16mm (CB400-V) | C27: TCVN 1651-2:2018 | D27: Giới hạn chảy Re, độ bền kéo Rm, Rm/Re, uốn 180° | E27: <= 50 Tấn / lô / đường kính | F27: Tấn | G27: =SUMIFS(THONG_KE_THEP_CHI_TIET!$O$6:$O$399, THONG_KE_THEP_CHI_TIET!$E$6:$E$399, 16) | H27: 50 | I27: =ROUNDUP(G27/H27, 0) | J27: 3 thanh kéo + 3 thanh uốn | K27: LAS-XD hợp chuẩn | L27: Bắt buộc có KQTN trước khi gia công
A28: 5 | B28: Cốt thép thanh vằn Ø18mm (CB400-V) | C28: TCVN 1651-2:2018 | D28: Giới hạn chảy Re, độ bền kéo Rm, Rm/Re, uốn 180° | E28: <= 50 Tấn / lô / đường kính | F28: Tấn | G28: =SUMIFS(THONG_KE_THEP_CHI_TIET!$O$6:$O$399, THONG_KE_THEP_CHI_TIET!$E$6:$E$399, 18) | H28: 50 | I28: =ROUNDUP(G28/H28, 0) | J28: 3 thanh kéo + 3 thanh uốn | K28: LAS-XD hợp chuẩn | L28: Bắt buộc có KQTN trước khi gia công
A29: 6 | B29: Cốt thép thanh vằn Ø20mm (CB400-V) | C29: TCVN 1651-2:2018 | D29: Giới hạn chảy Re, độ bền kéo Rm, Rm/Re, uốn 180° | E29: <= 50 Tấn / lô / đường kính | F29: Tấn | G29: =SUMIFS(THONG_KE_THEP_CHI_TIET!$O$6:$O$399, THONG_KE_THEP_CHI_TIET!$E$6:$E$399, 20) | H29: 50 | I29: =ROUNDUP(G29/H29, 0) | J29: 3 thanh kéo + 3 thanh uốn | K29: LAS-XD hợp chuẩn | L29: Bắt buộc có KQTN trước khi gia công
A30: 7 | B30: Cốt thép thanh vằn Ø22mm (CB400-V) | C30: TCVN 1651-2:2018 | D30: Giới hạn chảy Re, độ bền kéo Rm, Rm/Re, uốn 180° | E30: <= 50 Tấn / lô / đường kính | F30: Tấn | G30: =SUMIFS(THONG_KE_THEP_CHI_TIET!$O$6:$O$399, THONG_KE_THEP_CHI_TIET!$E$6:$E$399, 22) | H30: 50 | I30: =ROUNDUP(G30/H30, 0) | J30: 3 thanh kéo + 3 thanh uốn | K30: LAS-XD hợp chuẩn | L30: Bắt buộc có KQTN trước khi gia công
A31: 8 | B31: Cốt thép thanh vằn Ø25mm (CB400-V) | C31: TCVN 1651-2:2018 | D31: Giới hạn chảy Re, độ bền kéo Rm, Rm/Re, uốn 180° | E31: <= 50 Tấn / lô / đường kính | F31: Tấn | G31: =SUMIFS(THONG_KE_THEP_CHI_TIET!$O$6:$O$399, THONG_KE_THEP_CHI_TIET!$E$6:$E$399, 25) | H31: 50 | I31: =ROUNDUP(G31/H31, 0) | J31: 3 thanh kéo + 3 thanh uốn | K31: LAS-XD hợp chuẩn | L31: Bắt buộc có KQTN trước khi gia công
A32: 9 | B32: Cốt thép thanh vằn Ø28mm (CB400-V) | C32: TCVN 1651-2:2018 | D32: Giới hạn chảy Re, độ bền kéo Rm, Rm/Re, uốn 180° | E32: <= 50 Tấn / lô / đường kính | F32: Tấn | G32: =SUMIFS(THONG_KE_THEP_CHI_TIET!$O$6:$O$399, THONG_KE_THEP_CHI_TIET!$E$6:$E$399, 28) | H32: 50 | I32: =ROUNDUP(G32/H32, 0) | J32: 3 thanh kéo + 3 thanh uốn | K32: LAS-XD hợp chuẩn | L32: Bắt buộc có KQTN trước khi gia công
A33: 10 | B33: Cốt thép thanh vằn Ø32mm (CB400-V) | C33: TCVN 1651-2:2018 | D33: Giới hạn chảy Re, độ bền kéo Rm, Rm/Re, uốn 180° | E33: <= 50 Tấn / lô / đường kính | F33: Tấn | G33: =SUMIFS(THONG_KE_THEP_CHI_TIET!$O$6:$O$399, THONG_KE_THEP_CHI_TIET!$E$6:$E$399, 32) | H33: 50 | I33: =ROUNDUP(G33/H33, 0) | J33: 3 thanh kéo + 3 thanh uốn | K33: LAS-XD hợp chuẩn | L33: Bắt buộc có KQTN trước khi gia công
A34: 11 | B34: Cáp thép DƯL 15.2mm (7 sợi xoắn) | C34: ASTM A416 / TCVN 10569 | D34: Giới hạn chảy, lực kéo đứt >=260.7kN, độ giãn dài | E34: <= 20-50 Tấn / lô sản xuất | F34: Tấn | G34: =SUMIFS(THONG_KE_THEP_CHI_TIET!$O$6:$O$399, THONG_KE_THEP_CHI_TIET!$E$6:$E$399, 15.2) | H34: 30 | I34: =ROUNDUP(G34/H34, 0) | J34: 3 tao cáp L=1.5m | K34: LAS-XD chuyên ngành | L34: Nghiệm thu trước khi xỏ cáp dầm
A35: 12 | B35: Xi măng PCB40 (bao hoặc xá rời) | C35: TCVN 6260:2020 | D35: Độ mịn, thời gian đông kết, nén R3, R7, R28 | E35: <= 100-200 Tấn / lô nhập kho | F35: Tấn | G35: =K18 | H35: 100 | I35: =ROUNDUP(G35/H35, 0) | J35: 1 tổ mẫu 10kg | K35: LAS-XD hợp chuẩn | L35: Kiểm tra từng lô xuất xưởng
A36: 13 | B36: Cát vàng đổ bê tông (Mk >= 2.5) | C36: TCVN 7570:2006 | D36: Thành phần hạt, mô đun Mk, độ bẩn bùn sét, hữu cơ | E36: <= 200-250 m3 / lô tập kết | F36: m3 | G36: =L18 | H36: 200 | I36: =ROUNDUP(G36/H36, 0) | J36: 1 tổ mẫu 20kg | K36: LAS-XD hợp chuẩn | L36: Nghiệm thu bãi cát trước khi trộn
A37: 14 | B37: Đá dăm 1x2 bê tông chọn lọc | C37: TCVN 7570:2006 | D37: Thành phần hạt, độ nén dập, thoi dẹt, bùn bụi sét | E37: <= 200-250 m3 / lô tập kết | F37: m3 | G37: =M18 | H37: 200 | I37: =ROUNDUP(G37/H37, 0) | J37: 1 tổ mẫu 50kg | K37: LAS-XD hợp chuẩn | L37: Rửa đá sạch trước khi nạp trạm trộn
A38: 15 | B38: Nước sạch trộn & bảo dưỡng bê tông | C38: TCVN 4506:2012 | D38: Hàm lượng muối tan, ion Cl-, pH, tạp chất hữu cơ | E38: 1 mẫu / nguồn cấp nước thi công | F38: Nguồn | G38: =N18 | H38: 1 | I38: =ROUNDUP(G38/H38, 0) | J38: 1 can 5 lít | K38: LAS-XD hợp chuẩn | L38: Chấp thuận nguồn nước trước khi thi công
A39: 16 | B39: Phụ gia hoá dẻo, siêu dẻo & chậm đông kết | C39: TCVN 8826:2011 | D39: Tỷ trọng, độ pH, hàm lượng Cl-, tương thích xi măng | E39: 1 mẫu / lô nhập xưởng (hoặc CO/CQ) | F39: Lô | G39: =O18 | H39: 1 | I39: =ROUNDUP(G39/H39, 0) | J39: 1 chai 1 lít / lô | K39: LAS-XD hợp chuẩn | L39: Chấp thuận trước khi trộn hàng loạt
A40: 17 | B40: Độ sụt bê tông tươi tại hiện trường | C40: TCVN 3106:1993 | D40: Đo độ sụt kiểm tra tính công tác hỗn hợp | E40: 100% các xe / mẻ trộn trước khi đổ | F40: Xe | G40: =ROUNDUP(J18/8, 0) | H40: 1 | I40: =ROUNDUP(G40/H40, 0) | J40: 1 nón thử sụt / xe | K40: Bộ phận KCS & TVGS | L40: Đạt độ sụt mới cho phép xả bê tông
A41: 18 | B41: Mẫu nén bê tông Cọc khoan nhồi C30 | C41: TCVN 3118:1993 | D41: Cường độ chịu nén mẫu lập phương R7, R28 | E41: Mỗi cọc 1-2 tổ (<= 50m3 / tổ mẫu) | F41: Tổ | G41: =J11 | H41: 20 | I41: =ROUNDUP(G41/H41, 0) | J41: 3 viên R7 + 3 viên R28 | K41: LAS-XD hợp chuẩn | L41: Đạt R28 nghiệm thu cấu kiện cọc
A42: 19 | B42: Mẫu nén bê tông Móng & Thân mố M1, M2 | C42: TCVN 3118:1993 | D42: Cường độ chịu nén mẫu lập phương R7, R28 | E42: <= 50m3 hoặc 1 ca đổ đúc 1 tổ | F42: Tổ | G42: =J12 | H42: 40 | I42: =ROUNDUP(G42/H42, 0) | J42: 3 viên R7 + 3 viên R28 | K42: LAS-XD hợp chuẩn | L42: Đạt R28 nghiệm thu chuyển bước
A43: 20 | B43: Mẫu nén bê tông Bệ trụ & Thân trụ T1, T2 | C43: TCVN 3118:1993 | D43: Cường độ chịu nén mẫu lập phương R7, R28 | E43: <= 50m3 hoặc 1 ca đổ đúc 1 tổ | F43: Tổ | G43: =J13 | H43: 40 | I43: =ROUNDUP(G43/H43, 0) | J43: 3 viên R7 + 3 viên R28 | K43: LAS-XD hợp chuẩn | L43: Đạt R28 cho phép thi công thân/xà mũ
A44: 21 | B44: Mẫu nén bê tông Xà mũ trụ T1, T2 C35 | C44: TCVN 3118:1993 | D44: Cường độ chịu nén mẫu lập phương R7, R28 | E44: <= 50m3 hoặc 1 ca đổ đúc 1 tổ | F44: Tổ | G44: =J14 | H44: 36 | I44: =ROUNDUP(G44/H44, 0) | J44: 3 viên R7 + 3 viên R28 | K44: LAS-XD hợp chuẩn | L44: Đạt R28 cho phép đặt gối và lao dầm
A45: 22 | B45: Mẫu nén bê tông Dầm Super-T C45 (15 phiến) | C45: TCVN 3118:1993 | D45: Cường độ nén trước kéo cáp >=85%, R7, R28 | E45: Mỗi phiến dầm tối thiểu 3 tổ mẫu | F45: Tổ | G45: =J16 | H45: 9.66 | I45: =ROUNDUP(G45/H45, 0) | J45: 3 tổ (9 viên) / phiến dầm | K45: LAS-XD hợp chuẩn | L45: Đạt R kéo >= 85% mới cho kích cáp
...

Sheet QS_DIEN_GIAI_CHI_TIET
B2: DỰ ÁN: CAO TỐC TUYÊN QUANG - HÀ GIANG (GIAI ĐOẠN 1) - ĐOẠN QUA TỈNH HÀ GIANG
B3: BẢNG DIỄN GIẢI TIÊN LƯỢNG KHỐI LƯỢNG HÌNH HỌC CHI TIẾT - CẦU KM19+529.080
B4: Tuân thủ nghiêm ngặt nguyên tắc 100% công thức động: Khối lượng = Dài x Rộng x Cao x Số lượng x Hệ số (CẤM SỐ CHẾT)
A5: TT | B5: Mã hiệu | C5: Nội dung công tác & Diễn giải hình học cấu kiện | D5: ĐVT | E5: Số lượng (Cấu kiện) | F5: Dài (m) | G5: Rộng (m) | H5: Cao / Dày (m) | I5: Hệ số hình học | J5: Khối lượng (Công thức) | K5: Đơn giá (VNĐ) | L5: Thành tiền (VNĐ)
A6: PHẦN I: THI CÔNG CỌC KHOAN NHỒI D1200MM & THÍ NGHIỆM KIỂM SOÁT
A7: 1 | B7: AC.11111 | C7: Khoan tạo lỗ cọc khoan nhồi D1200mm vào đất và đá gốc (26 cọc) | D7: m | J7: =SUM(J8:J11) | K7: 2850000 | L7: =J7*K7
C8: - Cọc mố M1: 3 cọc chiều sâu L=20.0m | D8: m | E8: 3 | F8: 20 | G8: 1 | H8: 1 | I8: 1 | J8: =E8*F8*G8*H8*I8
C9: - Cọc trụ T1: 8 cọc chiều sâu L=40.0m | D9: m | E9: 8 | F9: 40 | G9: 1 | H9: 1 | I9: 1 | J9: =E9*F9*G9*H9*I9
C10: - Cọc trụ T2: 8 cọc chiều sâu L=30.0m | D10: m | E10: 8 | F10: 30 | G10: 1 | H10: 1 | I10: 1 | J10: =E10*F10*G10*H10*I10
C11: - Cọc mố M2: 7 cọc chiều sâu L=36.0m | D11: m | E11: 7 | F11: 36 | G11: 1 | H11: 1 | I11: 1 | J11: =E11*F11*G11*H11*I11
A12: 2 | B12: AC.12111 | C12: Hạ và nhổ ống vách thép dẫn hướng D1300mm d=8mm (luân chuyển) | D12: m | J12: =SUM(J13:J16) | K12: 1450000 | L12: =J12*K12
C13: - Ống vách thép cọc mố M1 (3 cọc x 6m) | D13: m | E13: 3 | F13: 6 | G13: 1 | H13: 1 | I13: 1 | J13: =E13*F13*G13*H13*I13
C14: - Ống vách thép cọc trụ T1 (8 cọc x 6m) | D14: m | E14: 8 | F14: 6 | G14: 1 | H14: 1 | I14: 1 | J14: =E14*F14*G14*H14*I14
C15: - Ống vách thép cọc trụ T2 (8 cọc x 6m) | D15: m | E15: 8 | F15: 6 | G15: 1 | H15: 1 | I15: 1 | J15: =E15*F15*G15*H15*I15
C16: - Ống vách thép cọc mố M2 (7 cọc x 6m) | D16: m | E16: 7 | F16: 6 | G16: 1 | H16: 1 | I16: 1 | J16: =E16*F16*G16*H16*I16
A17: 3 | B17: AF.21111 | C17: Bê tông cọc khoan nhồi C30/37 đổ bằng phương pháp rút ống tremie | D17: m3 | J17: =SUM(J18:J21) | K17: 1650000 | L17: =J17*K17
C18: - Bê tông 3 cọc mố M1 (L=20m, D=1.2m, hs nở thành 1.12) | D18: m3 | E18: 3 | F18: 20 | G18: 0.6 | H18: 0.6 | I18: 3.5186 | J18: =E18*F18*G18*H18*I18
C19: - Bê tông 8 cọc trụ T1 (L=40m, D=1.2m, hs nở thành 1.12) | D19: m3 | E19: 8 | F19: 40 | G19: 0.6 | H19: 0.6 | I19: 3.5186 | J19: =E19*F19*G19*H19*I19
C20: - Bê tông 8 cọc trụ T2 (L=30m, D=1.2m, hs nở thành 1.12) | D20: m3 | E20: 8 | F20: 30 | G20: 0.6 | H20: 0.6 | I20: 3.5186 | J20: =E20*F20*G20*H20*I20
C21: - Bê tông 7 cọc mố M2 (L=36m, D=1.2m, hs nở thành 1.12) | D21: m3 | E21: 7 | F21: 36 | G21: 0.6 | H21: 0.6 | I21: 3.5186 | J21: =E21*F21*G21*H21*I21
A22: 4 | B22: AF.61111 | C22: Cốt thép cọc khoan nhồi D1200mm (Thép chủ D25, đai D16, D10) | D22: Tấn | J22: =SUMIFS(THONG_KE_THEP_CHI_TIET!$O$6:$O$399, THONG_KE_THEP_CHI_TIET!$B$6:$B$399, "*Cọc khoan nhồi*") | K22: 18500000 | L22: =J22*K22
C23: - Cốt thép cọc mố M1 (3 cọc x 5.889 tấn/cọc) | D23: Tấn | E23: 3 | F23: 5.889 | G23: 1 | H23: 1 | I23: 1 | J23: =E23*F23*G23*H23*I23
C24: - Cốt thép cọc trụ T1 (8 cọc x 4.845 tấn/cọc) | D24: Tấn | E24: 8 | F24: 4.845 | G24: 1 | H24: 1 | I24: 1 | J24: =E24*F24*G24*H24*I24
C25: - Cốt thép cọc trụ T2 (8 cọc x 3.687 tấn/cọc) | D25: Tấn | E25: 8 | F25: 3.687 | G25: 1 | H25: 1 | I25: 1 | J25: =E25*F25*G25*H25*I25
C26: - Cốt thép cọc mố M2 (7 cọc x 4.721 tấn/cọc) | D26: Tấn | E26: 7 | F26: 4.721 | G26: 1 | H26: 1 | I26: 1 | J26: =E26*F26*G26*H26*I26
A27: 5 | B27: AC.13111 | C27: Đập đầu cọc khoan nhồi nhô lên đáy bệ ngàm vào kết cấu | D27: m3 | J27: =SUM(J28:J28) | K27: 550000 | L27: =J27*K27
C28: - Đập đầu 26 cọc khoan nhồi (chiều cao đập h=1.0m) | D28: m3 | E28: 26 | F28: 1 | G28: 0.6 | H28: 0.6 | I28: 3.1416 | J28: =E28*F28*G28*H28*I28
A29: 6 | B29: TN.11111 | C29: Thí nghiệm kiểm soát cọc (Siêu âm 156 mặt cắt, PDA 9434kN, lấy lõi 4 cọc) | D29: Gói | J29: =SUM(J30:J30) | K29: 450000000 | L29: =J29*K29
C30: - Gói thí nghiệm siêu âm 100% cọc, nén động PDA trụ T1 & khoan lấy lõi | D30: Gói | E30: 1 | F30: 1 | G30: 1 | H30: 1 | I30: 1 | J30: =E30*F30*G30*H30*I30
A31: PHẦN II: KẾT CẤU PHẦN DƯỚI (BỆ, THÂN, XÀ MŨ MỐ M1, M2 & TRỤ T1, T2)
A32: 7 | B32: AB.11111 | C32: Đào đất đá hố móng bệ mố M1, M2 và bệ trụ T1, T2 (Link Sheet Đào Đắp) | D32: m3 | J32: =SUM(J33:J33) | K32: 145000 | L32: =J32*K32
C33: - Đào đất đá hố móng bệ mố M1,M2 & bệ trụ T1,T2 → =KHOI_LUONG_DAO_DAP!F21 | D33: m3 | E33: 1 | F33: 1 | G33: 1 | H33: 1 | I33: 1 | J33: 6245
A34: 8 | B34: AF.11111 | C34: Bê tông lót đáy bệ móng mác C10 dày 10cm | D34: m3 | J34: =SUM(J35:J38) | K34: 1150000 | L34: =J34*K34
C35: - Lớp bê tông lót đáy bệ mố M1 chân dê | D35: m3 | E35: 1 | F35: 12.5 | G35: 6 | H35: 0.1 | I35: 1 | J35: =E35*F35*G35*H35*I35
C36: - Lớp bê tông lót đáy bệ mố M2 chữ U | D36: m3 | E36: 1 | F36: 14 | G36: 6.5 | H36: 0.1 | I36: 1 | J36: =E36*F36*G36*H36*I36
C37: - Lớp bê tông lót đáy bệ trụ T1 | D37: m3 | E37: 1 | F37: 13 | G37: 6.5 | H37: 0.1 | I37: 1 | J37: =E37*F37*G37*H37*I37
C38: - Lớp bê tông lót đáy bệ trụ T2 | D38: m3 | E38: 1 | F38: 13 | G38: 6.5 | H38: 0.1 | I38: 1 | J38: =E38*F38*G38*H38*I38
A39: 9 | B39: AF.12111 | C39: Bê tông bệ móng mố M1, M2 và bệ trụ T1, T2 mác C30 | D39: m3 | J39: =SUM(J40:J43) | K39: 1480000 | L39: =J39*K39
C40: - Bệ móng mố M1 chân dê (chiều cao bệ h=2.0m) | D40: m3 | E40: 1 | F40: 12 | G40: 5.5 | H40: 2 | I40: 1.1287 | J40: =E40*F40*G40*H40*I40
C41: - Bệ móng mố M2 chữ U (chiều cao bệ h=2.0m) | D41: m3 | E41: 1 | F41: 13.5 | G41: 5.5 | H41: 2 | I41: 1.0033 | J41: =E41*F41*G41*H41*I41
...

Sheet THONG_KE_THEP_CHI_TIET
B2: DỰ ÁN: CAO TỐC TUYÊN QUANG - HÀ GIANG (GIAI ĐOẠN 1) - CẦU KM19+529.080
B3: BẢNG THỐNG KÊ CHI TIẾT CỐT THÉP TỪNG HẠNG MỤC CÔNG TRÌNH (BAR BENDING SCHEDULE - BBS)
B4: Trích xuất chi tiết theo Bản vẽ thi công BVTC: Số hiệu thanh, ký hiệu Ø, mác thép, hình dạng, chiều dài, số lượng, trọng lượng riêng và tổng trọng lượng
A5: TT | B5: Hạng mục kết cấu | C5: Bộ phận cấu kiện | D5: Ký hiệu thanh | E5: Đường kính Ø (mm) | F5: Mác thép | G5: Hình dạng thanh | H5: Chiều dài 1 thanh (m) | I5: Số thanh / cấu kiện | J5: Số cấu kiện | K5: Tổng số thanh | L5: Tổng chiều dài (m) | M5: Trọng lượng 1m (kg/m) | N5: Tổng khối lượng (kg) | O5: Tổng khối lượng (Tấn) | P5: Phân nhóm Ø | Q5: Ghi chú & Tiêu chuẩn
A6: 02. KẾT CẤU PHẦN DƯỚI (SUBSTRUCTURE)
A7: 1 | B7: Mố M1 | C7: BỆ MỐ | D7: F1 | E7: 28 | F7: CB400-V | G7: S06 | H7: 6.578 | I7: 83 | J7: 1 | K7: =I7*J7 | L7: =H7*K7 | M7: 4.83 | N7: =L7*M7 | O7: =N7/1000 | P7: D>18mm | Q7: TCVN 1651:2018 / ASTM
A8: 2 | B8: Mố M1 | C8: Thân mố / Bệ mố | D8: F2 | E8: 18 | F8: CB400-V | G8: S06 | H8: 13.571 | I8: 40 | J8: 1 | K8: =I8*J8 | L8: =H8*K8 | M8: 2 | N8: =L8*M8 | O8: =N8/1000 | P8: 10<D<=18mm | Q8: TCVN 1651:2018 / ASTM
A9: 3 | B9: Mố M1 | C9: Thân mố / Bệ mố | D9: F3 | E9: 18 | F9: CB400-V | G9: S06 | H9: 6.336 | I9: 83 | J9: 1 | K9: =I9*J9 | L9: =H9*K9 | M9: 2 | N9: =L9*M9 | O9: =N9/1000 | P9: 10<D<=18mm | Q9: TCVN 1651:2018 / ASTM
A10: 4 | B10: Mố M1 | C10: Thân mố / Bệ mố | D10: F4 | E10: 18 | F10: CB400-V | G10: S06 | H10: 13.571 | I10: 30 | J10: 1 | K10: =I10*J10 | L10: =H10*K10 | M10: 2 | N10: =L10*M10 | O10: =N10/1000 | P10: 10<D<=18mm | Q10: TCVN 1651:2018 / ASTM
A11: 5 | B11: Mố M1 | C11: Thân mố / Bệ mố | D11: F5 | E11: 16 | F11: CB400-V | G11: S01 | H11: 5.85 | I11: 16 | J11: 1 | K11: =I11*J11 | L11: =H11*K11 | M11: 1.58 | N11: =L11*M11 | O11: =N11/1000 | P11: 10<D<=18mm | Q11: TCVN 1651:2018 / ASTM
A12: 6 | B12: Mố M1 | C12: Thân mố / Bệ mố | D12: F6 | E12: 16 | F12: CB400-V | G12: S06 | H12: 1.99 | I12: 182 | J12: 1 | K12: =I12*J12 | L12: =H12*K12 | M12: 1.58 | N12: =L12*M12 | O12: =N12/1000 | P12: 10<D<=18mm | Q12: TCVN 1651:2018 / ASTM
A13: 7 | B13: Mố M1 | C13: Thân mố / Bệ mố | D13: F7 | E13: 16 | F13: CB400-V | G13: S01 | H13: 13.005 | I13: 16 | J13: 1 | K13: =I13*J13 | L13: =H13*K13 | M13: 1.58 | N13: =L13*M13 | O13: =N13/1000 | P13: 10<D<=18mm | Q13: TCVN 1651:2018 / ASTM
A14: 8 | B14: Mố M1 | C14: Thân mố / Bệ mố | D14: F8 | E14: 16 | F14: CB400-V | G14: S06 | H14: 1.99 | I14: 140 | J14: 1 | K14: =I14*J14 | L14: =H14*K14 | M14: 1.58 | N14: =L14*M14 | O14: =N14/1000 | P14: 10<D<=18mm | Q14: TCVN 1651:2018 / ASTM
A15: 9 | B15: Mố M1 | C15: TƯỜNG THÂN | D15: A1 | E15: 22 | F15: CB400-V | G15: S02 | H15: 7.438 | I15: 73 | J15: 1 | K15: =I15*J15 | L15: =H15*K15 | M15: 2.98 | N15: =L15*M15 | O15: =N15/1000 | P15: D>18mm | Q15: TCVN 1651:2018 / ASTM
A16: 10 | B16: Mố M1 | C16: Thân mố / Bệ mố | D16: A2 | E16: 16 | F16: CB400-V | G16: S06 | H16: 13.487 | I16: 35 | J16: 1 | K16: =I16*J16 | L16: =H16*K16 | M16: 1.58 | N16: =L16*M16 | O16: =N16/1000 | P16: 10<D<=18mm | Q16: TCVN 1651:2018 / ASTM
A17: 11 | B17: Mố M1 | C17: Thân mố / Bệ mố | D17: A3 | E17: 16 | F17: CB400-V | G17: S02 | H17: 7.357 | I17: 83 | J17: 1 | K17: =I17*J17 | L17: =H17*K17 | M17: 1.58 | N17: =L17*M17 | O17: =N17/1000 | P17: 10<D<=18mm | Q17: TCVN 1651:2018 / ASTM
A18: 12 | B18: Mố M1 | C18: Thân mố / Bệ mố | D18: A4 | E18: 16 | F18: CB400-V | G18: S06 | H18: 13.487 | I18: 34 | J18: 1 | K18: =I18*J18 | L18: =H18*K18 | M18: 1.58 | N18: =L18*M18 | O18: =N18/1000 | P18: 10<D<=18mm | Q18: TCVN 1651:2018 / ASTM
... A228: 222 | B228: Trụ T1, T2 (Xà mũ trụ) | C228: Xà mũ trụ | D228: U4 | E228: 8 | F228: CB240-T | G228: S32 | H228: 1.837 | I228: 24 | J228: 1 | K228: =I228*J228 | L228: =H228*K228 | M228: 0.395 | N228: =L228*M228 | O228: =N228/1000 | P228: D<=10mm | Q228: TCVN 1651:2018 / ASTM
A229: 03. KẾT CẤU PHẦN TRÊN (SUPERSTRUCTURE)
A230: 223 | B230: Dầm chủ Super-T (15 phiến L=38.2m) | C230: Sườn dầm / Cánh dầm | D230: G1a | E230: 16 | F230: CB400-V | G230: S06 | H230: 5.056 | I230: 2160 | J230: 1 | K230: =I230*J230 | L230: =H230*K230 | M230: 1.58 | N230: =L230*M230 | O230: =N230/1000 | P230: 10<D<=18mm | Q230: TCVN 1651:2018 / ASTM
A231: 224 | B231: Dầm chủ Super-T (15 phiến L=38.2m) | C231: Sườn dầm / Cánh dầm | D231: G1b | E231: 12 | F231: CB400-V | G231: S06 | H231: 5.075 | I231: 1875 | J231: 1 | K231: =I231*J231 | L231: =H231*K231 | M231: 0.888 | N231: =L231*M231 | O231: =N231/1000 | P231: 10<D<=18mm | Q231: TCVN 1651:2018 / ASTM
A232: 225 | B232: Dầm chủ Super-T (15 phiến L=38.2m) | C232: Sườn dầm / Cánh dầm | D232: G2 | E232: 12 | F232: CB400-V | G232: S06 | H232: 1.184 | I232: 3825 | J232: 1 | K232: =I232*J232 | L232: =H232*K232 | M232: 0.888 | N232: =L232*M232 | O232: =N232/1000 | P232: 10<D<=18mm | Q232: TCVN 1651:2018 / ASTM
A233: 226 | B233: Dầm chủ Super-T (15 phiến L=38.2m) | C233: Sườn dầm / Cánh dầm | D233: G2a | E233: 12 | F233: CB400-V | G233: S06 | H233: 1.309 | I233: 4035 | J233: 1 | K233: =I233*J233 | L233: =H233*K233 | M233: 0.888 | N233: =L233*M233 | O233: =N233/1000 | P233: 10<D<=18mm | Q233: TCVN 1651:2018 / ASTM
A234: 227 | B234: Dầm chủ Super-T (15 phiến L=38.2m) | C234: Sườn dầm / Cánh dầm | D234: G3 | E234: 12 | F234: CB400-V | G234: S06 | H234: 1.259 | I234: 4035 | J234: 1 | K234: =I234*J234 | L234: =H234*K234 | M234: 0.888 | N234: =L234*M234 | O234: =N234/1000 | P234: 10<D<=18mm | Q234: TCVN 1651:2018 / ASTM
A235: 228 | B235: Dầm chủ Super-T (15 phiến L=38.2m) | C235: Sườn dầm / Cánh dầm | D235: G4a1 | E235: 12 | F235: CB400-V | G235: S01 | H235: 11.7 | I235: 315 | J235: 1 | K235: =I235*J235 | L235: =H235*K235 | M235: 0.888 | N235: =L235*M235 | O235: =N235/1000 | P235: 10<D<=18mm | Q235: TCVN 1651:2018 / ASTM
A236: 229 | B236: Dầm chủ Super-T (15 phiến L=38.2m) | C236: Sườn dầm / Cánh dầm | D236: G4a2 | E236: 12 | F236: CB400-V | G236: S06 | H236: 4.46 | I236: 105 | J236: 1 | K236: =I236*J236 | L236: =H236*K236 | M236: 0.888 | N236: =L236*M236 | O236: =N236/1000 | P236: 10<D<=18mm | Q236: TCVN 1651:2018 / ASTM
A237: 230 | B237: Dầm chủ Super-T (15 phiến L=38.2m) | C237: Sườn dầm / Cánh dầm | D237: G4b1 | E237: 12 | F237: CB400-V | G237: S01 | H237: 11.7 | I237: 180 | J237: 1 | K237: =I237*J237 | L237: =H237*K237 | M237: 0.888 | N237: =L237*M237 | O237: =N237/1000 | P237: 10<D<=18mm | Q237: TCVN 1651:2018 / ASTM
A238: 231 | B238: Dầm chủ Super-T (15 phiến L=38.2m) | C238: Sườn dầm / Cánh dầm | D238: G4b2 | E238: 12 | F238: CB400-V | G238: S06 | H238: 3.06 | I238: 60 | J238: 1 | K238: =I238*J238 | L238: =H238*K238 | M238: 0.888 | N238: =L238*M238 | O238: =N238/1000 | P238: 10<D<=18mm | Q238: TCVN 1651:2018 / ASTM
A239: 232 | B239: Dầm chủ Super-T (15 phiến L=38.2m) | C239: Sườn dầm / Cánh dầm | D239: G5a | E239: 16 | F239: CB400-V | G239: S01 | H239: 11.7 | I239: 420 | J239: 1 | K239: =I239*J239 | L239: =H239*K239 | M239: 1.58 | N239: =L239*M239 | O239: =N239/1000 | P239: 10<D<=18mm | Q239: TCVN 1651:2018 / ASTM
A240: 233 | B240: Dầm chủ Super-T (15 phiến L=38.2m) | C240: Sườn dầm / Cánh dầm | D240: G5b | E240: 18 | F240: CB400-V | G240: S06 | H240: 2.86 | I240: 210 | J240: 1 | K240: =I240*J240 | L240: =H240*K240 | M240: 2 | N240: =L240*M240 | O240: =N240/1000 | P240: 10<D<=18mm | Q240: TCVN 1651:2018 / ASTM
A241: 234 | B241: Dầm chủ Super-T (15 phiến L=38.2m) | C241: Sườn dầm / Cánh dầm | D241: G5c | E241: 16 | F241: CB400-V | G241: S01 | H241: 10.68 | I241: 210 | J241: 1 | K241: =I241*J241 | L241: =H241*K241 | M241: 1.58 | N241: =L241*M241 | O241: =N241/1000 | P241: 10<D<=18mm | Q241: TCVN 1651:2018 / ASTM
... A354: 347 | B354: Bản liên tục nhiệt (Link Slab) | C354: Liên tục nhiệt trên đỉnh trụ T1, T2 | D354: 18 | E354: 108 | F354: CB400-V | G354: S01 | H354: 0.002 | I354: 2100 | J354: 1 | K354: =I354*J354 | L354: =H354*K354 | M354: 453.6 | N354: =L354*M354 | O354: =N354/1000 | P354: D>18mm | Q354: TCVN 1651:2018 / ASTM
A355: 04. CÔNG TRÌNH PHỤ TRỢ (MISCELLANEOUS)
A356: 348 | B356: Bản quá độ Mố M1 | C356: Bản quá độ tiếp giáp mố | D356: A1 | E356: 16 | F356: CB400-V | G356: S06 | H356: 6.332 | I356: 57 | J356: 1 | K356: =I356*J356 | L356: =H356*K356 | M356: 1.58 | N356: =L356*M356 | O356: =N356/1000 | P356: 10<D<=18mm | Q356: TCVN 1651:2018 / ASTM
A357: 349 | B357: Bản quá độ Mố M1 | C357: Bản quá độ tiếp giáp mố | D357: A2 | E357: 16 | F357: CB400-V | G357: S06 | H357: 12.447 | I357: 30 | J357: 1 | K357: =I357*J357 | L357: =H357*K357 | M357: 1.58 | N357: =L357*M357 | O357: =N357/1000 | P357: 10<D<=18mm | Q357: TCVN 1651:2018 / ASTM
A358: 350 | B358: Bản quá độ Mố M1 | C358: Bản quá độ tiếp giáp mố | D358: A3 | E358: 20 | F358: CB400-V | G358: S06 | H358: 6.3 | I358: 113 | J358: 1 | K358: =I358*J358 | L358: =H358*K358 | M358: 2.47 | N358: =L358*M358 | O358: =N358/1000 | P358: D>18mm | Q358: TCVN 1651:2018 / ASTM
A359: 351 | B359: Bản quá độ Mố M1 | C359: Bản quá độ tiếp giáp mố | D359: A4 | E359: 16 | F359: CB400-V | G359: S06 | H359: 12.447 | I359: 30 | J359: 1 | K359: =I359*J359 | L359: =H359*K359 | M359: 1.58 | N359: =L359*M359 | O359: =N359/1000 | P359: 10<D<=18mm | Q359: TCVN 1651:2018 / ASTM
A360: 352 | B360: Bản quá độ Mố M1 | C360: Bản quá độ tiếp giáp mố | D360: A5 | E360: 18 | F360: CB400-V | G360: S29 | H360: 1.629 | I360: 113 | J360: 1 | K360: =I360*J360 | L360: =H360*K360 | M360: 2 | N360: =L360*M360 | O360: =N360/1000 | P360: 10<D<=18mm | Q360: TCVN 1651:2018 / ASTM
A361: 353 | B361: Bản quá độ Mố M1 | C361: Bản quá độ tiếp giáp mố | D361: A6 | E361: 12 | F361: CB400-V | G361: S06 | H361: 0.396 | I361: 222 | J361: 1 | K361: =I361*J361 | L361: =H361*K361 | M361: 0.888 | N361: =L361*M361 | O361: =N361/1000 | P361: 10<D<=18mm | Q361: TCVN 1651:2018 / ASTM
A362: 354 | B362: Bản quá độ Mố M1 | C362: Bản quá độ tiếp giáp mố | D362: A7 | E362: 10 | F362: CB240-T | G362: S32 | H362: 0.676 | I362: 23 | J362: 1 | K362: =I362*J362 | L362: =H362*K362 | M362: 0.617 | N362: =L362*M362 | O362: =N362/1000 | P362: D<=10mm | Q362: TCVN 1651:2018 / ASTM
...
