Workbook

Sheet HOSO_KCS_NGHIEM_THU
B2: DỰ ÁN: CAO TỐC TUYÊN QUANG - HÀ GIANG (GIAI ĐOẠN 1) - ĐOẠN QUA TỈNH HÀ GIANG
B3: DANH MỤC HỒ SƠ QUẢN LÝ CHẤT LƯỢNG & BIÊN BẢN NGHIỆM THU KCS - CẦU KM19+529.080
B4: Tuân thủ Luật Xây dựng số 135/2025/QH15 & Nghị định 207/2026/NĐ-CP (Khối lượng link trực tiếp từ Sheet QS)
A5: STT | B5: Số hiệu biên bản | C5: Tên công việc / Giai đoạn nghiệm thu KCS | D5: Khối lượng nghiệm thu | E5: ĐVT | F5: Căn cứ quy chuẩn / Tiêu chuẩn áp dụng | G5: Chỉ tiêu thí nghiệm & Điểm kiểm soát (Hold Points) | H5: Ngày nghiệm thu hoàn thành
A6: 1 | B6: BBNT-01 | C6: Bàn giao tim mốc VN2000, cao độ Hòn Dấu & tim mốc cầu Km19+529.080 | D6: 1 | E6: Điểm | F6: TCVN 9393:2012 | G6: Sai số tọa độ tim mốc <= 5mm, mốc cao độ <= 2mm | H6: =TIEN_DO_THI_CONG_WBS!J8
A7: 2 | B7: BBNT-02 | C7: Nghiệm thu dọn dẹp mặt bằng, thi công đường công vụ nhánh 6 & 6A | D7: =KHOI_LUONG_DAO_DAP!F19 | E7: m3 | F7: TCVN 4447:2012 | G7: Độ dầm chặt nền đường K >= 0.95, thoát nước tốt | H7: =TIEN_DO_THI_CONG_WBS!J10
A8: 3 | B8: BBNT-03 | C8: Kiểm tra nghiệm thu chất lượng vật liệu đầu vào (Thép, Cáp DUL, Xi măng) | D8: 1 | E8: Lô | F8: TCVN 1651:2018, ASTM A416 | G8: Chứng chỉ CO/CQ, thí nghiệm kéo uốn thép, nén xi măng | H8: =TIEN_DO_THI_CONG_WBS!I8
A9: 4 | B9: BBNT-04 | C9: Nghiệm thu trạm trộn BTXM, trạm biến áp & bệ đúc dầm Super-T | D9: 1 | E9: Hệ | F9: TCVN 9340:2012 | G9: Độ chính xác cân đong sai số <= 1%, bệ đúc đủ độ cứng | H9: =TIEN_DO_THI_CONG_WBS!J11
A10: 5 | B10: BBNT-05 | C10: Nghiệm thu định vị tim cọc & hạ ống vách thép dẫn hướng D1300mm | D10: =QS_DIEN_GIAI_CHI_TIET!J12 | E10: m | F10: TCVN 11823:2017 | G10: Độ nghiêng ống vách <= 1%, sai số tim cọc <= 50mm | H10: =TIEN_DO_THI_CONG_WBS!I14
A11: 6 | B11: BBNT-06 | C11: Nghiệm thu khoan thăm dò hang Karst sâu 5m dưới mũi cọc | D11: 26 | E11: Lỗ | F11: Chỉ dẫn TK Trang 11 | G11: Khoan vào đá liền khối tối thiểu 5m, không rỗng Karst | H11: =TIEN_DO_THI_CONG_WBS!J13
A12: 7 | B12: BBNT-07 | C12: Nghiệm thu hố khoan cọc D1200mm, thổi rửa đáy & kiểm tra dung dịch | D12: =QS_DIEN_GIAI_CHI_TIET!J7 | E12: m | F12: TCVN 9395:2012 | G12: Chiều dày cặn lắng đáy <= 50mm, tỷ trọng bentonite 1.05-1.15 | H12: =TIEN_DO_THI_CONG_WBS!J14
A13: 8 | B13: BBNT-08 | C13: Nghiệm thu gia công, lắp dựng lồng cốt thép & ống siêu âm cọc nhồi | D13: =QS_DIEN_GIAI_CHI_TIET!J22 | E13: Tấn | F13: TCVN 4453:1995 | G13: Chiều dài lồng thép, mối nối coupler, ống siêu âm kín nước | H13: =TIEN_DO_THI_CONG_WBS!J15
A14: 9 | B14: BBNT-09 | C14: Nghiệm thu đổ bê tông cọc khoan nhồi C30 bằng ống tremie | D14: =QS_DIEN_GIAI_CHI_TIET!J17 | E14: m3 | F14: TCVN 9395:2012 | G14: Độ sụt 18+-2cm, ống tremie ngập bê tông >= 2.0m liên tục | H14: =TIEN_DO_THI_CONG_WBS!J17
A15: 10 | B15: BBNT-10 | C15: Nghiệm thu thí nghiệm kiểm tra cọc (Siêu âm 100%, lõi bê tông & PDA) | D15: 1 | E15: Gói | F15: TCVN 9396, ASTM D4945 | G15: Siêu âm 156 mặt cắt; PDA trụ T1 đạt tải trọng 9434 kN | H15: =TIEN_DO_THI_CONG_WBS!J18
A16: 11 | B16: BBNT-11 | C16: Nghiệm thu đào hố móng, đập đầu 26 cọc & đổ bê tông lót bệ mác C10 | D16: =QS_DIEN_GIAI_CHI_TIET!J34 | E16: m3 | F16: TCVN 4453:1995 | G16: Đầu cọc ngàm vào bệ 10cm, cốt thép cọc neo sâu 40D | H16: =TIEN_DO_THI_CONG_WBS!J20
A17: 12 | B17: BBNT-12 | C17: Nghiệm thu ván khuôn, cốt thép & đổ bê tông bệ mố M1, M2 & bệ trụ T1, T2 C30 | D17: =QS_DIEN_GIAI_CHI_TIET!J39 | E17: m3 | F17: TCVN 3105:2022 | G17: Kích thước hình học bệ, 12 tổ mẫu thử nén đạt C30 | H17: =TIEN_DO_THI_CONG_WBS!J22
A18: 13 | B18: BBNT-13 | C18: Nghiệm thu thân mố chân dê M1 và thân mố chữ U M2 bê tông C30 | D18: =QS_DIEN_GIAI_CHI_TIET!J44 | E18: m3 | F18: TCVN 11823:2017 | G18: Độ thẳng đứng thân mố, bề mặt bê tông phẳng nhẵn | H18: =TIEN_DO_THI_CONG_WBS!J24
A19: 14 | B19: BBNT-14 | C19: Nghiệm thu cốt thép, ván khuôn & đổ bê tông thân đặc trụ T1, T2 C30 | D19: =QS_DIEN_GIAI_CHI_TIET!J50 | E19: m3 | F19: TCVN 4453:1995 | G19: Kích thước thân đặc 9.75x2.0m, chiều cao H=14.5m và 11.4m | H19: =TIEN_DO_THI_CONG_WBS!J23
A20: 15 | B20: BBNT-15 | C20: Nghiệm thu cốt thép, ván khuôn & đổ bê tông xà mũ trụ T1, T2, đá kê gối | D20: =QS_DIEN_GIAI_CHI_TIET!J53 | E20: m3 | F20: TCVN 11823:2017 | G20: Cao độ mặt đá kê gối sai số <= 2mm, tim đá kê <= 3mm | H20: =TIEN_DO_THI_CONG_WBS!J25
A21: 16 | B21: BBNT-16 | C21: Nghiệm thu cốt thép, ván khuôn & đổ bê tông C45 15 phiến dầm Super-T | D21: =QS_DIEN_GIAI_CHI_TIET!J62 | E21: m3 | F21: TCVN 3105:2022 | G21: Cường độ bê tông đạt R28 >= 45 MPa, không rỗ nứt | H21: =TIEN_DO_THI_CONG_WBS!J28
A22: 17 | B22: BBNT-17 | C22: Nghiệm thu căng kéo cáp DUL 15.2mm & bơm vữa ống gen dầm Super-T | D22: =QS_DIEN_GIAI_CHI_TIET!J64 | E22: Tấn | F22: TCVN 11823:2017 | G22: Sai số độ giãn dài cáp <= +-5%, vữa bơm lấp đầy 100% gen | H22: =TIEN_DO_THI_CONG_WBS!J29
A23: 18 | B23: BBNT-18 | C23: Nghiệm thu lắp đặt 30 gối chậu cao su & lao lắp 15 phiến dầm Super-T | D23: =QS_DIEN_GIAI_CHI_TIET!J70 | E23: Cái | F23: TCVN 10308:2014 | G23: Gối chậu nằm ngang chuẩn xác, dầm đặt êm thuận trên mố trụ | H23: =TIEN_DO_THI_CONG_WBS!J31
A24: 19 | B24: BBNT-19 | C24: Nghiệm thu đổ bê tông dầm ngang & mối nối liên tục nhiệt đỉnh trụ T1, T2 | D24: =QS_DIEN_GIAI_CHI_TIET!J73+QS_DIEN_GIAI_CHI_TIET!J79 | E24: m3 | F24: TCVN 4453:1995 | G24: Liên kết cứng dầm ngang, bản liên tục nhiệt triệt tiêu khe nứt | H24: =TIEN_DO_THI_CONG_WBS!J33
A25: 20 | B25: BBNT-20 | C25: Nghiệm thu cốt thép, ván khuôn & đổ bê tông bản mặt cầu C35 dày 180mm | D25: =QS_DIEN_GIAI_CHI_TIET!J77 | E25: m3 | F25: TCVN 11823:2017 | G25: Độ dốc ngang thoát nước 2%, chiều dày bảo vệ cốt thép chuẩn | H25: =TIEN_DO_THI_CONG_WBS!J35
A26: 21 | B26: BBNT-21 | C26: Nghiệm thu khe co giãn răng lược D=100mm, gờ lan can & thảm BTN C16 | D26: =QS_DIEN_GIAI_CHI_TIET!J84+QS_DIEN_GIAI_CHI_TIET!J86 | E26: m2 | F26: TCVN 8819:2011 | G26: Độ bằng phẳng mặt cầu IRI <= 1.5, khe răng lược êm thuận | H26: =TIEN_DO_THI_CONG_WBS!J39
A27: 22 | B27: BBNT-22 | C27: Nghiệm thu thử tải tĩnh/động toàn cầu & nghiệm thu hoàn thành đưa vào sử dụng | D27: 1 | E27: Gói | F27: Nghị định 207/2026/NĐ-CP | G27: Độ võng tĩnh f <= f_cp, hệ số xung kích động đạt tiêu chuẩn | H27: =TIEN_DO_THI_CONG_WBS!J42

Sheet QS_DIEN_GIAI_CHI_TIET
B2: DỰ ÁN: CAO TỐC TUYÊN QUANG - HÀ GIANG (GIAI ĐOẠN 1) - ĐOẠN QUA TỈNH HÀ GIANG
B3: BẢNG DIỄN GIẢI TIÊN LƯỢNG KHỐI LƯỢNG HÌNH HỌC CHI TIẾT - CẦU KM19+529.080
B4: Tuân thủ nghiêm ngặt nguyên tắc 100% công thức động: Khối lượng = Dài x Rộng x Cao x Số lượng x Hệ số (CẤM SỐ CHẾT)
A5: TT | B5: Mã hiệu | C5: Nội dung công tác & Diễn giải hình học cấu kiện | D5: ĐVT | E5: Số lượng (Cấu kiện) | F5: Dài (m) | G5: Rộng (m) | H5: Cao / Dày (m) | I5: Hệ số hình học | J5: Khối lượng (Công thức) | K5: Đơn giá (VNĐ) | L5: Thành tiền (VNĐ)
A6: PHẦN I: THI CÔNG CỌC KHOAN NHỒI D1200MM & THÍ NGHIỆM KIỂM SOÁT
A7: 1 | B7: AC.11111 | C7: Khoan tạo lỗ cọc khoan nhồi D1200mm vào đất và đá gốc (26 cọc) | D7: m | J7: =SUM(J8:J11) | K7: 2850000 | L7: =J7*K7
C8: - Cọc mố M1: 3 cọc chiều sâu L=20.0m | D8: m | E8: 3 | F8: 20 | G8: 1 | H8: 1 | I8: 1 | J8: =E8*F8*G8*H8*I8
C9: - Cọc trụ T1: 8 cọc chiều sâu L=40.0m | D9: m | E9: 8 | F9: 40 | G9: 1 | H9: 1 | I9: 1 | J9: =E9*F9*G9*H9*I9
C10: - Cọc trụ T2: 8 cọc chiều sâu L=30.0m | D10: m | E10: 8 | F10: 30 | G10: 1 | H10: 1 | I10: 1 | J10: =E10*F10*G10*H10*I10
C11: - Cọc mố M2: 7 cọc chiều sâu L=36.0m | D11: m | E11: 7 | F11: 36 | G11: 1 | H11: 1 | I11: 1 | J11: =E11*F11*G11*H11*I11
A12: 2 | B12: AC.12111 | C12: Hạ và nhổ ống vách thép dẫn hướng D1300mm d=8mm (luân chuyển) | D12: m | J12: =SUM(J13:J16) | K12: 1450000 | L12: =J12*K12
C13: - Ống vách thép cọc mố M1 (3 cọc x 6m) | D13: m | E13: 3 | F13: 6 | G13: 1 | H13: 1 | I13: 1 | J13: =E13*F13*G13*H13*I13
C14: - Ống vách thép cọc trụ T1 (8 cọc x 6m) | D14: m | E14: 8 | F14: 6 | G14: 1 | H14: 1 | I14: 1 | J14: =E14*F14*G14*H14*I14
C15: - Ống vách thép cọc trụ T2 (8 cọc x 6m) | D15: m | E15: 8 | F15: 6 | G15: 1 | H15: 1 | I15: 1 | J15: =E15*F15*G15*H15*I15
C16: - Ống vách thép cọc mố M2 (7 cọc x 6m) | D16: m | E16: 7 | F16: 6 | G16: 1 | H16: 1 | I16: 1 | J16: =E16*F16*G16*H16*I16
A17: 3 | B17: AF.21111 | C17: Bê tông cọc khoan nhồi C30/37 đổ bằng phương pháp rút ống tremie | D17: m3 | J17: =SUM(J18:J21) | K17: 1650000 | L17: =J17*K17
C18: - Bê tông 3 cọc mố M1 (L=20m, D=1.2m, hs nở thành 1.12) | D18: m3 | E18: 3 | F18: 20 | G18: 0.6 | H18: 0.6 | I18: 3.5186 | J18: =E18*F18*G18*H18*I18
C19: - Bê tông 8 cọc trụ T1 (L=40m, D=1.2m, hs nở thành 1.12) | D19: m3 | E19: 8 | F19: 40 | G19: 0.6 | H19: 0.6 | I19: 3.5186 | J19: =E19*F19*G19*H19*I19
C20: - Bê tông 8 cọc trụ T2 (L=30m, D=1.2m, hs nở thành 1.12) | D20: m3 | E20: 8 | F20: 30 | G20: 0.6 | H20: 0.6 | I20: 3.5186 | J20: =E20*F20*G20*H20*I20
C21: - Bê tông 7 cọc mố M2 (L=36m, D=1.2m, hs nở thành 1.12) | D21: m3 | E21: 7 | F21: 36 | G21: 0.6 | H21: 0.6 | I21: 3.5186 | J21: =E21*F21*G21*H21*I21
A22: 4 | B22: AF.61111 | C22: Cốt thép cọc khoan nhồi D1200mm (Thép chủ D25, đai D16, D10) | D22: Tấn | J22: 108.76599 | K22: 18500000 | L22: =J22*K22
C23: - Cốt thép cọc mố M1 (3 cọc x 5.889 tấn/cọc) | D23: Tấn | E23: 3 | F23: 5.889 | G23: 1 | H23: 1 | I23: 1 | J23: =E23*F23*G23*H23*I23
C24: - Cốt thép cọc trụ T1 (8 cọc x 4.845 tấn/cọc) | D24: Tấn | E24: 8 | F24: 4.845 | G24: 1 | H24: 1 | I24: 1 | J24: =E24*F24*G24*H24*I24
C25: - Cốt thép cọc trụ T2 (8 cọc x 3.687 tấn/cọc) | D25: Tấn | E25: 8 | F25: 3.687 | G25: 1 | H25: 1 | I25: 1 | J25: =E25*F25*G25*H25*I25
C26: - Cốt thép cọc mố M2 (7 cọc x 4.721 tấn/cọc) | D26: Tấn | E26: 7 | F26: 4.721 | G26: 1 | H26: 1 | I26: 1 | J26: =E26*F26*G26*H26*I26
A27: 5 | B27: AC.13111 | C27: Đập đầu cọc khoan nhồi nhô lên đáy bệ ngàm vào kết cấu | D27: m3 | J27: =SUM(J28:J28) | K27: 550000 | L27: =J27*K27
C28: - Đập đầu 26 cọc khoan nhồi (chiều cao đập h=1.0m) | D28: m3 | E28: 26 | F28: 1 | G28: 0.6 | H28: 0.6 | I28: 3.1416 | J28: =E28*F28*G28*H28*I28
A29: 6 | B29: TN.11111 | C29: Thí nghiệm kiểm soát cọc (Siêu âm 156 mặt cắt, PDA 9434kN, lấy lõi 4 cọc) | D29: Gói | J29: =SUM(J30:J30) | K29: 450000000 | L29: =J29*K29
C30: - Gói thí nghiệm siêu âm 100% cọc, nén động PDA trụ T1 & khoan lấy lõi | D30: Gói | E30: 1 | F30: 1 | G30: 1 | H30: 1 | I30: 1 | J30: =E30*F30*G30*H30*I30
A31: PHẦN II: KẾT CẤU PHẦN DƯỚI (BỆ, THÂN, XÀ MŨ MỐ M1, M2 & TRỤ T1, T2)
A32: 7 | B32: AB.11111 | C32: Đào đất đá hố móng bệ mố M1, M2 và bệ trụ T1, T2 (Link Sheet Đào Đắp) | D32: m3 | J32: =SUM(J33:J33) | K32: 145000 | L32: =J32*K32
C33: - Đào đất đá hố móng bệ mố M1,M2 & bệ trụ T1,T2 → =KHOI_LUONG_DAO_DAP!F21 | D33: m3 | E33: 1 | F33: 1 | G33: 1 | H33: 1 | I33: 1 | J33: =KHOI_LUONG_DAO_DAP!F21
A34: 8 | B34: AF.11111 | C34: Bê tông lót đáy bệ móng mác C10 dày 10cm | D34: m3 | J34: =SUM(J35:J38) | K34: 1150000 | L34: =J34*K34
C35: - Lớp bê tông lót đáy bệ mố M1 chân dê | D35: m3 | E35: 1 | F35: 12.5 | G35: 6 | H35: 0.1 | I35: 1 | J35: =E35*F35*G35*H35*I35
C36: - Lớp bê tông lót đáy bệ mố M2 chữ U | D36: m3 | E36: 1 | F36: 14 | G36: 6.5 | H36: 0.1 | I36: 1 | J36: =E36*F36*G36*H36*I36
C37: - Lớp bê tông lót đáy bệ trụ T1 | D37: m3 | E37: 1 | F37: 13 | G37: 6.5 | H37: 0.1 | I37: 1 | J37: =E37*F37*G37*H37*I37
C38: - Lớp bê tông lót đáy bệ trụ T2 | D38: m3 | E38: 1 | F38: 13 | G38: 6.5 | H38: 0.1 | I38: 1 | J38: =E38*F38*G38*H38*I38
A39: 9 | B39: AF.12111 | C39: Bê tông bệ móng mố M1, M2 và bệ trụ T1, T2 mác C30 | D39: m3 | J39: =SUM(J40:J43) | K39: 1480000 | L39: =J39*K39
C40: - Bệ móng mố M1 chân dê (chiều cao bệ h=2.0m) | D40: m3 | E40: 1 | F40: 12 | G40: 5.5 | H40: 2 | I40: 1.1287 | J40: =E40*F40*G40*H40*I40
C41: - Bệ móng mố M2 chữ U (chiều cao bệ h=2.0m) | D41: m3 | E41: 1 | F41: 13.5 | G41: 5.5 | H41: 2 | I41: 1.0033 | J41: =E41*F41*G41*H41*I41
...

Sheet KHOI_LUONG_DAO_DAP
B2: DỰ ÁN: CAO TỐC TUYÊN QUANG - HÀ GIANG (GIAI ĐOẠN 1) - ĐOẠN QUA TỈNH HÀ GIANG
B3: BẢNG TÍNH KHỐI LƯỢNG ĐÀO ĐẮP TRẮC NGANG V = ((F1+F2)/2)*L - ĐƯỜNG CÔNG VỤ VÀ MÓNG MỐ TRỤ
B4: Trích xuất từ Bản vẽ bình đồ, trắc dọc & trắc ngang thi công (Trang 138-150 Hồ sơ TKBVTC)
A5: STT | B5: Lý trình / Vị trí cọc | C5: Khoảng cách L (m) | D5: Diện tích Đào F1 (m2) | E5: Diện tích Đào F2 (m2) | F5: Thể tích Đào V_dao (m3) | G5: Diện tích Đắp F1 (m2) | H5: Diện tích Đắp F2 (m2) | I5: Thể tích Đắp V_dap (m3) | J5: Ghi chú
A6: I. ĐƯỜNG CÔNG VỤ NHÁNH 6 (TIẾP CẬN CẦU KM19+529.080)
A7: 1 | B7: Km 0+00.00 đến Km 0+10.00 | C7: 10 | D7: 51.47 | E7: 33.55 | F7: =((D7+E7)/2)*C7 | G7: 0 | H7: 0 | I7: =((G7+H7)/2)*C7 | J7: Chuẩn hình học
A8: 2 | B8: Km 0+10.00 đến cọc TD1 (Km 0+18.12) | C8: 8.12 | D8: 33.55 | E8: 10.5 | F8: =((D8+E8)/2)*C8 | G8: 0 | H8: 0 | I8: =((G8+H8)/2)*C8 | J8: Chuẩn hình học
A9: 3 | B9: Cọc TD1 đến cọc 2 (Km 0+20.00) | C9: 1.88 | D9: 10.5 | E9: 9.18 | F9: =((D9+E9)/2)*C9 | G9: 0 | H9: 0 | I9: =((G9+H9)/2)*C9 | J9: Chuẩn hình học
A10: 4 | B10: Cọc 2 đến cọc P1 (Km 0+21.65) | C10: 1.65 | D10: 9.18 | E10: 9.02 | F10: =((D10+E10)/2)*C10 | G10: 0 | H10: 0.22 | I10: =((G10+H10)/2)*C10 | J10: Chuẩn hình học
A11: 5 | B11: Cọc P1 đến cọc TC1 (Km 0+25.17) | C11: 3.52 | D11: 9.02 | E11: 11.58 | F11: =((D11+E11)/2)*C11 | G11: 0.22 | H11: 3.2 | I11: =((G11+H11)/2)*C11 | J11: Chuẩn hình học
A12: 6 | B12: Cọc TC1 đến cọc 3 (Km 0+30.00) | C12: 4.83 | D12: 11.58 | E12: 20.34 | F12: =((D12+E12)/2)*C12 | G12: 3.2 | H12: 0 | I12: =((G12+H12)/2)*C12 | J12: Chuẩn hình học
A13: 7 | B13: Cọc 3 đến cọc 4 (Km 0+40.00) | C13: 10 | D13: 20.34 | E13: 51.82 | F13: =((D13+E13)/2)*C13 | G13: 0 | H13: 0 | I13: =((G13+H13)/2)*C13 | J13: Chuẩn hình học
A14: 8 | B14: Km 0+40.00 đến Km 0+80.00 (Nhánh tiếp cận trụ T1) | C14: 40 | D14: 51.82 | E14: 28.4 | F14: =((D14+E14)/2)*C14 | G14: 0 | H14: 0 | I14: =((G14+H14)/2)*C14 | J14: Chuẩn hình học
A15: 9 | B15: Km 0+80.00 đến Km 0+120.00 (Nhánh tiếp cận trụ T2) | C15: 40 | D15: 28.4 | E15: 16.5 | F15: =((D15+E15)/2)*C15 | G15: 0 | H15: 0.5 | I15: =((G15+H15)/2)*C15 | J15: Chuẩn hình học
A16: II. HỐ MÓNG BỆ MỐ M1, M2 VÀ BỆ TRỤ T1, T2
A17: 10 | B17: Đào đất đá hố móng bệ mố M1 chân dê (Km19+463.88) | C17: 12 | D17: 36.5 | E17: 36.5 | F17: =((D17+E17)/2)*C17 | G17: 0 | H17: 0 | I17: =((G17+H17)/2)*C17 | J17: Chuẩn hình học
A18: 11 | B18: Đào đất đá hố móng bệ mố M2 chữ U (Km19+594.28) | C18: 14 | D18: 42 | E18: 42 | F18: =((D18+E18)/2)*C18 | G18: 0 | H18: 0 | I18: =((G18+H18)/2)*C18 | J18: Chuẩn hình học
A19: 12 | B19: Đào đất đá hố móng bệ trụ T1 (Km19+502.98) | C19: 15 | D19: 55 | E19: 55 | F19: =((D19+E19)/2)*C19 | G19: 0 | H19: 0 | I19: =((G19+H19)/2)*C19 | J19: Chuẩn hình học
A20: 13 | B20: Đào đất đá hố móng bệ trụ T2 (Km19+542.98) | C20: 15 | D20: 52 | E20: 52 | F20: =((D20+E20)/2)*C20 | G20: 0 | H20: 0 | I20: =((G20+H20)/2)*C20 | J20: Chuẩn hình học
A21: TỔNG CỘNG KHỐI LƯỢNG ĐÀO ĐẮP (M3) | F21: =F7+F8+F9+F10+F11+F12+F13+F14+F15+F17+F18+F19+F20 | I21: =I7+I8+I9+I10+I11+I12+I13+I14+I15+I17+I18+I19+I20

Sheet TIEN_DO_THI_CONG_WBS
B2: DỰ ÁN: CAO TỐC TUYÊN QUANG - HÀ GIANG (GIAI ĐOẠN 1) - ĐOẠN QUA TỈNH HÀ GIANG
B3: BẢNG KẾ HOẠCH TIẾN ĐỘ WBS, ĐIỀU PHỐI NHÂN CÔNG & BIỂU ĐỒ GANTT CPM - CẦU KM19+529.080
B4: Định mức ngày công TT 12/2021/TT-BXD, Luật Xây dựng số 135/2025/QH15 & NĐ 207/2026/NĐ-CP (Cột đỏ: Đường găng CPM)
A5: Mã WBS | B5: Danh mục công tác thi công | C5: Khối lượng | D5: ĐVT | E5: Định mức (công/ĐVT) | F5: Tổng công (công) | G5: Tổ đội (người) | H5: Thời gian Duration (ngày) | I5: Ngày bắt đầu Start | J5: Ngày hoàn thành Finish | K5: Quan hệ logic Predecessors | L5: Đường găng CPM | M5: Tháng 10/2026 | Q5: Tháng 11/2026 | U5: Tháng 12/2026 | Y5: Tháng 01/2027 | AC5: Tháng 02/2027 | AG5: Tháng 03/2027
M6: T1 | N6: T2 | O6: T3 | P6: T4 | Q6: T1 | R6: T2 | S6: T3 | T6: T4 | U6: T1 | V6: T2 | W6: T3 | X6: T4 | Y6: T1 | Z6: T2 | AA6: T3 | AB6: T4 | AC6: T1 | AD6: T2 | AE6: T3 | AF6: T4 | AG6: T1 | AH6: T2 | AI6: T3 | AJ6: T4
A7: 1.0
A8: 1.1 | B8: Bàn giao tim mốc VN2000, cao độ quốc gia Hòn Dấu & tim mốc cầu | C8: 1 | D8: Điểm | E8: 12 | F8: =C8*E8 | G8: 6 | H8: =ROUNDUP(F8/G8, 0) | I8: 2026-10-01 | J8: 2026-10-02 | K8: - | L8: YES
A9: 1.2 | B9: Rà phá bom mìn, dọn dẹp mặt bằng thi công & dựng lán trại | C9: 12500 | D9: m2 | E9: 0.02 | F9: =C9*E9 | G9: 10 | H9: =ROUNDUP(F9/G9, 0) | I9: 2026-10-03 | J9: 2026-10-08 | K9: 1.1FS | L9: YES
A10: 1.3 | B10: Thi công đường công vụ nhánh 6 & nhánh 6A tiếp cận mố trụ | C10: =KHOI_LUONG_DAO_DAP!F19 | D10: m3 | E10: 0.08 | F10: =C10*E10 | G10: 12 | H10: =ROUNDUP(F10/G10, 0) | I10: 2026-10-09 | J10: 2026-10-18 | K10: 1.2FS | L10: YES
A11: 1.4 | B11: Xây dựng bãi đúc dầm Super-T, bệ đúc cáp căng & trạm trộn BTXM | C11: 1 | D11: Hệ | E11: 180 | F11: =C11*E11 | G11: 15 | H11: =ROUNDUP(F11/G11, 0) | I11: 2026-10-12 | J11: 2026-10-24 | K11: 1.3SS+3d | L11: NO
A12: 2.0
A13: 2.1 | B13: Khoan thăm dò hang Karst sâu 5m vào đá liền khối dưới mũi cọc | C13: 26 | D13: Lỗ | E13: 12 | F13: =C13*E13 | G13: 8 | H13: =ROUNDUP(F13/G13, 0) | I13: 2026-10-25 | J13: 2026-11-05 | K13: 1.3FS | L13: YES
A14: 2.2 | B14: Khoan cọc nhồi D1200mm M1 (3 cọc L=20m) & đổ bê tông C30 | C14: =QS_DIEN_GIAI_CHI_TIET!J8 | D14: m | E14: 0.75 | F14: =C14*E14 | G14: 10 | H14: =ROUNDUP(F14/G14, 0) | I14: 2026-11-06 | J14: 2026-11-12 | K14: 2.1FS | L14: YES
A15: 2.3 | B15: Khoan cọc nhồi D1200mm Trụ T1 (8 cọc L=40m) & đổ bê tông C30 | C15: =QS_DIEN_GIAI_CHI_TIET!J9 | D15: m | E15: 0.75 | F15: =C15*E15 | G15: 16 | H15: =ROUNDUP(F15/G15, 0) | I15: 2026-11-10 | J15: 2026-11-28 | K15: 2.2SS+4d | L15: YES
A16: 2.4 | B16: Khoan cọc nhồi D1200mm Trụ T2 (8 cọc L=30m) & đổ bê tông C30 | C16: =QS_DIEN_GIAI_CHI_TIET!J10 | D16: m | E16: 0.75 | F16: =C16*E16 | G16: 14 | H16: =ROUNDUP(F16/G16, 0) | I16: 2026-11-18 | J16: 2026-12-04 | K16: 2.3SS+8d | L16: YES
A17: 2.5 | B17: Khoan cọc nhồi D1200mm M2 (7 cọc L=36m) & đổ bê tông C30 | C17: =QS_DIEN_GIAI_CHI_TIET!J11 | D17: m | E17: 0.75 | F17: =C17*E17 | G17: 14 | H17: =ROUNDUP(F17/G17, 0) | I17: 2026-11-25 | J17: 2026-12-12 | K17: 2.4SS+7d | L17: NO
A18: 2.6 | B18: Thí nghiệm siêu âm 156 mặt cắt, khoan kiểm tra mũi cọc & thử tải PDA | C18: 1 | D18: Gói | E18: 48 | F18: =C18*E18 | G18: 6 | H18: =ROUNDUP(F18/G18, 0) | I18: 2026-12-13 | J18: 2026-12-20 | K18: 2.4FS,2.5FS | L18: YES
A19: 3.0
A20: 3.1 | B20: Đào hố móng, đập đầu 26 cọc nhồi & đổ bê tông lót đáy bệ mác C10 | C20: 26 | D20: Cọc | E20: 2.5 | F20: =C20*E20 | G20: 10 | H20: =ROUNDUP(F20/G20, 0) | I20: 2026-12-21 | J20: 2026-12-27 | K20: 2.6FS | L20: YES
A21: 3.2 | B21: Gia công lắp dựng cốt thép, ván khuôn & đổ bê tông bệ móng mố M1, M2 | C21: =QS_DIEN_GIAI_CHI_TIET!J38 | D21: m3 | E21: 0.45 | F21: =C21*E21 | G21: 16 | H21: =ROUNDUP(F21/G21, 0) | I21: 2026-12-28 | J21: 2027-01-04 | K21: 3.1FS | L21: YES
A22: 3.3 | B22: Gia công lắp dựng cốt thép, ván khuôn & đổ bê tông bệ trụ T1, T2 | C22: =QS_DIEN_GIAI_CHI_TIET!J39 | D22: m3 | E22: 0.42 | F22: =C22*E22 | G22: 18 | H22: =ROUNDUP(F22/G22, 0) | I22: 2026-12-30 | J22: 2027-01-08 | K22: 3.1FS+2d | L22: YES
A23: 3.4 | B23: Thi công thân đặc trụ T1, T2 (H=14.5m & 11.4m) bê tông C30 | C23: =QS_DIEN_GIAI_CHI_TIET!J47 | D23: m3 | E23: 0.55 | F23: =C23*E23 | G23: 18 | H23: =ROUNDUP(F23/G23, 0) | I23: 2027-01-09 | J23: 2027-01-22 | K23: 3.3FS | L23: YES
A24: 3.5 | B24: Thi công thân mố chân dê M1 và mố chữ U M2 bê tông C30 | C24: =QS_DIEN_GIAI_CHI_TIET!J42 | D24: m3 | E24: 0.52 | F24: =C24*E24 | G24: 14 | H24: =ROUNDUP(F24/G24, 0) | I24: 2027-01-06 | J24: 2027-01-18 | K24: 3.2FS | L24: NO
A25: 3.6 | B25: Thi công xà mũ trụ T1, T2, đá kê gối & khối chống xô | C25: =QS_DIEN_GIAI_CHI_TIET!J51 | D25: m3 | E25: 0.65 | F25: =C25*E25 | G25: 14 | H25: =ROUNDUP(F25/G25, 0) | I25: 2027-01-23 | J25: 2027-01-30 | K25: 3.4FS | L25: YES
A26: 4.0
A27: 4.1 | B27: Gia công cốt thép, luồn cáp DUL 15.2mm 15 phiến dầm tại bãi đúc | C27: 15 | D27: Phiến | E27: 28 | F27: =C27*E27 | G27: 16 | H27: =ROUNDUP(F27/G27, 0) | I27: 2026-11-28 | J27: 2026-12-25 | K27: 1.4FS | L27: NO
A28: 4.2 | B28: Đổ bê tông C45 15 phiến dầm Super-T (bảo dưỡng đạt cường độ R28) | C28: =QS_DIEN_GIAI_CHI_TIET!J57 | D28: m3 | E28: 0.65 | F28: =C28*E28 | G28: 16 | H28: =ROUNDUP(F28/G28, 0) | I28: 2026-12-26 | J28: 2027-01-15 | K28: 4.1FS | L28: NO
A29: 4.3 | B29: Căng kéo cáp DUL tao xoắn 15.2mm & bơm vữa ống gen dầm | C29: 15 | D29: Phiến | E29: 4 | F29: =C29*E29 | G29: 8 | H29: =ROUNDUP(F29/G29, 0) | I29: 2027-01-16 | J29: 2027-01-25 | K29: 4.2FS | L29: YES
A30: 4.4 | B30: Lắp đặt 30 gối chậu cao su đơn/song hướng mố trụ | C30: 30 | D30: Cái | E30: 1.2 | F30: =C30*E30 | G30: 6 | H30: =ROUNDUP(F30/G30, 0) | I30: 2027-01-31 | J30: 2027-02-04 | K30: 3.6FS | L30: YES
A31: 4.5 | B31: Lắp đặt đường ray P43, vận chuyển & lao lắp 15 phiến dầm Super-T | C31: 15 | D31: Phiến | E31: 5 | F31: =C31*E31 | G31: 12 | H31: =ROUNDUP(F31/G31, 0) | I31: 2027-02-05 | J31: 2027-02-14 | K31: 4.3FS,4.4FS | L31: YES
A32: 5.0
A33: 5.1 | B33: Đổ bê tông dầm ngang mố, dầm ngang trụ và bản liên tục nhiệt C35 | C33: =QS_DIEN_GIAI_CHI_TIET!J68 | D33: m3 | E33: 0.85 | F33: =C33*E33 | G33: 12 | H33: =ROUNDUP(F33/G33, 0) | I33: 2027-02-15 | J33: 2027-02-19 | K33: 4.5FS | L33: YES
A34: 5.2 | B34: Lắp đặt 510 tấm ván khuôn đúc sẵn & lắp cốt thép bản mặt cầu C35 | C34: =QS_DIEN_GIAI_CHI_TIET!J72 | D34: Tấm | E34: 0.08 | F34: =C34*E34 | G34: 14 | H34: =ROUNDUP(F34/G34, 0) | I34: 2027-02-20 | J34: 2027-02-24 | K34: 5.1FS | L34: YES
A35: 5.3 | B35: Đổ bê tông bản mặt cầu tại chỗ C35 (dày tối thiểu 180mm) | C35: =QS_DIEN_GIAI_CHI_TIET!J74 | D35: m3 | E35: 0.45 | F35: =C35*E35 | G35: 18 | H35: =ROUNDUP(F35/G35, 0) | I35: 2027-02-25 | J35: 2027-03-02 | K35: 5.2FS | L35: YES
A36: 5.4 | B36: Đổ bê tông bản quá độ C25 sau 2 mố & đắp đất chọn lọc K98 | C36: 2 | D36: Bản | E36: 24 | F36: =C36*E36 | G36: 10 | H36: =ROUNDUP(F36/G36, 0) | I36: 2027-03-01 | J36: 2027-03-06 | K36: 5.1FS | L36: NO
A37: 5.5 | B37: Lắp đặt khe co giãn răng lược thép D=100mm & ống thoát nước PVC D150 | C37: 2 | D37: Bộ | E37: 18 | F37: =C37*E37 | G37: 6 | H37: =ROUNDUP(F37/G37, 0) | I37: 2027-03-07 | J37: 2027-03-12 | K37: 5.3FS | L37: YES
A38: 5.6 | B38: Đổ bê tông gờ lan can C25 & lắp dựng tay vịn thép mạ kẽm | C38: 260.8 | D38: m | E38: 0.35 | F38: =C38*E38 | G38: 10 | H38: =ROUNDUP(F38/G38, 0) | I38: 2027-03-08 | J38: 2027-03-15 | K38: 5.3FS | L38: NO
A39: 5.7 | B39: Phun lớp màng chống thấm & thảm bê tông nhựa C16 mặt cầu dày 7cm | C39: =QS_DIEN_GIAI_CHI_TIET!J87 | D39: m2 | E39: 0.04 | F39: =C39*E39 | G39: 12 | H39: =ROUNDUP(F39/G39, 0) | I39: 2027-03-16 | J39: 2027-03-19 | K39: 5.5FS | L39: YES
A40: 6.0
A41: 6.1 | B41: Thử tải tĩnh/động cầu bằng đoàn xe tải nặng, đo dao động & võng dầm | C41: 1 | D41: Gói | E41: 32 | F41: =C41*E41 | G41: 8 | H41: =ROUNDUP(F41/G41, 0) | I41: 2027-03-20 | J41: 2027-03-24 | K41: 5.7FS | L41: YES
...
